Workbook

Sheet Invoice Template
G2: SALES INVOICE
C5: =IF('Business Details'!B2>0,'Business Details'!B2," ")
J6: =IF('Business Details'!B12>0,'Business Details'!B12," ")
C8: =IF('Business Details'!B13>0,'Business Details'!B13," ") -> Thank you for your custom | J8: =IF(O8=" "," ",'Business Details'!A11) -> VAT Registration Number | O8: =IF('Business Details'!B11>0,'Business Details'!B11," ")
C10: Invoice to : | J10: =IF('Business Details'!B3>0,'Business Details'!B3," ") -> <enter business name>
C12: =IF(N27=" "," ",IF(N27>0,LOOKUP(N29,'Customer Details'!A:A,'Customer Details'!C:C))) | J12: =IF('Business Details'!B4>0,'Business Details'!B4," ")
C14: =IF(N27=" "," ",IF(N27>0,LOOKUP(N29,'Customer Details'!A:A,'Customer Details'!D:D))) | J14: =IF('Business Details'!B5>0,'Business Details'!B5," ")
C16: =IF(N27=" "," ",IF(N27>0,LOOKUP(N29,'Customer Details'!A:A,'Customer Details'!E:E))) | J16: =IF('Business Details'!B6>0,'Business Details'!B6," ")
C18: =IF(N27=" "," ",IF(N27>0,LOOKUP(N29,'Customer Details'!A:A,'Customer Details'!F:F))) | J18: =IF('Business Details'!B7>0,'Business Details'!B7," ")
C20: =IF(N27=" "," ",IF(N27>0,LOOKUP(N29,'Customer Details'!A:A,'Customer Details'!G:G))) | J20: ='Business Details'!A8 -> Telephone | N20: =IF('Business Details'!B8>0,'Business Details'!B8," ")
J22: ='Business Details'!A9 -> Fax number | N22: =IF('Business Details'!B9>0,'Business Details'!B9," ")
J24: ='Business Details'!A10 -> Email | L24: =IF('Business Details'!B10>0,'Business Details'!B10," ")
C25: Delivery Address :
C27: =IF(N27=" "," ",IF(N27>0,LOOKUP(N29,'Customer Details'!A:A,'Customer Details'!I:I))) | J27: Invoice Number | N27: =IF(SUM('Invoice Database'!A:A)=0," ",LOOKUP(1,'Invoice Database'!A:A,'Invoice Database'!B:B))
C29: =IF(N27=" "," ",IF(N27>0,LOOKUP(N29,'Customer Details'!A:A,'Customer Details'!J:J))) | J29: Account Number | N29: =IF(N27=" "," ",IF(N27>0,LOOKUP(N27,'Invoice Database'!B:B,'Invoice Database'!D:D)))
C31: =IF(N27=" "," ",IF(N27>0,LOOKUP(N29,'Customer Details'!A:A,'Customer Details'!K:K))) | J31: Terms | N31: =IF(N27=" "," ",IF(N27>0,LOOKUP(N29,'Customer Details'!A:A,'Customer Details'!B:B)))
C33: =IF(N27=" "," ",IF(N27>0,LOOKUP(N29,'Customer Details'!A:A,'Customer Details'!L:L))) | J33: Tax Point | N33: =IF(N27=" "," ",IF(N27>0,LOOKUP(N27,'Invoice Database'!B:B,'Invoice Database'!C:C)))
C35: =IF(N27=" "," ",IF(N27>0,LOOKUP(N29,'Customer Details'!A:A,'Customer Details'!M:M)))
C37: Product code | E37: Description | J37: Unit Cost | L37: Quantity | N37: Vat Rate | P37: Net Amount
C38: =IF(N27=" "," ",IF(LOOKUP(1,'Invoice Database'!A:A,'Invoice Database'!F:F)>0,LOOKUP(1,'Invoice Database'!A:A,'Invoice Database'!F:F)," ")) | E38: =IF(C38=" "," ",LOOKUP(C38,'Product Details'!A:A,'Product Details'!B:B)) | J38: =IF(C38=" "," ",LOOKUP(C38,'Product Details'!A:A,'Product Details'!C:C)) | L38: =IF(C38=" "," ",LOOKUP(1,'Invoice Database'!A:A,'Invoice Database'!G:G)) | N38: =IF(O8=" "," ",IF(C38=" "," ",LOOKUP(C38,'Product Details'!A:A,'Product Details'!D:D))) | P38: =IF(L38=" "," ",J38*L38) | V38: =IF(N38=" ",0,P38*N38/100) -> 0
C39: =IF(N27=" "," ",IF(LOOKUP(1,'Invoice Database'!A:A,'Invoice Database'!H:H)>0,LOOKUP(1,'Invoice Database'!A:A,'Invoice Database'!H:H)," ")) | E39: =IF(C39=" "," ",LOOKUP(C39,'Product Details'!A:A,'Product Details'!B:B)) | J39: =IF(C39=" "," ",LOOKUP(C39,'Product Details'!A:A,'Product Details'!C:C)) | L39: =IF(C39=" "," ",LOOKUP(1,'Invoice Database'!A:A,'Invoice Database'!I:I)) | N39: =IF(O8=" "," ",IF(C39=" "," ",LOOKUP(C39,'Product Details'!A:A,'Product Details'!D:D))) | P39: =IF(L39=" "," ",J39*L39) | V39: =IF(N39=" ",0,P39*N39/100) -> 0
C40: =IF(N27=" "," ",IF(LOOKUP(1,'Invoice Database'!A:A,'Invoice Database'!J:J)>0,LOOKUP(1,'Invoice Database'!A:A,'Invoice Database'!J:J)," ")) | E40: =IF(C40=" "," ",LOOKUP(C40,'Product Details'!A:A,'Product Details'!B:B)) | J40: =IF(C40=" "," ",LOOKUP(C40,'Product Details'!A:A,'Product Details'!C:C)) | L40: =IF(C40=" "," ",LOOKUP(1,'Invoice Database'!A:A,'Invoice Database'!K:K)) | N40: =IF(O8=" "," ",IF(C40=" "," ",LOOKUP(C40,'Product Details'!A:A,'Product Details'!D:D))) | P40: =IF(L40=" "," ",J40*L40) | V40: =IF(N40=" ",0,P40*N40/100) -> 0
C41: =IF(N27=" "," ",IF(LOOKUP(1,'Invoice Database'!A:A,'Invoice Database'!L:L)>0,LOOKUP(1,'Invoice Database'!A:A,'Invoice Database'!L:L)," ")) | E41: =IF(C41=" "," ",LOOKUP(C41,'Product Details'!A:A,'Product Details'!B:B)) | J41: =IF(C41=" "," ",LOOKUP(C41,'Product Details'!A:A,'Product Details'!C:C)) | L41: =IF(C41=" "," ",LOOKUP(1,'Invoice Database'!A:A,'Invoice Database'!M:M)) | N41: =IF(O8=" "," ",IF(C41=" "," ",LOOKUP(C41,'Product Details'!A:A,'Product Details'!D:D))) | P41: =IF(L41=" "," ",J41*L41) | V41: =IF(N41=" ",0,P41*N41/100) -> 0
C42: =IF(N27=" "," ",IF(LOOKUP(1,'Invoice Database'!A:A,'Invoice Database'!N:N)>0,LOOKUP(1,'Invoice Database'!A:A,'Invoice Database'!N:N)," ")) | E42: =IF(C42=" "," ",LOOKUP(C42,'Product Details'!A:A,'Product Details'!B:B)) | J42: =IF(C42=" "," ",LOOKUP(C42,'Product Details'!A:A,'Product Details'!C:C)) | L42: =IF(C42=" "," ",LOOKUP(1,'Invoice Database'!A:A,'Invoice Database'!O:O)) | N42: =IF(O8=" "," ",IF(C42=" "," ",LOOKUP(C42,'Product Details'!A:A,'Product Details'!D:D))) | P42: =IF(L42=" "," ",J42*L42) | V42: =IF(N42=" ",0,P42*N42/100) -> 0
C43: =IF(N27=" "," ",IF(LOOKUP(1,'Invoice Database'!A:A,'Invoice Database'!P:P)>0,LOOKUP(1,'Invoice Database'!A:A,'Invoice Database'!P:P)," ")) | E43: =IF(C43=" "," ",LOOKUP(C43,'Product Details'!A:A,'Product Details'!B:B)) | J43: =IF(C43=" "," ",LOOKUP(C43,'Product Details'!A:A,'Product Details'!C:C)) | L43: =IF(C43=" "," ",LOOKUP(1,'Invoice Database'!A:A,'Invoice Database'!Q:Q)) | N43: =IF(O8=" "," ",IF(C43=" "," ",LOOKUP(C43,'Product Details'!A:A,'Product Details'!D:D))) | P43: =IF(L43=" "," ",J43*L43) | V43: =IF(N43=" ",0,P43*N43/100) -> 0
C44: =IF(N27=" "," ",IF(LOOKUP(1,'Invoice Database'!A:A,'Invoice Database'!R:R)>0,LOOKUP(1,'Invoice Database'!A:A,'Invoice Database'!R:R)," ")) | E44: =IF(C44=" "," ",LOOKUP(C44,'Product Details'!A:A,'Product Details'!B:B)) | J44: =IF(C44=" "," ",LOOKUP(C44,'Product Details'!A:A,'Product Details'!C:C)) | L44: =IF(C44=" "," ",LOOKUP(1,'Invoice Database'!A:A,'Invoice Database'!S:S)) | N44: =IF(O8=" "," ",IF(C44=" "," ",LOOKUP(C44,'Product Details'!A:A,'Product Details'!D:D))) | P44: =IF(L44=" "," ",J44*L44) | V44: =IF(N44=" ",0,P44*N44/100) -> 0
C45: =IF(N27=" "," ",IF(LOOKUP(1,'Invoice Database'!A:A,'Invoice Database'!T:T)>0,LOOKUP(1,'Invoice Database'!A:A,'Invoice Database'!T:T)," ")) | E45: =IF(C45=" "," ",LOOKUP(C45,'Product Details'!A:A,'Product Details'!B:B)) | J45: =IF(C45=" "," ",LOOKUP(C45,'Product Details'!A:A,'Product Details'!C:C)) | L45: =IF(C45=" "," ",LOOKUP(1,'Invoice Database'!A:A,'Invoice Database'!U:U)) | N45: =IF(O8=" "," ",IF(C45=" "," ",LOOKUP(C45,'Product Details'!A:A,'Product Details'!D:D))) | P45: =IF(L45=" "," ",J45*L45) | V45: =IF(N45=" ",0,P45*N45/100) -> 0
C46: =IF(N27=" "," ",IF(LOOKUP(1,'Invoice Database'!A:A,'Invoice Database'!V:V)>0,LOOKUP(1,'Invoice Database'!A:A,'Invoice Database'!V:V)," ")) | E46: =IF(C46=" "," ",LOOKUP(C46,'Product Details'!A:A,'Product Details'!B:B)) | J46: =IF(C46=" "," ",LOOKUP(C46,'Product Details'!A:A,'Product Details'!C:C)) | L46: =IF(C46=" "," ",LOOKUP(1,'Invoice Database'!A:A,'Invoice Database'!W:W)) | N46: =IF(O8=" "," ",IF(C46=" "," ",LOOKUP(C46,'Product Details'!A:A,'Product Details'!D:D))) | P46: =IF(L46=" "," ",J46*L46) | V46: =IF(N46=" ",0,P46*N46/100) -> 0
C47: =IF(N27=" "," ",IF(LOOKUP(1,'Invoice Database'!A:A,'Invoice Database'!X:X)>0,LOOKUP(1,'Invoice Database'!A:A,'Invoice Database'!X:X)," ")) | E47: =IF(C47=" "," ",LOOKUP(C47,'Product Details'!A:A,'Product Details'!B:B)) | J47: =IF(C47=" "," ",LOOKUP(C47,'Product Details'!A:A,'Product Details'!C:C)) | L47: =IF(C47=" "," ",LOOKUP(1,'Invoice Database'!A:A,'Invoice Database'!Y:Y)) | N47: =IF(O8=" "," ",IF(C47=" "," ",LOOKUP(C47,'Product Details'!A:A,'Product Details'!D:D))) | P47: =IF(L47=" "," ",J47*L47) | V47: =IF(N47=" ",0,P47*N47/100) -> 0
C48: =IF(N27=" "," ",IF(N27=" "," ",IF(LOOKUP(1,'Invoice Database'!A:A,'Invoice Database'!Z:Z)>0,LOOKUP(1,'Invoice Database'!A:A,'Invoice Database'!Z:Z)," "))) | E48: =IF(C48=" "," ",LOOKUP(C48,'Product Details'!A:A,'Product Details'!B:B)) | J48: =IF(C48=" "," ",LOOKUP(C48,'Product Details'!A:A,'Product Details'!C:C)) | L48: =IF(C48=" "," ",LOOKUP(1,'Invoice Database'!A:A,'Invoice Database'!AA:AA)) | N48: =IF(O8=" "," ",IF(C48=" "," ",LOOKUP(C48,'Product Details'!A:A,'Product Details'!D:D))) | P48: =IF(L48=" "," ",J48*L48) | V48: =IF(N48=" ",0,P48*N48/100) -> 0
C49: =IF(N27=" "," ",IF(LOOKUP(1,'Invoice Database'!A:A,'Invoice Database'!AB:AB)>0,LOOKUP(1,'Invoice Database'!A:A,'Invoice Database'!AB:AB)," ")) | E49: =IF(C49=" "," ",LOOKUP(C49,'Product Details'!A:A,'Product Details'!B:B)) | J49: =IF(C49=" "," ",LOOKUP(C49,'Product Details'!A:A,'Product Details'!C:C)) | L49: =IF(C49=" "," ",LOOKUP(1,'Invoice Database'!A:A,'Invoice Database'!AC:AC)) | N49: =IF(O8=" "," ",IF(C49=" "," ",LOOKUP(C49,'Product Details'!A:A,'Product Details'!D:D))) | P49: =IF(L49=" "," ",J49*L49) | V49: =IF(N49=" ",0,P49*N49/100) -> 0
C50: =IF(N27=" "," ",IF(LOOKUP(1,'Invoice Database'!A:A,'Invoice Database'!AD:AD)>0,LOOKUP(1,'Invoice Database'!A:A,'Invoice Database'!AD:AD)," ")) | E50: =IF(C50=" "," ",LOOKUP(C50,'Product Details'!A:A,'Product Details'!B:B)) | J50: =IF(C50=" "," ",LOOKUP(C50,'Product Details'!A:A,'Product Details'!C:C)) | L50: =IF(C50=" "," ",LOOKUP(1,'Invoice Database'!A:A,'Invoice Database'!AE:AE)) | N50: =IF(O8=" "," ",IF(C50=" "," ",LOOKUP(C50,'Product Details'!A:A,'Product Details'!D:D))) | P50: =IF(L50=" "," ",J50*L50) | V50: =IF(N50=" ",0,P50*N50/100) -> 0
C51: =IF(N27=" "," ",IF(LOOKUP(1,'Invoice Database'!A:A,'Invoice Database'!AF:AF)>0,LOOKUP(1,'Invoice Database'!A:A,'Invoice Database'!AF:AF)," ")) | E51: =IF(C51=" "," ",LOOKUP(C51,'Product Details'!A:A,'Product Details'!B:B)) | J51: =IF(C51=" "," ",LOOKUP(C51,'Product Details'!A:A,'Product Details'!C:C)) | L51: =IF(C51=" "," ",LOOKUP(1,'Invoice Database'!A:A,'Invoice Database'!AG:AG)) | N51: =IF(O8=" "," ",IF(C51=" "," ",LOOKUP(C51,'Product Details'!A:A,'Product Details'!D:D))) | P51: =IF(L51=" "," ",J51*L51) | V51: =IF(N51=" ",0,P51*N51/100) -> 0
C52: =IF(N27=" "," ",IF(LOOKUP(1,'Invoice Database'!A:A,'Invoice Database'!AH:AH)>0,LOOKUP(1,'Invoice Database'!A:A,'Invoice Database'!AH:AH)," ")) | E52: =IF(C52=" "," ",LOOKUP(C52,'Product Details'!A:A,'Product Details'!B:B)) | J52: =IF(C52=" "," ",LOOKUP(C52,'Product Details'!A:A,'Product Details'!C:C)) | L52: =IF(C52=" "," ",LOOKUP(1,'Invoice Database'!A:A,'Invoice Database'!AI:AI)) | N52: =IF(O8=" "," ",IF(C52=" "," ",LOOKUP(C52,'Product Details'!A:A,'Product Details'!D:D))) | P52: =IF(L52=" "," ",J52*L52) | V52: =IF(N52=" ",0,P52*N52/100) -> 0
C53: =IF(N27=" "," ",IF(LOOKUP(1,'Invoice Database'!A:A,'Invoice Database'!AJ:AJ)>0,LOOKUP(1,'Invoice Database'!A:A,'Invoice Database'!AJ:AJ)," ")) | E53: =IF(C53=" "," ",LOOKUP(C53,'Product Details'!A:A,'Product Details'!B:B)) | J53: =IF(C53=" "," ",LOOKUP(C53,'Product Details'!A:A,'Product Details'!C:C)) | L53: =IF(C53=" "," ",LOOKUP(1,'Invoice Database'!A:A,'Invoice Database'!AK:AK)) | N53: =IF(O8=" "," ",IF(C53=" "," ",LOOKUP(C53,'Product Details'!A:A,'Product Details'!D:D))) | P53: =IF(L53=" "," ",J53*L53) | V53: =IF(N53=" ",0,P53*N53/100) -> 0
C54: =IF(N27=" "," ",IF(LOOKUP(1,'Invoice Database'!A:A,'Invoice Database'!AL:AL)>0,LOOKUP(1,'Invoice Database'!A:A,'Invoice Database'!AL:AL)," ")) | E54: =IF(C54=" "," ",LOOKUP(C54,'Product Details'!A:A,'Product Details'!B:B)) | J54: =IF(C54=" "," ",LOOKUP(C54,'Product Details'!A:A,'Product Details'!C:C)) | L54: =IF(C54=" "," ",LOOKUP(1,'Invoice Database'!A:A,'Invoice Database'!AM:AM)) | N54: =IF(O8=" "," ",IF(C54=" "," ",LOOKUP(C54,'Product Details'!A:A,'Product Details'!D:D))) | P54: =IF(L54=" "," ",J54*L54) | V54: =IF(N54=" ",0,P54*N54/100) -> 0
C55: =IF(N27=" "," ",IF(LOOKUP(1,'Invoice Database'!A:A,'Invoice Database'!AN:AN)>0,LOOKUP(1,'Invoice Database'!A:A,'Invoice Database'!AN:AN)," ")) | E55: =IF(C55=" "," ",LOOKUP(C55,'Product Details'!A:A,'Product Details'!B:B)) | J55: =IF(C55=" "," ",LOOKUP(C55,'Product Details'!A:A,'Product Details'!C:C)) | L55: =IF(C55=" "," ",LOOKUP(1,'Invoice Database'!A:A,'Invoice Database'!AO:AO)) | N55: =IF(O8=" "," ",IF(C55=" "," ",LOOKUP(C55,'Product Details'!A:A,'Product Details'!D:D))) | P55: =IF(L55=" "," ",J55*L55) | V55: =IF(N55=" ",0,P55*N55/100) -> 0
C56: =IF(N27=" "," ",IF(LOOKUP(1,'Invoice Database'!A:A,'Invoice Database'!AP:AP)>0,LOOKUP(1,'Invoice Database'!A:A,'Invoice Database'!AP:AP)," ")) | E56: =IF(C56=" "," ",LOOKUP(C56,'Product Details'!A:A,'Product Details'!B:B)) | J56: =IF(C56=" "," ",LOOKUP(C56,'Product Details'!A:A,'Product Details'!C:C)) | L56: =IF(C56=" "," ",LOOKUP(1,'Invoice Database'!A:A,'Invoice Database'!AQ:AQ)) | N56: =IF(O8=" "," ",IF(C56=" "," ",LOOKUP(C56,'Product Details'!A:A,'Product Details'!D:D))) | P56: =IF(L56=" "," ",J56*L56) | V56: =IF(N56=" ",0,P56*N56/100) -> 0
C57: =IF(N27=" "," ",IF(LOOKUP(1,'Invoice Database'!A:A,'Invoice Database'!AR:AR)>0,LOOKUP(1,'Invoice Database'!A:A,'Invoice Database'!AR:AR)," ")) | E57: =IF(C57=" "," ",LOOKUP(C57,'Product Details'!A:A,'Product Details'!B:B)) | J57: =IF(C57=" "," ",LOOKUP(C57,'Product Details'!A:A,'Product Details'!C:C)) | L57: =IF(C57=" "," ",LOOKUP(1,'Invoice Database'!A:A,'Invoice Database'!AS:AS)) | N57: =IF(O8=" "," ",IF(C57=" "," ",LOOKUP(C57,'Product Details'!A:A,'Product Details'!D:D))) | P57: =IF(L57=" "," ",J57*L57) | V57: =IF(N57=" ",0,P57*N57/100) -> 0
L58: Total Net Amount | P58: =SUM(P38:P57) -> 0
...

Sheet Invoice Database
A1: Enter 1 to ACTIVATE INVOICE | B1: Sales Invoice Number | C1: Invoice Date | D1: Customer Account Number | E1: Carriage Charge | F1: Product Code 1 | G1: Quantity | H1: Product Code 2 | I1: Quantity | J1: Product Code 3 | K1: Quantity | L1: Product Code 4 | M1: Quantity | N1: Product Code 5 | O1: Quantity | P1: Product Code 6 | Q1: Quantity | R1: Product Code 7 | S1: Quantity | T1: Product Code 8 | U1: Quantity | V1: Product Code 9 | W1: Quantity | X1: Product Code 10 | Y1: Quantity | Z1: Product Code 11 | AA1: Quantity | AB1: Product Code 12 | AC1: Quantity | AD1: Product Code 13 | AE1: Quantity | AF1: Product Code 14 | AG1: Quantity | AH1: Product Code 15 | AI1: Quantity | AJ1: Product Code 16 | AK1: Quantity | AL1: Product Code 17 | AM1: Quantity | AN1: Product Code 18 | AO1: Quantity | AP1: Product Code 19 | AQ1: Quantity | AR1: Product Code 20 | AS1: Quantity

Sheet Customer Details
A1: Customer Account Number | B1: Credit Terms | C1: Customer Name | D1: Customer Address Line 1 | E1: Customer Address Line 2 | F1: Customer Address Line 3 | G1: Customer Post Code | I1: Delivery Name | J1: Delivery Address Line 1 | K1: Delivery Address Line 2 | L1: Delivery Address Line 3 | M1: Delivery Post Code
A2: 101 | I2: =C2 | J2: =D2 | K2: =E2 | L2: =F2 | M2: =G2
I3: =C3 | J3: =D3 | K3: =E3 | L3: =F3 | M3: =G3
I4: =C4 | J4: =D4 | K4: =E4 | L4: =F4 | M4: =G4
I10: =IF(C10>0,C10," ") | J10: =IF(D10>0,D10," ") | K10: =IF(E10>0,E10," ") | L10: =IF(F10>0,F10," ") | M10: =IF(G10>0,G10," ")
I11: =IF(C11>0,C11," ") | J11: =IF(D11>0,D11," ") | K11: =IF(E11>0,E11," ") | L11: =IF(F11>0,F11," ") | M11: =IF(G11>0,G11," ")
I12: =IF(C12>0,C12," ") | J12: =IF(D12>0,D12," ") | K12: =IF(E12>0,E12," ") | L12: =IF(F12>0,F12," ") | M12: =IF(G12>0,G12," ")
I13: =IF(C13>0,C13," ") | J13: =IF(D13>0,D13," ") | K13: =IF(E13>0,E13," ") | L13: =IF(F13>0,F13," ") | M13: =IF(G13>0,G13," ")
I14: =IF(C14>0,C14," ") | J14: =IF(D14>0,D14," ") | K14: =IF(E14>0,E14," ") | L14: =IF(F14>0,F14," ") | M14: =IF(G14>0,G14," ")
I15: =IF(C15>0,C15," ") | J15: =IF(D15>0,D15," ") | K15: =IF(E15>0,E15," ") | L15: =IF(F15>0,F15," ") | M15: =IF(G15>0,G15," ")
I16: =IF(C16>0,C16," ") | J16: =IF(D16>0,D16," ") | K16: =IF(E16>0,E16," ") | L16: =IF(F16>0,F16," ") | M16: =IF(G16>0,G16," ")
I17: =IF(C17>0,C17," ") | J17: =IF(D17>0,D17," ") | K17: =IF(E17>0,E17," ") | L17: =IF(F17>0,F17," ") | M17: =IF(G17>0,G17," ")
I18: =IF(C18>0,C18," ") | J18: =IF(D18>0,D18," ") | K18: =IF(E18>0,E18," ") | L18: =IF(F18>0,F18," ") | M18: =IF(G18>0,G18," ")
I19: =IF(C19>0,C19," ") | J19: =IF(D19>0,D19," ") | K19: =IF(E19>0,E19," ") | L19: =IF(F19>0,F19," ") | M19: =IF(G19>0,G19," ")
I20: =IF(C20>0,C20," ") | J20: =IF(D20>0,D20," ") | K20: =IF(E20>0,E20," ") | L20: =IF(F20>0,F20," ") | M20: =IF(G20>0,G20," ")
I21: =IF(C21>0,C21," ") | J21: =IF(D21>0,D21," ") | K21: =IF(E21>0,E21," ") | L21: =IF(F21>0,F21," ") | M21: =IF(G21>0,G21," ")
... I101: =IF(C101>0,C101," ") | J101: =IF(D101>0,D101," ") | K101: =IF(E101>0,E101," ") | L101: =IF(F101>0,F101," ") | M101: =IF(G101>0,G101," ")

Sheet Product Details
A1: Product Code | B1: Product Description | C1: Product Selling Price | D1: VAT Rate | F1: Purchase Cost Price | G1: Gross Profit Margin | H1: Gross Profit Margin %
A2: 1001 | D2: 20 | G2: =IF(F2>0,C2-F2," ") | H2: =IF(F2>0,(C2-F2)*100/C2," ")
D3: 20 | G3: =IF(F3>0,C3-F3," ") | H3: =IF(F3>0,(C3-F3)*100/C3," ")
D4: 20 | G4: =IF(F4>0,C4-F4," ") | H4: =IF(F4>0,(C4-F4)*100/C4," ")
D5: 20 | G5: =IF(F5>0,C5-F5," ") | H5: =IF(F5>0,(C5-F5)*100/C5," ")
D6: 20 | G6: =IF(F6>0,(C6-F6)*100/C6," ")
D7: 20 | G7: =IF(F7>0,(C7-F7)*100/C7," ")
D8: 20 | G8: =IF(F8>0,(C8-F8)*100/C8," ")
D9: 20 | G9: =IF(F9>0,(C9-F9)*100/C9," ")
D10: 20 | G10: =IF(F10>0,(C10-F10)*100/C10," ")
D11: 20 | G11: =IF(F11>0,(C11-F11)*100/C11," ")
D12: 20 | G12: =IF(F12>0,(C12-F12)*100/C12," ")
D13: 20 | G13: =IF(F13>0,(C13-F13)*100/C13," ")
D14: 20 | G14: =IF(F14>0,(C14-F14)*100/C14," ")
D15: 20 | G15: =IF(F15>0,(C15-F15)*100/C15," ")
D16: 20 | G16: =IF(F16>0,(C16-F16)*100/C16," ")
D17: 20 | G17: =IF(F17>0,(C17-F17)*100/C17," ")
... D99: 20 | G99: =IF(F99>0,(C99-F99)*100/C99," ")

Sheet Business Details
A2: Business Logo Name | D2: Enter your business details in this sheet.
A3: Business Name | B3: <enter business name> | D3: List line items as "products" in Product Details.
A4: Address Line 1 | D4: List customers in "Customer Details".
A5: Address Line 2 | D5: Bring it all together in the "Invoice Database" sheet.
A6: Address Line 3 | D6: Print or generate a PDF from "Invoice Template"
A7: Post Code
A8: Telephone
A9: Fax number
A10: Email
A11: VAT Registration Number | D11: Not VAT registered? Enter single space in B11
A12: Company Slogan 1
A13: Company Slogan 2 | B13: Thank you for your custom
A14: Terms of Trade 1 | B14: Terms strictly 30 days net
A15: Terms of Trade 2 | B15: Overdue accounts charged at 2% per month
A16: Terms of Trade 3
A17: Footnote 1 | B17: ="All goods remain the property of "&B3&" until paid for in full" -> All goods remain the property of <enter business name> until paid for in full
A18: Footnote 2
