Workbook

Sheet Apr
A1: 25000 | B1: < Opening Bank Balance | C1: =[1]Admin!$B$4 -> 46118 | D1: Totals > | E1: =F1-SUM(G1:M1) -> 0 | F1: =SUM(F6:F200) -> 44200 | G1: =SUM(G6:G200) -> 0 | H1: =SUM(H6:H200) -> 44200 | I1: =SUM(I6:I200) -> 0 | J1: =SUM(J6:J200) -> 0 | K1: =SUM(K6:K200) -> 0 | L1: =SUM(L6:L200) -> 0 | M1: =SUM(M6:M200) -> 0 | O1: =IF(S1=0," ","Check all payment code letters entered") | R1: Totals > | S1: =T1-SUM(U1:AC1) -> 0 | T1: =SUM(T6:T200) -> 12525.2 | U1: =SUM(U6:U200) -> 0 | V1: =SUM(V6:V200) -> 3700 | W1: =SUM(W6:W200) -> 0 | X1: =SUM(X6:X200) -> 5652 | Y1: =SUM(Y6:Y200) -> 0 | Z1: =SUM(Z6:Z200) -> 0 | AA1: =SUM(AA6:AA200) -> 1673.2 | ... AC1: =SUM(AC6:AC200) -> 500
A2: =A1+F1-T1 -> 56674.8 | B2: < Closing Bank Balance | C2: =[1]Admin!$B$5 -> 46142 | D2: Deposit Bank Reference | E2: Enter Code Letters | F2: ENTER BANK RECEIPTS | G2: CURRENT ACCOUNT STATEMENT RECEIPTS | O2: =IF(E1=0," ","Check all Receipts Code Letters entered") | Q2: Enter Purchase Invoice No. | R2: Cheque number Direct Debit | S2: Enter Code Letters | T2: ENTER BANK PAYMENT | U2: CURRENT ACCOUNT STATEMENT PAYMENTS
B3: < Statement Bank Balance | C3: =C2 -> 46142 | G3: Cash paid into Bank | H3: Amount Received Debtors | I3: Amount Received Creditors | J3: Bank Interest Received | K3: HMRC Refunded | L3: Capital Introduced | M3: Bank Contra items | U3: Cash Withdrawn from Bank | V3: Amount Paid Creditors | W3: Amount Paid Debtors | X3: Net Wages Paid | Y3: HP Interest Leasing & Bank Charges | Z3: Bank Loan & Overdraft Interest | AA3: HMRC Payments | AB3: Drawings | AC3: Bank Contra items
A4: =A2-A3 -> 56674.8 | B4: =IF(A4=0,"< Bank Balances with Statement","< Check Bank Entries With Statement") -> < Check Bank Entries With Statement | O4: Payment Date | P4: Suppliers paid
A5: Date | B5: Source of Funds Received | C5: Sales Invoice | G5: BC | H5: DR | I5: CR | J5: K | K5: RV | L5: DL | M5: X | U5: BC | V5: CR | W5: DR | X5: W | Y5: B | Z5: J | AA5: RP | AB5: DL | AC5: X
A6: 46122 | B6: Acme Corp | C6: BNK-DR-037 | D6: Opening debtor receipt | E6: DR | F6: 7200 | G6: =IF(E6="BC",F6," ") | H6: =IF(E6="DR",F6," ") -> 7200 | I6: =IF(E6="CR",F6," ") | J6: =IF(E6="K",F6," ") | K6: =IF(E6="RV",F6," ") | L6: =IF(E6="DL",F6," ") | M6: =IF(E6="X",F6," ") | O6: 46113 | P6: WorkSpace Ltd | Q6: BNK-CR-001 | R6: Office rent payment | S6: CR | T6: 1200 | U6: =IF(S6="BC",T6," ") | V6: =IF(S6="CR",T6," ") -> 1200 | W6: =IF(S6="DR",T6," ") | X6: =IF(S6="W",T6," ") | Y6: =IF(S6="B",T6," ") | Z6: =IF(S6="J",T6," ") | AA6: =IF(S6="RP",T6," ") | AB6: =IF(S6="DL",T6," ") | AC6: =IF(S6="X",T6," ")
A7: 46127 | B7: Beta Systems | C7: BNK-DR-038 | D7: Opening debtor receipt | E7: DR | F7: 1200 | G7: =IF(E7="BC",F7," ") | H7: =IF(E7="DR",F7," ") -> 1200 | I7: =IF(E7="CR",F7," ") | J7: =IF(E7="K",F7," ") | K7: =IF(E7="RV",F7," ") | L7: =IF(E7="DL",F7," ") | M7: =IF(E7="X",F7," ") | O7: 46113 | P7: Director | Q7: BNK-DL-001 | R7: Directors loan repayment | S7: DL | T7: 1000 | U7: =IF(S7="BC",T7," ") | V7: =IF(S7="CR",T7," ") | W7: =IF(S7="DR",T7," ") | X7: =IF(S7="W",T7," ") | Y7: =IF(S7="B",T7," ") | Z7: =IF(S7="J",T7," ") | AA7: =IF(S7="RP",T7," ") | AB7: =IF(S7="DL",T7," ") -> 1000 | AC7: =IF(S7="X",T7," ")
A8: 46132 | B8: Acme Corp | C8: BNK-DR-001 | D8: Customer receipt | E8: DR | F8: 8000 | G8: =IF(E8="BC",F8," ") | H8: =IF(E8="DR",F8," ") -> 8000 | I8: =IF(E8="CR",F8," ") | J8: =IF(E8="K",F8," ") | K8: =IF(E8="RV",F8," ") | L8: =IF(E8="DL",F8," ") | M8: =IF(E8="X",F8," ") | O8: 46117 | P8: Various suppliers | Q8: BNK-CR-MISC-001 | R8: Aggregate supplier payments | S8: CR | T8: 2200 | U8: =IF(S8="BC",T8," ") | V8: =IF(S8="CR",T8," ") -> 2200 | W8: =IF(S8="DR",T8," ") | X8: =IF(S8="W",T8," ") | Y8: =IF(S8="B",T8," ") | Z8: =IF(S8="J",T8," ") | AA8: =IF(S8="RP",T8," ") | AB8: =IF(S8="DL",T8," ") | AC8: =IF(S8="X",T8," ")
A9: 46137 | B9: TechStart Ltd | C9: BNK-DR-013 | D9: Customer receipt | E9: DR | F9: 2400 | G9: =IF(E9="BC",F9," ") | H9: =IF(E9="DR",F9," ") -> 2400 | I9: =IF(E9="CR",F9," ") | J9: =IF(E9="K",F9," ") | K9: =IF(E9="RV",F9," ") | L9: =IF(E9="DL",F9," ") | M9: =IF(E9="X",F9," ") | O9: 46131 | P9: HMRC | Q9: BNK-RP-001 | R9: Monthly PAYE/NI payment | S9: RP | T9: 1673.2 | U9: =IF(S9="BC",T9," ") | V9: =IF(S9="CR",T9," ") | W9: =IF(S9="DR",T9," ") | X9: =IF(S9="W",T9," ") | Y9: =IF(S9="B",T9," ") | Z9: =IF(S9="J",T9," ") | AA9: =IF(S9="RP",T9," ") -> 1673.2 | AB9: =IF(S9="DL",T9," ") | AC9: =IF(S9="X",T9," ")
A10: 46137 | B10: Gamma Ltd | C10: BNK-DR-039 | D10: Opening debtor receipt | E10: DR | F10: 2400 | G10: =IF(E10="BC",F10," ") | H10: =IF(E10="DR",F10," ") -> 2400 | I10: =IF(E10="CR",F10," ") | J10: =IF(E10="K",F10," ") | K10: =IF(E10="RV",F10," ") | L10: =IF(E10="DL",F10," ") | M10: =IF(E10="X",F10," ") | O10: 46140 | P10: Payroll | Q10: BNK-W-001 | R10: Monthly net wages (all staff) | S10: W | T10: 5652 | U10: =IF(S10="BC",T10," ") | V10: =IF(S10="CR",T10," ") | W10: =IF(S10="DR",T10," ") | X10: =IF(S10="W",T10," ") -> 5652 | Y10: =IF(S10="B",T10," ") | Z10: =IF(S10="J",T10," ") | AA10: =IF(S10="RP",T10," ") | AB10: =IF(S10="DL",T10," ") | AC10: =IF(S10="X",T10," ")
A11: 46140 | B11: Various customers | C11: BNK-DR-025 | D11: Aggregate customer receipts | E11: DR | F11: 23000 | G11: =IF(E11="BC",F11," ") | H11: =IF(E11="DR",F11," ") -> 23000 | I11: =IF(E11="CR",F11," ") | J11: =IF(E11="K",F11," ") | K11: =IF(E11="RV",F11," ") | L11: =IF(E11="DL",F11," ") | M11: =IF(E11="X",F11," ") | O11: 46142 | P11: Smith & Co | Q11: BNK-CR-013 | R11: Accountancy fee payment | S11: CR | T11: 300 | U11: =IF(S11="BC",T11," ") | V11: =IF(S11="CR",T11," ") -> 300 | W11: =IF(S11="DR",T11," ") | X11: =IF(S11="W",T11," ") | Y11: =IF(S11="B",T11," ") | Z11: =IF(S11="J",T11," ") | AA11: =IF(S11="RP",T11," ") | AB11: =IF(S11="DL",T11," ") | AC11: =IF(S11="X",T11," ")
E12: =IF(F12<>0,"Enter Code"," ") | G12: =IF(E12="BC",F12," ") | H12: =IF(E12="DR",F12," ") | I12: =IF(E12="CR",F12," ") | J12: =IF(E12="K",F12," ") | K12: =IF(E12="RV",F12," ") | L12: =IF(E12="DL",F12," ") | M12: =IF(E12="X",F12," ") | O12: 46142 | P12: Credit card payment | Q12: BNK-X-CC-001 | R12: Pay credit card balance | S12: X | T12: 500 | U12: =IF(S12="BC",T12," ") | V12: =IF(S12="CR",T12," ") | W12: =IF(S12="DR",T12," ") | X12: =IF(S12="W",T12," ") | Y12: =IF(S12="B",T12," ") | Z12: =IF(S12="J",T12," ") | AA12: =IF(S12="RP",T12," ") | AB12: =IF(S12="DL",T12," ") | AC12: =IF(S12="X",T12," ") -> 500
E13: =IF(F13<>0,"Enter Code"," ") | G13: =IF(E13="BC",F13," ") | H13: =IF(E13="DR",F13," ") | I13: =IF(E13="CR",F13," ") | J13: =IF(E13="K",F13," ") | K13: =IF(E13="RV",F13," ") | L13: =IF(E13="DL",F13," ") | M13: =IF(E13="X",F13," ") | S13: =IF(T13<>0,"Enter Code"," ") | U13: =IF(S13="BC",T13," ") | V13: =IF(S13="CR",T13," ") | W13: =IF(S13="DR",T13," ") | X13: =IF(S13="W",T13," ") | Y13: =IF(S13="B",T13," ") | Z13: =IF(S13="J",T13," ") | AA13: =IF(S13="RP",T13," ") | AB13: =IF(S13="DL",T13," ") | AC13: =IF(S13="X",T13," ")
E14: =IF(F14<>0,"Enter Code"," ") | G14: =IF(E14="BC",F14," ") | H14: =IF(E14="DR",F14," ") | I14: =IF(E14="CR",F14," ") | J14: =IF(E14="K",F14," ") | K14: =IF(E14="RV",F14," ") | L14: =IF(E14="DL",F14," ") | M14: =IF(E14="X",F14," ") | S14: =IF(T14<>0,"Enter Code"," ") | U14: =IF(S14="BC",T14," ") | V14: =IF(S14="CR",T14," ") | W14: =IF(S14="DR",T14," ") | X14: =IF(S14="W",T14," ") | Y14: =IF(S14="B",T14," ") | Z14: =IF(S14="J",T14," ") | AA14: =IF(S14="RP",T14," ") | AB14: =IF(S14="DL",T14," ") | AC14: =IF(S14="X",T14," ")
E15: =IF(F15<>0,"Enter Code"," ") | G15: =IF(E15="BC",F15," ") | H15: =IF(E15="DR",F15," ") | I15: =IF(E15="CR",F15," ") | J15: =IF(E15="K",F15," ") | K15: =IF(E15="RV",F15," ") | L15: =IF(E15="DL",F15," ") | M15: =IF(E15="X",F15," ") | S15: =IF(T15<>0,"Enter Code"," ") | U15: =IF(S15="BC",T15," ") | V15: =IF(S15="CR",T15," ") | W15: =IF(S15="DR",T15," ") | X15: =IF(S15="W",T15," ") | Y15: =IF(S15="B",T15," ") | Z15: =IF(S15="J",T15," ") | AA15: =IF(S15="RP",T15," ") | AB15: =IF(S15="DL",T15," ") | AC15: =IF(S15="X",T15," ")
E16: =IF(F16<>0,"Enter Code"," ") | G16: =IF(E16="BC",F16," ") | H16: =IF(E16="DR",F16," ") | I16: =IF(E16="CR",F16," ") | J16: =IF(E16="K",F16," ") | K16: =IF(E16="RV",F16," ") | L16: =IF(E16="DL",F16," ") | M16: =IF(E16="X",F16," ") | S16: =IF(T16<>0,"Enter Code"," ") | U16: =IF(S16="BC",T16," ") | V16: =IF(S16="CR",T16," ") | W16: =IF(S16="DR",T16," ") | X16: =IF(S16="W",T16," ") | Y16: =IF(S16="B",T16," ") | Z16: =IF(S16="J",T16," ") | AA16: =IF(S16="RP",T16," ") | AB16: =IF(S16="DL",T16," ") | AC16: =IF(S16="X",T16," ")
E17: =IF(F17<>0,"Enter Code"," ") | G17: =IF(E17="BC",F17," ") | H17: =IF(E17="DR",F17," ") | I17: =IF(E17="CR",F17," ") | J17: =IF(E17="K",F17," ") | K17: =IF(E17="RV",F17," ") | L17: =IF(E17="DL",F17," ") | M17: =IF(E17="X",F17," ") | S17: =IF(T17<>0,"Enter Code"," ") | U17: =IF(S17="BC",T17," ") | V17: =IF(S17="CR",T17," ") | W17: =IF(S17="DR",T17," ") | X17: =IF(S17="W",T17," ") | Y17: =IF(S17="B",T17," ") | Z17: =IF(S17="J",T17," ") | AA17: =IF(S17="RP",T17," ") | AB17: =IF(S17="DL",T17," ") | AC17: =IF(S17="X",T17," ")
E18: =IF(F18<>0,"Enter Code"," ") | G18: =IF(E18="BC",F18," ") | H18: =IF(E18="DR",F18," ") | I18: =IF(E18="CR",F18," ") | J18: =IF(E18="K",F18," ") | K18: =IF(E18="RV",F18," ") | L18: =IF(E18="DL",F18," ") | M18: =IF(E18="X",F18," ") | S18: =IF(T18<>0,"Enter Code"," ") | U18: =IF(S18="BC",T18," ") | V18: =IF(S18="CR",T18," ") | W18: =IF(S18="DR",T18," ") | X18: =IF(S18="W",T18," ") | Y18: =IF(S18="B",T18," ") | Z18: =IF(S18="J",T18," ") | AA18: =IF(S18="RP",T18," ") | AB18: =IF(S18="DL",T18," ") | AC18: =IF(S18="X",T18," ")
E19: =IF(F19<>0,"Enter Code"," ") | G19: =IF(E19="BC",F19," ") | H19: =IF(E19="DR",F19," ") | I19: =IF(E19="CR",F19," ") | J19: =IF(E19="K",F19," ") | K19: =IF(E19="RV",F19," ") | L19: =IF(E19="DL",F19," ") | M19: =IF(E19="X",F19," ") | S19: =IF(T19<>0,"Enter Code"," ") | U19: =IF(S19="BC",T19," ") | V19: =IF(S19="CR",T19," ") | W19: =IF(S19="DR",T19," ") | X19: =IF(S19="W",T19," ") | Y19: =IF(S19="B",T19," ") | Z19: =IF(S19="J",T19," ") | AA19: =IF(S19="RP",T19," ") | AB19: =IF(S19="DL",T19," ") | AC19: =IF(S19="X",T19," ")
E20: =IF(F20<>0,"Enter Code"," ") | G20: =IF(E20="BC",F20," ") | H20: =IF(E20="DR",F20," ") | I20: =IF(E20="CR",F20," ") | J20: =IF(E20="K",F20," ") | K20: =IF(E20="RV",F20," ") | L20: =IF(E20="DL",F20," ") | M20: =IF(E20="X",F20," ") | S20: =IF(T20<>0,"Enter Code"," ") | U20: =IF(S20="BC",T20," ") | V20: =IF(S20="CR",T20," ") | W20: =IF(S20="DR",T20," ") | X20: =IF(S20="W",T20," ") | Y20: =IF(S20="B",T20," ") | Z20: =IF(S20="J",T20," ") | AA20: =IF(S20="RP",T20," ") | AB20: =IF(S20="DL",T20," ") | AC20: =IF(S20="X",T20," ")
E21: =IF(F21<>0,"Enter Code"," ") | G21: =IF(E21="BC",F21," ") | H21: =IF(E21="DR",F21," ") | I21: =IF(E21="CR",F21," ") | J21: =IF(E21="K",F21," ") | K21: =IF(E21="RV",F21," ") | L21: =IF(E21="DL",F21," ") | M21: =IF(E21="X",F21," ") | S21: =IF(T21<>0,"Enter Code"," ") | U21: =IF(S21="BC",T21," ") | V21: =IF(S21="CR",T21," ") | W21: =IF(S21="DR",T21," ") | X21: =IF(S21="W",T21," ") | Y21: =IF(S21="B",T21," ") | Z21: =IF(S21="J",T21," ") | AA21: =IF(S21="RP",T21," ") | AB21: =IF(S21="DL",T21," ") | AC21: =IF(S21="X",T21," ")
E22: =IF(F22<>0,"Enter Code"," ") | G22: =IF(E22="BC",F22," ") | H22: =IF(E22="DR",F22," ") | I22: =IF(E22="CR",F22," ") | J22: =IF(E22="K",F22," ") | K22: =IF(E22="RV",F22," ") | L22: =IF(E22="DL",F22," ") | M22: =IF(E22="X",F22," ") | S22: =IF(T22<>0,"Enter Code"," ") | U22: =IF(S22="BC",T22," ") | V22: =IF(S22="CR",T22," ") | W22: =IF(S22="DR",T22," ") | X22: =IF(S22="W",T22," ") | Y22: =IF(S22="B",T22," ") | Z22: =IF(S22="J",T22," ") | AA22: =IF(S22="RP",T22," ") | AB22: =IF(S22="DL",T22," ") | AC22: =IF(S22="X",T22," ")
E23: =IF(F23<>0,"Enter Code"," ") | G23: =IF(E23="BC",F23," ") | H23: =IF(E23="DR",F23," ") | I23: =IF(E23="CR",F23," ") | J23: =IF(E23="K",F23," ") | K23: =IF(E23="RV",F23," ") | L23: =IF(E23="DL",F23," ") | M23: =IF(E23="X",F23," ") | S23: =IF(T23<>0,"Enter Code"," ") | U23: =IF(S23="BC",T23," ") | V23: =IF(S23="CR",T23," ") | W23: =IF(S23="DR",T23," ") | X23: =IF(S23="W",T23," ") | Y23: =IF(S23="B",T23," ") | Z23: =IF(S23="J",T23," ") | AA23: =IF(S23="RP",T23," ") | AB23: =IF(S23="DL",T23," ") | AC23: =IF(S23="X",T23," ")
E24: =IF(F24<>0,"Enter Code"," ") | G24: =IF(E24="BC",F24," ") | H24: =IF(E24="DR",F24," ") | I24: =IF(E24="CR",F24," ") | J24: =IF(E24="K",F24," ") | K24: =IF(E24="RV",F24," ") | L24: =IF(E24="DL",F24," ") | M24: =IF(E24="X",F24," ") | S24: =IF(T24<>0,"Enter Code"," ") | U24: =IF(S24="BC",T24," ") | V24: =IF(S24="CR",T24," ") | W24: =IF(S24="DR",T24," ") | X24: =IF(S24="W",T24," ") | Y24: =IF(S24="B",T24," ") | Z24: =IF(S24="J",T24," ") | AA24: =IF(S24="RP",T24," ") | AB24: =IF(S24="DL",T24," ") | AC24: =IF(S24="X",T24," ")
... E200: =IF(F200<>0,"Enter Code"," ") | G200: =IF(E200="BC",F200," ") | H200: =IF(E200="DR",F200," ") | I200: =IF(E200="CR",F200," ") | J200: =IF(E200="K",F200," ") | K200: =IF(E200="RV",F200," ") | L200: =IF(E200="DL",F200," ") | M200: =IF(E200="X",F200," ") | S200: =IF(T200<>0,"Enter Code"," ") | U200: =IF(S200="BC",T200," ") | V200: =IF(S200="CR",T200," ") | W200: =IF(S200="DR",T200," ") | X200: =IF(S200="W",T200," ") | Y200: =IF(S200="B",T200," ") | Z200: =IF(S200="J",T200," ") | AA200: =IF(S200="RP",T200," ") | AB200: =IF(S200="DL",T200," ") | AC200: =IF(S200="X",T200," ")

Sheet May
A1: =Apr!A2 -> 56674.8 | B1: < Opening Bank Balance | C1: =Apr!C2 -> 46142 | D1: Totals > | E1: =F1-SUM(G1:M1) -> 0 | F1: =SUM(F6:F200) -> 32920 | G1: =SUM(G6:G200) -> 0 | H1: =SUM(H6:H200) -> 32920 | I1: =SUM(I6:I200) -> 0 | J1: =SUM(J6:J200) -> 0 | K1: =SUM(K6:K200) -> 0 | L1: =SUM(L6:L200) -> 0 | M1: =SUM(M6:M200) -> 0 | O1: =IF(S1=0," ","Check all payment code letters entered") | R1: Totals > | S1: =T1-SUM(U1:AC1) -> 0 | T1: =SUM(T6:T200) -> 14150.2 | U1: =SUM(U6:U200) -> 0 | V1: =SUM(V6:V200) -> 4300 | W1: =SUM(W6:W200) -> 0 | X1: =SUM(X6:X200) -> 5652 | Y1: =SUM(Y6:Y200) -> 25 | Z1: =SUM(Z6:Z200) -> 0 | AA1: =SUM(AA6:AA200) -> 3173.2 | ... AC1: =SUM(AC6:AC200) -> 0
A2: =A1+F1-T1 -> 75444.6 | B2: < Closing Bank Balance | C2: =[1]Admin!$B$6 -> 46173 | D2: Deposit Bank Reference | E2: Enter Code Letters | F2: ENTER BANK RECEIPTS | G2: CURRENT ACCOUNT STATEMENT RECEIPTS | O2: =IF(E1=0," ","Check all Receipts Code Letters entered") | Q2: Enter Purchase Invoice No. | R2: Cheque number Direct Debit | S2: Enter Code Letters | T2: ENTER BANK PAYMENT | U2: CURRENT ACCOUNT STATEMENT PAYMENTS
B3: < Statement Bank Balance | C3: =C2 -> 46173 | G3: Cash paid into Bank | H3: Amount Received Debtors | I3: Amount Received Creditors | J3: Bank Interest Received | K3: HMRC Refunded | L3: Capital Introduced | M3: Bank Contra items | U3: Cash Withdrawn from Bank | V3: Amount Paid Creditors | W3: Amount Paid Debtors | X3: Net Wages Paid | Y3: HP Interest Leasing & Bank Charges | Z3: Bank Loan & Overdraft Interest | AA3: HMRC Payments | AB3: Drawings | AC3: Bank Contra items
A4: =A2-A3 -> 75444.6 | B4: =IF(A4=0,"< Bank Balances with Statement","< Check Bank Entries With Statement") -> < Check Bank Entries With Statement | O4: Payment Date | P4: Suppliers paid
A5: Date | B5: Source of Funds Received | C5: Sales Invoice | G5: BC | H5: DR | I5: CR | J5: K | K5: RV | L5: DL | M5: X | U5: BC | V5: CR | W5: DR | X5: W | Y5: B | Z5: J | AA5: RP | AB5: DL | AC5: X
A6: 46162 | B6: Acme Corp | C6: BNK-DR-002 | D6: Customer receipt | E6: DR | F6: 8000 | G6: =IF(E6="BC",F6," ") | H6: =IF(E6="DR",F6," ") -> 8000 | I6: =IF(E6="CR",F6," ") | J6: =IF(E6="K",F6," ") | K6: =IF(E6="RV",F6," ") | L6: =IF(E6="DL",F6," ") | M6: =IF(E6="X",F6," ") | O6: 46143 | P6: WorkSpace Ltd | Q6: BNK-CR-002 | R6: Office rent payment | S6: CR | T6: 1200 | U6: =IF(S6="BC",T6," ") | V6: =IF(S6="CR",T6," ") -> 1200 | W6: =IF(S6="DR",T6," ") | X6: =IF(S6="W",T6," ") | Y6: =IF(S6="B",T6," ") | Z6: =IF(S6="J",T6," ") | AA6: =IF(S6="RP",T6," ") | AB6: =IF(S6="DL",T6," ") | AC6: =IF(S6="X",T6," ")
A7: 46167 | B7: TechStart Ltd | C7: BNK-DR-014 | D7: Customer receipt | E7: DR | F7: 2400 | G7: =IF(E7="BC",F7," ") | H7: =IF(E7="DR",F7," ") -> 2400 | I7: =IF(E7="CR",F7," ") | J7: =IF(E7="K",F7," ") | K7: =IF(E7="RV",F7," ") | L7: =IF(E7="DL",F7," ") | M7: =IF(E7="X",F7," ") | O7: 46143 | P7: Director | Q7: BNK-DL-002 | R7: Directors loan repayment | S7: DL | T7: 1000 | U7: =IF(S7="BC",T7," ") | V7: =IF(S7="CR",T7," ") | W7: =IF(S7="DR",T7," ") | X7: =IF(S7="W",T7," ") | Y7: =IF(S7="B",T7," ") | Z7: =IF(S7="J",T7," ") | AA7: =IF(S7="RP",T7," ") | AB7: =IF(S7="DL",T7," ") -> 1000 | AC7: =IF(S7="X",T7," ")
A8: 46170 | B8: Various customers | C8: BNK-DR-026 | D8: Aggregate customer receipts | E8: DR | F8: 22520 | G8: =IF(E8="BC",F8," ") | H8: =IF(E8="DR",F8," ") -> 22520 | I8: =IF(E8="CR",F8," ") | J8: =IF(E8="K",F8," ") | K8: =IF(E8="RV",F8," ") | L8: =IF(E8="DL",F8," ") | M8: =IF(E8="X",F8," ") | O8: 46147 | P8: Various suppliers | Q8: BNK-CR-MISC-002 | R8: Aggregate supplier payments | S8: CR | T8: 2800 | U8: =IF(S8="BC",T8," ") | V8: =IF(S8="CR",T8," ") -> 2800 | W8: =IF(S8="DR",T8," ") | X8: =IF(S8="W",T8," ") | Y8: =IF(S8="B",T8," ") | Z8: =IF(S8="J",T8," ") | AA8: =IF(S8="RP",T8," ") | AB8: =IF(S8="DL",T8," ") | AC8: =IF(S8="X",T8," ")
E9: =IF(F9<>0,"Enter Code"," ") | G9: =IF(E9="BC",F9," ") | H9: =IF(E9="DR",F9," ") | I9: =IF(E9="CR",F9," ") | J9: =IF(E9="K",F9," ") | K9: =IF(E9="RV",F9," ") | L9: =IF(E9="DL",F9," ") | M9: =IF(E9="X",F9," ") | O9: 46161 | P9: HMRC | Q9: BNK-RP-002 | R9: Monthly PAYE/NI payment | S9: RP | T9: 1673.2 | U9: =IF(S9="BC",T9," ") | V9: =IF(S9="CR",T9," ") | W9: =IF(S9="DR",T9," ") | X9: =IF(S9="W",T9," ") | Y9: =IF(S9="B",T9," ") | Z9: =IF(S9="J",T9," ") | AA9: =IF(S9="RP",T9," ") -> 1673.2 | AB9: =IF(S9="DL",T9," ") | AC9: =IF(S9="X",T9," ")
E10: =IF(F10<>0,"Enter Code"," ") | G10: =IF(E10="BC",F10," ") | H10: =IF(E10="DR",F10," ") | I10: =IF(E10="CR",F10," ") | J10: =IF(E10="K",F10," ") | K10: =IF(E10="RV",F10," ") | L10: =IF(E10="DL",F10," ") | M10: =IF(E10="X",F10," ") | O10: 46167 | P10: HSBC | Q10: BNK-B-001 | R10: Bank charges | S10: B | T10: 25 | U10: =IF(S10="BC",T10," ") | V10: =IF(S10="CR",T10," ") | W10: =IF(S10="DR",T10," ") | X10: =IF(S10="W",T10," ") | Y10: =IF(S10="B",T10," ") -> 25 | Z10: =IF(S10="J",T10," ") | AA10: =IF(S10="RP",T10," ") | AB10: =IF(S10="DL",T10," ") | AC10: =IF(S10="X",T10," ")
E11: =IF(F11<>0,"Enter Code"," ") | G11: =IF(E11="BC",F11," ") | H11: =IF(E11="DR",F11," ") | I11: =IF(E11="CR",F11," ") | J11: =IF(E11="K",F11," ") | K11: =IF(E11="RV",F11," ") | L11: =IF(E11="DL",F11," ") | M11: =IF(E11="X",F11," ") | O11: 46170 | P11: Payroll | Q11: BNK-W-002 | R11: Monthly net wages (all staff) | S11: W | T11: 5652 | U11: =IF(S11="BC",T11," ") | V11: =IF(S11="CR",T11," ") | W11: =IF(S11="DR",T11," ") | X11: =IF(S11="W",T11," ") -> 5652 | Y11: =IF(S11="B",T11," ") | Z11: =IF(S11="J",T11," ") | AA11: =IF(S11="RP",T11," ") | AB11: =IF(S11="DL",T11," ") | AC11: =IF(S11="X",T11," ")
E12: =IF(F12<>0,"Enter Code"," ") | G12: =IF(E12="BC",F12," ") | H12: =IF(E12="DR",F12," ") | I12: =IF(E12="CR",F12," ") | J12: =IF(E12="K",F12," ") | K12: =IF(E12="RV",F12," ") | L12: =IF(E12="DL",F12," ") | M12: =IF(E12="X",F12," ") | O12: 46173 | P12: Smith & Co | Q12: BNK-CR-014 | R12: Accountancy fee payment | S12: CR | T12: 300 | U12: =IF(S12="BC",T12," ") | V12: =IF(S12="CR",T12," ") -> 300 | W12: =IF(S12="DR",T12," ") | X12: =IF(S12="W",T12," ") | Y12: =IF(S12="B",T12," ") | Z12: =IF(S12="J",T12," ") | AA12: =IF(S12="RP",T12," ") | AB12: =IF(S12="DL",T12," ") | AC12: =IF(S12="X",T12," ")
E13: =IF(F13<>0,"Enter Code"," ") | G13: =IF(E13="BC",F13," ") | H13: =IF(E13="DR",F13," ") | I13: =IF(E13="CR",F13," ") | J13: =IF(E13="K",F13," ") | K13: =IF(E13="RV",F13," ") | L13: =IF(E13="DL",F13," ") | M13: =IF(E13="X",F13," ") | O13: 46149 | P13: HMRC | Q13: BNK-RV-VAT-000 | R13: VAT payment, prior year fourth quarter | S13: RP | T13: 1500 | U13: =IF(S13="BC",T13," ") | V13: =IF(S13="CR",T13," ") | W13: =IF(S13="DR",T13," ") | X13: =IF(S13="W",T13," ") | Y13: =IF(S13="B",T13," ") | Z13: =IF(S13="J",T13," ") | AA13: =IF(S13="RP",T13," ") -> 1500 | AB13: =IF(S13="DL",T13," ") | AC13: =IF(S13="X",T13," ")
E14: =IF(F14<>0,"Enter Code"," ") | G14: =IF(E14="BC",F14," ") | H14: =IF(E14="DR",F14," ") | I14: =IF(E14="CR",F14," ") | J14: =IF(E14="K",F14," ") | K14: =IF(E14="RV",F14," ") | L14: =IF(E14="DL",F14," ") | M14: =IF(E14="X",F14," ") | S14: =IF(T14<>0,"Enter Code"," ") | U14: =IF(S14="BC",T14," ") | V14: =IF(S14="CR",T14," ") | W14: =IF(S14="DR",T14," ") | X14: =IF(S14="W",T14," ") | Y14: =IF(S14="B",T14," ") | Z14: =IF(S14="J",T14," ") | AA14: =IF(S14="RP",T14," ") | AB14: =IF(S14="DL",T14," ") | AC14: =IF(S14="X",T14," ")
E15: =IF(F15<>0,"Enter Code"," ") | G15: =IF(E15="BC",F15," ") | H15: =IF(E15="DR",F15," ") | I15: =IF(E15="CR",F15," ") | J15: =IF(E15="K",F15," ") | K15: =IF(E15="RV",F15," ") | L15: =IF(E15="DL",F15," ") | M15: =IF(E15="X",F15," ") | S15: =IF(T15<>0,"Enter Code"," ") | U15: =IF(S15="BC",T15," ") | V15: =IF(S15="CR",T15," ") | W15: =IF(S15="DR",T15," ") | X15: =IF(S15="W",T15," ") | Y15: =IF(S15="B",T15," ") | Z15: =IF(S15="J",T15," ") | AA15: =IF(S15="RP",T15," ") | AB15: =IF(S15="DL",T15," ") | AC15: =IF(S15="X",T15," ")
E16: =IF(F16<>0,"Enter Code"," ") | G16: =IF(E16="BC",F16," ") | H16: =IF(E16="DR",F16," ") | I16: =IF(E16="CR",F16," ") | J16: =IF(E16="K",F16," ") | K16: =IF(E16="RV",F16," ") | L16: =IF(E16="DL",F16," ") | M16: =IF(E16="X",F16," ") | S16: =IF(T16<>0,"Enter Code"," ") | U16: =IF(S16="BC",T16," ") | V16: =IF(S16="CR",T16," ") | W16: =IF(S16="DR",T16," ") | X16: =IF(S16="W",T16," ") | Y16: =IF(S16="B",T16," ") | Z16: =IF(S16="J",T16," ") | AA16: =IF(S16="RP",T16," ") | AB16: =IF(S16="DL",T16," ") | AC16: =IF(S16="X",T16," ")
E17: =IF(F17<>0,"Enter Code"," ") | G17: =IF(E17="BC",F17," ") | H17: =IF(E17="DR",F17," ") | I17: =IF(E17="CR",F17," ") | J17: =IF(E17="K",F17," ") | K17: =IF(E17="RV",F17," ") | L17: =IF(E17="DL",F17," ") | M17: =IF(E17="X",F17," ") | S17: =IF(T17<>0,"Enter Code"," ") | U17: =IF(S17="BC",T17," ") | V17: =IF(S17="CR",T17," ") | W17: =IF(S17="DR",T17," ") | X17: =IF(S17="W",T17," ") | Y17: =IF(S17="B",T17," ") | Z17: =IF(S17="J",T17," ") | AA17: =IF(S17="RP",T17," ") | AB17: =IF(S17="DL",T17," ") | AC17: =IF(S17="X",T17," ")
E18: =IF(F18<>0,"Enter Code"," ") | G18: =IF(E18="BC",F18," ") | H18: =IF(E18="DR",F18," ") | I18: =IF(E18="CR",F18," ") | J18: =IF(E18="K",F18," ") | K18: =IF(E18="RV",F18," ") | L18: =IF(E18="DL",F18," ") | M18: =IF(E18="X",F18," ") | S18: =IF(T18<>0,"Enter Code"," ") | U18: =IF(S18="BC",T18," ") | V18: =IF(S18="CR",T18," ") | W18: =IF(S18="DR",T18," ") | X18: =IF(S18="W",T18," ") | Y18: =IF(S18="B",T18," ") | Z18: =IF(S18="J",T18," ") | AA18: =IF(S18="RP",T18," ") | AB18: =IF(S18="DL",T18," ") | AC18: =IF(S18="X",T18," ")
E19: =IF(F19<>0,"Enter Code"," ") | G19: =IF(E19="BC",F19," ") | H19: =IF(E19="DR",F19," ") | I19: =IF(E19="CR",F19," ") | J19: =IF(E19="K",F19," ") | K19: =IF(E19="RV",F19," ") | L19: =IF(E19="DL",F19," ") | M19: =IF(E19="X",F19," ") | S19: =IF(T19<>0,"Enter Code"," ") | U19: =IF(S19="BC",T19," ") | V19: =IF(S19="CR",T19," ") | W19: =IF(S19="DR",T19," ") | X19: =IF(S19="W",T19," ") | Y19: =IF(S19="B",T19," ") | Z19: =IF(S19="J",T19," ") | AA19: =IF(S19="RP",T19," ") | AB19: =IF(S19="DL",T19," ") | AC19: =IF(S19="X",T19," ")
E20: =IF(F20<>0,"Enter Code"," ") | G20: =IF(E20="BC",F20," ") | H20: =IF(E20="DR",F20," ") | I20: =IF(E20="CR",F20," ") | J20: =IF(E20="K",F20," ") | K20: =IF(E20="RV",F20," ") | L20: =IF(E20="DL",F20," ") | M20: =IF(E20="X",F20," ") | S20: =IF(T20<>0,"Enter Code"," ") | U20: =IF(S20="BC",T20," ") | V20: =IF(S20="CR",T20," ") | W20: =IF(S20="DR",T20," ") | X20: =IF(S20="W",T20," ") | Y20: =IF(S20="B",T20," ") | Z20: =IF(S20="J",T20," ") | AA20: =IF(S20="RP",T20," ") | AB20: =IF(S20="DL",T20," ") | AC20: =IF(S20="X",T20," ")
E21: =IF(F21<>0,"Enter Code"," ") | G21: =IF(E21="BC",F21," ") | H21: =IF(E21="DR",F21," ") | I21: =IF(E21="CR",F21," ") | J21: =IF(E21="K",F21," ") | K21: =IF(E21="RV",F21," ") | L21: =IF(E21="DL",F21," ") | M21: =IF(E21="X",F21," ") | S21: =IF(T21<>0,"Enter Code"," ") | U21: =IF(S21="BC",T21," ") | V21: =IF(S21="CR",T21," ") | W21: =IF(S21="DR",T21," ") | X21: =IF(S21="W",T21," ") | Y21: =IF(S21="B",T21," ") | Z21: =IF(S21="J",T21," ") | AA21: =IF(S21="RP",T21," ") | AB21: =IF(S21="DL",T21," ") | AC21: =IF(S21="X",T21," ")
E22: =IF(F22<>0,"Enter Code"," ") | G22: =IF(E22="BC",F22," ") | H22: =IF(E22="DR",F22," ") | I22: =IF(E22="CR",F22," ") | J22: =IF(E22="K",F22," ") | K22: =IF(E22="RV",F22," ") | L22: =IF(E22="DL",F22," ") | M22: =IF(E22="X",F22," ") | S22: =IF(T22<>0,"Enter Code"," ") | U22: =IF(S22="BC",T22," ") | V22: =IF(S22="CR",T22," ") | W22: =IF(S22="DR",T22," ") | X22: =IF(S22="W",T22," ") | Y22: =IF(S22="B",T22," ") | Z22: =IF(S22="J",T22," ") | AA22: =IF(S22="RP",T22," ") | AB22: =IF(S22="DL",T22," ") | AC22: =IF(S22="X",T22," ")
E23: =IF(F23<>0,"Enter Code"," ") | G23: =IF(E23="BC",F23," ") | H23: =IF(E23="DR",F23," ") | I23: =IF(E23="CR",F23," ") | J23: =IF(E23="K",F23," ") | K23: =IF(E23="RV",F23," ") | L23: =IF(E23="DL",F23," ") | M23: =IF(E23="X",F23," ") | S23: =IF(T23<>0,"Enter Code"," ") | U23: =IF(S23="BC",T23," ") | V23: =IF(S23="CR",T23," ") | W23: =IF(S23="DR",T23," ") | X23: =IF(S23="W",T23," ") | Y23: =IF(S23="B",T23," ") | Z23: =IF(S23="J",T23," ") | AA23: =IF(S23="RP",T23," ") | AB23: =IF(S23="DL",T23," ") | AC23: =IF(S23="X",T23," ")
E24: =IF(F24<>0,"Enter Code"," ") | G24: =IF(E24="BC",F24," ") | H24: =IF(E24="DR",F24," ") | I24: =IF(E24="CR",F24," ") | J24: =IF(E24="K",F24," ") | K24: =IF(E24="RV",F24," ") | L24: =IF(E24="DL",F24," ") | M24: =IF(E24="X",F24," ") | S24: =IF(T24<>0,"Enter Code"," ") | U24: =IF(S24="BC",T24," ") | V24: =IF(S24="CR",T24," ") | W24: =IF(S24="DR",T24," ") | X24: =IF(S24="W",T24," ") | Y24: =IF(S24="B",T24," ") | Z24: =IF(S24="J",T24," ") | AA24: =IF(S24="RP",T24," ") | AB24: =IF(S24="DL",T24," ") | AC24: =IF(S24="X",T24," ")
E25: =IF(F25<>0,"Enter Code"," ") | G25: =IF(E25="BC",F25," ") | H25: =IF(E25="DR",F25," ") | I25: =IF(E25="CR",F25," ") | J25: =IF(E25="K",F25," ") | K25: =IF(E25="RV",F25," ") | L25: =IF(E25="DL",F25," ") | M25: =IF(E25="X",F25," ") | S25: =IF(T25<>0,"Enter Code"," ") | U25: =IF(S25="BC",T25," ") | V25: =IF(S25="CR",T25," ") | W25: =IF(S25="DR",T25," ") | X25: =IF(S25="W",T25," ") | Y25: =IF(S25="B",T25," ") | Z25: =IF(S25="J",T25," ") | AA25: =IF(S25="RP",T25," ") | AB25: =IF(S25="DL",T25," ") | AC25: =IF(S25="X",T25," ")
... E200: =IF(F200<>0,"Enter Code"," ") | G200: =IF(E200="BC",F200," ") | H200: =IF(E200="DR",F200," ") | I200: =IF(E200="CR",F200," ") | J200: =IF(E200="K",F200," ") | K200: =IF(E200="RV",F200," ") | L200: =IF(E200="DL",F200," ") | M200: =IF(E200="X",F200," ") | S200: =IF(T200<>0,"Enter Code"," ") | U200: =IF(S200="BC",T200," ") | V200: =IF(S200="CR",T200," ") | W200: =IF(S200="DR",T200," ") | X200: =IF(S200="W",T200," ") | Y200: =IF(S200="B",T200," ") | Z200: =IF(S200="J",T200," ") | AA200: =IF(S200="RP",T200," ") | AB200: =IF(S200="DL",T200," ") | AC200: =IF(S200="X",T200," ")

Sheet Jun
A1: =May!A2 -> 75444.6 | B1: < Opening Bank Balance | C1: =May!C2 -> 46173 | D1: Totals > | E1: =F1-SUM(G1:M1) -> 0 | F1: =SUM(F6:F200) -> 35200 | G1: =SUM(G6:G200) -> 0 | H1: =SUM(H6:H200) -> 35200 | I1: =SUM(I6:I200) -> 0 | J1: =SUM(J6:J200) -> 0 | K1: =SUM(K6:K200) -> 0 | L1: =SUM(L6:L200) -> 0 | M1: =SUM(M6:M200) -> 0 | O1: =IF(S1=0," ","Check all payment code letters entered") | R1: Totals > | S1: =T1-SUM(U1:AC1) -> 0 | T1: =SUM(T6:T200) -> 27675.2 | U1: =SUM(U6:U200) -> 0 | V1: =SUM(V6:V200) -> 17000 | W1: =SUM(W6:W200) -> 0 | X1: =SUM(X6:X200) -> 5652 | Y1: =SUM(Y6:Y200) -> 2250 | Z1: =SUM(Z6:Z200) -> 0 | AA1: =SUM(AA6:AA200) -> 1673.2 | ... AC1: =SUM(AC6:AC200) -> 100
A2: =A1+F1-T1 -> 82969.4 | B2: < Closing Bank Balance | C2: =[1]Admin!$B$7 -> 46203 | D2: Deposit Bank Reference | E2: Enter Code Letters | F2: ENTER BANK RECEIPTS | G2: CURRENT ACCOUNT STATEMENT RECEIPTS | O2: =IF(E1=0," ","Check all Receipts Code Letters entered") | Q2: Enter Purchase Invoice No. | R2: Cheque number Direct Debit | S2: Enter Code Letters | T2: ENTER BANK PAYMENT | U2: CURRENT ACCOUNT STATEMENT PAYMENTS
B3: < Statement Bank Balance | C3: =C2 -> 46203 | G3: Cash paid into Bank | H3: Amount Received Debtors | I3: Amount Received Creditors | J3: Bank Interest Received | K3: HMRC Refunded | L3: Capital Introduced | M3: Bank Contra items | U3: Cash Withdrawn from Bank | V3: Amount Paid Creditors | W3: Amount Paid Debtors | X3: Net Wages Paid | Y3: HP Interest Leasing & Bank Charges | Z3: Bank Loan & Overdraft Interest | AA3: HMRC Payments | AB3: Drawings | AC3: Bank Contra items
A4: =A2-A3 -> 82969.4 | B4: =IF(A4=0,"< Bank Balances with Statement","< Check Bank Entries With Statement") -> < Check Bank Entries With Statement | O4: Payment Date | P4: Suppliers paid
A5: Date | B5: Source of Funds Received | C5: Sales Invoice | G5: BC | H5: DR | I5: CR | J5: K | K5: RV | L5: DL | M5: X | U5: BC | V5: CR | W5: DR | X5: W | Y5: B | Z5: J | AA5: RP | AB5: DL | AC5: X
A6: 46193 | B6: Acme Corp | C6: BNK-DR-003 | D6: Customer receipt | E6: DR | F6: 8000 | G6: =IF(E6="BC",F6," ") | H6: =IF(E6="DR",F6," ") -> 8000 | I6: =IF(E6="CR",F6," ") | J6: =IF(E6="K",F6," ") | K6: =IF(E6="RV",F6," ") | L6: =IF(E6="DL",F6," ") | M6: =IF(E6="X",F6," ") | O6: 46174 | P6: WorkSpace Ltd | Q6: BNK-CR-003 | R6: Office rent payment | S6: CR | T6: 1200 | U6: =IF(S6="BC",T6," ") | V6: =IF(S6="CR",T6," ") -> 1200 | W6: =IF(S6="DR",T6," ") | X6: =IF(S6="W",T6," ") | Y6: =IF(S6="B",T6," ") | Z6: =IF(S6="J",T6," ") | AA6: =IF(S6="RP",T6," ") | AB6: =IF(S6="DL",T6," ") | AC6: =IF(S6="X",T6," ")
A7: 46198 | B7: TechStart Ltd | C7: BNK-DR-015 | D7: Customer receipt | E7: DR | F7: 2400 | G7: =IF(E7="BC",F7," ") | H7: =IF(E7="DR",F7," ") -> 2400 | I7: =IF(E7="CR",F7," ") | J7: =IF(E7="K",F7," ") | K7: =IF(E7="RV",F7," ") | L7: =IF(E7="DL",F7," ") | M7: =IF(E7="X",F7," ") | O7: 46174 | P7: Director | Q7: BNK-DL-003 | R7: Directors loan repayment | S7: DL | T7: 1000 | U7: =IF(S7="BC",T7," ") | V7: =IF(S7="CR",T7," ") | W7: =IF(S7="DR",T7," ") | X7: =IF(S7="W",T7," ") | Y7: =IF(S7="B",T7," ") | Z7: =IF(S7="J",T7," ") | AA7: =IF(S7="RP",T7," ") | AB7: =IF(S7="DL",T7," ") -> 1000 | AC7: =IF(S7="X",T7," ")
A8: 46201 | B8: Various customers | C8: BNK-DR-027 | D8: Aggregate customer receipts | E8: DR | F8: 24800 | G8: =IF(E8="BC",F8," ") | H8: =IF(E8="DR",F8," ") -> 24800 | I8: =IF(E8="CR",F8," ") | J8: =IF(E8="K",F8," ") | K8: =IF(E8="RV",F8," ") | L8: =IF(E8="DL",F8," ") | M8: =IF(E8="X",F8," ") | O8: 46178 | P8: Various suppliers | Q8: BNK-CR-MISC-003 | R8: Aggregate supplier payments | S8: CR | T8: 2500 | U8: =IF(S8="BC",T8," ") | V8: =IF(S8="CR",T8," ") -> 2500 | W8: =IF(S8="DR",T8," ") | X8: =IF(S8="W",T8," ") | Y8: =IF(S8="B",T8," ") | Z8: =IF(S8="J",T8," ") | AA8: =IF(S8="RP",T8," ") | AB8: =IF(S8="DL",T8," ") | AC8: =IF(S8="X",T8," ")
E9: =IF(F9<>0,"Enter Code"," ") | G9: =IF(E9="BC",F9," ") | H9: =IF(E9="DR",F9," ") | I9: =IF(E9="CR",F9," ") | J9: =IF(E9="K",F9," ") | K9: =IF(E9="RV",F9," ") | L9: =IF(E9="DL",F9," ") | M9: =IF(E9="X",F9," ") | O9: 46183 | P9: Cash top-up | Q9: BNK-BC-001 | R9: Transfer to cash float | S9: X | T9: 100 | U9: =IF(S9="BC",T9," ") | V9: =IF(S9="CR",T9," ") | W9: =IF(S9="DR",T9," ") | X9: =IF(S9="W",T9," ") | Y9: =IF(S9="B",T9," ") | Z9: =IF(S9="J",T9," ") | AA9: =IF(S9="RP",T9," ") | AB9: =IF(S9="DL",T9," ") | AC9: =IF(S9="X",T9," ") -> 100
E10: =IF(F10<>0,"Enter Code"," ") | G10: =IF(E10="BC",F10," ") | H10: =IF(E10="DR",F10," ") | I10: =IF(E10="CR",F10," ") | J10: =IF(E10="K",F10," ") | K10: =IF(E10="RV",F10," ") | L10: =IF(E10="DL",F10," ") | M10: =IF(E10="X",F10," ") | O10: 46192 | P10: HMRC | Q10: BNK-RP-003 | R10: Monthly PAYE/NI payment | S10: RP | T10: 1673.2 | U10: =IF(S10="BC",T10," ") | V10: =IF(S10="CR",T10," ") | W10: =IF(S10="DR",T10," ") | X10: =IF(S10="W",T10," ") | Y10: =IF(S10="B",T10," ") | Z10: =IF(S10="J",T10," ") | AA10: =IF(S10="RP",T10," ") -> 1673.2 | AB10: =IF(S10="DL",T10," ") | AC10: =IF(S10="X",T10," ")
E11: =IF(F11<>0,"Enter Code"," ") | G11: =IF(E11="BC",F11," ") | H11: =IF(E11="DR",F11," ") | I11: =IF(E11="CR",F11," ") | J11: =IF(E11="K",F11," ") | K11: =IF(E11="RV",F11," ") | L11: =IF(E11="DL",F11," ") | M11: =IF(E11="X",F11," ") | O11: 46201 | P11: Payroll | Q11: BNK-W-003 | R11: Monthly net wages (all staff) | S11: W | T11: 5652 | U11: =IF(S11="BC",T11," ") | V11: =IF(S11="CR",T11," ") | W11: =IF(S11="DR",T11," ") | X11: =IF(S11="W",T11," ") -> 5652 | Y11: =IF(S11="B",T11," ") | Z11: =IF(S11="J",T11," ") | AA11: =IF(S11="RP",T11," ") | AB11: =IF(S11="DL",T11," ") | AC11: =IF(S11="X",T11," ")
E12: =IF(F12<>0,"Enter Code"," ") | G12: =IF(E12="BC",F12," ") | H12: =IF(E12="DR",F12," ") | I12: =IF(E12="CR",F12," ") | J12: =IF(E12="K",F12," ") | K12: =IF(E12="RV",F12," ") | L12: =IF(E12="DL",F12," ") | M12: =IF(E12="X",F12," ") | O12: 46203 | P12: Directors loan interest | Q12: BNK-B-INT-001 | R12: Quarterly loan interest payment | S12: B | T12: 250 | U12: =IF(S12="BC",T12," ") | V12: =IF(S12="CR",T12," ") | W12: =IF(S12="DR",T12," ") | X12: =IF(S12="W",T12," ") | Y12: =IF(S12="B",T12," ") -> 250 | Z12: =IF(S12="J",T12," ") | AA12: =IF(S12="RP",T12," ") | AB12: =IF(S12="DL",T12," ") | AC12: =IF(S12="X",T12," ")
E13: =IF(F13<>0,"Enter Code"," ") | G13: =IF(E13="BC",F13," ") | H13: =IF(E13="DR",F13," ") | I13: =IF(E13="CR",F13," ") | J13: =IF(E13="K",F13," ") | K13: =IF(E13="RV",F13," ") | L13: =IF(E13="DL",F13," ") | M13: =IF(E13="X",F13," ") | O13: 46203 | P13: Smith & Co | Q13: BNK-CR-015 | R13: Accountancy fee payment | S13: CR | T13: 300 | U13: =IF(S13="BC",T13," ") | V13: =IF(S13="CR",T13," ") -> 300 | W13: =IF(S13="DR",T13," ") | X13: =IF(S13="W",T13," ") | Y13: =IF(S13="B",T13," ") | Z13: =IF(S13="J",T13," ") | AA13: =IF(S13="RP",T13," ") | AB13: =IF(S13="DL",T13," ") | AC13: =IF(S13="X",T13," ")
E14: =IF(F14<>0,"Enter Code"," ") | G14: =IF(E14="BC",F14," ") | H14: =IF(E14="DR",F14," ") | I14: =IF(E14="CR",F14," ") | J14: =IF(E14="K",F14," ") | K14: =IF(E14="RV",F14," ") | L14: =IF(E14="DL",F14," ") | M14: =IF(E14="X",F14," ") | O14: 46174 | P14: Close Brothers Asset Finance | Q14: BNK-HP-INT-001 | R14: HP-2025-01 admin charges and interest | S14: B | T14: 2000 | U14: =IF(S14="BC",T14," ") | V14: =IF(S14="CR",T14," ") | W14: =IF(S14="DR",T14," ") | X14: =IF(S14="W",T14," ") | Y14: =IF(S14="B",T14," ") -> 2000 | Z14: =IF(S14="J",T14," ") | AA14: =IF(S14="RP",T14," ") | AB14: =IF(S14="DL",T14," ") | AC14: =IF(S14="X",T14," ")
E15: =IF(F15<>0,"Enter Code"," ") | G15: =IF(E15="BC",F15," ") | H15: =IF(E15="DR",F15," ") | I15: =IF(E15="CR",F15," ") | J15: =IF(E15="K",F15," ") | K15: =IF(E15="RV",F15," ") | L15: =IF(E15="DL",F15," ") | M15: =IF(E15="X",F15," ") | O15: 46174 | P15: Close Brothers Asset Finance | Q15: BNK-HP-CAP-001 | R15: HP-2025-01 capital repayment | S15: CR | T15: 13000 | U15: =IF(S15="BC",T15," ") | V15: =IF(S15="CR",T15," ") -> 13000 | W15: =IF(S15="DR",T15," ") | X15: =IF(S15="W",T15," ") | Y15: =IF(S15="B",T15," ") | Z15: =IF(S15="J",T15," ") | AA15: =IF(S15="RP",T15," ") | AB15: =IF(S15="DL",T15," ") | AC15: =IF(S15="X",T15," ")
E16: =IF(F16<>0,"Enter Code"," ") | G16: =IF(E16="BC",F16," ") | H16: =IF(E16="DR",F16," ") | I16: =IF(E16="CR",F16," ") | J16: =IF(E16="K",F16," ") | K16: =IF(E16="RV",F16," ") | L16: =IF(E16="DL",F16," ") | M16: =IF(E16="X",F16," ") | S16: =IF(T16<>0,"Enter Code"," ") | U16: =IF(S16="BC",T16," ") | V16: =IF(S16="CR",T16," ") | W16: =IF(S16="DR",T16," ") | X16: =IF(S16="W",T16," ") | Y16: =IF(S16="B",T16," ") | Z16: =IF(S16="J",T16," ") | AA16: =IF(S16="RP",T16," ") | AB16: =IF(S16="DL",T16," ") | AC16: =IF(S16="X",T16," ")
E17: =IF(F17<>0,"Enter Code"," ") | G17: =IF(E17="BC",F17," ") | H17: =IF(E17="DR",F17," ") | I17: =IF(E17="CR",F17," ") | J17: =IF(E17="K",F17," ") | K17: =IF(E17="RV",F17," ") | L17: =IF(E17="DL",F17," ") | M17: =IF(E17="X",F17," ") | S17: =IF(T17<>0,"Enter Code"," ") | U17: =IF(S17="BC",T17," ") | V17: =IF(S17="CR",T17," ") | W17: =IF(S17="DR",T17," ") | X17: =IF(S17="W",T17," ") | Y17: =IF(S17="B",T17," ") | Z17: =IF(S17="J",T17," ") | AA17: =IF(S17="RP",T17," ") | AB17: =IF(S17="DL",T17," ") | AC17: =IF(S17="X",T17," ")
E18: =IF(F18<>0,"Enter Code"," ") | G18: =IF(E18="BC",F18," ") | H18: =IF(E18="DR",F18," ") | I18: =IF(E18="CR",F18," ") | J18: =IF(E18="K",F18," ") | K18: =IF(E18="RV",F18," ") | L18: =IF(E18="DL",F18," ") | M18: =IF(E18="X",F18," ") | S18: =IF(T18<>0,"Enter Code"," ") | U18: =IF(S18="BC",T18," ") | V18: =IF(S18="CR",T18," ") | W18: =IF(S18="DR",T18," ") | X18: =IF(S18="W",T18," ") | Y18: =IF(S18="B",T18," ") | Z18: =IF(S18="J",T18," ") | AA18: =IF(S18="RP",T18," ") | AB18: =IF(S18="DL",T18," ") | AC18: =IF(S18="X",T18," ")
E19: =IF(F19<>0,"Enter Code"," ") | G19: =IF(E19="BC",F19," ") | H19: =IF(E19="DR",F19," ") | I19: =IF(E19="CR",F19," ") | J19: =IF(E19="K",F19," ") | K19: =IF(E19="RV",F19," ") | L19: =IF(E19="DL",F19," ") | M19: =IF(E19="X",F19," ") | S19: =IF(T19<>0,"Enter Code"," ") | U19: =IF(S19="BC",T19," ") | V19: =IF(S19="CR",T19," ") | W19: =IF(S19="DR",T19," ") | X19: =IF(S19="W",T19," ") | Y19: =IF(S19="B",T19," ") | Z19: =IF(S19="J",T19," ") | AA19: =IF(S19="RP",T19," ") | AB19: =IF(S19="DL",T19," ") | AC19: =IF(S19="X",T19," ")
E20: =IF(F20<>0,"Enter Code"," ") | G20: =IF(E20="BC",F20," ") | H20: =IF(E20="DR",F20," ") | I20: =IF(E20="CR",F20," ") | J20: =IF(E20="K",F20," ") | K20: =IF(E20="RV",F20," ") | L20: =IF(E20="DL",F20," ") | M20: =IF(E20="X",F20," ") | S20: =IF(T20<>0,"Enter Code"," ") | U20: =IF(S20="BC",T20," ") | V20: =IF(S20="CR",T20," ") | W20: =IF(S20="DR",T20," ") | X20: =IF(S20="W",T20," ") | Y20: =IF(S20="B",T20," ") | Z20: =IF(S20="J",T20," ") | AA20: =IF(S20="RP",T20," ") | AB20: =IF(S20="DL",T20," ") | AC20: =IF(S20="X",T20," ")
E21: =IF(F21<>0,"Enter Code"," ") | G21: =IF(E21="BC",F21," ") | H21: =IF(E21="DR",F21," ") | I21: =IF(E21="CR",F21," ") | J21: =IF(E21="K",F21," ") | K21: =IF(E21="RV",F21," ") | L21: =IF(E21="DL",F21," ") | M21: =IF(E21="X",F21," ") | S21: =IF(T21<>0,"Enter Code"," ") | U21: =IF(S21="BC",T21," ") | V21: =IF(S21="CR",T21," ") | W21: =IF(S21="DR",T21," ") | X21: =IF(S21="W",T21," ") | Y21: =IF(S21="B",T21," ") | Z21: =IF(S21="J",T21," ") | AA21: =IF(S21="RP",T21," ") | AB21: =IF(S21="DL",T21," ") | AC21: =IF(S21="X",T21," ")
E22: =IF(F22<>0,"Enter Code"," ") | G22: =IF(E22="BC",F22," ") | H22: =IF(E22="DR",F22," ") | I22: =IF(E22="CR",F22," ") | J22: =IF(E22="K",F22," ") | K22: =IF(E22="RV",F22," ") | L22: =IF(E22="DL",F22," ") | M22: =IF(E22="X",F22," ") | S22: =IF(T22<>0,"Enter Code"," ") | U22: =IF(S22="BC",T22," ") | V22: =IF(S22="CR",T22," ") | W22: =IF(S22="DR",T22," ") | X22: =IF(S22="W",T22," ") | Y22: =IF(S22="B",T22," ") | Z22: =IF(S22="J",T22," ") | AA22: =IF(S22="RP",T22," ") | AB22: =IF(S22="DL",T22," ") | AC22: =IF(S22="X",T22," ")
E23: =IF(F23<>0,"Enter Code"," ") | G23: =IF(E23="BC",F23," ") | H23: =IF(E23="DR",F23," ") | I23: =IF(E23="CR",F23," ") | J23: =IF(E23="K",F23," ") | K23: =IF(E23="RV",F23," ") | L23: =IF(E23="DL",F23," ") | M23: =IF(E23="X",F23," ") | S23: =IF(T23<>0,"Enter Code"," ") | U23: =IF(S23="BC",T23," ") | V23: =IF(S23="CR",T23," ") | W23: =IF(S23="DR",T23," ") | X23: =IF(S23="W",T23," ") | Y23: =IF(S23="B",T23," ") | Z23: =IF(S23="J",T23," ") | AA23: =IF(S23="RP",T23," ") | AB23: =IF(S23="DL",T23," ") | AC23: =IF(S23="X",T23," ")
E24: =IF(F24<>0,"Enter Code"," ") | G24: =IF(E24="BC",F24," ") | H24: =IF(E24="DR",F24," ") | I24: =IF(E24="CR",F24," ") | J24: =IF(E24="K",F24," ") | K24: =IF(E24="RV",F24," ") | L24: =IF(E24="DL",F24," ") | M24: =IF(E24="X",F24," ") | S24: =IF(T24<>0,"Enter Code"," ") | U24: =IF(S24="BC",T24," ") | V24: =IF(S24="CR",T24," ") | W24: =IF(S24="DR",T24," ") | X24: =IF(S24="W",T24," ") | Y24: =IF(S24="B",T24," ") | Z24: =IF(S24="J",T24," ") | AA24: =IF(S24="RP",T24," ") | AB24: =IF(S24="DL",T24," ") | AC24: =IF(S24="X",T24," ")
E25: =IF(F25<>0,"Enter Code"," ") | G25: =IF(E25="BC",F25," ") | H25: =IF(E25="DR",F25," ") | I25: =IF(E25="CR",F25," ") | J25: =IF(E25="K",F25," ") | K25: =IF(E25="RV",F25," ") | L25: =IF(E25="DL",F25," ") | M25: =IF(E25="X",F25," ") | S25: =IF(T25<>0,"Enter Code"," ") | U25: =IF(S25="BC",T25," ") | V25: =IF(S25="CR",T25," ") | W25: =IF(S25="DR",T25," ") | X25: =IF(S25="W",T25," ") | Y25: =IF(S25="B",T25," ") | Z25: =IF(S25="J",T25," ") | AA25: =IF(S25="RP",T25," ") | AB25: =IF(S25="DL",T25," ") | AC25: =IF(S25="X",T25," ")
E26: =IF(F26<>0,"Enter Code"," ") | G26: =IF(E26="BC",F26," ") | H26: =IF(E26="DR",F26," ") | I26: =IF(E26="CR",F26," ") | J26: =IF(E26="K",F26," ") | K26: =IF(E26="RV",F26," ") | L26: =IF(E26="DL",F26," ") | M26: =IF(E26="X",F26," ") | S26: =IF(T26<>0,"Enter Code"," ") | U26: =IF(S26="BC",T26," ") | V26: =IF(S26="CR",T26," ") | W26: =IF(S26="DR",T26," ") | X26: =IF(S26="W",T26," ") | Y26: =IF(S26="B",T26," ") | Z26: =IF(S26="J",T26," ") | AA26: =IF(S26="RP",T26," ") | AB26: =IF(S26="DL",T26," ") | AC26: =IF(S26="X",T26," ")
E27: =IF(F27<>0,"Enter Code"," ") | G27: =IF(E27="BC",F27," ") | H27: =IF(E27="DR",F27," ") | I27: =IF(E27="CR",F27," ") | J27: =IF(E27="K",F27," ") | K27: =IF(E27="RV",F27," ") | L27: =IF(E27="DL",F27," ") | M27: =IF(E27="X",F27," ") | S27: =IF(T27<>0,"Enter Code"," ") | U27: =IF(S27="BC",T27," ") | V27: =IF(S27="CR",T27," ") | W27: =IF(S27="DR",T27," ") | X27: =IF(S27="W",T27," ") | Y27: =IF(S27="B",T27," ") | Z27: =IF(S27="J",T27," ") | AA27: =IF(S27="RP",T27," ") | AB27: =IF(S27="DL",T27," ") | AC27: =IF(S27="X",T27," ")
... E200: =IF(F200<>0,"Enter Code"," ") | G200: =IF(E200="BC",F200," ") | H200: =IF(E200="DR",F200," ") | I200: =IF(E200="CR",F200," ") | J200: =IF(E200="K",F200," ") | K200: =IF(E200="RV",F200," ") | L200: =IF(E200="DL",F200," ") | M200: =IF(E200="X",F200," ") | S200: =IF(T200<>0,"Enter Code"," ") | U200: =IF(S200="BC",T200," ") | V200: =IF(S200="CR",T200," ") | W200: =IF(S200="DR",T200," ") | X200: =IF(S200="W",T200," ") | Y200: =IF(S200="B",T200," ") | Z200: =IF(S200="J",T200," ") | AA200: =IF(S200="RP",T200," ") | AB200: =IF(S200="DL",T200," ") | AC200: =IF(S200="X",T200," ")

Sheet Jul
A1: =Jun!A2 -> 82969.4 | B1: < Opening Bank Balance | C1: =Jun!C2 -> 46203 | D1: Totals > | E1: =F1-SUM(G1:M1) -> 0 | F1: =SUM(F6:F200) -> 33760 | G1: =SUM(G6:G200) -> 0 | H1: =SUM(H6:H200) -> 33760 | I1: =SUM(I6:I200) -> 0 | J1: =SUM(J6:J200) -> 0 | K1: =SUM(K6:K200) -> 0 | L1: =SUM(L6:L200) -> 0 | M1: =SUM(M6:M200) -> 0 | O1: =IF(S1=0," ","Check all payment code letters entered") | R1: Totals > | S1: =T1-SUM(U1:AC1) -> 0 | T1: =SUM(T6:T200) -> 16425.2 | U1: =SUM(U6:U200) -> 0 | V1: =SUM(V6:V200) -> 3800 | W1: =SUM(W6:W200) -> 0 | X1: =SUM(X6:X200) -> 5652 | Y1: =SUM(Y6:Y200) -> 0 | Z1: =SUM(Z6:Z200) -> 0 | AA1: =SUM(AA6:AA200) -> 2673.2 | ... AC1: =SUM(AC6:AC200) -> 300
A2: =A1+F1-T1 -> 100304.2 | B2: < Closing Bank Balance | C2: =[1]Admin!$B$8 -> 46234 | D2: Deposit Bank Reference | E2: Enter Code Letters | F2: ENTER BANK RECEIPTS | G2: CURRENT ACCOUNT STATEMENT RECEIPTS | O2: =IF(E1=0," ","Check all Receipts Code Letters entered") | Q2: Enter Purchase Invoice No. | R2: Cheque number Direct Debit | S2: Enter Code Letters | T2: ENTER BANK PAYMENT | U2: CURRENT ACCOUNT STATEMENT PAYMENTS
B3: < Statement Bank Balance | C3: =C2 -> 46234 | G3: Cash paid into Bank | H3: Amount Received Debtors | I3: Amount Received Creditors | J3: Bank Interest Received | K3: HMRC Refunded | L3: Capital Introduced | M3: Bank Contra items | U3: Cash Withdrawn from Bank | V3: Amount Paid Creditors | W3: Amount Paid Debtors | X3: Net Wages Paid | Y3: HP Interest Leasing & Bank Charges | Z3: Bank Loan & Overdraft Interest | AA3: HMRC Payments | AB3: Drawings | AC3: Bank Contra items
A4: =A2-A3 -> 100304.2 | B4: =IF(A4=0,"< Bank Balances with Statement","< Check Bank Entries With Statement") -> < Check Bank Entries With Statement | O4: Payment Date | P4: Suppliers paid
A5: Date | B5: Source of Funds Received | C5: Sales Invoice | G5: BC | H5: DR | I5: CR | J5: K | K5: RV | L5: DL | M5: X | U5: BC | V5: CR | W5: DR | X5: W | Y5: B | Z5: J | AA5: RP | AB5: DL | AC5: X
A6: 46223 | B6: Acme Corp | C6: BNK-DR-004 | D6: Customer receipt | E6: DR | F6: 8000 | G6: =IF(E6="BC",F6," ") | H6: =IF(E6="DR",F6," ") -> 8000 | I6: =IF(E6="CR",F6," ") | J6: =IF(E6="K",F6," ") | K6: =IF(E6="RV",F6," ") | L6: =IF(E6="DL",F6," ") | M6: =IF(E6="X",F6," ") | O6: 46204 | P6: WorkSpace Ltd | Q6: BNK-CR-004 | R6: Office rent payment | S6: CR | T6: 1200 | U6: =IF(S6="BC",T6," ") | V6: =IF(S6="CR",T6," ") -> 1200 | W6: =IF(S6="DR",T6," ") | X6: =IF(S6="W",T6," ") | Y6: =IF(S6="B",T6," ") | Z6: =IF(S6="J",T6," ") | AA6: =IF(S6="RP",T6," ") | AB6: =IF(S6="DL",T6," ") | AC6: =IF(S6="X",T6," ")
A7: 46228 | B7: TechStart Ltd | C7: BNK-DR-016 | D7: Customer receipt | E7: DR | F7: 2400 | G7: =IF(E7="BC",F7," ") | H7: =IF(E7="DR",F7," ") -> 2400 | I7: =IF(E7="CR",F7," ") | J7: =IF(E7="K",F7," ") | K7: =IF(E7="RV",F7," ") | L7: =IF(E7="DL",F7," ") | M7: =IF(E7="X",F7," ") | O7: 46204 | P7: Director | Q7: BNK-DL-004 | R7: Directors loan repayment | S7: DL | T7: 1000 | U7: =IF(S7="BC",T7," ") | V7: =IF(S7="CR",T7," ") | W7: =IF(S7="DR",T7," ") | X7: =IF(S7="W",T7," ") | Y7: =IF(S7="B",T7," ") | Z7: =IF(S7="J",T7," ") | AA7: =IF(S7="RP",T7," ") | AB7: =IF(S7="DL",T7," ") -> 1000 | AC7: =IF(S7="X",T7," ")
A8: 46231 | B8: Various customers | C8: BNK-DR-028 | D8: Aggregate customer receipts | E8: DR | F8: 23360 | G8: =IF(E8="BC",F8," ") | H8: =IF(E8="DR",F8," ") -> 23360 | I8: =IF(E8="CR",F8," ") | J8: =IF(E8="K",F8," ") | K8: =IF(E8="RV",F8," ") | L8: =IF(E8="DL",F8," ") | M8: =IF(E8="X",F8," ") | O8: 46208 | P8: Various suppliers | Q8: BNK-CR-MISC-004 | R8: Aggregate supplier payments | S8: CR | T8: 2300 | U8: =IF(S8="BC",T8," ") | V8: =IF(S8="CR",T8," ") -> 2300 | W8: =IF(S8="DR",T8," ") | X8: =IF(S8="W",T8," ") | Y8: =IF(S8="B",T8," ") | Z8: =IF(S8="J",T8," ") | AA8: =IF(S8="RP",T8," ") | AB8: =IF(S8="DL",T8," ") | AC8: =IF(S8="X",T8," ")
E9: =IF(F9<>0,"Enter Code"," ") | G9: =IF(E9="BC",F9," ") | H9: =IF(E9="DR",F9," ") | I9: =IF(E9="CR",F9," ") | J9: =IF(E9="K",F9," ") | K9: =IF(E9="RV",F9," ") | L9: =IF(E9="DL",F9," ") | M9: =IF(E9="X",F9," ") | O9: 46218 | P9: Proprietor | Q9: BNK-DV-001 | R9: Quarterly drawings payment | S9: DL | T9: 3000 | U9: =IF(S9="BC",T9," ") | V9: =IF(S9="CR",T9," ") | W9: =IF(S9="DR",T9," ") | X9: =IF(S9="W",T9," ") | Y9: =IF(S9="B",T9," ") | Z9: =IF(S9="J",T9," ") | AA9: =IF(S9="RP",T9," ") | AB9: =IF(S9="DL",T9," ") -> 3000 | AC9: =IF(S9="X",T9," ")
E10: =IF(F10<>0,"Enter Code"," ") | G10: =IF(E10="BC",F10," ") | H10: =IF(E10="DR",F10," ") | I10: =IF(E10="CR",F10," ") | J10: =IF(E10="K",F10," ") | K10: =IF(E10="RV",F10," ") | L10: =IF(E10="DL",F10," ") | M10: =IF(E10="X",F10," ") | O10: 46222 | P10: HMRC | Q10: BNK-RP-004 | R10: Monthly PAYE/NI payment | S10: RP | T10: 1673.2 | U10: =IF(S10="BC",T10," ") | V10: =IF(S10="CR",T10," ") | W10: =IF(S10="DR",T10," ") | X10: =IF(S10="W",T10," ") | Y10: =IF(S10="B",T10," ") | Z10: =IF(S10="J",T10," ") | AA10: =IF(S10="RP",T10," ") -> 1673.2 | AB10: =IF(S10="DL",T10," ") | AC10: =IF(S10="X",T10," ")
E11: =IF(F11<>0,"Enter Code"," ") | G11: =IF(E11="BC",F11," ") | H11: =IF(E11="DR",F11," ") | I11: =IF(E11="CR",F11," ") | J11: =IF(E11="K",F11," ") | K11: =IF(E11="RV",F11," ") | L11: =IF(E11="DL",F11," ") | M11: =IF(E11="X",F11," ") | O11: 46222 | P11: HMRC | Q11: BNK-RC-CIS-001 | R11: CIS deduction remittance | S11: RP | T11: 1000 | U11: =IF(S11="BC",T11," ") | V11: =IF(S11="CR",T11," ") | W11: =IF(S11="DR",T11," ") | X11: =IF(S11="W",T11," ") | Y11: =IF(S11="B",T11," ") | Z11: =IF(S11="J",T11," ") | AA11: =IF(S11="RP",T11," ") -> 1000 | AB11: =IF(S11="DL",T11," ") | AC11: =IF(S11="X",T11," ")
E12: =IF(F12<>0,"Enter Code"," ") | G12: =IF(E12="BC",F12," ") | H12: =IF(E12="DR",F12," ") | I12: =IF(E12="CR",F12," ") | J12: =IF(E12="K",F12," ") | K12: =IF(E12="RV",F12," ") | L12: =IF(E12="DL",F12," ") | M12: =IF(E12="X",F12," ") | O12: 46231 | P12: Payroll | Q12: BNK-W-004 | R12: Monthly net wages (all staff) | S12: W | T12: 5652 | U12: =IF(S12="BC",T12," ") | V12: =IF(S12="CR",T12," ") | W12: =IF(S12="DR",T12," ") | X12: =IF(S12="W",T12," ") -> 5652 | Y12: =IF(S12="B",T12," ") | Z12: =IF(S12="J",T12," ") | AA12: =IF(S12="RP",T12," ") | AB12: =IF(S12="DL",T12," ") | AC12: =IF(S12="X",T12," ")
E13: =IF(F13<>0,"Enter Code"," ") | G13: =IF(E13="BC",F13," ") | H13: =IF(E13="DR",F13," ") | I13: =IF(E13="CR",F13," ") | J13: =IF(E13="K",F13," ") | K13: =IF(E13="RV",F13," ") | L13: =IF(E13="DL",F13," ") | M13: =IF(E13="X",F13," ") | O13: 46234 | P13: Smith & Co | Q13: BNK-CR-016 | R13: Accountancy fee payment | S13: CR | T13: 300 | U13: =IF(S13="BC",T13," ") | V13: =IF(S13="CR",T13," ") -> 300 | W13: =IF(S13="DR",T13," ") | X13: =IF(S13="W",T13," ") | Y13: =IF(S13="B",T13," ") | Z13: =IF(S13="J",T13," ") | AA13: =IF(S13="RP",T13," ") | AB13: =IF(S13="DL",T13," ") | AC13: =IF(S13="X",T13," ")
E14: =IF(F14<>0,"Enter Code"," ") | G14: =IF(E14="BC",F14," ") | H14: =IF(E14="DR",F14," ") | I14: =IF(E14="CR",F14," ") | J14: =IF(E14="K",F14," ") | K14: =IF(E14="RV",F14," ") | L14: =IF(E14="DL",F14," ") | M14: =IF(E14="X",F14," ") | O14: 46234 | P14: Credit card payment | Q14: BNK-X-CC-002 | R14: Pay credit card balance | S14: X | T14: 300 | U14: =IF(S14="BC",T14," ") | V14: =IF(S14="CR",T14," ") | W14: =IF(S14="DR",T14," ") | X14: =IF(S14="W",T14," ") | Y14: =IF(S14="B",T14," ") | Z14: =IF(S14="J",T14," ") | AA14: =IF(S14="RP",T14," ") | AB14: =IF(S14="DL",T14," ") | AC14: =IF(S14="X",T14," ") -> 300
E15: =IF(F15<>0,"Enter Code"," ") | G15: =IF(E15="BC",F15," ") | H15: =IF(E15="DR",F15," ") | I15: =IF(E15="CR",F15," ") | J15: =IF(E15="K",F15," ") | K15: =IF(E15="RV",F15," ") | L15: =IF(E15="DL",F15," ") | M15: =IF(E15="X",F15," ") | S15: =IF(T15<>0,"Enter Code"," ") | U15: =IF(S15="BC",T15," ") | V15: =IF(S15="CR",T15," ") | W15: =IF(S15="DR",T15," ") | X15: =IF(S15="W",T15," ") | Y15: =IF(S15="B",T15," ") | Z15: =IF(S15="J",T15," ") | AA15: =IF(S15="RP",T15," ") | AB15: =IF(S15="DL",T15," ") | AC15: =IF(S15="X",T15," ")
E16: =IF(F16<>0,"Enter Code"," ") | G16: =IF(E16="BC",F16," ") | H16: =IF(E16="DR",F16," ") | I16: =IF(E16="CR",F16," ") | J16: =IF(E16="K",F16," ") | K16: =IF(E16="RV",F16," ") | L16: =IF(E16="DL",F16," ") | M16: =IF(E16="X",F16," ") | S16: =IF(T16<>0,"Enter Code"," ") | U16: =IF(S16="BC",T16," ") | V16: =IF(S16="CR",T16," ") | W16: =IF(S16="DR",T16," ") | X16: =IF(S16="W",T16," ") | Y16: =IF(S16="B",T16," ") | Z16: =IF(S16="J",T16," ") | AA16: =IF(S16="RP",T16," ") | AB16: =IF(S16="DL",T16," ") | AC16: =IF(S16="X",T16," ")
E17: =IF(F17<>0,"Enter Code"," ") | G17: =IF(E17="BC",F17," ") | H17: =IF(E17="DR",F17," ") | I17: =IF(E17="CR",F17," ") | J17: =IF(E17="K",F17," ") | K17: =IF(E17="RV",F17," ") | L17: =IF(E17="DL",F17," ") | M17: =IF(E17="X",F17," ") | S17: =IF(T17<>0,"Enter Code"," ") | U17: =IF(S17="BC",T17," ") | V17: =IF(S17="CR",T17," ") | W17: =IF(S17="DR",T17," ") | X17: =IF(S17="W",T17," ") | Y17: =IF(S17="B",T17," ") | Z17: =IF(S17="J",T17," ") | AA17: =IF(S17="RP",T17," ") | AB17: =IF(S17="DL",T17," ") | AC17: =IF(S17="X",T17," ")
E18: =IF(F18<>0,"Enter Code"," ") | G18: =IF(E18="BC",F18," ") | H18: =IF(E18="DR",F18," ") | I18: =IF(E18="CR",F18," ") | J18: =IF(E18="K",F18," ") | K18: =IF(E18="RV",F18," ") | L18: =IF(E18="DL",F18," ") | M18: =IF(E18="X",F18," ") | S18: =IF(T18<>0,"Enter Code"," ") | U18: =IF(S18="BC",T18," ") | V18: =IF(S18="CR",T18," ") | W18: =IF(S18="DR",T18," ") | X18: =IF(S18="W",T18," ") | Y18: =IF(S18="B",T18," ") | Z18: =IF(S18="J",T18," ") | AA18: =IF(S18="RP",T18," ") | AB18: =IF(S18="DL",T18," ") | AC18: =IF(S18="X",T18," ")
E19: =IF(F19<>0,"Enter Code"," ") | G19: =IF(E19="BC",F19," ") | H19: =IF(E19="DR",F19," ") | I19: =IF(E19="CR",F19," ") | J19: =IF(E19="K",F19," ") | K19: =IF(E19="RV",F19," ") | L19: =IF(E19="DL",F19," ") | M19: =IF(E19="X",F19," ") | S19: =IF(T19<>0,"Enter Code"," ") | U19: =IF(S19="BC",T19," ") | V19: =IF(S19="CR",T19," ") | W19: =IF(S19="DR",T19," ") | X19: =IF(S19="W",T19," ") | Y19: =IF(S19="B",T19," ") | Z19: =IF(S19="J",T19," ") | AA19: =IF(S19="RP",T19," ") | AB19: =IF(S19="DL",T19," ") | AC19: =IF(S19="X",T19," ")
E20: =IF(F20<>0,"Enter Code"," ") | G20: =IF(E20="BC",F20," ") | H20: =IF(E20="DR",F20," ") | I20: =IF(E20="CR",F20," ") | J20: =IF(E20="K",F20," ") | K20: =IF(E20="RV",F20," ") | L20: =IF(E20="DL",F20," ") | M20: =IF(E20="X",F20," ") | S20: =IF(T20<>0,"Enter Code"," ") | U20: =IF(S20="BC",T20," ") | V20: =IF(S20="CR",T20," ") | W20: =IF(S20="DR",T20," ") | X20: =IF(S20="W",T20," ") | Y20: =IF(S20="B",T20," ") | Z20: =IF(S20="J",T20," ") | AA20: =IF(S20="RP",T20," ") | AB20: =IF(S20="DL",T20," ") | AC20: =IF(S20="X",T20," ")
E21: =IF(F21<>0,"Enter Code"," ") | G21: =IF(E21="BC",F21," ") | H21: =IF(E21="DR",F21," ") | I21: =IF(E21="CR",F21," ") | J21: =IF(E21="K",F21," ") | K21: =IF(E21="RV",F21," ") | L21: =IF(E21="DL",F21," ") | M21: =IF(E21="X",F21," ") | S21: =IF(T21<>0,"Enter Code"," ") | U21: =IF(S21="BC",T21," ") | V21: =IF(S21="CR",T21," ") | W21: =IF(S21="DR",T21," ") | X21: =IF(S21="W",T21," ") | Y21: =IF(S21="B",T21," ") | Z21: =IF(S21="J",T21," ") | AA21: =IF(S21="RP",T21," ") | AB21: =IF(S21="DL",T21," ") | AC21: =IF(S21="X",T21," ")
E22: =IF(F22<>0,"Enter Code"," ") | G22: =IF(E22="BC",F22," ") | H22: =IF(E22="DR",F22," ") | I22: =IF(E22="CR",F22," ") | J22: =IF(E22="K",F22," ") | K22: =IF(E22="RV",F22," ") | L22: =IF(E22="DL",F22," ") | M22: =IF(E22="X",F22," ") | S22: =IF(T22<>0,"Enter Code"," ") | U22: =IF(S22="BC",T22," ") | V22: =IF(S22="CR",T22," ") | W22: =IF(S22="DR",T22," ") | X22: =IF(S22="W",T22," ") | Y22: =IF(S22="B",T22," ") | Z22: =IF(S22="J",T22," ") | AA22: =IF(S22="RP",T22," ") | AB22: =IF(S22="DL",T22," ") | AC22: =IF(S22="X",T22," ")
E23: =IF(F23<>0,"Enter Code"," ") | G23: =IF(E23="BC",F23," ") | H23: =IF(E23="DR",F23," ") | I23: =IF(E23="CR",F23," ") | J23: =IF(E23="K",F23," ") | K23: =IF(E23="RV",F23," ") | L23: =IF(E23="DL",F23," ") | M23: =IF(E23="X",F23," ") | S23: =IF(T23<>0,"Enter Code"," ") | U23: =IF(S23="BC",T23," ") | V23: =IF(S23="CR",T23," ") | W23: =IF(S23="DR",T23," ") | X23: =IF(S23="W",T23," ") | Y23: =IF(S23="B",T23," ") | Z23: =IF(S23="J",T23," ") | AA23: =IF(S23="RP",T23," ") | AB23: =IF(S23="DL",T23," ") | AC23: =IF(S23="X",T23," ")
E24: =IF(F24<>0,"Enter Code"," ") | G24: =IF(E24="BC",F24," ") | H24: =IF(E24="DR",F24," ") | I24: =IF(E24="CR",F24," ") | J24: =IF(E24="K",F24," ") | K24: =IF(E24="RV",F24," ") | L24: =IF(E24="DL",F24," ") | M24: =IF(E24="X",F24," ") | S24: =IF(T24<>0,"Enter Code"," ") | U24: =IF(S24="BC",T24," ") | V24: =IF(S24="CR",T24," ") | W24: =IF(S24="DR",T24," ") | X24: =IF(S24="W",T24," ") | Y24: =IF(S24="B",T24," ") | Z24: =IF(S24="J",T24," ") | AA24: =IF(S24="RP",T24," ") | AB24: =IF(S24="DL",T24," ") | AC24: =IF(S24="X",T24," ")
E25: =IF(F25<>0,"Enter Code"," ") | G25: =IF(E25="BC",F25," ") | H25: =IF(E25="DR",F25," ") | I25: =IF(E25="CR",F25," ") | J25: =IF(E25="K",F25," ") | K25: =IF(E25="RV",F25," ") | L25: =IF(E25="DL",F25," ") | M25: =IF(E25="X",F25," ") | S25: =IF(T25<>0,"Enter Code"," ") | U25: =IF(S25="BC",T25," ") | V25: =IF(S25="CR",T25," ") | W25: =IF(S25="DR",T25," ") | X25: =IF(S25="W",T25," ") | Y25: =IF(S25="B",T25," ") | Z25: =IF(S25="J",T25," ") | AA25: =IF(S25="RP",T25," ") | AB25: =IF(S25="DL",T25," ") | AC25: =IF(S25="X",T25," ")
E26: =IF(F26<>0,"Enter Code"," ") | G26: =IF(E26="BC",F26," ") | H26: =IF(E26="DR",F26," ") | I26: =IF(E26="CR",F26," ") | J26: =IF(E26="K",F26," ") | K26: =IF(E26="RV",F26," ") | L26: =IF(E26="DL",F26," ") | M26: =IF(E26="X",F26," ") | S26: =IF(T26<>0,"Enter Code"," ") | U26: =IF(S26="BC",T26," ") | V26: =IF(S26="CR",T26," ") | W26: =IF(S26="DR",T26," ") | X26: =IF(S26="W",T26," ") | Y26: =IF(S26="B",T26," ") | Z26: =IF(S26="J",T26," ") | AA26: =IF(S26="RP",T26," ") | AB26: =IF(S26="DL",T26," ") | AC26: =IF(S26="X",T26," ")
... E200: =IF(F200<>0,"Enter Code"," ") | G200: =IF(E200="BC",F200," ") | H200: =IF(E200="DR",F200," ") | I200: =IF(E200="CR",F200," ") | J200: =IF(E200="K",F200," ") | K200: =IF(E200="RV",F200," ") | L200: =IF(E200="DL",F200," ") | M200: =IF(E200="X",F200," ") | S200: =IF(T200<>0,"Enter Code"," ") | U200: =IF(S200="BC",T200," ") | V200: =IF(S200="CR",T200," ") | W200: =IF(S200="DR",T200," ") | X200: =IF(S200="W",T200," ") | Y200: =IF(S200="B",T200," ") | Z200: =IF(S200="J",T200," ") | AA200: =IF(S200="RP",T200," ") | AB200: =IF(S200="DL",T200," ") | AC200: =IF(S200="X",T200," ")

Sheet Aug
A1: =Jul!A2 -> 100304.2 | B1: < Opening Bank Balance | C1: =Jul!C2 -> 46234 | D1: Totals > | E1: =F1-SUM(G1:M1) -> 0 | F1: =SUM(F6:F200) -> 38520 | G1: =SUM(G6:G200) -> 0 | H1: =SUM(H6:H200) -> 38520 | I1: =SUM(I6:I200) -> 0 | J1: =SUM(J6:J200) -> 0 | K1: =SUM(K6:K200) -> 0 | L1: =SUM(L6:L200) -> 0 | M1: =SUM(M6:M200) -> 0 | O1: =IF(S1=0," ","Check all payment code letters entered") | R1: Totals > | S1: =T1-SUM(U1:AC1) -> 0 | T1: =SUM(T6:T200) -> 26233.37 | U1: =SUM(U6:U200) -> 0 | V1: =SUM(V6:V200) -> 4100 | W1: =SUM(W6:W200) -> 0 | X1: =SUM(X6:X200) -> 5652 | Y1: =SUM(Y6:Y200) -> 0 | Z1: =SUM(Z6:Z200) -> 0 | AA1: =SUM(AA6:AA200) -> 15481.37 | ... AC1: =SUM(AC6:AC200) -> 0
A2: =A1+F1-T1 -> 112590.83 | B2: < Closing Bank Balance | C2: =[1]Admin!$B$9 -> 46265 | D2: Deposit Bank Reference | E2: Enter Code Letters | F2: ENTER BANK RECEIPTS | G2: CURRENT ACCOUNT STATEMENT RECEIPTS | O2: =IF(E1=0," ","Check all Receipts Code Letters entered") | Q2: Enter Purchase Invoice No. | R2: Cheque number Direct Debit | S2: Enter Code Letters | T2: ENTER BANK PAYMENT | U2: CURRENT ACCOUNT STATEMENT PAYMENTS
B3: < Statement Bank Balance | C3: =C2 -> 46265 | G3: Cash paid into Bank | H3: Amount Received Debtors | I3: Amount Received Creditors | J3: Bank Interest Received | K3: HMRC Refunded | L3: Capital Introduced | M3: Bank Contra items | U3: Cash Withdrawn from Bank | V3: Amount Paid Creditors | W3: Amount Paid Debtors | X3: Net Wages Paid | Y3: HP Interest Leasing & Bank Charges | Z3: Bank Loan & Overdraft Interest | AA3: HMRC Payments | AB3: Drawings | AC3: Bank Contra items
A4: =A2-A3 -> 112590.83 | B4: =IF(A4=0,"< Bank Balances with Statement","< Check Bank Entries With Statement") -> < Check Bank Entries With Statement | O4: Payment Date | P4: Suppliers paid
A5: Date | B5: Source of Funds Received | C5: Sales Invoice | G5: BC | H5: DR | I5: CR | J5: K | K5: RV | L5: DL | M5: X | U5: BC | V5: CR | W5: DR | X5: W | Y5: B | Z5: J | AA5: RP | AB5: DL | AC5: X
A6: 46239 | B6: Innovate UK | C6: BNK-RV-001 | D6: Grant received | E6: DR | F6: 2500 | G6: =IF(E6="BC",F6," ") | H6: =IF(E6="DR",F6," ") -> 2500 | I6: =IF(E6="CR",F6," ") | J6: =IF(E6="K",F6," ") | K6: =IF(E6="RV",F6," ") | L6: =IF(E6="DL",F6," ") | M6: =IF(E6="X",F6," ") | O6: 46241 | P6: HMRC | Q6: BNK-RV-VAT-001 | R6: VAT payment Q1 Apr-Jun | S6: RP | T6: 13808.17 | U6: =IF(S6="BC",T6," ") | V6: =IF(S6="CR",T6," ") | W6: =IF(S6="DR",T6," ") | X6: =IF(S6="W",T6," ") | Y6: =IF(S6="B",T6," ") | Z6: =IF(S6="J",T6," ") | AA6: =IF(S6="RP",T6," ") -> 13808.17 | AB6: =IF(S6="DL",T6," ") | AC6: =IF(S6="X",T6," ")
A7: 46254 | B7: Acme Corp | C7: BNK-DR-005 | D7: Customer receipt | E7: DR | F7: 8000 | G7: =IF(E7="BC",F7," ") | H7: =IF(E7="DR",F7," ") -> 8000 | I7: =IF(E7="CR",F7," ") | J7: =IF(E7="K",F7," ") | K7: =IF(E7="RV",F7," ") | L7: =IF(E7="DL",F7," ") | M7: =IF(E7="X",F7," ") | O7: 46235 | P7: WorkSpace Ltd | Q7: BNK-CR-005 | R7: Office rent payment | S7: CR | T7: 1200 | U7: =IF(S7="BC",T7," ") | V7: =IF(S7="CR",T7," ") -> 1200 | W7: =IF(S7="DR",T7," ") | X7: =IF(S7="W",T7," ") | Y7: =IF(S7="B",T7," ") | Z7: =IF(S7="J",T7," ") | AA7: =IF(S7="RP",T7," ") | AB7: =IF(S7="DL",T7," ") | AC7: =IF(S7="X",T7," ")
