Workbook

Sheet Business Details
A1: ENTER YOUR BUSINESS DETAILS - which are then transferred to the Self-employment Tax Return
C3: Your name | N3: Your unique taxpayer reference (UTR)
C5: Precision Code Trading
A9: Business details
A11: 1 | C11: Business name - unless it is in your own name | L11: 5 | N11: If the details in boxes 1,2,3 or 4 have changed in the
N12: 12 months put 'X' in the box and give details in the
N13: 'Any other information' box
A16: 2 | C16: Description of business | L16: 6 | N16: If your business started after | S16: =Admin!B4 -> 46118
C17: IT consultancy and software development | N17: enter the start date DD/MM/YYYY
L21: 7 | N21: If your business ceased before | S21: =Admin!B17 -> 46482
N22: enter the final date of trading
A23: 3 | C23: First line of your business address - unless you work
C24: from home
L25: 8 | N25: Date your books or accounts start - the beginning of
N26: your accounting period
A29: 4 | C29: Postcode of your business | L29: 9 | N29: Date your books or accounts are made up to or the end
N30: of your accounting period - read page SEFN 3 of the
N31: notes if you have filled in box 6 or 7
A34: Other information
A36: 10 | C36: If you used traditional accounting rather than cash basis to | L36: 13 | N36: If special arrangements apply, put 'X' in the box - read the
C37: calculate your income and expenses, put 'X' in the box | N37: notes
C41: Boxes 11 and 12 are not in use | L41: 14 | N41: ="If you have provided the information about your "&Admin!G2 -> If you have provided the information about your 2026-27
N42: profit on last year's Tax Return put 'X' in the box
A48: 26 | C48: ENTER: Total losses brought forward from earlier years | L48: 24 | N48: ENTER: Value of goods and services for your own use
N49: - read page SESN 7 of the notes
C50: £ | D50: 0 | G50: . | H50: 0 | I50: 0 | N50: £ | O50: 640 | R50: . | S50: 0 | T50: 0
C52: Loss used this year | N52: Total loss carried forward to future years
C53: Calculated no entry required | N53: Calculated no entry required
C55: £ | D55: ='SE Short'!O94 -> 0 | G55: . | H55: 0 | I55: 0 | N55: £ | O55: =D50-D55+'SE Short'!O106 -> 0 | R55: . | S55: 0 | T55: 0
C57: ENTER: Overlap profit brought forward from earlier years | N57: ENTER: Transition profit not yet treated as arising at the start of this tax year
C58: - box 69; the 2023-24 return uses all of it | N58: - your 2023-24 transition profit less every amount already charged
C59: £ | D59: 2400 | G59: . | H59: 0 | I59: 0 | N59: £ | O59: 6000 | R59: . | S59: 0 | T59: 0
C61: Overlap relief used this year | N61: Transition profit treated as arising this year, before any election
C62: Calculated no entry required | N62: Calculated no entry required
C64: £ | D64: =IF(YEAR(Admin!$B$17)=2024,D59,0) -> 0 | G64: . | H64: 0 | I64: 0 | N64: £ | O64: =IF(YEAR(Admin!$B$17)<2024,0,O59/MAX(1,2029-YEAR(Admin!$B$17))) -> 3000 | R64: . | S64: 0 | T64: 0
C66: Overlap profit carried forward | N66: ENTER: Additional transition profit you elect to treat as arising this year
C67: Calculated no entry required | N67: - the election itself goes in box 103
C69: £ | D69: =D59-D64 -> 2400 | G69: . | H69: 0 | I69: 0 | N69: £ | O69: 1000 | R69: . | S69: 0 | T69: 0
C71: ENTER: Profit of your next accounting period, a loss with a minus sign, provisional until its accounts are final | N71: Transition profit carried forward to next year
C72: - only if box 9 is not 31 March to 5 April; box 68 apportions both periods to the tax year by days | N72: Calculated no entry required
...

Sheet SE Short
A1: HM Revenue & Customs | G1: COPY DETAILS TO HMRC FORM Submit HMRC RETURN ONLINE by 31st January 2027 | O1: Self-employment (short)
O2: Tax year | Q2: =Admin!B4 -> 46118 | U2: to | V2: =Admin!B17 -> 46482
C6: Your name | N6: Your unique taxpayer reference (UTR)
C8: =IF('Business Details'!C5>0,'Business Details'!C5:J5," ") -> Precision Code Trading | O8: =IF('Business Details'!O5>0,'Business Details'!O5," ") | R8: =IF('Business Details'!R5>0,'Business Details'!R5," ")
A10: Business details
A12: 1 | C12: Description of business | L12: 4 | N12: If you are a foster carer or adult placement carer, put 'X'
C13: =IF('Business Details'!C17>0,'Business Details'!C17," ") -> IT consultancy and software development | N13: in the box - read page SESN 2 of the notes
C15: =IF('Business Details'!C19>0,'Business Details'!C19," ") | N15: =IF('Business Details'!N14="X","X"," ")
C17: =IF('Business Details'!C21>0,'Business Details'!C21," ") | L17: 5 | N17: If your business started after | S17: =Q2 -> 46118
N18: enter the start date DD/MM/YYYY
A20: 2 | C20: Postcode of your business | N20: =IF('Business Details'!N19>0,'Business Details'!N19," ")
C22: =IF('Business Details'!C30>0,'Business Details'!C30," ") | F22: =IF('Business Details'!F30>0,'Business Details'!F30," ")
L23: 6 | N23: If your business ceased before | S23: =V2 -> 46482
A24: 3 | C24: If your business name, description, address or postcode | N24: enter the final date of trading
C25: have changed in the last 12 months, put 'X' in the box
C26: and give details in the 'Any other information' box of | N26: =IF('Business Details'!N24>0,'Business Details'!N24," ")
C27: of your Tax Return
L28: 7 | N28: Date your books or accounts are made up to - read
N29: page SESN 2 of the notes
N31: =Admin!B17 -> 46482
A33: =IF(D38>Admin!F26,"SELF-EMPLOYMENT FULL RETURN REQUIRED AS TURNOVER EXCEEDS £"&Admin!F26&" VAT threshold","Business income - if your annual turnover was below £"&Admin!F26&" VAT threshold") -> SELF-EMPLOYMENT FULL RETURN REQUIRED AS TURNOVER EXCEEDS £90000 VAT threshold
A35: 9 | C35: Your turnover - the takings, fees, sales or money earned | L35: 10 | N35: Any other business income not included in box 9
C36: by your business | N36: - excluding Business Start-up Allowance
C38: £ | D38: ='Profit & Loss Account'!B9 -> 339200 | G38: . | H38: 0 | I38: 0 | N38: £ | O38: ='Profit & Loss Account'!B38 -> 0 | R38: . | S38: 0 | T38: 0
A40: Allowable business expenses
A41: Read pages SESN 3 of the notes to see which expenses are allowed for tax purposes. If your annual turnover was below the VAT threshold shown above
A42: you may just put your total expenses in box 20, rather than filling in the whole section.
A44: 11 | C44: Cost of goods bought for re-sale or goods used | L44: 16 | N44: Accountancy, legal and other professional fees
C46: £ | D46: =IF('Profit & Loss Account'!B9>Admin!F26,'Profit & Loss Account'!B17-'SE Full'!O66-'SE Full'!O70," ") -> 19667.267 | G46: . | H46: 0 | I46: 0 | N46: £ | O46: =IF('Profit & Loss Account'!B9>Admin!F26,'Profit & Loss Account'!B28-'SE Full'!O110," ") -> 6094 | R46: . | S46: 0 | T46: 0
A48: 12 | C48: Car, van and other travel expenses - after private | L48: 17 | N48: Interest and bank and credit card etc. financial charges
C49: use proportion
C51: £ | D51: =IF('Profit & Loss Account'!B9>Admin!F26,'Profit & Loss Account'!B25+'Profit & Loss Account'!B26-'SE Full'!O78," ") -> 6090.5625 | G51: . | H51: 0 | I51: 0 | N51: £ | O51: =IF('Profit & Loss Account'!B9>Admin!F26,'Profit & Loss Account'!B30+'Profit & Loss Account'!B31-'SE Full'!O98-'SE Full'!O102," ") -> 3510 | R51: . | S51: 0 | T51: 0
A53: 13 | C53: Wages, salaries and other staff costs | L53: 18 | N53: Telephone, fax, stationery and other office costs
C55: £ | D55: =IF('Profit & Loss Account'!B9>Admin!F26,'Profit & Loss Account'!B21-'SE Full'!O74," ") -> 89026.304 | G55: . | H55: 0 | I55: 0 | N55: £ | O55: =IF('Profit & Loss Account'!B9>Admin!F26,'Profit & Loss Account'!B24-'SE Full'!O90," ") -> 2822.55 | R55: . | S55: 0 | T55: 0
A57: 14 | C57: Rent, rates, power and insurance costs | L57: 19 | N57: Other allowable business expenses - client entertaining
N58: costs are not an allowable expense
C60: £ | D60: =IF('Profit & Loss Account'!B9>Admin!F26,'Profit & Loss Account'!B22-'SE Full'!O82," ") -> 12540 | G60: . | H60: 0 | I60: 0 | N60: £ | O60: =IF('Profit & Loss Account'!B9>Admin!F26,'Profit & Loss Account'!B27+'Profit & Loss Account'!B29+'Profit & Loss Account'!B32+'Profit & Loss Account'!B33-'SE Full'!O94-'SE Full'!O106-'SE Full'!O118," ") -> 6723.2167 | R60: . | S60: 0 | T60: 0
A62: 15 | C62: Repairs and renewals of property and equipment | L62: 20 | N62: Total allowable expenses - total of boxes 11 to 19
C64: £ | D64: =IF('Profit & Loss Account'!B9>Admin!F26,'Profit & Loss Account'!B23-'SE Full'!O86," ") -> 893 | G64: . | H64: 0 | I64: 0 | N64: £ | O64: ='Profit & Loss Account'!B17+'Profit & Loss Account'!B35-'SE Full'!O122 -> 147366.9 | R64: . | S64: 0 | T64: 0
A66: Net profit or loss
...

Sheet SE Full
A1: HM Revenue & Customs | G1: ="COPY DETAILS TO HMRC FORM Submit HMRC RETURN ONLINE by 31st January "&TEXT(Admin!B21,"yyyy") -> COPY DETAILS TO HMRC FORM Submit HMRC RETURN ONLINE by 31st January 2028 | N1: Self-employment (full)
N2: Tax year | Q2: =Admin!B4 -> 46118 | U2: to | V2: =Admin!B17 -> 46482
C6: Your name | N6: Your unique taxpayer reference (UTR)
C8: =IF('Business Details'!C5>0,'Business Details'!C5," ") -> Precision Code Trading | O8: =IF('Business Details'!O5>0,'Business Details'!O5," ") | R8: =IF('Business Details'!R5>0,'Business Details'!R5," ")
C10: =IF('Business Details'!C7>0,'Business Details'!C7," ")
A12: Business details
A14: 1 | C14: Business name - unless it is in your own name | L14: 5 | N14: If the details in boxes 1, 2, 3 or 4 have changed in the last 12
C15: =IF('Business Details'!C12>0,'Business Details'!C12," ") | N15: months, put 'X' in the box and give details in the 'Any other
N16: information' box
C17: =IF('Business Details'!C14>0,'Business Details'!C14," ") | N17: =IF('Business Details'!N14="X","X"," ")
A19: 2 | C19: Description of business | L19: 6 | N19: If your business started after | S19: =Admin!B4 -> 46118
C20: =IF('Business Details'!C17>0,'Business Details'!C17," ") -> IT consultancy and software development | N20: enter the start date DD/MM/YYYY
C22: =IF('Business Details'!C19>0,'Business Details'!C19," ") | N22: =IF('Business Details'!N10>0,'Business Details'!N19," ")
C24: =IF('Business Details'!C21>0,'Business Details'!C21," ") | L24: 7 | N24: If your business ceased before | S24: =Admin!B17 -> 46482
N25: enter the final date of trading
A26: 3 | C26: First line of your business address - unless you work
C27: from home | N27: =IF('Business Details'!N24>0,'Business Details'!N24," ")
C28: =IF('Business Details'!C25>0,'Business Details'!C25," ") | L28: 8 | N28: Date your books or accounts start - the beginning of
N29: your accounting period
C30: =IF('Business Details'!C27>0,'Business Details'!C27," ") | N30: =IF('Business Details'!N27>0,'Business Details'!N27," ")
A32: 4 | C32: Postcode of your business address | L32: 9 | N32: Date your books or accounts are made up to or the end
C33: =IF('Business Details'!C30>0,'Business Details'!C30," ") | F33: =IF('Business Details'!F30>0,'Business Details'!F30," ") | N33: of your accounting period - read the notes if you have
N34: filled in box 6 or 7
N35: =Admin!B17 -> 46482
A37: Other information
A39: 10 | C39: If you used traditional accounting rather than cash basis to | L39: 13 | N39: If special arrangements apply, put 'X' in the box - read the
C40: calculate your income and expenses, put 'X' in the box | N40: notes
C42: =IF('Business Details'!C39="x","x"," ") | N42: =IF('Business Details'!N39="x","x"," ")
C44: Boxes 11 and 12 are not in use | L44: 14 | N44: ="If you provided the information about your "&Admin!G2 -> If you provided the information about your 2026-27
N45: profit on last year's tax return, put 'X' in the box
N48: =IF('Business Details'!N45="x","x"," ")
A50: Business income
A52: 15 | C52: Your turnover - the takings, fees, sales or money earned | L52: 16 | N52: Any other business income not included in box 15
C53: by your business
C55: £ | D55: ='Profit & Loss Account'!B9 -> 339200 | G55: . | H55: 0 | I55: 0 | N55: £ | O55: ='Profit & Loss Account'!B38 -> 0 | R55: . | S55: 0 | T55: 0
A57: Business expenses
A58: Please read the 'Self-employment (full) notes' before filling in this section.
C60: Total expenses | N60: Disallowable expenses
C61: If your annual turnover was below £90,000, you may | N61: Use this column if the figures in boxes 17 to 30
C62: just put your total expenses in box 31 | N62: include disallowable amounts
...

Sheet Profit & Loss Account
A2: Monthly Management Accounts Profit and Loss Account | B2: Total Year | C2: =Admin!B5 -> 46142 | D2: =Admin!B6 -> 46173 | E2: =Admin!B7 -> 46203 | F2: =Admin!B8 -> 46234 | G2: =Admin!B9 -> 46265 | H2: =Admin!B10 -> 46295 | I2: =Admin!B11 -> 46326 | J2: =Admin!B12 -> 46356 | K2: =Admin!B13 -> 46387 | L2: =Admin!B14 -> 46418 | M2: =Admin!B15 -> 46446 | N2: =Admin!B16 -> 46477
B3: =Admin!B$17 -> 46482
B4: £ | C4: £ | D4: £ | E4: £ | F4: £ | G4: £ | H4: £ | I4: £ | J4: £ | K4: £ | L4: £ | M4: £ | N4: £
A5: Sales Product A | B5: =SUM(C5:N5) -> 311600 | C5: =[2]Apr!$P$1 -> 25333.333 | D5: =[2]May!$P$1 -> 25633.333 | E5: =[2]Jun!$P$1 -> 26533.333 | F5: =[2]Jul!$P$1 -> 25633.333 | G5: =[2]Aug!$P$1 -> 27133.333 | H5: =[2]Sep!$P$1 -> 25033.333 | I5: =[2]Oct!$P$1 -> 27133.333 | J5: =[2]Nov!$P$1 -> 25633.333 | K5: =[2]Dec!$P$1 -> 26533.333 | L5: =[2]Jan!$P$1 -> 25633.333 | M5: =[2]Feb!$P$1 -> 26333.333 | N5: =[2]Mar!$P$1 -> 25033.333
A6: Sales Product B | B6: =SUM(C6:N6) -> 13600 | C6: =[2]Apr!$Q$1 -> 1800 | D6: =[2]May!$Q$1 -> 800 | E6: =[2]Jun!$Q$1 -> 800 | F6: =[2]Jul!$Q$1 -> 1800 | G6: =[2]Aug!$Q$1 -> 800 | H6: =[2]Sep!$Q$1 -> 800 | I6: =[2]Oct!$Q$1 -> 1800 | J6: =[2]Nov!$Q$1 -> 800 | K6: =[2]Dec!$Q$1 -> 800 | L6: =[2]Jan!$Q$1 -> 1800 | M6: =[2]Feb!$Q$1 -> 800 | N6: =[2]Mar!$Q$1 -> 800
A7: Sales Product C | B7: =SUM(C7:N7) -> 10300 | C7: =[2]Apr!$R$1 -> 0 | D7: =[2]May!$R$1 -> 1000 | E7: =[2]Jun!$R$1 -> 2000 | F7: =[2]Jul!$R$1 -> 0 | G7: =[2]Aug!$R$1 -> 0 | H7: =[2]Sep!$R$1 -> 1800 | I7: =[2]Oct!$R$1 -> 0 | J7: =[2]Nov!$R$1 -> 3000 | K7: =[2]Dec!$R$1 -> 0 | L7: =[2]Jan!$R$1 -> 1000 | M7: =[2]Feb!$R$1 -> 1500 | N7: =[2]Mar!$R$1 -> 0
A8: Other Income | B8: =SUM(C8:N8) -> 3700 | C8: =[2]Apr!$S$1 -> 700 | D8: =[2]May!$S$1 -> 0 | E8: =[2]Jun!$S$1 -> 0 | F8: =[2]Jul!$S$1 -> 700 | G8: =[2]Aug!$S$1 -> 0 | H8: =[2]Sep!$S$1 -> 500 | I8: =[2]Oct!$S$1 -> 700 | J8: =[2]Nov!$S$1 -> 0 | K8: =[2]Dec!$S$1 -> 0 | L8: =[2]Jan!$S$1 -> 1100 | M8: =[2]Feb!$S$1 -> 0 | N8: =[2]Mar!$S$1 -> 0
A9: Sales Turnover | B9: =SUM(B5:B8) -> 339200 | C9: =SUM(C5:C8) -> 27833.333 | D9: =SUM(D5:D8) -> 27433.333 | E9: =SUM(E5:E8) -> 29333.333 | F9: =SUM(F5:F8) -> 28133.333 | G9: =SUM(G5:G8) -> 27933.333 | H9: =SUM(H5:H8) -> 28133.333 | I9: =SUM(I5:I8) -> 29633.333 | ... N9: =SUM(N5:N8) -> 25833.333
A11: Investment Grants received | B11: =SUM(C11:N11) -> 2083.3333 | C11: =[2]Apr!$T$1 -> 0 | D11: =[2]May!$T$1 -> 0 | E11: =[2]Jun!$T$1 -> 0 | F11: =[2]Jul!$T$1 -> 0 | G11: =[2]Aug!$T$1 -> 2083.3333 | H11: =[2]Sep!$T$1 -> 0 | I11: =[2]Oct!$T$1 -> 0 | J11: =[2]Nov!$T$1 -> 0 | K11: =[2]Dec!$T$1 -> 0 | L11: =[2]Jan!$T$1 -> 0 | M11: =[2]Feb!$T$1 -> 0 | N11: =[2]Mar!$T$1 -> 0
A13: Direct Costs
A14: Purchases after stock adjustment | B14: =SUM(C14:N14) -> 9450 | C14: =[3]Apr!$P$1+StockControl!AB6-StockControl!AB8 -> 500 | D14: =[3]May!$P$1+StockControl!AB8-StockControl!AB10 -> 600 | E14: =[3]Jun!$P$1+StockControl!AB10-StockControl!AB12 -> 300 | F14: =[3]Jul!$P$1+StockControl!AB12-StockControl!AB14 -> 600 | G14: =[3]Aug!$P$1+StockControl!AB14-StockControl!AB16 -> 450 | H14: =[3]Sep!$P$1+StockControl!AB16-StockControl!AB18 -> 200 | I14: =[3]Oct!$P$1+StockControl!AB18-StockControl!AB20 -> 400 | J14: =[3]Nov!$P$1+StockControl!AB20-StockControl!AB22 -> 700 | K14: =[3]Dec!$P$1+StockControl!AB22-StockControl!AB24 -> 400 | L14: =[3]Jan!$P$1+StockControl!AB24-StockControl!AB26 -> 500 | M14: =[3]Feb!$P$1+StockControl!AB26-StockControl!AB28 -> 550 | N14: =[3]Mar!$P$1+StockControl!AB28-StockControl!AB30 -> 4250
A15: Sub contractors | B15: =SUM(C15:N15) -> 6666.6667 | C15: =[3]Apr!$Q$1 -> 0 | D15: =[3]May!$Q$1 -> 0 | E15: =[3]Jun!$Q$1 -> 4166.6667 | F15: =[3]Jul!$Q$1 -> 0 | G15: =[3]Aug!$Q$1 -> 0 | H15: =[3]Sep!$Q$1 -> 0 | I15: =[3]Oct!$Q$1 -> 0 | J15: =[3]Nov!$Q$1 -> 2500 | K15: =[3]Dec!$Q$1 -> 0 | L15: =[3]Jan!$Q$1 -> 0 | M15: =[3]Feb!$Q$1 -> 0 | N15: =[3]Mar!$Q$1 -> 0
A16: Other Direct Cost of Sales | B16: =SUM(C16:N16) -> 4020 | C16: =[3]Apr!$R$1 -> 237.5 | D16: =[3]May!$R$1 -> 407.5 | E16: =[3]Jun!$R$1 -> 237.5 | F16: =[3]Jul!$R$1 -> 607.5 | G16: =[3]Aug!$R$1 -> 237.5 | H16: =[3]Sep!$R$1 -> 507.5 | I16: =[3]Oct!$R$1 -> 237.5 | J16: =[3]Nov!$R$1 -> 207.5 | K16: =[3]Dec!$R$1 -> 237.5 | L16: =[3]Jan!$R$1 -> 357.5 | M16: =[3]Feb!$R$1 -> 537.5 | N16: =[3]Mar!$R$1 -> 207.5
A17: Cost of Sales | B17: =SUM(B14:B16) -> 20136.667 | C17: =SUM(C14:C16) -> 737.5 | D17: =SUM(D14:D16) -> 1007.5 | E17: =SUM(E14:E16) -> 4704.1667 | F17: =SUM(F14:F16) -> 1207.5 | G17: =SUM(G14:G16) -> 687.5 | H17: =SUM(H14:H16) -> 707.5 | I17: =SUM(I14:I16) -> 637.5 | ... N17: =SUM(N14:N16) -> 4457.5
A19: Gross Profit | B19: =B9+B11-B17 -> 321146.67 | C19: =C9+C11-C17 -> 27095.833 | D19: =D9+D11-D17 -> 26425.833 | E19: =E9+E11-E17 -> 24629.167 | F19: =F9+F11-F17 -> 26925.833 | G19: =G9+G11-G17 -> 29329.167 | H19: =H9+H11-H17 -> 27425.833 | I19: =I9+I11-I17 -> 28995.833 | ... N19: =N9+N11-N17 -> 21375.833
A20: Administrative Expenses
A21: Wages and Salaries | B21: =SUM(C21:N21) -> 92735.733 | C21: =[3]Apr!$S$1+Wagesinterface!C4+Wagesinterface!H4-Wagesinterface!I4 -> 7325.2 | D21: =[3]May!$S$1+Wagesinterface!C5+Wagesinterface!H5-Wagesinterface!I5 -> 7325.2 | E21: =[3]Jun!$S$1+Wagesinterface!C6+Wagesinterface!H6-Wagesinterface!I6 -> 7325.2 | F21: =[3]Jul!$S$1+Wagesinterface!C7+Wagesinterface!H7-Wagesinterface!I7 -> 7325.2 | G21: =[3]Aug!$S$1+Wagesinterface!C8+Wagesinterface!H8-Wagesinterface!I8 -> 7991.8667 | H21: =[3]Sep!$S$1+Wagesinterface!C9+Wagesinterface!H9-Wagesinterface!I9 -> 7325.2 | I21: =[3]Oct!$S$1+Wagesinterface!C10+Wagesinterface!H10-Wagesinterface!I10 -> 7325.2 | J21: =[3]Nov!$S$1+Wagesinterface!C11+Wagesinterface!H11-Wagesinterface!I11 -> 7325.2 | K21: =[3]Dec!$S$1+Wagesinterface!C12+Wagesinterface!H12-Wagesinterface!I12 -> 11491.867 | L21: =[3]Jan!$S$1+Wagesinterface!C13+Wagesinterface!H13-Wagesinterface!I13 -> 7325.2 | M21: =[3]Feb!$S$1+Wagesinterface!C14+Wagesinterface!H14-Wagesinterface!I14 -> 7325.2 | N21: =[3]Mar!$S$1+Wagesinterface!C15+Wagesinterface!H15-Wagesinterface!I15 -> 7325.2
A22: Premises Rent Rates Power | B22: =SUM(C22:N22) -> 13200 | C22: =[3]Apr!$T$1 -> 1000 | D22: =[3]May!$T$1 -> 1000 | E22: =[3]Jun!$T$1 -> 1300 | F22: =[3]Jul!$T$1 -> 1000 | G22: =[3]Aug!$T$1 -> 1000 | H22: =[3]Sep!$T$1 -> 1250 | I22: =[3]Oct!$T$1 -> 1000 | J22: =[3]Nov!$T$1 -> 1000 | K22: =[3]Dec!$T$1 -> 1350 | L22: =[3]Jan!$T$1 -> 1000 | M22: =[3]Feb!$T$1 -> 1000 | N22: =[3]Mar!$T$1 -> 1300
A23: Repairs & Maintenance | B23: =SUM(C23:N23) -> 950 | C23: =[3]Apr!$U$1 -> 100 | D23: =[3]May!$U$1 -> 0 | E23: =[3]Jun!$U$1 -> 0 | F23: =[3]Jul!$U$1 -> 150 | G23: =[3]Aug!$U$1 -> 200 | H23: =[3]Sep!$U$1 -> 0 | I23: =[3]Oct!$U$1 -> 80 | J23: =[3]Nov!$U$1 -> 0 | K23: =[3]Dec!$U$1 -> 0 | L23: =[3]Jan!$U$1 -> 120 | M23: =[3]Feb!$U$1 -> 300 | N23: =[3]Mar!$U$1 -> 0
A24: General Administrative Expenses | B24: =SUM(C24:N24) -> 3035 | C24: =[3]Apr!$V$1 -> 262.5 | D24: =[3]May!$V$1 -> 277.5 | E24: =[3]Jun!$V$1 -> 192.5 | F24: =[3]Jul!$V$1 -> 382.5 | G24: =[3]Aug!$V$1 -> 112.5 | H24: =[3]Sep!$V$1 -> 202.5 | I24: =[3]Oct!$V$1 -> 262.5 | J24: =[3]Nov!$V$1 -> 337.5 | K24: =[3]Dec!$V$1 -> 212.5 | L24: =[3]Jan!$V$1 -> 427.5 | M24: =[3]Feb!$V$1 -> 112.5 | N24: =[3]Mar!$V$1 -> 252.5
A25: Motor Expenses | B25: =SUM(C25:N25) -> 6570.75 | C25: =[3]Apr!$W$1 -> 516.75 | D25: =[3]May!$W$1 -> 576 | E25: =[3]Jun!$W$1 -> 580 | F25: =[3]Jul!$W$1 -> 494.75 | G25: =[3]Aug!$W$1 -> 516.75 | H25: =[3]Sep!$W$1 -> 618 | I25: =[3]Oct!$W$1 -> 522.25 | J25: =[3]Nov!$W$1 -> 569 | K25: =[3]Dec!$W$1 -> 530.5 | L25: =[3]Jan!$W$1 -> 546.75 | M25: =[3]Feb!$W$1 -> 508.5 | N25: =[3]Mar!$W$1 -> 591.5
A26: Travel Hotel & Subsistence | B26: =SUM(C26:N26) -> 1550 | C26: =[3]Apr!$X$1 -> 76.666667 | D26: =[3]May!$X$1 -> 126.66667 | E26: =[3]Jun!$X$1 -> 226.66667 | F26: =[3]Jul!$X$1 -> 76.666667 | G26: =[3]Aug!$X$1 -> 116.66667 | H26: =[3]Sep!$X$1 -> 76.666667 | I26: =[3]Oct!$X$1 -> 176.66667 | J26: =[3]Nov!$X$1 -> 136.66667 | K26: =[3]Dec!$X$1 -> 76.666667 | L26: =[3]Jan!$X$1 -> 76.666667 | M26: =[3]Feb!$X$1 -> 306.66667 | N26: =[3]Mar!$X$1 -> 76.666667
A27: Advertising Promotion & Entertainment | B27: =SUM(C27:N27) -> 4091.6667 | C27: =[3]Apr!$Y$1+[3]Apr!$AC$1 -> 0 | D27: =[3]May!$Y$1+[3]May!$AC$1 -> 500 | E27: =[3]Jun!$Y$1+[3]Jun!$AC$1 -> 0 | F27: =[3]Jul!$Y$1+[3]Jul!$AC$1 -> 400 | G27: =[3]Aug!$Y$1+[3]Aug!$AC$1 -> 291.66667 | H27: =[3]Sep!$Y$1+[3]Sep!$AC$1 -> 0 | I27: =[3]Oct!$Y$1+[3]Oct!$AC$1 -> 2500 | J27: =[3]Nov!$Y$1+[3]Nov!$AC$1 -> 0 | K27: =[3]Dec!$Y$1+[3]Dec!$AC$1 -> 0 | L27: =[3]Jan!$Y$1+[3]Jan!$AC$1 -> 400 | M27: =[3]Feb!$Y$1+[3]Feb!$AC$1 -> 0 | N27: =[3]Mar!$Y$1+[3]Mar!$AC$1 -> 0
A28: Legal & Professional Fees | B28: =SUM(C28:N28) -> 6925 | C28: =[3]Apr!$Z$1 -> 250 | D28: =[3]May!$Z$1 -> 250 | E28: =[3]Jun!$Z$1 -> 458.33333 | F28: =[3]Jul!$Z$1 -> 2750 | G28: =[3]Aug!$Z$1 -> 250 | H28: =[3]Sep!$Z$1 -> 1223.3333 | I28: =[3]Oct!$Z$1 -> 250 | J28: =[3]Nov!$Z$1 -> 250 | K28: =[3]Dec!$Z$1 -> 389.16667 | L28: =[3]Jan!$Z$1 -> 250 | M28: =[3]Feb!$Z$1 -> 250 | N28: =[3]Mar!$Z$1 -> 354.16667
A29: Bad Debts written off | B29: =SUM(C29:N29) -> 300 | C29: =-[2]Apr!$U$1 -> 0 | D29: =-[2]May!$U$1 -> 0 | E29: =-[2]Jun!$U$1 -> 0 | F29: =-[2]Jul!$U$1 -> 0 | G29: =-[2]Aug!$U$1 -> 0 | H29: =-[2]Sep!$U$1 -> 0 | I29: =-[2]Oct!$U$1 -> 0 | J29: =-[2]Nov!$U$1 -> 0 | K29: =-[2]Dec!$U$1 -> 0 | L29: =-[2]Jan!$U$1 -> 0 | M29: =-[2]Feb!$U$1 -> 0 | N29: =-[2]Mar!$U$1 -> 300
A30: Bank Interest Paid | B30: =SUM(C30:N30) -> 0 | C30: =[4]Apr!$Z$1 -> 0 | D30: =[4]May!$Z$1 -> 0 | E30: =[4]Jun!$Z$1 -> 0 | F30: =[4]Jul!$Z$1 -> 0 | G30: =[4]Aug!$Z$1 -> 0 | H30: =[4]Sep!$Z$1 -> 0 | I30: =[4]Oct!$Z$1 -> 0 | J30: =[4]Nov!$Z$1 -> 0 | K30: =[4]Dec!$Z$1 -> 0 | L30: =[4]Jan!$Z$1 -> 0 | M30: =[4]Feb!$Z$1 -> 0 | N30: =[4]Mar!$Z$1 -> 0
A31: HP Interest Lease Bank Charges | B31: =SUM(C31:N31) -> 3900 | C31: =[5]Apr!$V$1+[4]Apr!$Y$1 -> 0 | D31: =[5]May!$V$1+[4]May!$Y$1 -> 25 | E31: =[5]Jun!$V$1+[4]Jun!$Y$1 -> 2250 | F31: =[5]Jul!$V$1+[4]Jul!$Y$1 -> 0 | G31: =[5]Aug!$V$1+[4]Aug!$Y$1 -> 0 | H31: =[5]Sep!$V$1+[4]Sep!$Y$1 -> 1308 | I31: =[5]Oct!$V$1+[4]Oct!$Y$1 -> 0 | J31: =[5]Nov!$V$1+[4]Nov!$Y$1 -> 25 | K31: =[5]Dec!$V$1+[4]Dec!$Y$1 -> 167 | L31: =[5]Jan!$V$1+[4]Jan!$Y$1 -> 0 | M31: =[5]Feb!$V$1+[4]Feb!$Y$1 -> 0 | N31: =[5]Mar!$V$1+[4]Mar!$Y$1 -> 125
A32: Other Expenses | B32: =SUM(C32:N32) -> 3231.6667 | C32: =[3]Apr!$AA$1 -> 1330.8333 | D32: =[3]May!$AA$1 -> 95.833333 | E32: =[3]Jun!$AA$1 -> 120.83333 | F32: =[3]Jul!$AA$1 -> 95.833333 | G32: =[3]Aug!$AA$1 -> 135.83333 | H32: =[3]Sep!$AA$1 -> 95.833333 | I32: =[3]Oct!$AA$1 -> 425.83333 | J32: =[3]Nov!$AA$1 -> 95.833333 | K32: =[3]Dec!$AA$1 -> 532.5 | L32: =[3]Jan!$AA$1 -> 95.833333 | M32: =[3]Feb!$AA$1 -> 110.83333 | N32: =[3]Mar!$AA$1 -> 95.833333
A33: Loss (profit) disposal of assets | B33: =SUM(C33:N33) -> 172 | C33: =-([1]Schedule!$V$1-[1]Schedule!$W$1+[1]Schedule!$X$1)/12 -> 14.333333 | D33: =-([1]Schedule!$V$1-[1]Schedule!$W$1+[1]Schedule!$X$1)/12 -> 14.333333 | E33: =-([1]Schedule!$V$1-[1]Schedule!$W$1+[1]Schedule!$X$1)/12 -> 14.333333 | F33: =-([1]Schedule!$V$1-[1]Schedule!$W$1+[1]Schedule!$X$1)/12 -> 14.333333 | G33: =-([1]Schedule!$V$1-[1]Schedule!$W$1+[1]Schedule!$X$1)/12 -> 14.333333 | H33: =-([1]Schedule!$V$1-[1]Schedule!$W$1+[1]Schedule!$X$1)/12 -> 14.333333 | I33: =-([1]Schedule!$V$1-[1]Schedule!$W$1+[1]Schedule!$X$1)/12 -> 14.333333 | J33: =-([1]Schedule!$V$1-[1]Schedule!$W$1+[1]Schedule!$X$1)/12 -> 14.333333 | ... N33: =-([1]Schedule!$V$1-[1]Schedule!$W$1+[1]Schedule!$X$1)/12 -> 14.333333
A34: Depreciation | B34: =SUM(C34:N34) -> 20865 | C34: =([1]Schedule!$I$1)/12 -> 1738.75 | D34: =([1]Schedule!$I$1)/12 -> 1738.75 | E34: =([1]Schedule!$I$1)/12 -> 1738.75 | F34: =([1]Schedule!$I$1)/12 -> 1738.75 | G34: =([1]Schedule!$I$1)/12 -> 1738.75 | H34: =([1]Schedule!$I$1)/12 -> 1738.75 | I34: =([1]Schedule!$I$1)/12 -> 1738.75 | J34: =([1]Schedule!$I$1)/12 -> 1738.75 | ... N34: =([1]Schedule!$I$1)/12 -> 1738.75
A35: Administrative Expenses | B35: =SUM(B21:B34) -> 157526.82 | C35: =SUM(C21:C34) -> 12615.033 | D35: =SUM(D21:D34) -> 11929.283 | E35: =SUM(E21:E34) -> 14206.617 | F35: =SUM(F21:F34) -> 14428.033 | G35: =SUM(G21:G34) -> 12368.367 | H35: =SUM(H21:H34) -> 13852.617 | I35: =SUM(I21:I34) -> 14295.533 | ... N35: =SUM(N21:N34) -> 12173.95
A37: Operating Profit | B37: =B19-B35 -> 163619.85 | C37: =C19-C35 -> 14480.8 | D37: =D19-D35 -> 14496.55 | E37: =E19-E35 -> 10422.55 | F37: =F19-F35 -> 12497.8 | G37: =G19-G35 -> 16960.8 | H37: =H19-H35 -> 13573.217 | I37: =I19-I35 -> 14700.3 | ... N37: =N19-N35 -> 9201.8833
A38: Interest received | B38: =SUM(C38:N38) -> 0 | C38: =[4]Apr!$J$1 -> 0 | D38: =[4]May!$J$1 -> 0 | E38: =[4]Jun!$J$1 -> 0 | F38: =[4]Jul!$J$1 -> 0 | G38: =[4]Aug!$J$1 -> 0 | H38: =[4]Sep!$J$1 -> 0 | I38: =[4]Oct!$J$1 -> 0 | J38: =[4]Nov!$J$1 -> 0 | K38: =[4]Dec!$J$1 -> 0 | L38: =[4]Jan!$J$1 -> 0 | M38: =[4]Feb!$J$1 -> 0 | N38: =[4]Mar!$J$1 -> 0
A39: Profit (Loss) before Tax | B39: =B37+B38 -> 163619.85 | C39: =C37+C38 -> 14480.8 | D39: =D37+D38 -> 14496.55 | E39: =E37+E38 -> 10422.55 | F39: =F37+F38 -> 12497.8 | G39: =G37+G38 -> 16960.8 | H39: =H37+H38 -> 13573.217 | I39: =I37+I38 -> 14700.3 | ... N39: =N37+N38 -> 9201.8833
A41: Financial Business Health Check
A42: Self Employed Drawings | B42: =SUM(C42:N42) -> 27000 | C42: =[5]Apr!$X$1+[4]Apr!$AB$1 -> 1000 | D42: =[5]May!$X$1+[4]May!$AB$1 -> 1000 | E42: =[5]Jun!$X$1+[4]Jun!$AB$1 -> 1000 | F42: =[5]Jul!$X$1+[4]Jul!$AB$1 -> 4000 | G42: =[5]Aug!$X$1+[4]Aug!$AB$1 -> 1000 | H42: =[5]Sep!$X$1+[4]Sep!$AB$1 -> 1000 | I42: =[5]Oct!$X$1+[4]Oct!$AB$1 -> 4000 | J42: =[5]Nov!$X$1+[4]Nov!$AB$1 -> 1000 | K42: =[5]Dec!$X$1+[4]Dec!$AB$1 -> 1000 | L42: =[5]Jan!$X$1+[4]Jan!$AB$1 -> 4000 | M42: =[5]Feb!$X$1+[4]Feb!$AB$1 -> 1000 | N42: =[5]Mar!$X$1+[4]Mar!$AB$1 -> 7000
A43: CIS Tax deducted | B43: =SUM(C43:N43) -> 0 | C43: =-[2]Apr!$W$1 -> 0 | D43: =-[2]May!$W$1 -> 0 | E43: =-[2]Jun!$W$1 -> 0 | F43: =-[2]Jul!$W$1 -> 0 | G43: =-[2]Aug!$W$1 -> 0 | H43: =-[2]Sep!$W$1 -> 0 | I43: =-[2]Oct!$W$1 -> 0 | J43: =-[2]Nov!$W$1 -> 0 | K43: =-[2]Dec!$W$1 -> 0 | L43: =-[2]Jan!$W$1 -> 0 | M43: =-[2]Feb!$W$1 -> 0 | N43: =-[2]Mar!$W$1 -> 0
A44: Income Tax & NI Liability | B44: =SUM(C44:N44) -> 42674.967 | C44: =IF(C9>0,'Profit Forecast'!C$46/12,0) -> 3556.2472 | D44: =IF(D9>0,'Profit Forecast'!C$46/12,0) -> 3556.2472 | E44: =IF(E9>0,'Profit Forecast'!C$46/12,0) -> 3556.2472 | F44: =IF(F9>0,'Profit Forecast'!C$46/12,0) -> 3556.2472 | G44: =IF(G9>0,'Profit Forecast'!C$46/12,0) -> 3556.2472 | H44: =IF(H9>0,'Profit Forecast'!C$46/12,0) -> 3556.2472 | I44: =IF(I9>0,'Profit Forecast'!C$46/12,0) -> 3556.2472 | J44: =IF(J9>0,'Profit Forecast'!C$46/12,0) -> 3556.2472 | K44: =IF(K9>0,'Profit Forecast'!C$46/12,0) -> 3556.2472 | L44: =IF(L9>0,'Profit Forecast'!C$46/12,0) -> 3556.2472 | M44: =IF(M9>0,'Profit Forecast'!C$46/12,0) -> 3556.2472 | N44: =IF(N9>0,'Profit Forecast'!C$46/12,0) -> 3556.2472
A45: Financial Health Check | B45: =SUM(C45:N45) -> 93944.883 | C45: =C39-C42-C44 -> 9924.5527 | D45: =D39-D42-D44 -> 9940.3027 | E45: =E39-E42-E44 -> 5866.3027 | F45: =F39-F42-F44 -> 4941.5527 | G45: =G39-G42-G44 -> 12404.553 | H45: =H39-H42-H44 -> 9016.9694 | I45: =I39-I42-I44 -> 7144.0527 | J45: =J39-J42-J44 -> 9977.3027 | ... N45: =N39-N42-N44 -> -1354.3639
A46: Capital introduced | B46: =SUM(C46:N46) -> 5000 | C46: =[5]Apr!$J$1+[4]Apr!$L$1 -> 0 | D46: =[5]May!$J$1+[4]May!$L$1 -> 0 | E46: =[5]Jun!$J$1+[4]Jun!$L$1 -> 0 | F46: =[5]Jul!$J$1+[4]Jul!$L$1 -> 0 | G46: =[5]Aug!$J$1+[4]Aug!$L$1 -> 0 | H46: =[5]Sep!$J$1+[4]Sep!$L$1 -> 0 | I46: =[5]Oct!$J$1+[4]Oct!$L$1 -> 0 | J46: =[5]Nov!$J$1+[4]Nov!$L$1 -> 0 | K46: =[5]Dec!$J$1+[4]Dec!$L$1 -> 0 | L46: =[5]Jan!$J$1+[4]Jan!$L$1 -> 5000 | M46: =[5]Feb!$J$1+[4]Feb!$L$1 -> 0 | N46: =[5]Mar!$J$1+[4]Mar!$L$1 -> 0
...

Sheet VitalTax
B2: VitalTax summary | C2: Q1 | D2: Q2 | E2: Q3 | F2: Q4 | G2: Annual | H2: Notes
B5: Turnover | C5: =SUM('Profit & Loss Account'!C5:E7) -> 83900 | D5: =SUM('Profit & Loss Account'!F5:H7) -> 83000 | E5: =SUM('Profit & Loss Account'!I5:K7) -> 85700 | F5: =SUM('Profit & Loss Account'!L5:N7) -> 82900 | G5: =SUM(C5:F5) -> 335500
B6: Other income | C6: =SUM('Profit & Loss Account'!C8:E8)+SUM('Profit & Loss Account'!C11:E11)+SUM('Profit & Loss Account'!C38:E38) -> 700 | D6: =SUM('Profit & Loss Account'!F8:H8)+SUM('Profit & Loss Account'!F11:H11)+SUM('Profit & Loss Account'!F38:H38) -> 3283.3333 | E6: =SUM('Profit & Loss Account'!I8:K8)+SUM('Profit & Loss Account'!I11:K11)+SUM('Profit & Loss Account'!I38:K38) -> 700 | F6: =SUM('Profit & Loss Account'!L8:N8)+SUM('Profit & Loss Account'!L11:N11)+SUM('Profit & Loss Account'!L38:N38) -> 1100 | G6: =SUM(C6:F6) -> 5783.3333
B7: Cost of goods bought | C7: =SUM('Profit & Loss Account'!C14:E14)+SUM('Profit & Loss Account'!C16:E16) -> 2282.5 | D7: =SUM('Profit & Loss Account'!F14:H14)+SUM('Profit & Loss Account'!F16:H16) -> 2602.5 | E7: =SUM('Profit & Loss Account'!I14:K14)+SUM('Profit & Loss Account'!I16:K16) -> 2182.5 | F7: =SUM('Profit & Loss Account'!L14:N14)+SUM('Profit & Loss Account'!L16:N16) -> 6402.5 | G7: =SUM(C7:F7) -> 13470
B10: Allowable expenses
B12: Staff costs | C12: =SUM('Profit & Loss Account'!C21:E21) -> 21975.6 | D12: =SUM('Profit & Loss Account'!F21:H21) -> 22642.267 | E12: =SUM('Profit & Loss Account'!I21:K21) -> 26142.267 | F12: =SUM('Profit & Loss Account'!L21:N21) -> 21975.6 | G12: =SUM(C12:F12) -> 92735.733
B13: Premises running costs | C13: =SUM('Profit & Loss Account'!C22:E22) -> 3300 | D13: =SUM('Profit & Loss Account'!F22:H22) -> 3250 | E13: =SUM('Profit & Loss Account'!I22:K22) -> 3350 | F13: =SUM('Profit & Loss Account'!L22:N22) -> 3300 | G13: =SUM(C13:F13) -> 13200
B14: Maintenance | C14: =SUM('Profit & Loss Account'!C23:E23) -> 100 | D14: =SUM('Profit & Loss Account'!F23:H23) -> 350 | E14: =SUM('Profit & Loss Account'!I23:K23) -> 80 | F14: =SUM('Profit & Loss Account'!L23:N23) -> 420 | G14: =SUM(C14:F14) -> 950
B15: Admin | C15: =SUM('Profit & Loss Account'!C24:E24) -> 732.5 | D15: =SUM('Profit & Loss Account'!F24:H24) -> 697.5 | E15: =SUM('Profit & Loss Account'!I24:K24) -> 812.5 | F15: =SUM('Profit & Loss Account'!L24:N24) -> 792.5 | G15: =SUM(C15:F15) -> 3035
B16: Financial charges | C16: =SUM('Profit & Loss Account'!C31:E31) -> 2275 | D16: =SUM('Profit & Loss Account'!F31:H31) -> 1308 | E16: =SUM('Profit & Loss Account'!I31:K31) -> 192 | F16: =SUM('Profit & Loss Account'!L31:N31) -> 125 | G16: =SUM(C16:F16) -> 3900
B17: Travel | C17: =SUM('Profit & Loss Account'!C25:E26) -> 2102.75 | D17: =SUM('Profit & Loss Account'!F25:H26) -> 1899.5 | E17: =SUM('Profit & Loss Account'!I25:K26) -> 2011.75 | F17: =SUM('Profit & Loss Account'!L25:N26) -> 2106.75 | G17: =SUM(C17:F17) -> 8120.75
B18: Advertising | C18: =SUM('Profit & Loss Account'!C27:E27) -> 500 | D18: =SUM('Profit & Loss Account'!F27:H27) -> 691.66667 | E18: =SUM('Profit & Loss Account'!I27:K27) -> 2500 | F18: =SUM('Profit & Loss Account'!L27:N27) -> 400 | G18: =SUM(C18:F18) -> 4091.6667
B19: Professional | C19: =SUM('Profit & Loss Account'!C28:E28) -> 958.33333 | D19: =SUM('Profit & Loss Account'!F28:H28) -> 4223.3333 | E19: =SUM('Profit & Loss Account'!I28:K28) -> 889.16667 | F19: =SUM('Profit & Loss Account'!L28:N28) -> 854.16667 | G19: =SUM(C19:F19) -> 6925
B20: Bad debt | C20: =SUM('Profit & Loss Account'!C29:E29) -> 0 | D20: =SUM('Profit & Loss Account'!F29:H29) -> 0 | E20: =SUM('Profit & Loss Account'!I29:K29) -> 0 | F20: =SUM('Profit & Loss Account'!L29:N29) -> 300 | G20: =SUM(C20:F20) -> 300
B21: Interest | C21: =SUM('Profit & Loss Account'!C30:E30) -> 0 | D21: =SUM('Profit & Loss Account'!F30:H30) -> 0 | E21: =SUM('Profit & Loss Account'!I30:K30) -> 0 | F21: =SUM('Profit & Loss Account'!L30:N30) -> 0 | G21: =SUM(C21:F21) -> 0
B22: Other | C22: =SUM('Profit & Loss Account'!C32:E32) -> 1547.5 | D22: =SUM('Profit & Loss Account'!F32:H32) -> 327.5 | E22: =SUM('Profit & Loss Account'!I32:K32) -> 1054.1667 | F22: =SUM('Profit & Loss Account'!L32:N32) -> 302.5 | G22: =SUM(C22:F22) -> 3231.6667
B24: CIS payment to subcontractors | C24: =SUM('Profit & Loss Account'!C15:E15) -> 4166.6667 | D24: =SUM('Profit & Loss Account'!F15:H15) -> 0 | E24: =SUM('Profit & Loss Account'!I15:K15) -> 2500 | F24: =SUM('Profit & Loss Account'!L15:N15) -> 0 | G24: =SUM(C24:F24) -> 6666.6667
B25: Business entertainment | C25: =SUM('Profit & Loss Account'!C49:E49) -> 0 | D25: =SUM('Profit & Loss Account'!F49:H49) -> 291.66667 | E25: =SUM('Profit & Loss Account'!I49:K49) -> 0 | F25: =SUM('Profit & Loss Account'!L49:N49) -> 0 | G25: =SUM(C25:F25) -> 291.66667
B26: Depreciation | C26: =SUM('Profit & Loss Account'!C33:E34) -> 5259.25 | D26: =SUM('Profit & Loss Account'!F33:H34) -> 5259.25 | E26: =SUM('Profit & Loss Account'!I33:K34) -> 5259.25 | F26: =SUM('Profit & Loss Account'!L33:N34) -> 5259.25 | G26: =SUM(C26:F26) -> 21037
B29: Total allowable expenses | C29: =SUM(C7,C12,C13,C14,C15,C16,C17,C18,C19,C20,C21,C22,C24,C26) -> 45200.1 | D29: =SUM(D7,D12,D13,D14,D15,D16,D17,D18,D19,D20,D21,D22,D24,D26) -> 43251.517 | E29: =SUM(E7,E12,E13,E14,E15,E16,E17,E18,E19,E20,E21,E22,E24,E26) -> 46973.6 | F29: =SUM(F7,F12,F13,F14,F15,F16,F17,F18,F19,F20,F21,F22,F24,F26) -> 42238.267 | G29: =SUM(G7,G12,G13,G14,G15,G16,G17,G18,G19,G20,G21,G22,G24,G26) -> 177663.48
B34: Disallowable expenses
B36: Cost of goods bought | C36: =C7*$I$36 -> 45.65 | D36: =D7*$I$36 -> 52.05 | E36: =E7*$I$36 -> 43.65 | F36: =F7*$I$36 -> 128.05 | G36: =SUM(C36:F36) -> 269.4 | H36: Enter the % of this category that is private use or otherwise disallowable | I36: 0.02
B37: CIS payment to subcontractors | C37: =C24*$I$37 -> 125 | D37: =D24*$I$37 -> 0 | E37: =E24*$I$37 -> 75 | F37: =F24*$I$37 -> 0 | G37: =SUM(C37:F37) -> 200 | H37: Enter the % of this category that is private use or otherwise disallowable | I37: 0.03
B38: Staff costs | C38: =C12*$I$38 -> 879.024 | D38: =D12*$I$38 -> 905.69067 | E38: =E12*$I$38 -> 1045.6907 | F38: =F12*$I$38 -> 879.024 | G38: =SUM(C38:F38) -> 3709.4293 | H38: Enter the % of this category that is private use or otherwise disallowable | I38: 0.04
B39: Travel | C39: =C17*$I$39 -> 525.6875 | D39: =D17*$I$39 -> 474.875 | E39: =E17*$I$39 -> 502.9375 | F39: =F17*$I$39 -> 526.6875 | G39: =SUM(C39:F39) -> 2030.1875 | H39: Enter the % of this category that is private use or otherwise disallowable | I39: 0.25
B40: Premises running costs | C40: =C13*$I$40 -> 165 | D40: =D13*$I$40 -> 162.5 | E40: =E13*$I$40 -> 167.5 | F40: =F13*$I$40 -> 165 | G40: =SUM(C40:F40) -> 660 | H40: Enter the % of this category that is private use or otherwise disallowable | I40: 0.05
B41: Maintenance | C41: =C14*$I$41 -> 6 | D41: =D14*$I$41 -> 21 | E41: =E14*$I$41 -> 4.8 | F41: =F14*$I$41 -> 25.2 | G41: =SUM(C41:F41) -> 57 | H41: Enter the % of this category that is private use or otherwise disallowable | I41: 0.06
B42: Admin | C42: =C15*$I$42 -> 51.275 | D42: =D15*$I$42 -> 48.825 | E42: =E15*$I$42 -> 56.875 | F42: =F15*$I$42 -> 55.475 | G42: =SUM(C42:F42) -> 212.45 | H42: Enter the % of this category that is private use or otherwise disallowable | I42: 0.07
B43: Advertising | C43: =C18*$I$43 -> 40 | D43: =D18*$I$43 -> 55.333333 | E43: =E18*$I$43 -> 200 | F43: =F18*$I$43 -> 32 | G43: =SUM(C43:F43) -> 327.33333 | H43: Enter the % of this category that is private use or otherwise disallowable | I43: 0.08
B44: Business entertainment | C44: =C25 -> 0 | D44: =D25 -> 291.66667 | E44: =E25 -> 0 | F44: =F25 -> 0 | G44: =SUM(C44:F44) -> 291.66667 | H44: Wholly disallowable
B45: Interest | C45: =C21*$I$45 -> 0 | D45: =D21*$I$45 -> 0 | E45: =E21*$I$45 -> 0 | F45: =F21*$I$45 -> 0 | G45: =SUM(C45:F45) -> 0 | H45: Enter the % of this category that is private use or otherwise disallowable | I45: 0.09
B46: Financial charges | C46: =C16*$I$46 -> 227.5 | D46: =D16*$I$46 -> 130.8 | E46: =E16*$I$46 -> 19.2 | F46: =F16*$I$46 -> 12.5 | G46: =SUM(C46:F46) -> 390 | H46: Enter the % of this category that is private use or otherwise disallowable | I46: 0.1
B47: Bad debt | C47: =C20*$I$47 -> 0 | D47: =D20*$I$47 -> 0 | E47: =E20*$I$47 -> 0 | F47: =F20*$I$47 -> 33 | G47: =SUM(C47:F47) -> 33 | H47: Enter the % of this category that is private use or otherwise disallowable | I47: 0.11
B48: Professional | C48: =C19*$I$48 -> 115 | D48: =D19*$I$48 -> 506.8 | E48: =E19*$I$48 -> 106.7 | F48: =F19*$I$48 -> 102.5 | G48: =SUM(C48:F48) -> 831 | H48: Enter the % of this category that is private use or otherwise disallowable | I48: 0.12
B49: Depreciation | C49: =SUM('Profit & Loss Account'!C34:E34) -> 5216.25 | D49: =SUM('Profit & Loss Account'!F34:H34) -> 5216.25 | E49: =SUM('Profit & Loss Account'!I34:K34) -> 5216.25 | F49: =SUM('Profit & Loss Account'!L34:N34) -> 5216.25 | G49: =SUM(C49:F49) -> 20865 | H49: Reads the depreciation charge automatically
B50: Other | C50: =C22*$I$50 -> 201.175 | D50: =D22*$I$50 -> 42.575 | E50: =E22*$I$50 -> 137.04167 | F50: =F22*$I$50 -> 39.325 | G50: =SUM(C50:F50) -> 420.11667 | H50: Enter the % of this category that is private use or otherwise disallowable | I50: 0.13

Sheet Income Tax
B2: TAXATION CALCULATION | C2: =Admin!L2 -> 2026-27 | D2: This section an indication and for your information only
B5: Profit from Self employment | E5: ='SE Full'!O210 -> 123647.78
B6: Minus Personal Allowance | C6: =C2 -> 2026-27 | E6: =IF(E5<=0,0,MAX(0,Admin!N$4-MAX(0,E5-Admin!N$5)/2)) -> 746.11202
B7: Total income on which tax is due | E7: =IF((E5>E6),(E5-E6),0) -> 122901.66
B8: Income Tax first band | C8: =Admin!N$11 -> 0 | D8: =Admin!N$6 -> 0.2 | E8: =IF((E7>0),(IF((E7<C9),E7*D8,C9*D8)),0) -> 7540
B9: Income Tax second band | C9: =Admin!M$11 -> 37700 | D9: =Admin!N$7 -> 0.4 | E9: =IF(E7>C9,(MIN(E7,C10)-C9)*D9,0) -> 34080.666
B10: Income Tax third band | C10: =Admin!N$13 -> 125140 | D10: =Admin!N$8 -> 0.45 | E10: =IF(E7>C10,(E7-C10)*D10,0) -> 0
B11: Income Tax payable | E11: =SUM(E8:E10) -> 41620.666
B12: Deductions by contractors | E12: =-[2]Mar!$X$1 -> 0
B13: Amounts Payable by | C13: =Admin!B21 -> 46783
B14: Income Tax on transition profit (box 73.3), charged as the top slice | E14: =IF('SE Full'!D201>0,IF(E7+'SE Full'!D201<C9,(E7+'SE Full'!D201)*D8,C9*D8)+IF(E7+'SE Full'!D201>C9,(MIN(E7+'SE Full'!D201,C10)-C9)*D9,0)+IF(E7+'SE Full'!D201>C10,(E7+'SE Full'!D201-C10)*D10,0)-E11,0) -> 1688.0832
B15: Class 4 NI Contribution Lower - Upper profits | D15: =Admin!L20 -> 0.06 | E15: =IF((E5+'SE Full'!D201)>Admin!N20,IF((E5+'SE Full'!D201)<Admin!N$23,((E5+'SE Full'!D201)-Admin!N20)*D15,(Admin!N$23-Admin!N20)*D15),0) -> 2262
B16: Class 4 NI Contribution Upper profits | D16: =Admin!L23 -> 0.02 | E16: =IF(((E5+'SE Full'!D201)>Admin!N$23),(((E5+'SE Full'!D201)-Admin!N$23)*D16),0) -> 1547.5555
B18: TOTAL Income Tax & NI Liability | E18: =SUM(E11:E17) -> 47118.304
B21: FUTURE TAX LIABILITY (if over £500) | D21: This section for your information only
D23: Due Date | E23: Amount Payable
B25: Tax & NI Assessment | C25: =Admin!B24 -> 2027-28 | D25: Previous Year | E25: =E18 -> 47118.304
B26: 50% Payable | D26: =Admin!B21 -> 46783 | E26: =E25/2 -> 23559.152
B27: 50% Payable | D27: =Admin!B22 -> 46965 | E27: =E25/2 -> 23559.152
B29: NOTES:
B30: Working Tax Credit
B31: Not taxable and not added to self employment income for tax purposes
B32: Pension Entitlement
B33: To receive Full Pension entitlement NI has to be paid 44 years out of 49 years (16 - 65)
B34: UK residents aged 60 - 65 get 5 years bonus.
B35: To confirm current NI / Pension entitlement years the helpline number is 0845 3000 168

Sheet Wagesinterface
B2: Month | C2: Gross Wages paid | D2: Income Tax deducted | E2: Employees National Insurance deducted | F2: Other Deductions | G2: Net Wages Paid | H2: Employers National Insurance | I2: Recoverable Statutory Payments | K2: WAGES INTERFACE
B3: EMPLOYEES
B4: =Admin!B5 -> 46142 | C4: =[6]Apr!$M$1 -> 6748 | D4: =[6]Apr!$N$1 -> 800 | E4: =[6]Apr!$O$1 -> 296 | F4: =[6]Apr!$P$1+[6]Apr!$Q$1 -> 0 | G4: =C4-SUM(D4:F4) -> 5652 | H4: =[6]Apr!$T$1 -> 577.2 | I4: =[6]Apr!$G$1 -> 0 | K4: 1. If you are using a DIY Accounting payroll package then no action is required for the pay periods during which that payroll package is relevant April to March each year.
B5: =Admin!B6 -> 46173 | C5: =[6]May!$M$1 -> 6748 | D5: =[6]May!$N$1 -> 800 | E5: =[6]May!$O$1 -> 296 | F5: =[6]May!$P$1+[6]May!$Q$1 -> 0 | G5: =C5-SUM(D5:F5) -> 5652 | H5: =[6]May!$T$1 -> 577.2 | I5: =[6]May!$G$1 -> 0
B6: =Admin!B7 -> 46203 | C6: =[6]Jun!$M$1 -> 6748 | D6: =[6]Jun!$N$1 -> 800 | E6: =[6]Jun!$O$1 -> 296 | F6: =[6]Jun!$P$1+[6]Jun!$Q$1 -> 0 | G6: =C6-SUM(D6:F6) -> 5652 | H6: =[6]Jun!$T$1 -> 577.2 | I6: =[6]Jun!$G$1 -> 0
B7: =Admin!B8 -> 46234 | C7: =[6]Jul!$M$1 -> 6748 | D7: =[6]Jul!$N$1 -> 800 | E7: =[6]Jul!$O$1 -> 296 | F7: =[6]Jul!$P$1+[6]Jul!$Q$1 -> 0 | G7: =C7-SUM(D7:F7) -> 5652 | H7: =[6]Jul!$T$1 -> 577.2 | I7: =[6]Jul!$G$1 -> 0
B8: =Admin!B9 -> 46265 | C8: =[6]Aug!$M$1 -> 6748 | D8: =[6]Aug!$N$1 -> 800 | E8: =[6]Aug!$O$1 -> 296 | F8: =[6]Aug!$P$1+[6]Aug!$Q$1 -> 0 | G8: =C8-SUM(D8:F8) -> 5652 | H8: =[6]Aug!$T$1 -> 577.2 | I8: =[6]Aug!$G$1 -> 0 | K8: 2. Non DIY Accounting Payroll employers should overwrite the formulae with the actual monthly payroll totals
B9: =Admin!B10 -> 46295 | C9: =[6]Sep!$M$1 -> 6748 | D9: =[6]Sep!$N$1 -> 800 | E9: =[6]Sep!$O$1 -> 296 | F9: =[6]Sep!$P$1+[6]Sep!$Q$1 -> 0 | G9: =C9-SUM(D9:F9) -> 5652 | H9: =[6]Sep!$T$1 -> 577.2 | I9: =[6]Sep!$G$1 -> 0
B10: =Admin!B11 -> 46326 | C10: =[6]Oct!$M$1 -> 6748 | D10: =[6]Oct!$N$1 -> 800 | E10: =[6]Oct!$O$1 -> 296 | F10: =[6]Oct!$P$1+[6]Oct!$Q$1 -> 0 | G10: =C10-SUM(D10:F10) -> 5652 | H10: =[6]Oct!$T$1 -> 577.2 | I10: =[6]Oct!$G$1 -> 0
B11: =Admin!B12 -> 46356 | C11: =[6]Nov!$M$1 -> 6748 | D11: =[6]Nov!$N$1 -> 800 | E11: =[6]Nov!$O$1 -> 296 | F11: =[6]Nov!$P$1+[6]Nov!$Q$1 -> 0 | G11: =C11-SUM(D11:F11) -> 5652 | H11: =[6]Nov!$T$1 -> 577.2 | I11: =[6]Nov!$G$1 -> 0
B12: =Admin!B13 -> 46387 | C12: =[6]Dec!$M$1 -> 6748 | D12: =[6]Dec!$N$1 -> 800 | E12: =[6]Dec!$O$1 -> 296 | F12: =[6]Dec!$P$1+[6]Dec!$Q$1 -> 0 | G12: =C12-SUM(D12:F12) -> 5652 | H12: =[6]Dec!$T$1 -> 577.2 | I12: =[6]Dec!$G$1 -> 0
B13: =Admin!B14 -> 46418 | C13: =[6]Jan!$M$1 -> 6748 | D13: =[6]Jan!$N$1 -> 800 | E13: =[6]Jan!$O$1 -> 296 | F13: =[6]Jan!$P$1+[6]Jan!$Q$1 -> 0 | G13: =C13-SUM(D13:F13) -> 5652 | H13: =[6]Jan!$T$1 -> 577.2 | I13: =[6]Jan!$G$1 -> 0
B14: =Admin!B15 -> 46446 | C14: =[6]Feb!$M$1 -> 6748 | D14: =[6]Feb!$N$1 -> 800 | E14: =[6]Feb!$O$1 -> 296 | F14: =[6]Feb!$P$1+[6]Feb!$Q$1 -> 0 | G14: =C14-SUM(D14:F14) -> 5652 | H14: =[6]Feb!$T$1 -> 577.2 | I14: =[6]Feb!$G$1 -> 0
B15: =Admin!B16 -> 46477 | C15: =[6]Mar!$M$1 -> 6748 | D15: =[6]Mar!$N$1 -> 800 | E15: =[6]Mar!$O$1 -> 296 | F15: =[6]Mar!$P$1+[6]Mar!$Q$1 -> 0 | G15: =C15-SUM(D15:F15) -> 5652 | H15: =[6]Mar!$T$1 -> 577.2 | I15: =[6]Mar!$G$1 -> 0

Sheet StockControl
H1: Calculation Of Stock Sold | N1: Calculation Of Stock Sold | T1: Calculation Of Stock Sold
B2: Date | D2: Calculated Stock value | F2: Direct Material BOUGHT | H2: Stock % Prod A | J2: Net Sales Product A | L2: Direct Material SOLD | N2: Stock % Prod B | P2: Net Sales Product B | R2: Direct Material SOLD | T2: Stock % Prod C | V2: Net Sales Product C | X2: Direct Material SOLD | Z2: Stock Loss Adjustment | AB2: ACTUAL STOCK VALUE | AD2: Stock Control User Notes
AD3: 1. Enter the average percentage stock value in cell H4. This is the average % of direct materials included in the net sales value of each product type. The table will repeat this same % for each month unless a new percentage is entered in a specific month which will then overwrite the originally % entered for that and the remaining months
B4: Enter % to change % materials sold | H4: 0 | N4: 0 | T4: 0
B6: =Admin!B4 -> 46118 | D6: =AB6 -> 10000 | AB6: 10000
B8: =Admin!B5 -> 46142 | D8: =D6+F8-L8-R8-X8+Z6 -> 10000 | F8: =IF((H$4+N$4+T$4)=0,0,[3]Apr!$P$1) -> 0 | H8: =H4 -> 0 | J8: =[2]Apr!$P$1 -> 25333.333 | L8: =J8*H8 -> 0 | N8: =N4 -> 0 | P8: =[2]Apr!$Q$1 -> 1800 | R8: =P8*N8 -> 0 | T8: =T4 -> 0 | V8: =[2]Apr!$R$1 -> 0 | X8: =V8*T8 -> 0 | Z8: =IF(AB8<>D8,AB8-D8,0) -> 0 | AB8: =AB6+F8-L8-R8-X8 -> 10000
B10: =Admin!B6 -> 46173 | D10: =D8+F10-L10-R10-X10+Z8 -> 10000 | F10: =IF((H$4+N$4+T$4)=0,0,[3]May!$P$1) -> 0 | H10: =H8 -> 0 | J10: =[2]May!$P$1 -> 25633.333 | L10: =J10*H10 -> 0 | N10: =N8 -> 0 | P10: =[2]May!$Q$1 -> 800 | R10: =P10*N10 -> 0 | T10: =T8 -> 0 | V10: =[2]May!$R$1 -> 1000 | X10: =V10*T10 -> 0 | Z10: =IF(AB10<>D10,AB10-D10,0) -> 0 | AB10: =AB8+F10-L10-R10-X10 -> 10000
AD11: 2. Optional: manually calculate the % of direct materials included in net sales value and enter this percentage in Column H against each month
B12: =Admin!B7 -> 46203 | D12: =D10+F12-L12-R12-X12+Z10 -> 10000 | F12: =IF((H$4+N$4+T$4)=0,0,[3]Jun!$P$1) -> 0 | H12: =H10 -> 0 | J12: =[2]Jun!$P$1 -> 26533.333 | L12: =J12*H12 -> 0 | N12: =N10 -> 0 | P12: =[2]Jun!$Q$1 -> 800 | R12: =P12*N12 -> 0 | T12: =T10 -> 0 | V12: =[2]Jun!$R$1 -> 2000 | X12: =V12*T12 -> 0 | Z12: =IF(AB12<>D12,AB12-D12,0) -> 0 | AB12: =AB10+F12-L12-R12-X12 -> 10000
B14: =Admin!B8 -> 46234 | D14: =D12+F14-L14-R14-X14+Z12 -> 10000 | F14: =IF((H$4+N$4+T$4)=0,0,[3]Jul!$P$1) -> 0 | H14: =H12 -> 0 | J14: =[2]Jul!$P$1 -> 25633.333 | L14: =J14*H14 -> 0 | N14: =N12 -> 0 | P14: =[2]Jul!$Q$1 -> 1800 | R14: =P14*N14 -> 0 | T14: =T12 -> 0 | V14: =[2]Jul!$R$1 -> 0 | X14: =V14*T14 -> 0 | Z14: =IF(AB14<>D14,AB14-D14,0) -> 0 | AB14: =AB12+F14-L14-R14-X14 -> 10000
AD15: 3. Column F automatically collects the value of direct material purchased from the monthly purchases worksheet
B16: =Admin!B9 -> 46265 | D16: =D14+F16-L16-R16-X16+Z14 -> 10000 | F16: =IF((H$4+N$4+T$4)=0,0,[3]Aug!$P$1) -> 0 | H16: =H14 -> 0 | J16: =[2]Aug!$P$1 -> 27133.333 | L16: =J16*H16 -> 0 | N16: =N14 -> 0 | P16: =[2]Aug!$Q$1 -> 800 | R16: =P16*N16 -> 0 | T16: =T14 -> 0 | V16: =[2]Aug!$R$1 -> 0 | X16: =V16*T16 -> 0 | Z16: =IF(AB16<>D16,AB16-D16,0) -> 0 | AB16: =AB14+F16-L16-R16-X16 -> 10000
B18: =Admin!B10 -> 46295 | D18: =D16+F18-L18-R18-X18+Z16 -> 10000 | F18: =IF((H$4+N$4+T$4)=0,0,[3]Sep!$P$1) -> 0 | H18: =H16 -> 0 | J18: =[2]Sep!$P$1 -> 25033.333 | L18: =J18*H18 -> 0 | N18: =N16 -> 0 | P18: =[2]Sep!$Q$1 -> 800 | R18: =P18*N18 -> 0 | T18: =T16 -> 0 | V18: =[2]Sep!$R$1 -> 1800 | X18: =V18*T18 -> 0 | Z18: =IF(AB18<>D18,AB18-D18,0) -> 0 | AB18: =AB16+F18-L18-R18-X18 -> 10000
AD19: 4. Column L automatically calculates the value of direct materials sold by applying the stock sales % to the net sales value from the sales worksheet
B20: =Admin!B11 -> 46326 | D20: =D18+F20-L20-R20-X20+Z18 -> 10000 | F20: =IF((H$4+N$4+T$4)=0,0,[3]Oct!$P$1) -> 0 | H20: =H18 -> 0 | J20: =[2]Oct!$P$1 -> 27133.333 | L20: =J20*H20 -> 0 | N20: =N18 -> 0 | P20: =[2]Oct!$Q$1 -> 1800 | R20: =P20*N20 -> 0 | T20: =T18 -> 0 | V20: =[2]Oct!$R$1 -> 0 | X20: =V20*T20 -> 0 | Z20: =IF(AB20<>D20,AB20-D20,0) -> 0 | AB20: =AB18+F20-L20-R20-X20 -> 10000
B22: =Admin!B12 -> 46356 | D22: =D20+F22-L22-R22-X22+Z20 -> 10000 | F22: =IF((H$4+N$4+T$4)=0,0,[3]Nov!$P$1) -> 0 | H22: =H20 -> 0 | J22: =[2]Nov!$P$1 -> 25633.333 | L22: =J22*H22 -> 0 | N22: =N20 -> 0 | P22: =[2]Nov!$Q$1 -> 800 | R22: =P22*N22 -> 0 | T22: =T20 -> 0 | V22: =[2]Nov!$R$1 -> 3000 | X22: =V22*T22 -> 0 | Z22: =IF(AB22<>D22,AB22-D22,0) -> 0 | AB22: =AB20+F22-L22-R22-X22 -> 10000
AD23: 5. Optional: At the end of each month conduct a physical stock check and value the items counted at cost price. Enter this actual physical value in column P at the appropriate month end date
B24: =Admin!B13 -> 46387 | D24: =D22+F24-L24-R24-X24+Z22 -> 10000 | F24: =IF((H$4+N$4+T$4)=0,0,[3]Dec!$P$1) -> 0 | H24: =H22 -> 0 | J24: =[2]Dec!$P$1 -> 26533.333 | L24: =J24*H24 -> 0 | N24: =N22 -> 0 | P24: =[2]Dec!$Q$1 -> 800 | R24: =P24*N24 -> 0 | T24: =T22 -> 0 | V24: =[2]Dec!$R$1 -> 0 | X24: =V24*T24 -> 0 | Z24: =IF(AB24<>D24,AB24-D24,0) -> 0 | AB24: =AB22+F24-L24-R24-X24 -> 10000
B26: =Admin!B14 -> 46418 | D26: =D24+F26-L26-R26-X26+Z24 -> 10000 | F26: =IF((H$4+N$4+T$4)=0,0,[3]Jan!$P$1) -> 0 | H26: =H24 -> 0 | J26: =[2]Jan!$P$1 -> 25633.333 | L26: =J26*H26 -> 0 | N26: =N24 -> 0 | P26: =[2]Jan!$Q$1 -> 1800 | R26: =P26*N26 -> 0 | T26: =T24 -> 0 | V26: =[2]Jan!$R$1 -> 1000 | X26: =V26*T26 -> 0 | Z26: =IF(AB26<>D26,AB26-D26,0) -> 0 | AB26: =AB24+F26-L26-R26-X26 -> 10000
B28: =Admin!B15 -> 46446 | D28: =D26+F28-L28-R28-X28+Z26 -> 10000 | F28: =IF((H$4+N$4+T$4)=0,0,[3]OpeningCreditors!$P$1) -> 0 | H28: =H26 -> 0 | J28: =[2]Feb!$P$1 -> 26333.333 | L28: =J28*H28 -> 0 | N28: =N26 -> 0 | P28: =[2]Feb!$Q$1 -> 800 | R28: =P28*N28 -> 0 | T28: =T26 -> 0 | V28: =[2]Feb!$R$1 -> 1500 | X28: =V28*T28 -> 0 | Z28: =IF(AB28<>D28,AB28-D28,0) -> 0 | AB28: =AB26+F28-L28-R28-X28 -> 10000 | AD28: 6. If the % of stock sold in net sales is correct then Column Z should be zero unless stock has been lost.. Investigate significant Stock Loss Adjustments
B30: =Admin!B17 -> 46482 | D30: =D28+F30-L30-R30-X30+Z28 -> 10000 | F30: =IF((H$4+N$4+T$4)=0,0,[3]Mar!$P$1) -> 0 | H30: =H28 -> 0 | J30: =[2]Mar!$P$1 -> 25033.333 | L30: =J30*H30 -> 0 | N30: =N28 -> 0 | P30: =[2]Mar!$Q$1 -> 800 | R30: =P30*N30 -> 0 | T30: =T28 -> 0 | V30: =[2]Mar!$R$1 -> 0 | X30: =V30*T30 -> 0 | Z30: =IF(AB30<>D30,AB30-D30,0) -> -4000 | AB30: 6000

Sheet Profit Forecast
B2: ACTUAL Profit and Loss Account | C2: Total Year | D2: =Admin!B5 -> 46142 | E2: =Admin!B6 -> 46173 | F2: =Admin!B7 -> 46203 | G2: =Admin!B8 -> 46234 | H2: =Admin!B9 -> 46265 | I2: =Admin!B10 -> 46295 | J2: =Admin!B11 -> 46326 | K2: =Admin!B12 -> 46356 | L2: =Admin!B13 -> 46387 | M2: =Admin!B14 -> 46418 | N2: =Admin!B15 -> 46446 | O2: =Admin!B16 -> 46477
C3: =Admin!B$17 -> 46482
C4: £ | D4: £ | E4: £ | F4: £ | G4: £ | H4: £ | I4: £ | J4: £ | K4: £ | L4: £ | M4: £ | N4: £ | O4: £
B5: Sales Turnover | C5: =SUM(D5:O5) -> 339200 | D5: ='Profit & Loss Account'!C9 -> 27833.333 | E5: ='Profit & Loss Account'!D9 -> 27433.333 | F5: ='Profit & Loss Account'!E9 -> 29333.333 | G5: ='Profit & Loss Account'!F9 -> 28133.333 | H5: ='Profit & Loss Account'!G9 -> 27933.333 | I5: ='Profit & Loss Account'!H9 -> 28133.333 | J5: ='Profit & Loss Account'!I9 -> 29633.333 | K5: ='Profit & Loss Account'!J9 -> 29433.333 | ... O5: ='Profit & Loss Account'!N9 -> 25833.333
B7: Investment Grants | C7: =SUM(D7:O7) -> 2083.3333 | D7: ='Profit & Loss Account'!C11 -> 0 | E7: ='Profit & Loss Account'!D11 -> 0 | F7: ='Profit & Loss Account'!E11 -> 0 | G7: ='Profit & Loss Account'!F11 -> 0 | H7: ='Profit & Loss Account'!G11 -> 2083.3333 | I7: ='Profit & Loss Account'!H11 -> 0 | J7: ='Profit & Loss Account'!I11 -> 0 | K7: ='Profit & Loss Account'!J11 -> 0 | ... O7: ='Profit & Loss Account'!N11 -> 0
B9: Cost of Sales | C9: =SUM(D9:O9) -> 20136.667 | D9: ='Profit & Loss Account'!C17 -> 737.5 | E9: ='Profit & Loss Account'!D17 -> 1007.5 | F9: ='Profit & Loss Account'!E17 -> 4704.1667 | G9: ='Profit & Loss Account'!F17 -> 1207.5 | H9: ='Profit & Loss Account'!G17 -> 687.5 | I9: ='Profit & Loss Account'!H17 -> 707.5 | J9: ='Profit & Loss Account'!I17 -> 637.5 | K9: ='Profit & Loss Account'!J17 -> 3407.5 | ... O9: ='Profit & Loss Account'!N17 -> 4457.5
B11: Gross Profit | C11: =SUM(D11:O11) -> 321146.67 | D11: =D5+D7-D9 -> 27095.833 | E11: =E5+E7-E9 -> 26425.833 | F11: =F5+F7-F9 -> 24629.167 | G11: =G5+G7-G9 -> 26925.833 | H11: =H5+H7-H9 -> 29329.167 | I11: =I5+I7-I9 -> 27425.833 | J11: =J5+J7-J9 -> 28995.833 | K11: =K5+K7-K9 -> 26025.833 | ... O11: =O5+O7-O9 -> 21375.833
B13: General Expenses | C13: =SUM(D13:O13) -> 157526.82 | D13: ='Profit & Loss Account'!C35 -> 12615.033 | E13: ='Profit & Loss Account'!D35 -> 11929.283 | F13: ='Profit & Loss Account'!E35 -> 14206.617 | G13: ='Profit & Loss Account'!F35 -> 14428.033 | H13: ='Profit & Loss Account'!G35 -> 12368.367 | I13: ='Profit & Loss Account'!H35 -> 13852.617 | J13: ='Profit & Loss Account'!I35 -> 14295.533 | K13: ='Profit & Loss Account'!J35 -> 11492.283 | ... O13: ='Profit & Loss Account'!N35 -> 12173.95
B15: Operating Profit | C15: =SUM(D15:O15) -> 163619.85 | D15: =D11-D13 -> 14480.8 | E15: =E11-E13 -> 14496.55 | F15: =F11-F13 -> 10422.55 | G15: =G11-G13 -> 12497.8 | H15: =H11-H13 -> 16960.8 | I15: =I11-I13 -> 13573.217 | J15: =J11-J13 -> 14700.3 | K15: =K11-K13 -> 14533.55 | ... O15: =O11-O13 -> 9201.8833
B16: Interest received | C16: =SUM(D16:O16) -> 0 | D16: ='Profit & Loss Account'!C38 -> 0 | E16: ='Profit & Loss Account'!D38 -> 0 | F16: ='Profit & Loss Account'!E38 -> 0 | G16: ='Profit & Loss Account'!F38 -> 0 | H16: ='Profit & Loss Account'!G38 -> 0 | I16: ='Profit & Loss Account'!H38 -> 0 | J16: ='Profit & Loss Account'!I38 -> 0 | K16: ='Profit & Loss Account'!J38 -> 0 | ... O16: ='Profit & Loss Account'!N38 -> 0
B17: Profit (Loss) before Tax | C17: =SUM(D17:O17) -> 163619.85 | D17: =D15+D16 -> 14480.8 | E17: =E15+E16 -> 14496.55 | F17: =F15+F16 -> 10422.55 | G17: =G15+G16 -> 12497.8 | H17: =H15+H16 -> 16960.8 | I17: =I15+I16 -> 13573.217 | J17: =J15+J16 -> 14700.3 | K17: =K15+K16 -> 14533.55 | ... O17: =O15+O16 -> 9201.8833
B19: FORECAST Profit and Loss Account | C19: Total Year | D19: =D2 -> 46142 | E19: =E2 -> 46173 | F19: =F2 -> 46203 | G19: =G2 -> 46234 | H19: =H2 -> 46265 | I19: =I2 -> 46295 | J19: =J2 -> 46326 | K19: =K2 -> 46356 | ... O19: =O2 -> 46477
C20: =Admin!B$17 -> 46482
C21: =SUM(D21:O21) -> 12 | D21: =IF(D5>0,1," ") -> 1 | E21: =IF(E5>0,1," ") -> 1 | F21: =IF(F5>0,1," ") -> 1 | G21: =IF(G5>0,1," ") -> 1 | H21: =IF(H5>0,1," ") -> 1 | I21: =IF(I5>0,1," ") -> 1 | J21: =IF(J5>0,1," ") -> 1 | K21: =IF(K5>0,1," ") -> 1 | ... O21: =IF(O5>0,1," ") -> 1
B22: Sales Turnover | C22: =SUM(D22:O22) -> 339200 | D22: =IF(C5>0,IF(D5>0,D5,C5/C21),0) -> 27833.333 | E22: =IF(C5>0,IF(E5>0,E5,C5/C21),0) -> 27433.333 | F22: =IF(C5>0,IF(F5>0,F5,C5/C21),0) -> 29333.333 | G22: =IF(C5>0,IF(G5>0,G5,C5/C21),0) -> 28133.333 | H22: =IF(C5>0,IF(H5>0,H5,C5/C21),0) -> 27933.333 | I22: =IF(C5>0,IF(I5>0,I5,C5/C21),0) -> 28133.333 | J22: =IF(C5>0,IF(J5>0,J5,C5/C21),0) -> 29633.333 | K22: =IF(C5>0,IF(K5>0,K5,C5/C21),0) -> 29433.333 | L22: =IF(C5>0,IF(L5>0,L5,C5/C21),0) -> 27333.333 | M22: =IF(C5>0,IF(M5>0,M5,C5/C21),0) -> 29533.333 | N22: =IF(C5>0,IF(N5>0,N5,C5/C21),0) -> 28633.333 | O22: =IF(C5>0,IF(O5>0,O5,C5/C21),0) -> 25833.333
B24: Investment Grants | C24: =SUM(D24:O24) -> 2083.3333 | D24: =D7 -> 0 | E24: =E7 -> 0 | F24: =F7 -> 0 | G24: =G7 -> 0 | H24: =H7 -> 2083.3333 | I24: =I7 -> 0 | J24: =J7 -> 0 | K24: =K7 -> 0 | ... O24: =O7 -> 0
B26: Cost of Sales | C26: =SUM(D26:O26) -> 20136.667 | D26: =IF(C5>0,IF(D5>0,D9,C9/C21),0) -> 737.5 | E26: =IF(C5>0,IF(E5>0,E9,C9/C21),0) -> 1007.5 | F26: =IF(C5>0,IF(F5>0,F9,C9/C21),0) -> 4704.1667 | G26: =IF(C5>0,IF(G5>0,G9,C9/C21),0) -> 1207.5 | H26: =IF(C5>0,IF(H5>0,H9,C9/C21),0) -> 687.5 | I26: =IF(C5>0,IF(I5>0,I9,C9/C21),0) -> 707.5 | J26: =IF(C5>0,IF(J5>0,J9,C9/C21),0) -> 637.5 | K26: =IF(C5>0,IF(K5>0,K9,C9/C21),0) -> 3407.5 | L26: =IF(C5>0,IF(L5>0,L9,C9/C21),0) -> 637.5 | M26: =IF(C5>0,IF(M5>0,M9,C9/C21),0) -> 857.5 | N26: =IF(C5>0,IF(N5>0,N9,C9/C21),0) -> 1087.5 | O26: =IF(C5>0,IF(O5>0,O9,C9/C21),0) -> 4457.5
B28: Gross Profit | C28: =SUM(D28:O28) -> 321146.67 | D28: =D22+D24-D26 -> 27095.833 | E28: =E22+E24-E26 -> 26425.833 | F28: =F22+F24-F26 -> 24629.167 | G28: =G22+G24-G26 -> 26925.833 | H28: =H22+H24-H26 -> 29329.167 | I28: =I22+I24-I26 -> 27425.833 | J28: =J22+J24-J26 -> 28995.833 | K28: =K22+K24-K26 -> 26025.833 | ... O28: =O22+O24-O26 -> 21375.833
B30: General Expenses | C30: =SUM(D30:O30) -> 157526.82 | D30: =IF(C5>0,IF(D5>0,D13,C13/C21),0) -> 12615.033 | E30: =IF(C5>0,IF(E5>0,E13,C13/C21),0) -> 11929.283 | F30: =IF(C5>0,IF(F5>0,F13,C13/C21),0) -> 14206.617 | G30: =IF(C5>0,IF(G5>0,G13,C13/C21),0) -> 14428.033 | H30: =IF(C5>0,IF(H5>0,H13,C13/C21),0) -> 12368.367 | I30: =IF(C5>0,IF(I5>0,I13,C13/C21),0) -> 13852.617 | J30: =IF(C5>0,IF(J5>0,J13,C13/C21),0) -> 14295.533 | K30: =IF(C5>0,IF(K5>0,K13,C13/C21),0) -> 11492.283 | L30: =IF(C5>0,IF(L5>0,L13,C13/C21),0) -> 16503.283 | M30: =IF(C5>0,IF(M5>0,M13,C13/C21),0) -> 11995.033 | N30: =IF(C5>0,IF(N5>0,N13,C13/C21),0) -> 11666.783 | O30: =IF(C5>0,IF(O5>0,O13,C13/C21),0) -> 12173.95
B32: Operating Profit | C32: =SUM(D32:O32) -> 163619.85 | D32: =D28-D30 -> 14480.8 | E32: =E28-E30 -> 14496.55 | F32: =F28-F30 -> 10422.55 | G32: =G28-G30 -> 12497.8 | H32: =H28-H30 -> 16960.8 | I32: =I28-I30 -> 13573.217 | J32: =J28-J30 -> 14700.3 | K32: =K28-K30 -> 14533.55 | ... O32: =O28-O30 -> 9201.8833
B33: Interest received | C33: =SUM(D33:O33) -> 0 | D33: =D16 -> 0 | E33: =E16 -> 0 | F33: =F16 -> 0 | G33: =G16 -> 0 | H33: =H16 -> 0 | I33: =I16 -> 0 | J33: =J16 -> 0 | K33: =K16 -> 0 | ... O33: =O16 -> 0
B34: Profit (Loss) before Tax | C34: =SUM(D34:O34) -> 163619.85 | D34: =D32+D33 -> 14480.8 | E34: =E32+E33 -> 14496.55 | F34: =F32+F33 -> 10422.55 | G34: =G32+G33 -> 12497.8 | H34: =H32+H33 -> 16960.8 | I34: =I32+I33 -> 13573.217 | J34: =J32+J33 -> 14700.3 | K34: =K32+K33 -> 14533.55 | ... O34: =O32+O33 -> 9201.8833
B36: FORECAST TAX CALCULATION
B37: Add Depreciation | C37: ='Profit & Loss Account'!B33+'Profit & Loss Account'!B34 -> 21037
B38: Less Capital Allowances | C38: =[1]Schedule!$Q$1+[1]Schedule!$R$1+[1]Schedule!$AC$1+[1]Schedule!$Y$1-[1]Schedule!$Z$1 -> 65324
B39: Profit before Tax | C39: =C34+C37-C38 -> 119332.85
B40: Personal Allowance | C40: =IF(C39<=0,0,MAX(0,Admin!N$4-MAX(0,C39-Admin!N$5)/2)) -> 2903.575
B41: Profit after Allowance | C41: =IF((C39>C40),(C39-C40),0) -> 116429.27
B42: Tax at standard rate | C42: =IF((C41>0),(IF((C41<Admin!M$11),C41*Admin!N$6,Admin!M$11*Admin!N$6)),0) -> 7540
B43: Tax at higher rate | C43: =IF(C41>Admin!M$11,(MIN(C41,Admin!N$13)-Admin!M$11)*Admin!N$7,0) -> 31491.71
B44: Tax at additional rate | C44: =IF(C41>Admin!N$13,(C41-Admin!N$13)*Admin!N$8,0) -> 0
B45: National Insurance | C45: =IF(C39>Admin!N$20,IF(C39<Admin!N$23,(C39-Admin!N$20)*Admin!L$20,(Admin!N$23-Admin!N$20)*Admin!L$20),0)+IF(C39>Admin!N$23,(C39-Admin!N$23)*Admin!L$23,0) -> 3643.257
B46: TAX & NI LIABILITY | C46: =C42+C43+C44+C45 -> 42674.967

Sheet Admin
B1: Dates
B2: 46081 | D2: Capital Tax Allowances | G2: =B23 -> 2026-27 | J2: Income Tax Rates | L2: =G2 -> 2026-27
B3: 46112
B4: 46118 | D4: Annual Investment Allowance | G4: 1 | I4: Personal allowance | N4: 12570 | O4: £
B5: 46142 | D5: Writing down allowance | G5: 0.14 | I5: Personal allowance taper threshold | N5: 100000 | O5: £
B6: 46173 | D6: Special rate writing down allowance | G6: 0.06 | I6: Basic rate applicable on taxable income up to higher rate | N6: 0.2 | O6: %
B7: 46203 | D7: Allowances restricted on Motor vehicles | I7: Higher rate applicable on taxable income over higher rate | N7: 0.4 | O7: %
B8: 46234 | I8: Additional rate applicable above the higher rate limit | N8: 0.45 | O8: %
B9: 46265 | D9: Structures and buildings allowance | G9: 0.03 | I9: Taxable Bands Allowances | L9: Start Level | M9: End Level | N9: Tax Band
B10: 46295 | D10: Freeport and Investment Zone SBA | G10: 0.1
B11: 46326 | D11: Depreciation Rates Applied | G11: % | I11: Basic rate | K11: 0.2 | L11: =N11 -> 0 | M11: 37700 | N11: 0
B12: 46356 | I12: Higher rate | K12: 0.4 | L12: 37701 | N12: 37701
B13: 46387 | D13: Land & Property | G13: 0 | I13: Additional rate | K13: 0.45 | L13: 125141 | N13: 125140
B14: 46418 | D14: Plant & Machinery | G14: 0.1 | I14: National Insurance rates | L14: =G2 -> 2026-27
B15: 46446 | D15: Fixtures & Fittings | G15: 0.2
B16: 46477 | D16: Computer Equipment | G16: 0.33 | I16: NI Class 2 rate | L16: 3.65 | M16: Above Lower Profits Threshold (LPT) | N16: 7105 | O16: £
B17: 46482 | D17: Motor Vehicles | G17: 0.25
B18: 46507
B19: 46538 | D19: Mileage Allowances | F19: Miles | G19: p per mile | I19: NI Class 4 rate between lower profits and upper profits limit | M19: NIC class 4 lower limit
B20: 46568 | L20: 0.06 | N20: 12570 | O20: £
B21: 46783 | D21: Higher rate allowance up to | F21: 10000 | G21: 0.55
