Workbook

Sheet Home
B2: Taxi Driver Accounts
B4: Click a link below to navigate to the desired page. To return to the home page click the Home tab. If you can't see the Home tab, you can scroll to it by clicking the |< symbol (bottom left).
B6: Preparation | C6: Taxi Receipts | D6: Expenses | E6: Results
B8: =HYPERLINK("#'Business Details'!C5","Business Details") -> Business Details | C8: =HYPERLINK("#'SalesApr'!E5","SalesApr") -> SalesApr | D8: =HYPERLINK("#'PurchasesApr'!A5","PurchasesApr") -> PurchasesApr | E8: =HYPERLINK("#'SE Short'!C8","SE Short") -> SE Short
B9: =HYPERLINK("#'Fixed Assets'!A7","Fixed Assets") -> Fixed Assets | C9: =HYPERLINK("#'SalesMay'!E5","SalesMay") -> SalesMay | D9: =HYPERLINK("#'PurchasesMay'!A5","PurchasesMay") -> PurchasesMay | E9: =HYPERLINK("#'Profit & Loss Acc'!A1","Profit & Loss Acc") -> Profit & Loss Acc
C10: =HYPERLINK("#'SalesJun'!E5","SalesJun") -> SalesJun | D10: =HYPERLINK("#'PurchasesJun'!A5","PurchasesJun") -> PurchasesJun | E10: =HYPERLINK("#'Draft Tax Calculation'!D2","Draft Tax Calculation") -> Draft Tax Calculation
C11: =HYPERLINK("#'SalesJul'!E5","SalesJul") -> SalesJul | D11: =HYPERLINK("#'PurchasesJul'!A5","PurchasesJul") -> PurchasesJul
C12: =HYPERLINK("#'SalesAug'!E5","SalesAug") -> SalesAug | D12: =HYPERLINK("#'PurchasesAug'!A5","PurchasesAug") -> PurchasesAug
C13: =HYPERLINK("#'SalesSep'!E5","SalesSep") -> SalesSep | D13: =HYPERLINK("#'PurchasesSep'!A5","PurchasesSep") -> PurchasesSep
C14: =HYPERLINK("#'SalesOct'!E5","SalesOct") -> SalesOct | D14: =HYPERLINK("#'PurchasesOct'!A5","PurchasesOct") -> PurchasesOct
C15: =HYPERLINK("#'SalesNov'!E5","SalesNov") -> SalesNov | D15: =HYPERLINK("#'PurchasesNov'!A5","PurchasesNov") -> PurchasesNov
C16: =HYPERLINK("#'SalesDec'!E5","SalesDec") -> SalesDec | D16: =HYPERLINK("#'PurchasesDec'!A5","PurchasesDec") -> PurchasesDec
C17: =HYPERLINK("#'SalesJan'!E5","SalesJan") -> SalesJan | D17: =HYPERLINK("#'PurchasesJan'!A5","PurchasesJan") -> PurchasesJan
C18: =HYPERLINK("#'SalesFeb'!E5","SalesFeb") -> SalesFeb | D18: =HYPERLINK("#'PurchasesFeb'!A5","PurchasesFeb") -> PurchasesFeb
C19: =HYPERLINK("#'SalesMar'!E5","SalesMar") -> SalesMar | D19: =HYPERLINK("#'PurchasesMar'!A5","PurchasesMar") -> PurchasesMar

Sheet Business Details
A1: ENTER YOUR BUSINESS DETAILS - which are then transferred to the Self-employment Tax Return
C3: Your name | N3: Your unique taxpayer reference (UTR)
A7: 1 | C7: Description of business | L7: 4 | N7: If you are a foster carer or adult placement carer, put 'X'
C8: Taxi Driver | N8: in the box - read page SESN 2 of the notes
L12: 5 | N12: If your business started sifter | S12: =Admin!B4 -> 43927
N13: enter the start date DD/MM/YYY
A15: 2 | C15: Postcode of your business
L18: 6 | N18: If your business ceased before | S18: =Admin!B17 -> 44291
A19: 3 | C19: If your business name, description, address or postcode | N19: enter the final date of trading
C20: have changed in the last 12 months, put 'X' in the box
C21: and give details in the 'Any other information' box of
C22: of your Tax Return
L23: 7 | N23: Date your books or accounts are made up to - read
N24: page SESN 2 of the notes
N25: =Admin!B17 -> 44291
A27: 26 | C27: ENTER: Total losses brought forward from earlier years | L27: 24 | N27: ENTER: Value of goods and services for your own use
N28: - read page SESN 7 of the notes
C29: £ | G29: . | H29: 0 | I29: 0 | N29: £ | R29: . | S29: 0 | T29: 0
C31: Loss used this year | N31: Total loss carried forward to future years
C32: Calculated no entry required | N32: Calculated no entry required
C34: £ | D34: ='SE Short'!O94 -> 0 | G34: . | H34: 0 | I34: 0 | N34: £ | O34: =D29-D34+'SE Short'!O106 -> 0 | R34: . | S34: 0 | T34: 0

Sheet SE Short
A1: HM Revenue & Customs | G1: COPY DETAILS TO HMRC FORM Submit HMRC ONLINE by 31st January 2022 | O1: Self-employment (short)
O2: Tax year | Q2: =Admin!B4 -> 43927 | U2: to | V2: =Admin!B17 -> 44291
C6: Your name | N6: Your unique taxpayer reference (UTR)
C8: =IF('Business Details'!C5>0,'Business Details'!C5," ") | O8: =IF('Business Details'!O5>0,'Business Details'!O5," ") | R8: =IF('Business Details'!R5>0,'Business Details'!R5," ")
A10: Business details
A12: 1 | C12: Description of business | L12: 4 | N12: If you are a foster carer or adult placement carer, put 'X'
C13: =IF('Business Details'!C8>0,'Business Details'!C8," ") -> Taxi Driver | N13: in the box - read page SESN 2 of the notes
C15: =IF('Business Details'!C10>0,'Business Details'!C10," ")
C17: =IF('Business Details'!C12>0,'Business Details'!C12," ") | L17: 5 | N17: If your business started sifter | S17: =Admin!B4 -> 43927
N18: enter the start date DD/MM/YYYY
A20: 2 | C20: Postcode of your business | N20: =IF('Business Details'!N15>0,'Business Details'!N15," ")
C22: =IF('Business Details'!C17>0,'Business Details'!C17," ") | F22: =IF('Business Details'!F17>0,'Business Details'!F17," ")
L23: 6 | N23: If your business ceased before | S23: =Admin!B17 -> 44291
A24: 3 | C24: If your business name, description, address or postcode | N24: enter the final date of trading
C25: have changed in the last 12 months, put 'X' in the box
C26: and give details in the 'Any other information' box of | N26: =IF('Business Details'!N21>0,'Business Details'!N21," ")
C27: of your Tax Return
L28: 7 | N28: Date your books or accounts are made up to - read
C29: =IF('Business Details'!C24="x","x"," ") | N29: page SESN 2 of the notes
N31: =Admin!B17 -> 44291
A33: ="Business income - if your annual turnover was below £"&Admin!F26&" VAT threshold" -> Business income - if your annual turnover was below £85000 VAT threshold
A35: 8 | C35: Your turnover - the takings, fees, sales or money earned | L35: 9 | N35: Any other business income not included in box 8
C36: by your business | N36: - excluding Business Start-up Allowance
C38: £ | D38: ='Profit & Loss Acc'!B5 -> 36000 | G38: . | H38: 0 | I38: 0 | N38: £ | R38: . | S38: 0 | T38: 0
A40: Allowable business expenses
A41: Read pages SESN 3 of the notes to see which expenses are allowed for tax purposes. If your annual turnover was below £30,000
A42: you may just put your total expenses in box 19, rather than filling in the whole section.
A44: 10 | C44: Cost of goods bought for re-sale or goods used | L44: 15 | N44: Accountancy, legal and other professional fees
C46: £ | D46: =IF(('Profit & Loss Acc'!B5<30000)," ",'Profit & Loss Acc'!B12-'Profit & Loss Acc'!B10) -> 4980 | G46: . | H46: 0 | I46: 0 | N46: £ | O46: =IF(('Profit & Loss Acc'!B5<30000)," ",'Profit & Loss Acc'!B18) -> 900 | R46: . | S46: 0 | T46: 0
A48: 11 | C48: Car, van and other travel expenses - after private | L48: 16 | N48: Interest and bank and credit card etc. financial charges
C49: use proportion
C51: £ | G51: . | H51: 0 | I51: 0 | N51: £ | O51: =IF(('Profit & Loss Acc'!B5<30000)," ",'Profit & Loss Acc'!B19+'Profit & Loss Acc'!B20) -> 0 | R51: . | S51: 0 | T51: 0
A53: 12 | C53: Wages, salaries and other staff costs | L53: 17 | N53: Telephone, fax, stationery and other office costs
C55: £ | D55: =IF(('Profit & Loss Acc'!B5<30000)," ",'Profit & Loss Acc'!B14) -> 0 | G55: . | H55: 0 | I55: 0 | N55: £ | O55: =IF(('Profit & Loss Acc'!B5<30000)," ",'Profit & Loss Acc'!B16) -> 480 | R55: . | S55: 0 | T55: 0
A57: 13 | C57: Rent, rates, power and insurance costs | L57: 18 | N57: Other allowable business expenses - client entertaining
N58: costs are not an allowable expense
C60: £ | D60: =IF(('Profit & Loss Acc'!B5<30000)," ",'Profit & Loss Acc'!B15) -> 0 | G60: . | H60: 0 | I60: 0 | N60: £ | O60: =IF(('Profit & Loss Acc'!B5<30000)," ",'Profit & Loss Acc'!B17+'Profit & Loss Acc'!B21) -> 0 | R60: . | S60: 0 | T60: 0
A62: 14 | C62: Repairs and renewals of property and equipment | L62: 19 | N62: Total allowable expenses - total of boxes 10 to 18
C64: £ | G64: . | H64: 0 | I64: 0 | N64: £ | O64: ='Profit & Loss Acc'!B12+'Profit & Loss Acc'!B22-'Profit & Loss Acc'!B10 -> 6360 | R64: . | S64: 0 | T64: 0
A66: Net profit or loss
...

Sheet Profit & Loss Acc
A1: Profit & Loss account automatically updates with the most tax efficient option | B1: =ROUND(PurchasesMar!$A$2,0) -> 0 | C1: =IF(B1>J1,"MILEAGE ALLOWANCE"," ") | D1: =IF(J1>=B1,"CABSMART MOST TAX EFFICIENT OPTION IS > > > >","CABSMART < < < < MOST TAX EFFICIENT OPTION IS") -> CABSMART MOST TAX EFFICIENT OPTION IS > > > > | I1: =IF(J1>=B1,"VEHICLE EXPENSES"," ") -> VEHICLE EXPENSES | J1: =ROUND(PurchasesMar!$I$2+'Fixed Assets'!I1-'Fixed Assets'!I15-'Fixed Assets'!I44+'Fixed Assets'!J1-'Fixed Assets'!J15-'Fixed Assets'!J44+'Fixed Assets'!P1-'Fixed Assets'!P15-'Fixed Assets'!P44-'Fixed Assets'!Q1+'Fixed Assets'!Q15+'Fixed Assets'!Q44,0) -> 4980 | K1: Enter mileage and vehicle expenses on the sales and expenses sheet and the formula will automatically select the best option
A2: Profit & Loss Account | B2: TOTAL | C2: =Admin!B$5 -> 43951 | D2: =Admin!B$6 -> 43982 | E2: =Admin!B$7 -> 44012 | F2: =Admin!B$8 -> 44043 | G2: =Admin!B$9 -> 44074 | H2: =Admin!B$10 -> 44104 | I2: =Admin!B$11 -> 44135 | J2: =Admin!B$12 -> 44165 | K2: =Admin!B$13 -> 44196 | L2: =Admin!B$14 -> 44227 | M2: =Admin!B$15 -> 44255 | N2: =Admin!B$16 -> 44286
B3: =Admin!G$2 -> 2020-21
A4: =IF(B4=" "," ","Purchase analysis errors") | B4: =IF((SUM(C4:N4)>1),ROUND(SUM(C4:N4),0)," ") | C4: =IF((PurchasesApr!$D$1<>0),PurchasesApr!$D$1," ") | D4: =IF((PurchasesMay!$D$1<>0),PurchasesMay!$D$1," ") | E4: =IF((PurchasesJun!$D$1<>0),PurchasesJun!$D$1," ") | F4: =IF((PurchasesJul!$D$1<>0),PurchasesJul!$D$1," ") | G4: =IF((PurchasesAug!$D$1<>0),PurchasesAug!$D$1," ") | H4: =IF((PurchasesSep!$D$1<>0),PurchasesSep!$D$1," ") | I4: =IF((PurchasesOct!$D$1<>0),PurchasesOct!$D$1," ") | J4: =IF((PurchasesNov!$D$1<>0),PurchasesNov!$D$1," ") | K4: =IF((PurchasesDec!$D$1<>0),PurchasesDec!$D$1," ") | L4: =IF((PurchasesJan!$D$1<>0),PurchasesJan!$D$1," ") | M4: =IF((PurchasesFeb!$D$1<>0),PurchasesFeb!$D$1," ") | N4: =IF((PurchasesMar!$D$1<>0),PurchasesMar!$D$1," ")
A5: Sales Turnover | B5: =ROUNDDOWN(SUM(C5:N5),0) -> 36000 | C5: =SalesApr!$E$1 -> 3000 | D5: =SalesMay!$E$1 -> 3000 | E5: =SalesJun!$E$1 -> 3000 | F5: =SalesJul!$E$1 -> 3000 | G5: =SalesAug!$E$1 -> 3000 | H5: =SalesSep!$E$1 -> 3000 | I5: =SalesOct!$E$1 -> 3000 | J5: =SalesNov!$E$1 -> 3000 | K5: =SalesDec!$E$1 -> 3000 | L5: =SalesJan!$E$1 -> 3000 | M5: =SalesFeb!$E$1 -> 3000 | N5: =SalesMar!$E$1 -> 3000
A6: Fuel & Oil Expenses | B6: =ROUNDUP(SUM(C6:N6),0) -> 3600 | C6: =IF((C1="mileage allowance"),0,(PurchasesApr!$G$1)) -> 300 | D6: =IF((C1="mileage allowance"),0,(PurchasesMay!$G$1)) -> 300 | E6: =IF((C1="mileage allowance"),0,(PurchasesJun!$G$1)) -> 300 | F6: =IF((C1="mileage allowance"),0,(PurchasesJul!$G$1)) -> 300 | G6: =IF((C1="mileage allowance"),0,(PurchasesAug!$G$1)) -> 300 | H6: =IF((C1="mileage allowance"),0,(PurchasesSep!$G$1)) -> 300 | I6: =IF((C1="mileage allowance"),0,(PurchasesOct!$G$1)) -> 300 | J6: =IF((C1="mileage allowance"),0,(PurchasesNov!$G$1)) -> 300 | K6: =IF((C1="mileage allowance"),0,(PurchasesDec!$G$1)) -> 300 | L6: =IF((C1="mileage allowance"),0,(PurchasesJan!$G$1)) -> 300 | M6: =IF((C1="mileage allowance"),0,(PurchasesFeb!$G$1)) -> 300 | N6: =IF((C1="mileage allowance"),0,(PurchasesMar!$G$1)) -> 300
A7: Car Hire/Vehicle Leasing | B7: =ROUNDUP(SUM(C7:N7),0) -> 0 | C7: =IF((C1="mileage allowance"),0,(PurchasesApr!$H$1)) -> 0 | D7: =IF((C1="mileage allowance"),0,(PurchasesMay!$H$1)) -> 0 | E7: =IF((C1="mileage allowance"),0,(PurchasesJun!$H$1)) -> 0 | F7: =IF((C1="mileage allowance"),0,(PurchasesJul!$H$1)) -> 0 | G7: =IF((C1="mileage allowance"),0,(PurchasesAug!$H$1)) -> 0 | H7: =IF((C1="mileage allowance"),0,(PurchasesSep!$H$1)) -> 0 | I7: =IF((C1="mileage allowance"),0,(PurchasesOct!$H$1)) -> 0 | J7: =IF((C1="mileage allowance"),0,(PurchasesNov!$H$1)) -> 0 | K7: =IF((C1="mileage allowance"),0,(PurchasesDec!$H$1)) -> 0 | L7: =IF((C1="mileage allowance"),0,(PurchasesJan!$H$1)) -> 0 | M7: =IF((C1="mileage allowance"),0,(PurchasesFeb!$H$1)) -> 0 | N7: =IF((C1="mileage allowance"),0,(PurchasesMar!$H$1)) -> 0
A8: Repairs, servicing and parts | B8: =ROUNDUP(SUM(C8:N8),0) -> 0 | C8: =IF((C1="mileage allowance"),0,(PurchasesApr!$I$1)) -> 0 | D8: =IF((C1="mileage allowance"),0,(PurchasesMay!$I$1)) -> 0 | E8: =IF((C1="mileage allowance"),0,(PurchasesJun!$I$1)) -> 0 | F8: =IF((C1="mileage allowance"),0,(PurchasesJul!$I$1)) -> 0 | G8: =IF((C1="mileage allowance"),0,(PurchasesAug!$I$1)) -> 0 | H8: =IF((C1="mileage allowance"),0,(PurchasesSep!$I$1)) -> 0 | I8: =IF((C1="mileage allowance"),0,(PurchasesOct!$I$1)) -> 0 | J8: =IF((C1="mileage allowance"),0,(PurchasesNov!$I$1)) -> 0 | K8: =IF((C1="mileage allowance"),0,(PurchasesDec!$I$1)) -> 0 | L8: =IF((C1="mileage allowance"),0,(PurchasesJan!$I$1)) -> 0 | M8: =IF((C1="mileage allowance"),0,(PurchasesFeb!$I$1)) -> 0 | N8: =IF((C1="mileage allowance"),0,(PurchasesMar!$I$1)) -> 0
A9: Road tax and insurance | B9: =ROUNDUP(SUM(C9:N9),0) -> 1380 | C9: =IF((C1="mileage allowance"),0,(PurchasesApr!$J$1)) -> 1380 | D9: =IF((C1="mileage allowance"),0,(PurchasesMay!$J$1)) -> 0 | E9: =IF((C1="mileage allowance"),0,(PurchasesJun!$J$1)) -> 0 | F9: =IF((C1="mileage allowance"),0,(PurchasesJul!$J$1)) -> 0 | G9: =IF((C1="mileage allowance"),0,(PurchasesAug!$J$1)) -> 0 | H9: =IF((C1="mileage allowance"),0,(PurchasesSep!$J$1)) -> 0 | I9: =IF((C1="mileage allowance"),0,(PurchasesOct!$J$1)) -> 0 | J9: =IF((C1="mileage allowance"),0,(PurchasesNov!$J$1)) -> 0 | K9: =IF((C1="mileage allowance"),0,(PurchasesDec!$J$1)) -> 0 | L9: =IF((C1="mileage allowance"),0,(PurchasesJan!$J$1)) -> 0 | M9: =IF((C1="mileage allowance"),0,(PurchasesFeb!$J$1)) -> 0 | N9: =IF((C1="mileage allowance"),0,(PurchasesMar!$J$1)) -> 0
A10: Capital Allowances | B10: =IF((C1="mileage allowance"),0,('Fixed Assets'!I1+'Fixed Assets'!J1+'Fixed Assets'!P1-'Fixed Assets'!Q1)) -> 0 | C10: =B10/12 -> 0 | D10: =B10/12 -> 0 | E10: =B10/12 -> 0 | F10: =B10/12 -> 0 | G10: =B10/12 -> 0 | H10: =B10/12 -> 0 | I10: =B10/12 -> 0 | J10: =B10/12 -> 0 | K10: =B10/12 -> 0 | L10: =B10/12 -> 0 | M10: =B10/12 -> 0 | N10: =B10/12 -> 0
A11: Mileage Allowance | B11: =ROUNDUP(SUM(C11:N11),0) -> 0 | C11: =IF((C1="mileage allowance"),(PurchasesApr!$U$1),0) -> 0 | D11: =IF((C1="mileage allowance"),(PurchasesMay!$U$1),0) -> 0 | E11: =IF((C1="mileage allowance"),(PurchasesJun!$U$1),0) -> 0 | F11: =IF((C1="mileage allowance"),(PurchasesJul!$U$1),0) -> 0 | G11: =IF((C1="mileage allowance"),(PurchasesAug!$U$1),0) -> 0 | H11: =IF((C1="mileage allowance"),(PurchasesSep!$U$1),0) -> 0 | I11: =IF((C1="mileage allowance"),(PurchasesOct!$U$1),0) -> 0 | J11: =IF((C1="mileage allowance"),(PurchasesNov!$U$1),0) -> 0 | K11: =IF((C1="mileage allowance"),(PurchasesDec!$U$1),0) -> 0 | L11: =IF((C1="mileage allowance"),(PurchasesJan!$U$1),0) -> 0 | M11: =IF((C1="mileage allowance"),(PurchasesFeb!$U$1),0) -> 0 | N11: =IF((C1="mileage allowance"),(PurchasesMar!$U$1),0) -> 0
A12: Cost of Sales | B12: =ROUNDUP(SUM(B6:B11),0) -> 4980 | C12: =SUM(C6:C11) -> 1680 | D12: =SUM(D6:D11) -> 300 | E12: =SUM(E6:E11) -> 300 | F12: =SUM(F6:F11) -> 300 | G12: =SUM(G6:G11) -> 300 | H12: =SUM(H6:H11) -> 300 | I12: =SUM(I6:I11) -> 300 | J12: =SUM(J6:J11) -> 300 | ... N12: =SUM(N6:N11) -> 300
A13: Gross Profit | B13: =ROUNDUP(B5-B12,0) -> 31020 | C13: =C5-C12 -> 1320 | D13: =D5-D12 -> 2700 | E13: =E5-E12 -> 2700 | F13: =F5-F12 -> 2700 | G13: =G5-G12 -> 2700 | H13: =H5-H12 -> 2700 | I13: =I5-I12 -> 2700 | J13: =J5-J12 -> 2700 | ... N13: =N5-N12 -> 2700
A14: Employee costs | B14: =ROUNDUP(SUM(C14:N14),0) -> 0 | C14: =PurchasesApr!$K$1 -> 0 | D14: =PurchasesMay!$K$1 -> 0 | E14: =PurchasesJun!$K$1 -> 0 | F14: =PurchasesJul!$K$1 -> 0 | G14: =PurchasesAug!$K$1 -> 0 | H14: =PurchasesSep!$K$1 -> 0 | I14: =PurchasesOct!$K$1 -> 0 | J14: =PurchasesNov!$K$1 -> 0 | K14: =PurchasesDec!$K$1 -> 0 | L14: =PurchasesJan!$K$1 -> 0 | M14: =PurchasesFeb!$K$1 -> 0 | N14: =PurchasesMar!$K$1 -> 0
A15: Premises costs | B15: =ROUNDUP(SUM(C15:N15),0) -> 0 | C15: =PurchasesApr!$L$1 -> 0 | D15: =PurchasesMay!$L$1 -> 0 | E15: =PurchasesJun!$L$1 -> 0 | F15: =PurchasesJul!$L$1 -> 0 | G15: =PurchasesAug!$L$1 -> 0 | H15: =PurchasesSep!$L$1 -> 0 | I15: =PurchasesOct!$L$1 -> 0 | J15: =PurchasesNov!$L$1 -> 0 | K15: =PurchasesDec!$L$1 -> 0 | L15: =PurchasesJan!$L$1 -> 0 | M15: =PurchasesFeb!$L$1 -> 0 | N15: =PurchasesMar!$L$1 -> 0
A16: General admin expenses | B16: =ROUNDUP(SUM(C16:N16),0) -> 480 | C16: =PurchasesApr!$M$1 -> 120 | D16: =PurchasesMay!$M$1 -> 0 | E16: =PurchasesJun!$M$1 -> 0 | F16: =PurchasesJul!$M$1 -> 120 | G16: =PurchasesAug!$M$1 -> 0 | H16: =PurchasesSep!$M$1 -> 0 | I16: =PurchasesOct!$M$1 -> 120 | J16: =PurchasesNov!$M$1 -> 0 | K16: =PurchasesDec!$M$1 -> 0 | L16: =PurchasesJan!$M$1 -> 120 | M16: =PurchasesFeb!$M$1 -> 0 | N16: =PurchasesMar!$M$1 -> 0
A17: Advertising & promotion | B17: =ROUNDUP(SUM(C17:N17),0) -> 0 | C17: =PurchasesApr!$N$1 -> 0 | D17: =PurchasesMay!$N$1 -> 0 | E17: =PurchasesJun!$N$1 -> 0 | F17: =PurchasesJul!$N$1 -> 0 | G17: =PurchasesAug!$N$1 -> 0 | H17: =PurchasesSep!$N$1 -> 0 | I17: =PurchasesOct!$N$1 -> 0 | J17: =PurchasesNov!$N$1 -> 0 | K17: =PurchasesDec!$N$1 -> 0 | L17: =PurchasesJan!$N$1 -> 0 | M17: =PurchasesFeb!$N$1 -> 0 | N17: =PurchasesMar!$N$1 -> 0
A18: Legal & professional | B18: =ROUNDUP(SUM(C18:N18),0) -> 900 | C18: =PurchasesApr!$O$1 -> 400 | D18: =PurchasesMay!$O$1 -> 0 | E18: =PurchasesJun!$O$1 -> 0 | F18: =PurchasesJul!$O$1 -> 0 | G18: =PurchasesAug!$O$1 -> 0 | H18: =PurchasesSep!$O$1 -> 0 | I18: =PurchasesOct!$O$1 -> 0 | J18: =PurchasesNov!$O$1 -> 0 | K18: =PurchasesDec!$O$1 -> 0 | L18: =PurchasesJan!$O$1 -> 500 | M18: =PurchasesFeb!$O$1 -> 0 | N18: =PurchasesMar!$O$1 -> 0
A19: Interest | B19: =ROUNDUP(SUM(C19:N19),0) -> 0 | C19: =PurchasesApr!$P$1 -> 0 | D19: =PurchasesMay!$P$1 -> 0 | E19: =PurchasesJun!$P$1 -> 0 | F19: =PurchasesJul!$P$1 -> 0 | G19: =PurchasesAug!$P$1 -> 0 | H19: =PurchasesSep!$P$1 -> 0 | I19: =PurchasesOct!$P$1 -> 0 | J19: =PurchasesNov!$P$1 -> 0 | K19: =PurchasesDec!$P$1 -> 0 | L19: =PurchasesJan!$P$1 -> 0 | M19: =PurchasesFeb!$P$1 -> 0 | N19: =PurchasesMar!$P$1 -> 0
A20: Other finance charges | B20: =ROUNDUP(SUM(C20:N20),0) -> 0 | C20: =PurchasesApr!$Q$1 -> 0 | D20: =PurchasesMay!$Q$1 -> 0 | E20: =PurchasesJun!$Q$1 -> 0 | F20: =PurchasesJul!$Q$1 -> 0 | G20: =PurchasesAug!$Q$1 -> 0 | H20: =PurchasesSep!$Q$1 -> 0 | I20: =PurchasesOct!$Q$1 -> 0 | J20: =PurchasesNov!$Q$1 -> 0 | K20: =PurchasesDec!$Q$1 -> 0 | L20: =PurchasesJan!$Q$1 -> 0 | M20: =PurchasesFeb!$Q$1 -> 0 | N20: =PurchasesMar!$Q$1 -> 0
A21: Other expenses | B21: =ROUNDUP(SUM(C21:N21),0) -> 0 | C21: =PurchasesApr!$R$1 -> 0 | D21: =PurchasesMay!$R$1 -> 0 | E21: =PurchasesJun!$R$1 -> 0 | F21: =PurchasesJul!$R$1 -> 0 | G21: =PurchasesAug!$R$1 -> 0 | H21: =PurchasesSep!$R$1 -> 0 | I21: =PurchasesOct!$R$1 -> 0 | J21: =PurchasesNov!$R$1 -> 0 | K21: =PurchasesDec!$R$1 -> 0 | L21: =PurchasesJan!$R$1 -> 0 | M21: =PurchasesFeb!$R$1 -> 0 | N21: =PurchasesMar!$R$1 -> 0
A22: Total Expenses | B22: =ROUNDUP(SUM(B14:B21),0) -> 1380 | C22: =SUM(C14:C21) -> 520 | D22: =SUM(D14:D21) -> 0 | E22: =SUM(E14:E21) -> 0 | F22: =SUM(F14:F21) -> 120 | G22: =SUM(G14:G21) -> 0 | H22: =SUM(H14:H21) -> 0 | I22: =SUM(I14:I21) -> 120 | J22: =SUM(J14:J21) -> 0 | ... N22: =SUM(N14:N21) -> 0
A23: Net Profit/Loss | B23: =ROUNDDOWN((B13-B22),0) -> 29640 | C23: =C13-C22 -> 800 | D23: =D13-D22 -> 2700 | E23: =E13-E22 -> 2700 | F23: =F13-F22 -> 2580 | G23: =G13-G22 -> 2700 | H23: =H13-H22 -> 2700 | I23: =I13-I22 -> 2580 | J23: =J13-J22 -> 2700 | ... N23: =N13-N22 -> 2700
A24: Any Other Business Income | B24: =ROUNDDOWN(SUM(C24:N24),0) -> 0 | C24: =SalesApr!$F$1 -> 0 | D24: =SalesMay!$F$1 -> 0 | E24: =SalesJun!$F$1 -> 0 | F24: =SalesJul!$F$1 -> 0 | G24: =SalesAug!$F$1 -> 0 | H24: =SalesSep!$F$1 -> 0 | I24: =SalesOct!$F$1 -> 0 | J24: =SalesNov!$F$1 -> 0 | K24: =SalesDec!$F$1 -> 0 | L24: =SalesJan!$F$1 -> 0 | M24: =SalesFeb!$F$1 -> 0 | N24: =SalesMar!$F$1 -> 0
A26: Financial Business Health Check
A27: Forecast Profit | B27: =SUM(C27:N27) -> 29640 | C27: ='Wages Forecast'!D30 -> 800 | D27: ='Wages Forecast'!E30 -> 2700 | E27: ='Wages Forecast'!F30 -> 2700 | F27: ='Wages Forecast'!G30 -> 2580 | G27: ='Wages Forecast'!H30 -> 2700 | H27: ='Wages Forecast'!I30 -> 2700 | I27: ='Wages Forecast'!J30 -> 2580 | J27: ='Wages Forecast'!K30 -> 2700 | ... N27: ='Wages Forecast'!O30 -> 2700
A28: Drawings Week 1 | B28: =SUM(C28:N28) -> 0
A29: Drawings Week 2 | B29: =SUM(C29:N29) -> 0
A30: Drawings Week 3 | B30: =SUM(C30:N30) -> 0
A31: Drawings Week 4 | B31: =SUM(C31:N31) -> 0
A32: Income Tax & NI Liability | B32: =SUM(C32:N32) -> 4970.6 | C32: ='Wages Forecast'!C$41/12 -> 414.21667 | D32: ='Wages Forecast'!C$41/12 -> 414.21667 | E32: ='Wages Forecast'!C$41/12 -> 414.21667 | F32: ='Wages Forecast'!C$41/12 -> 414.21667 | G32: ='Wages Forecast'!C$41/12 -> 414.21667 | H32: ='Wages Forecast'!C$41/12 -> 414.21667 | I32: ='Wages Forecast'!C$41/12 -> 414.21667 | J32: ='Wages Forecast'!C$41/12 -> 414.21667 | K32: ='Wages Forecast'!C$41/12 -> 414.21667 | L32: ='Wages Forecast'!C$41/12 -> 414.21667 | M32: ='Wages Forecast'!C$41/12 -> 414.21667 | N32: ='Wages Forecast'!C$41/12 -> 414.21667
A33: Financial Health Check | B33: =SUM(C33:N33) -> 24669.4 | C33: =C27-SUM(C28:C31)-C32 -> 385.78333 | D33: =D27-SUM(D28:D31)-D32 -> 2285.7833 | E33: =E27-SUM(E28:E31)-E32 -> 2285.7833 | F33: =F27-SUM(F28:F31)-F32 -> 2165.7833 | G33: =G27-SUM(G28:G31)-G32 -> 2285.7833 | H33: =H27-SUM(H28:H31)-H32 -> 2285.7833 | I33: =I27-SUM(I28:I31)-I32 -> 2165.7833 | J33: =J27-SUM(J28:J31)-J32 -> 2285.7833 | ... N33: =N27-SUM(N28:N31)-N32 -> 2285.7833

Sheet VitalTax
B2: VitalTax summary | C2: Q1 | D2: Q2 | E2: Q3 | F2: Q4 | G2: Annual | H2: Notes
B5: Turnover | C5: =SUM('Profit & Loss Acc'!C5:E5) -> 9000 | D5: =SUM('Profit & Loss Acc'!F5:H5) -> 9000 | E5: =SUM('Profit & Loss Acc'!I5:K5) -> 9000 | F5: =SUM('Profit & Loss Acc'!L5:N5) -> 9000 | G5: =SUM(C5:F5) -> 36000
B6: Other income | C6: =SUM('Profit & Loss Acc'!C24:E24) -> 0 | D6: =SUM('Profit & Loss Acc'!F24:H24) -> 0 | E6: =SUM('Profit & Loss Acc'!I24:K24) -> 0 | F6: =SUM('Profit & Loss Acc'!L24:N24) -> 0 | G6: =SUM(C6:F6) -> 0
B7: Cost of goods bought | C7: =SUM('Profit & Loss Acc'!C11:E11) -> 0 | D7: =SUM('Profit & Loss Acc'!F11:H11) -> 0 | E7: =SUM('Profit & Loss Acc'!I11:K11) -> 0 | F7: =SUM('Profit & Loss Acc'!L11:N11) -> 0 | G7: =SUM(C7:F7) -> 0
B10: Allowable expenses
B12: Staff costs | C12: =SUM('Profit & Loss Acc'!C14:E14) -> 0 | D12: =SUM('Profit & Loss Acc'!F14:H14) -> 0 | E12: =SUM('Profit & Loss Acc'!I14:K14) -> 0 | F12: =SUM('Profit & Loss Acc'!L14:N14) -> 0 | G12: =SUM(C12:F12) -> 0
B13: Premises running costs | C13: =SUM('Profit & Loss Acc'!C15:E15) -> 0 | D13: =SUM('Profit & Loss Acc'!F15:H15) -> 0 | E13: =SUM('Profit & Loss Acc'!I15:K15) -> 0 | F13: =SUM('Profit & Loss Acc'!L15:N15) -> 0 | G13: =SUM(C13:F13) -> 0
B14: Maintenance | C14: =SUM('Profit & Loss Acc'!C8:E9) -> 1380 | D14: =SUM('Profit & Loss Acc'!F8:H9) -> 0 | E14: =SUM('Profit & Loss Acc'!I8:K9) -> 0 | F14: =SUM('Profit & Loss Acc'!L8:N9) -> 0 | G14: =SUM(C14:F14) -> 1380
B15: Admin | C15: =SUM('Profit & Loss Acc'!C16:E16) -> 120 | D15: =SUM('Profit & Loss Acc'!F16:H16) -> 120 | E15: =SUM('Profit & Loss Acc'!I16:K16) -> 120 | F15: =SUM('Profit & Loss Acc'!L16:N16) -> 120 | G15: =SUM(C15:F15) -> 480
B16: Financial charges | C16: =SUM('Profit & Loss Acc'!C20:E20) -> 0 | D16: =SUM('Profit & Loss Acc'!F20:H20) -> 0 | E16: =SUM('Profit & Loss Acc'!I20:K20) -> 0 | F16: =SUM('Profit & Loss Acc'!L20:N20) -> 0 | G16: =SUM(C16:F16) -> 0
B17: Travel | C17: =SUM('Profit & Loss Acc'!C6:E7) -> 900 | D17: =SUM('Profit & Loss Acc'!F6:H7) -> 900 | E17: =SUM('Profit & Loss Acc'!I6:K7) -> 900 | F17: =SUM('Profit & Loss Acc'!L6:N7) -> 900 | G17: =SUM(C17:F17) -> 3600
B18: Advertising | C18: =SUM('Profit & Loss Acc'!C17:E17) -> 0 | D18: =SUM('Profit & Loss Acc'!F17:H17) -> 0 | E18: =SUM('Profit & Loss Acc'!I17:K17) -> 0 | F18: =SUM('Profit & Loss Acc'!L17:N17) -> 0 | G18: =SUM(C18:F18) -> 0
B19: Professional | C19: =SUM('Profit & Loss Acc'!C18:E18) -> 400 | D19: =SUM('Profit & Loss Acc'!F18:H18) -> 0 | E19: =SUM('Profit & Loss Acc'!I18:K18) -> 0 | F19: =SUM('Profit & Loss Acc'!L18:N18) -> 500 | G19: =SUM(C19:F19) -> 900
B20: Bad debt | C20: 0 | D20: 0 | E20: 0 | F20: 0 | G20: =SUM(C20:F20) -> 0 | H20: Not captured in DIY Accounting
B21: Interest | C21: =SUM('Profit & Loss Acc'!C19:E19) -> 0 | D21: =SUM('Profit & Loss Acc'!F19:H19) -> 0 | E21: =SUM('Profit & Loss Acc'!I19:K19) -> 0 | F21: =SUM('Profit & Loss Acc'!L19:N19) -> 0 | G21: =SUM(C21:F21) -> 0
B22: Other | C22: =SUM('Profit & Loss Acc'!C21:E21) -> 0 | D22: =SUM('Profit & Loss Acc'!F21:H21) -> 0 | E22: =SUM('Profit & Loss Acc'!I21:K21) -> 0 | F22: =SUM('Profit & Loss Acc'!L21:N21) -> 0 | G22: =SUM(C22:F22) -> 0
B24: CIS payment to subcontractors | C24: 0 | D24: 0 | E24: 0 | F24: 0 | G24: =SUM(C24:F24) -> 0 | H24: Not captured in DIY Accounting
B25: Business entertainment | C25: 0 | D25: 0 | E25: 0 | F25: 0 | G25: =SUM(C25:F25) -> 0 | H25: Not captured in DIY Accounting
B26: Depreciation | C26: =SUM('Profit & Loss Acc'!C10:E10) -> 0 | D26: =SUM('Profit & Loss Acc'!F10:H10) -> 0 | E26: =SUM('Profit & Loss Acc'!I10:K10) -> 0 | F26: =SUM('Profit & Loss Acc'!L10:N10) -> 0 | G26: =SUM(C26:F26) -> 0
B29: Total allowable expenses | C29: =SUM(C7,C12,C13,C14,C15,C16,C17,C18,C19,C20,C21,C22,C24,C25,C26) -> 2800 | D29: =SUM(D7,D12,D13,D14,D15,D16,D17,D18,D19,D20,D21,D22,D24,D25,D26) -> 1020 | E29: =SUM(E7,E12,E13,E14,E15,E16,E17,E18,E19,E20,E21,E22,E24,E25,E26) -> 1020 | F29: =SUM(F7,F12,F13,F14,F15,F16,F17,F18,F19,F20,F21,F22,F24,F25,F26) -> 1520 | G29: =SUM(G7,G12,G13,G14,G15,G16,G17,G18,G19,G20,G21,G22,G24,G25,G26) -> 6360
B34: Disallowable expenses
B36: Cost of goods bought | C36: 0 | D36: 0 | E36: 0 | F36: 0 | G36: =SUM(C36:F36) -> 0 | H36: Not captured in DIY Accounting
B37: CIS payment to subcontractors | C37: 0 | D37: 0 | E37: 0 | F37: 0 | G37: =SUM(C37:F37) -> 0 | H37: Not captured in DIY Accounting
B38: Staff costs | C38: 0 | D38: 0 | E38: 0 | F38: 0 | G38: =SUM(C38:F38) -> 0 | H38: Not captured in DIY Accounting
B39: Travel | C39: 0 | D39: 0 | E39: 0 | F39: 0 | G39: =SUM(C39:F39) -> 0 | H39: Not captured in DIY Accounting
B40: Premises running costs | C40: 0 | D40: 0 | E40: 0 | F40: 0 | G40: =SUM(C40:F40) -> 0 | H40: Not captured in DIY Accounting
B41: Maintenance | C41: 0 | D41: 0 | E41: 0 | F41: 0 | G41: =SUM(C41:F41) -> 0 | H41: Not captured in DIY Accounting
B42: Admin | C42: 0 | D42: 0 | E42: 0 | F42: 0 | G42: =SUM(C42:F42) -> 0 | H42: Not captured in DIY Accounting
B43: Advertising | C43: 0 | D43: 0 | E43: 0 | F43: 0 | G43: =SUM(C43:F43) -> 0 | H43: Not captured in DIY Accounting
B44: Business entertainment | C44: 0 | D44: 0 | E44: 0 | F44: 0 | G44: =SUM(C44:F44) -> 0 | H44: Not captured in DIY Accounting
B45: Interest | C45: 0 | D45: 0 | E45: 0 | F45: 0 | G45: =SUM(C45:F45) -> 0 | H45: Not captured in DIY Accounting
B46: Financial charges | C46: 0 | D46: 0 | E46: 0 | F46: 0 | G46: =SUM(C46:F46) -> 0 | H46: Not captured in DIY Accounting
B47: Bad debt | C47: 0 | D47: 0 | E47: 0 | F47: 0 | G47: =SUM(C47:F47) -> 0 | H47: Not captured in DIY Accounting
... B50: Other | C50: 0 | D50: 0 | E50: 0 | F50: 0 | G50: =SUM(C50:F50) -> 0 | H50: Not captured in DIY Accounting

Sheet Fixed Assets
A1: Date Asset Purchased | B1: TOTAL FIXED ASSETS AT | C1: =Admin!B17 -> 44291 | D1: =D33+D62 -> 0 | F1: Enter % Personal use of vehicles | H1: =H33+H62 -> 0 | I1: =I33+I62 -> 0 | J1: =J33+J62 -> 0 | K1: =K33+K62 -> 0 | M1: Date Asset or Vehicle Sold | N1: =N33+N62 -> 0 | P1: =P33+P62 -> 0 | Q1: =Q33+Q62 -> 0
B2: Asset Description | C2: Purchase Reference | D2: Original Cost | H2: W Down Net Value | I2: Annual Investment Allowance | J2: W Down Allowance | K2: W Down Net Value | N2: Sales Value | P2: Capital Allowance | Q2: Balancing Charge
H4: =Admin!B$4 -> 43927 | I4: =Admin!G$4 -> 1 | J4: =Admin!G$5 -> 0.18 | K4: =Admin!B$17 -> 44291
A6: Fixed Assets including Commercial vehicles bought before | D6: =Admin!B$4 -> 43927
I7: 0 | J7: =IF((H7>0),H7*J$4," ") | K7: =IF(H7>0,H7-H7*J$4," ") | P7: =IF((M7+N7)>0,IF(N7<K7,(K7-N7)," ")," ") | Q7: =IF((M7+N7)>0,IF(N7>K7,(N7-K7)," ")," ")
I8: 0 | J8: =IF((H8>0),H8*J$4," ") | K8: =IF(H8>0,H8-H8*J$4," ") | P8: =IF((M8+N8)>0,IF(N8<K8,(K8-N8)," ")," ") | Q8: =IF((M8+N8)>0,IF(N8>K8,(N8-K8)," ")," ")
I9: 0 | J9: =IF((H9>0),H9*J$4," ") | K9: =IF(H9>0,H9-H9*J$4," ") | P9: =IF((M9+N9)>0,IF(N9<K9,(K9-N9)," ")," ") | Q9: =IF((M9+N9)>0,IF(N9>K9,(N9-K9)," ")," ")
I10: 0 | J10: =IF((H10>0),H10*J$4," ") | K10: =IF(H10>0,H10-H10*J$4," ") | P10: =IF((M10+N10)>0,IF(N10<K10,(K10-N10)," ")," ") | Q10: =IF((M10+N10)>0,IF(N10>K10,(N10-K10)," ")," ")
I11: 0 | J11: =IF((H11>0),H11*J$4," ") | K11: =IF(H11>0,H11-H11*J$4," ") | P11: =IF((M11+N11)>0,IF(N11<K11,(K11-N11)," ")," ") | Q11: =IF((M11+N11)>0,IF(N11>K11,(N11-K11)," ")," ")
I12: 0 | J12: =IF((H12>0),H12*J$4," ") | K12: =IF(H12>0,H12-H12*J$4," ") | P12: =IF((M12+N12)>0,IF(N12<K12,(K12-N12)," ")," ") | Q12: =IF((M12+N12)>0,IF(N12>K12,(N12-K12)," ")," ")
I13: 0 | J13: =IF((H13>0),H13*J$4," ") | K13: =IF(H13>0,H13-H13*J$4," ") | P13: =IF((M13+N13)>0,IF(N13<K13,(K13-N13)," ")," ") | Q13: =IF((M13+N13)>0,IF(N13>K13,(N13-K13)," ")," ")
I14: 0 | J14: =IF((H14>0),H14*J$4," ") | K14: =IF(H14>0,H14-H14*J$4," ") | P14: =IF((M14+N14)>0,IF(N14<K14,(K14-N14)," ")," ") | Q14: =IF((M14+N14)>0,IF(N14>K14,(N14-K14)," ")," ")
A15: Fixed Assets incl Commercial vehicles bght before | C15: =Admin!B$4 -> 43927 | D15: =SUM(D7:D14) -> 0 | H15: =SUM(H7:H14) -> 0 | I15: =SUM(I7:I14) -> 0 | J15: =SUM(J7:J14) -> 0 | K15: =SUM(K7:K14) -> 0 | N15: =SUM(N7:N14) -> 0 | P15: =SUM(P7:P14) -> 0 | Q15: =SUM(Q7:Q14) -> 0
A17: Vehicles under £12,000 bought before | C17: =Admin!B$4 -> 43927
I18: 0 | J18: =IF(H18>0,MIN(H18*J$4*(1-F18),Admin!G$8*(1-F18))," ") | K18: =IF(H18>0,H18-J18," ") | P18: =IF((M18+N18)>0,IF(N18<K18,(K18-N18)*(1-F18)," ")," ") | Q18: =IF((M18+N18)>0,IF(N18>K18,(N18-K18)*(1-F18)," ")," ")
I19: 0 | J19: =IF(H19>0,MIN(H19*J$4*(1-F19),Admin!G$8*(1-F19))," ") | K19: =IF(H19>0,H19-J19," ") | P19: =IF((M19+N19)>0,IF(N19<K19,(K19-N19)*(1-F19)," ")," ") | Q19: =IF((M19+N19)>0,IF(N19>K19,(N19-K19)*(1-F19)," ")," ")
I20: 0 | J20: =IF(H20>0,MIN(H20*J$4*(1-F20),Admin!G$8*(1-F20))," ") | K20: =IF(H20>0,H20-J20," ") | P20: =IF((M20+N20)>0,IF(N20<K20,(K20-N20)*(1-F20)," ")," ") | Q20: =IF((M20+N20)>0,IF(N20>K20,(N20-K20)*(1-F20)," ")," ")
I21: 0 | J21: =IF(H21>0,MIN(H21*J$4*(1-F21),Admin!G$8*(1-F21))," ") | K21: =IF(H21>0,H21-J21," ") | P21: =IF((M21+N21)>0,IF(N21<K21,(K21-N21)*(1-F21)," ")," ") | Q21: =IF((M21+N21)>0,IF(N21>K21,(N21-K21)*(1-F21)," ")," ")
I22: 0 | J22: =IF(H22>0,MIN(H22*J$4*(1-F22),Admin!G$8*(1-F22))," ") | K22: =IF(H22>0,H22-J22," ") | P22: =IF((M22+N22)>0,IF(N22<K22,(K22-N22)*(1-F22)," ")," ") | Q22: =IF((M22+N22)>0,IF(N22>K22,(N22-K22)*(1-F22)," ")," ")
A23: Sub total Vehicles under £12000 purchased before | C23: =Admin!B$4 -> 43927 | D23: =SUM(D18:D22) -> 0 | H23: =SUM(H18:H22) -> 0 | I23: =SUM(I18:I22) -> 0 | J23: =SUM(J18:J22) -> 0 | K23: =SUM(K18:K22) -> 0 | N23: =SUM(N18:N22) -> 0 | P23: =SUM(P18:P22) -> 0 | Q23: =SUM(Q18:Q22) -> 0
A25: Vehicles over £12,000 bought before | C25: =Admin!B$4 -> 43927
I26: 0 | J26: =IF(H26>0,MIN(H26*J$4*(1-F26),Admin!G$8*(1-F26))," ") | K26: =IF(H26>0,H26-J26," ") | P26: =IF((M26+N26)>0,IF(N26<K26,(K26-N26)*(1-F26)," ")," ") | Q26: =IF((M26+N26)>0,IF(N26>K26,(N26-K26)*(1-F26)," ")," ")
I27: 0 | J27: =IF(H27>0,MIN(H27*J$4*(1-F27),Admin!G$8*(1-F27))," ") | K27: =IF(H27>0,H27-J27," ") | P27: =IF((M27+N27)>0,IF(N27<K27,(K27-N27)*(1-F27)," ")," ") | Q27: =IF((M27+N27)>0,IF(N27>K27,(N27-K27)*(1-F27)," ")," ")
I28: 0 | J28: =IF(H28>0,MIN(H28*J$4*(1-F28),Admin!G$8*(1-F28))," ") | K28: =IF(H28>0,H28-J28," ") | P28: =IF((M28+N28)>0,IF(N28<K28,(K28-N28)*(1-F28)," ")," ") | Q28: =IF((M28+N28)>0,IF(N28>K28,(N28-K28)*(1-F28)," ")," ")
I29: 0 | J29: =IF(H29>0,MIN(H29*J$4*(1-F29),Admin!G$8*(1-F29))," ") | K29: =IF(H29>0,H29-J29," ") | P29: =IF((M29+N29)>0,IF(N29<K29,(K29-N29)*(1-F29)," ")," ") | Q29: =IF((M29+N29)>0,IF(N29>K29,(N29-K29)*(1-F29)," ")," ")
I30: 0 | J30: =IF(H30>0,MIN(H30*J$4*(1-F30),Admin!G$8*(1-F30))," ") | K30: =IF(H30>0,H30-J30," ") | P30: =IF((M30+N30)>0,IF(N30<K30,(K30-N30)*(1-F30)," ")," ") | Q30: =IF((M30+N30)>0,IF(N30>K30,(N30-K30)*(1-F30)," ")," ")
A31: Sub total Vehicles over £12000 purchased before | C31: =Admin!B$4 -> 43927 | D31: =SUM(D26:D30) -> 0 | H31: =SUM(H26:H30) -> 0 | I31: =SUM(I26:I30) -> 0 | J31: =SUM(J26:J30) -> 0 | K31: =SUM(K26:K30) -> 0 | N31: =SUM(N26:N30) -> 0 | P31: =SUM(P26:P30) -> 0 | Q31: =SUM(Q26:Q30) -> 0
A33: FIXED ASSETS EXISTING at | C33: =Admin!B4 -> 43927 | D33: =D15+D23+D31 -> 0 | H33: =H15+H23+H31 -> 0 | I33: =I15+I23+I31 -> 0 | J33: =J15+J23+J31 -> 0 | K33: =K15+K23+K31 -> 0 | N33: =N15+N23+N31 -> 0 | P33: =P15+P23+P31 -> 0 | Q33: =Q15+Q23+Q31 -> 0
A35: Fixed Assets including Commercial vehicles bought after | D35: =Admin!B$4 -> 43927
H36: 0 | I36: =IF((D36>0),D36*I$4," ") | J36: 0 | K36: =IF(D36>0,D36-D36*I$4," ") | P36: =IF((M36+N36)>0,IF(N36<K36,(K36-N36)," ")," ") | Q36: =IF((M36+N36)>0,IF(N36>K36,(N36-K36)," ")," ")
H37: 0 | I37: =IF((D37>0),D37*I$4," ") | J37: 0 | K37: =IF(D37>0,D37-D37*I$4," ") | P37: =IF((M37+N37)>0,IF(N37<K37,(K37-N37)," ")," ") | Q37: =IF((M37+N37)>0,IF(N37>K37,(N37-K37)," ")," ")
H38: 0 | I38: =IF((D38>0),D38*I$4," ") | J38: 0 | K38: =IF(D38>0,D38-D38*I$4," ") | P38: =IF((M38+N38)>0,IF(N38<K38,(K38-N38)," ")," ") | Q38: =IF((M38+N38)>0,IF(N38>K38,(N38-K38)," ")," ")
H39: 0 | I39: =IF((D39>0),D39*I$4," ") | J39: 0 | K39: =IF(D39>0,D39-D39*I$4," ") | P39: =IF((M39+N39)>0,IF(N39<K39,(K39-N39)," ")," ") | Q39: =IF((M39+N39)>0,IF(N39>K39,(N39-K39)," ")," ")
H40: 0 | I40: =IF((D40>0),D40*I$4," ") | J40: 0 | K40: =IF(D40>0,D40-D40*I$4," ") | P40: =IF((M40+N40)>0,IF(N40<K40,(K40-N40)," ")," ") | Q40: =IF((M40+N40)>0,IF(N40>K40,(N40-K40)," ")," ")
H41: 0 | I41: =IF((D41>0),D41*I$4," ") | J41: 0 | K41: =IF(D41>0,D41-D41*I$4," ") | P41: =IF((M41+N41)>0,IF(N41<K41,(K41-N41)," ")," ") | Q41: =IF((M41+N41)>0,IF(N41>K41,(N41-K41)," ")," ")
H42: 0 | I42: =IF((D42>0),D42*I$4," ") | J42: 0 | K42: =IF(D42>0,D42-D42*I$4," ") | P42: =IF((M42+N42)>0,IF(N42<K42,(K42-N42)," ")," ") | Q42: =IF((M42+N42)>0,IF(N42>K42,(N42-K42)," ")," ")
H43: 0 | I43: =IF((D43>0),D43*I$4," ") | J43: 0 | K43: =IF(D43>0,D43-D43*I$4," ") | P43: =IF((M43+N43)>0,IF(N43<K43,(K43-N43)," ")," ") | Q43: =IF((M43+N43)>0,IF(N43>K43,(N43-K43)," ")," ")
A44: Fixed Assets incl Commercial vehicles bght after | C44: =Admin!B$4 -> 43927 | D44: =SUM(D36:D43) -> 0 | H44: =SUM(H36:H43) -> 0 | I44: =SUM(I36:I43) -> 0 | J44: =SUM(J36:J43) -> 0 | K44: =SUM(K36:K43) -> 0 | N44: =SUM(N36:N43) -> 0 | P44: =SUM(P36:P43) -> 0 | Q44: =SUM(Q36:Q43) -> 0
A46: Vehicles under £12,000 bought after | C46: =Admin!B$4 -> 43927
H47: 0 | I47: 0 | J47: =IF(D47>0,MIN(D47*J$4*(1-F47),Admin!G$8*(1-F47))," ") | K47: =IF(D47>0,D47-J47," ") | P47: =IF((M47+N47)>0,IF(N47<K47,(K47-N47)*(1-F47)," ")," ") | Q47: =IF((M47+N47)>0,IF(N47>K47,(N47-K47)*(1-F47)," ")," ")
...

Sheet Draft Tax calculation
B2: TAXATION CALCULATION | C2: =Admin!K$2 -> 2020-21 | D2: This section an indication and for your information only
B5: Profit from Self employment | E5: ='SE Short'!D106 -> 29640
B6: Minus Personal Allowance | C6: =C2 -> 2020-21 | E6: =IF((E5>0),Admin!N$4,0) -> 12500
B7: Total income on which tax is due | E7: =IF((E5>E6),(E5-E6),0) -> 17140
B8: Income Tax first band | C8: =Admin!N$11 -> 0 | D8: =Admin!N$6 -> 0 | E8: =IF((E7>0),(IF((E7<C9),E7*D8,C9*D8)),0) -> 0
B9: Income Tax second band | C9: =Admin!N$12 -> 0 | D9: =Admin!N$7 -> 0.2 | E9: =IF((E7>C9),((E7-C9)*D9),0) -> 3428
B10: Income Tax payable | E10: =SUM(E8:E9) -> 3428
B12: Amounts Payable by | C12: =Admin!B$21 -> 44592
B14: Class 4 NI Contribution Lower - Upper profits | D14: =Admin!L$20 -> 0.09 | E14: =IF(E5>Admin!N20,IF(E5<Admin!N$23,(E5-Admin!N20)*D14,(Admin!N$23-Admin!N20)*D14),0) -> 1812.6
B15: Class 4 NI Contribution Upper profits | D15: =Admin!L$23 -> 0.02 | E15: =IF((E5>Admin!N$23),((E5-Admin!N$23)*D15),0) -> 0
B17: TOTAL Income Tax & NI Liability | E17: =SUM(E10:E16) -> 5240.6
B20: FUTURE TAX LIABILITY (if over £500) | D20: This section for your information only
D22: Due Date | E22: Amount Payable
B24: Tax & NI Assessment | C24: =Admin!B$24 -> 2021-22 | D24: Previous Year | E24: =E17 -> 5240.6
B25: 50% Payable | D25: =Admin!B$21 -> 44592 | E25: =E24/2 -> 2620.3
B26: 50% Payable | D26: =Admin!B$22 -> 44773 | E26: =E24/2 -> 2620.3
B28: NOTES:
B29: Working Tax Credit
B30: Not taxable and not added to self employment income for tax purposes
B31: Pension Entitlement
B32: To receive Full Pension entitlement NI has to be paid 44 years out of 49 years (16 - 65)
B33: UK residents aged 60 - 65 get 5 years bonus.
B34: To confirm current NI / Pension entitlement years the helpline number is 0845 3000 168

Sheet Wages Forecast
B2: ACTUAL Profit and Loss Account | C2: Total Year | D2: =Admin!B$5 -> 43951 | E2: =Admin!B$6 -> 43982 | F2: =Admin!B$7 -> 44012 | G2: =Admin!B$8 -> 44043 | H2: =Admin!B$9 -> 44074 | I2: =Admin!B$10 -> 44104 | J2: =Admin!B$11 -> 44135 | K2: =Admin!B$12 -> 44165 | L2: =Admin!B$13 -> 44196 | M2: =Admin!B$14 -> 44227 | N2: =Admin!B$15 -> 44255 | O2: =Admin!B$16 -> 44286
C3: =Admin!B$17 -> 44291
C4: £ | D4: £ | E4: £ | F4: £ | G4: £ | H4: £ | I4: £ | J4: £ | K4: £ | L4: £ | M4: £ | N4: £ | O4: £
B5: Sales Turnover | C5: =SUM(D5:O5) -> 36000 | D5: ='Profit & Loss Acc'!C5 -> 3000 | E5: ='Profit & Loss Acc'!D5 -> 3000 | F5: ='Profit & Loss Acc'!E5 -> 3000 | G5: ='Profit & Loss Acc'!F5 -> 3000 | H5: ='Profit & Loss Acc'!G5 -> 3000 | I5: ='Profit & Loss Acc'!H5 -> 3000 | J5: ='Profit & Loss Acc'!I5 -> 3000 | K5: ='Profit & Loss Acc'!J5 -> 3000 | ... O5: ='Profit & Loss Acc'!N5 -> 3000
B7: Investment Grants | C7: =SUM(D7:O7) -> 0 | D7: ='Profit & Loss Acc'!C24 -> 0 | E7: ='Profit & Loss Acc'!D24 -> 0 | F7: ='Profit & Loss Acc'!E24 -> 0 | G7: ='Profit & Loss Acc'!F24 -> 0 | H7: ='Profit & Loss Acc'!G24 -> 0 | I7: ='Profit & Loss Acc'!H24 -> 0 | J7: ='Profit & Loss Acc'!I24 -> 0 | K7: ='Profit & Loss Acc'!J24 -> 0 | ... O7: ='Profit & Loss Acc'!N24 -> 0
B9: Cost of Sales | C9: =SUM(D9:O9) -> 4980 | D9: ='Profit & Loss Acc'!C12 -> 1680 | E9: ='Profit & Loss Acc'!D12 -> 300 | F9: ='Profit & Loss Acc'!E12 -> 300 | G9: ='Profit & Loss Acc'!F12 -> 300 | H9: ='Profit & Loss Acc'!G12 -> 300 | I9: ='Profit & Loss Acc'!H12 -> 300 | J9: ='Profit & Loss Acc'!I12 -> 300 | K9: ='Profit & Loss Acc'!J12 -> 300 | ... O9: ='Profit & Loss Acc'!N12 -> 300
B11: Gross Profit | C11: =SUM(D11:O11) -> 31020 | D11: =D5+D7-D9 -> 1320 | E11: =E5+E7-E9 -> 2700 | F11: =F5+F7-F9 -> 2700 | G11: =G5+G7-G9 -> 2700 | H11: =H5+H7-H9 -> 2700 | I11: =I5+I7-I9 -> 2700 | J11: =J5+J7-J9 -> 2700 | K11: =K5+K7-K9 -> 2700 | ... O11: =O5+O7-O9 -> 2700
B13: General Expenses | C13: =SUM(D13:O13) -> 1380 | D13: ='Profit & Loss Acc'!C22 -> 520 | E13: ='Profit & Loss Acc'!D22 -> 0 | F13: ='Profit & Loss Acc'!E22 -> 0 | G13: ='Profit & Loss Acc'!F22 -> 120 | H13: ='Profit & Loss Acc'!G22 -> 0 | I13: ='Profit & Loss Acc'!H22 -> 0 | J13: ='Profit & Loss Acc'!I22 -> 120 | K13: ='Profit & Loss Acc'!J22 -> 0 | ... O13: ='Profit & Loss Acc'!N22 -> 0
B15: Profit (Loss) before Tax | C15: =SUM(D15:O15) -> 29640 | D15: =D11-D13 -> 800 | E15: =E11-E13 -> 2700 | F15: =F11-F13 -> 2700 | G15: =G11-G13 -> 2580 | H15: =H11-H13 -> 2700 | I15: =I11-I13 -> 2700 | J15: =J11-J13 -> 2580 | K15: =K11-K13 -> 2700 | ... O15: =O11-O13 -> 2700
B17: FORECAST Profit and Loss Account | C17: Total Year | D17: =D2 -> 43951 | E17: =E2 -> 43982 | F17: =F2 -> 44012 | G17: =G2 -> 44043 | H17: =H2 -> 44074 | I17: =I2 -> 44104 | J17: =J2 -> 44135 | K17: =K2 -> 44165 | ... O17: =O2 -> 44286
C18: =C3 -> 44291
C19: =SUM(D19:O19) -> 12 | D19: =IF(D5>0,1," ") -> 1 | E19: =IF(E5>0,1," ") -> 1 | F19: =IF(F5>0,1," ") -> 1 | G19: =IF(G5>0,1," ") -> 1 | H19: =IF(H5>0,1," ") -> 1 | I19: =IF(I5>0,1," ") -> 1 | J19: =IF(J5>0,1," ") -> 1 | K19: =IF(K5>0,1," ") -> 1 | ... O19: =IF(O5>0,1," ") -> 1
B20: Sales Turnover | C20: =SUM(D20:O20) -> 36000 | D20: =IF(C5>0,IF(D5>0,D5,C5/C19),0) -> 3000 | E20: =IF(C5>0,IF(E5>0,E5,C5/C19),0) -> 3000 | F20: =IF(C5>0,IF(F5>0,F5,C5/C19),0) -> 3000 | G20: =IF(C5>0,IF(G5>0,G5,C5/C19),0) -> 3000 | H20: =IF(C5>0,IF(H5>0,H5,C5/C19),0) -> 3000 | I20: =IF(C5>0,IF(I5>0,I5,C5/C19),0) -> 3000 | J20: =IF(C5>0,IF(J5>0,J5,C5/C19),0) -> 3000 | K20: =IF(C5>0,IF(K5>0,K5,C5/C19),0) -> 3000 | L20: =IF(C5>0,IF(L5>0,L5,C5/C19),0) -> 3000 | M20: =IF(C5>0,IF(M5>0,M5,C5/C19),0) -> 3000 | N20: =IF(C5>0,IF(N5>0,N5,C5/C19),0) -> 3000 | O20: =IF(C5>0,IF(O5>0,O5,C5/C19),0) -> 3000
B22: Investment Grants | C22: =SUM(D22:O22) -> 0 | D22: =D7 -> 0 | E22: =E7 -> 0 | F22: =F7 -> 0 | G22: =G7 -> 0 | H22: =H7 -> 0 | I22: =I7 -> 0 | J22: =J7 -> 0 | K22: =K7 -> 0 | ... O22: =O7 -> 0
B24: Cost of Sales | C24: =SUM(D24:O24) -> 4980 | D24: =IF($C5>0,IF(D5>0,D9,($C9-'Profit & Loss Acc'!$B10)/$C19+'Profit & Loss Acc'!$B10/12),0) -> 1680 | E24: =IF($C5>0,IF(E5>0,E9,($C9-'Profit & Loss Acc'!$B10)/$C19+'Profit & Loss Acc'!$B10/12),0) -> 300 | F24: =IF($C5>0,IF(F5>0,F9,($C9-'Profit & Loss Acc'!$B10)/$C19+'Profit & Loss Acc'!$B10/12),0) -> 300 | G24: =IF($C5>0,IF(G5>0,G9,($C9-'Profit & Loss Acc'!$B10)/$C19+'Profit & Loss Acc'!$B10/12),0) -> 300 | H24: =IF($C5>0,IF(H5>0,H9,($C9-'Profit & Loss Acc'!$B10)/$C19+'Profit & Loss Acc'!$B10/12),0) -> 300 | I24: =IF($C5>0,IF(I5>0,I9,($C9-'Profit & Loss Acc'!$B10)/$C19+'Profit & Loss Acc'!$B10/12),0) -> 300 | J24: =IF($C5>0,IF(J5>0,J9,($C9-'Profit & Loss Acc'!$B10)/$C19+'Profit & Loss Acc'!$B10/12),0) -> 300 | K24: =IF($C5>0,IF(K5>0,K9,($C9-'Profit & Loss Acc'!$B10)/$C19+'Profit & Loss Acc'!$B10/12),0) -> 300 | ... O24: =IF($C5>0,IF(O5>0,O9,($C9-'Profit & Loss Acc'!$B10)/$C19+'Profit & Loss Acc'!$B10/12),0) -> 300
B26: Gross Profit | C26: =SUM(D26:O26) -> 31020 | D26: =D20+D22-D24 -> 1320 | E26: =E20+E22-E24 -> 2700 | F26: =F20+F22-F24 -> 2700 | G26: =G20+G22-G24 -> 2700 | H26: =H20+H22-H24 -> 2700 | I26: =I20+I22-I24 -> 2700 | J26: =J20+J22-J24 -> 2700 | K26: =K20+K22-K24 -> 2700 | ... O26: =O20+O22-O24 -> 2700
B28: General Expenses | C28: =SUM(D28:O28) -> 1380 | D28: =IF($C5>0,IF(D5>0,D13,$C13/$C19),0) -> 520 | E28: =IF($C5>0,IF(E5>0,E13,$C13/$C19),0) -> 0 | F28: =IF($C5>0,IF(F5>0,F13,$C13/$C19),0) -> 0 | G28: =IF($C5>0,IF(G5>0,G13,$C13/$C19),0) -> 120 | H28: =IF($C5>0,IF(H5>0,H13,$C13/$C19),0) -> 0 | I28: =IF($C5>0,IF(I5>0,I13,$C13/$C19),0) -> 0 | J28: =IF($C5>0,IF(J5>0,J13,$C13/$C19),0) -> 120 | K28: =IF($C5>0,IF(K5>0,K13,$C13/$C19),0) -> 0 | ... O28: =IF($C5>0,IF(O5>0,O13,$C13/$C19),0) -> 0
B30: Profit (Loss) before Tax | C30: =SUM(D30:O30) -> 29640 | D30: =D26-D28 -> 800 | E30: =E26-E28 -> 2700 | F30: =F26-F28 -> 2700 | G30: =G26-G28 -> 2580 | H30: =H26-H28 -> 2700 | I30: =I26-I28 -> 2700 | J30: =J26-J28 -> 2580 | K30: =K26-K28 -> 2700 | ... O30: =O26-O28 -> 2700
B32: FORECAST TAX CALCULATION
B34: Profit before Tax | C34: =C30-C33 -> 29640
B35: Personal Allowance | C35: =IF(C34>0,Admin!N$4,0) -> 12500
B36: Profit after Allowance | C36: =IF((C34>C35),(C34-C35),0) -> 17140
B37: Tax at standard rate | C37: =IF((C36>0),(IF((C36<Admin!N$12),C36*Admin!N$6,Admin!N$12*Admin!N$6)),0) -> 0
B38: Tax at higher rate | C38: =IF((C36>Admin!N$12),((C36-Admin!N$12)*Admin!N$7),0) -> 3428
B39: National Insurance | C39: =IF((C36>0),C36*Admin!L$20,0) -> 1542.6
B41: TAX & NI LIABILITY | C41: =C37+C38+C39 -> 4970.6

Sheet SalesApr
A1: Sales Date | B1: Day | C1: Total for Month | D1: =SUM(D4:D36) -> 0 | E1: =SUM(E4:E36)/2 -> 3000 | F1: =SUM(F4:F36)/2 -> 0
C2: Customer Name (rental/other income) | D2: Sales Mileage | E2: Gross takings including tips | F2: Other Income (start up grants)
A5: 43927 | B5: 43927
A6: 43928 | B6: 43928 | E6: 200
A7: 43929 | B7: 43929 | E7: 220
A8: 43930 | B8: 43930 | E8: 180
A9: 43931 | B9: 43931 | E9: 210
A10: 43932 | B10: 43932 | E10: 190
A11: 43933 | B11: 43933
A12: 43933 | B12: Rental due
A13: 43933 | B13: Any other income
E14: =SUM(E5:E13) -> 1000 | F14: =SUM(F5:F13) -> 0
A16: 43934 | B16: 43934
A17: 43935 | B17: 43935 | E17: 200
A18: 43936 | B18: 43936 | E18: 220
A19: 43937 | B19: 43937 | E19: 180
A20: 43938 | B20: 43938 | E20: 200
A21: 43939 | B21: 43939 | E21: 200
A22: 43940 | B22: 43940
A23: 43940 | B23: Rental due
A24: 43940 | B24: Any other income
E25: =SUM(E16:E24) -> 1000 | F25: =SUM(F16:F24) -> 0
A27: 43941 | B27: 43941
A28: 43942 | B28: 43942 | E28: 200
A29: 43943 | B29: 43943 | E29: 200
A30: 43944 | B30: 43944 | E30: 200
A31: 43945 | B31: 43945 | E31: 200
A32: 43946 | B32: 43946 | E32: 200
A33: 43947 | B33: 43947
A34: 43947 | B34: Rental due
A35: 43947 | B35: Any other income
E36: =SUM(E27:E35) -> 1000 | F36: =SUM(F27:F35) -> 0

Sheet PurchasesApr
A1: =E1+SalesApr!$D$1 -> 0 | B1: Mileage to date | C1: Total for Month | D1: =IF((F1-SUM(G1:S1)<>0),(F1-SUM(G1:S1))," ") | E1: =SUM(E5:E199) -> 0 | F1: =SUM(F5:F199) -> 2200 | G1: =SUM(G5:G199) -> 300 | H1: =SUM(H5:H199) -> 0 | I1: =SUM(I5:I199) -> 0 | J1: =SUM(J5:J199) -> 1380 | K1: =SUM(K5:K199) -> 0 | L1: =SUM(L5:L199) -> 0 | ... S1: =SUM(S5:S199) -> 0 | T1: =S1 -> 0 | U1: =SUM(U4:U199) -> 0
A2: =U1 -> 0 | B2: Mileage expenses to date | C2: Purchase Reference / Invoice Number | D2: Enter Expense Code Letter | E2: Mileage | F2: Total Purchase Value incl Vat | G2: Vehicle expenses to date | I2: =G1+H1+I1+J1 -> 1680 | K2: Employee Costs | L2: Premises Costs | M2: General Admin Tel Postage Stationery Radio hire | N2: Advertising & Promotion | O2: Legal & Professional incl Council Taxi Licence Costs | P2: Bank Business Account Interest | Q2: Bank Charges & Other Leasing | R2: Other Expenses incl valet costs | S2: Fixed Assets Motor Vehicles | T2: =IF(T1>'Fixed Assets'!$D$74,"ENTER VEHICLE CHANGES on Fixed Asset schedule","Motor Vehicles: make, model, date reg. and reg. Mark") -> Motor Vehicles: make, model, date reg. and reg. Mark | U2: Mileage Allowance
A3: Purchase Date | B3: Supplier | G3: Fuel & Oil Expenses | H3: Car Hire & Vehicle Leasing costs | I3: Repairs, servicing and parts | J3: Road tax and insurance
A4: =IF((E1<>0),Admin!$B$5," ") | G4: D | H4: H | I4: R | J4: T | K4: E | L4: P | M4: G | N4: A | O4: L | P4: I | Q4: B | R4: O | S4: F | U4: =IF((A1<Admin!$F$22),((A1)*Admin!$G$21),(A1*Admin!$G$21-(A1-Admin!$F$21)*(Admin!$G$21-Admin!$G$22))) -> 0
A5: 45762 | B5: Shell | D5: d | F5: 300 | G5: =IF((D5="d"),F5," ") -> 300 | H5: =IF((D5="h"),F5," ") | I5: =IF((D5="r"),F5," ") | J5: =IF((D5="t"),F5," ") | K5: =IF((D5="e"),F5," ") | L5: =IF((D5="p"),F5," ") | M5: =IF((D5="g"),F5," ") | N5: =IF((D5="a"),F5," ") | O5: =IF((D5="l"),F5," ") | P5: =IF((D5="i"),F5," ") | Q5: =IF((D5="b"),F5," ") | R5: =IF((D5="o"),F5," ") | S5: =IF((D5="f"),F5," ")
A6: 45753 | B6: DVLA | D6: t | F6: 180 | G6: =IF((D6="d"),F6," ") | H6: =IF((D6="h"),F6," ") | I6: =IF((D6="r"),F6," ") | J6: =IF((D6="t"),F6," ") -> 180 | K6: =IF((D6="e"),F6," ") | L6: =IF((D6="p"),F6," ") | M6: =IF((D6="g"),F6," ") | N6: =IF((D6="a"),F6," ") | O6: =IF((D6="l"),F6," ") | P6: =IF((D6="i"),F6," ") | Q6: =IF((D6="b"),F6," ") | R6: =IF((D6="o"),F6," ") | S6: =IF((D6="f"),F6," ")
A7: 45757 | B7: Insurance Co | D7: t | F7: 1200 | G7: =IF((D7="d"),F7," ") | H7: =IF((D7="h"),F7," ") | I7: =IF((D7="r"),F7," ") | J7: =IF((D7="t"),F7," ") -> 1200 | K7: =IF((D7="e"),F7," ") | L7: =IF((D7="p"),F7," ") | M7: =IF((D7="g"),F7," ") | N7: =IF((D7="a"),F7," ") | O7: =IF((D7="l"),F7," ") | P7: =IF((D7="i"),F7," ") | Q7: =IF((D7="b"),F7," ") | R7: =IF((D7="o"),F7," ") | S7: =IF((D7="f"),F7," ")
A8: 45767 | B8: Vodafone | D8: g | F8: 120 | G8: =IF((D8="d"),F8," ") | H8: =IF((D8="h"),F8," ") | I8: =IF((D8="r"),F8," ") | J8: =IF((D8="t"),F8," ") | K8: =IF((D8="e"),F8," ") | L8: =IF((D8="p"),F8," ") | M8: =IF((D8="g"),F8," ") -> 120 | N8: =IF((D8="a"),F8," ") | O8: =IF((D8="l"),F8," ") | P8: =IF((D8="i"),F8," ") | Q8: =IF((D8="b"),F8," ") | R8: =IF((D8="o"),F8," ") | S8: =IF((D8="f"),F8," ")
A9: 45755 | B9: Council | D9: l | F9: 400 | G9: =IF((D9="d"),F9," ") | H9: =IF((D9="h"),F9," ") | I9: =IF((D9="r"),F9," ") | J9: =IF((D9="t"),F9," ") | K9: =IF((D9="e"),F9," ") | L9: =IF((D9="p"),F9," ") | M9: =IF((D9="g"),F9," ") | N9: =IF((D9="a"),F9," ") | O9: =IF((D9="l"),F9," ") -> 400 | P9: =IF((D9="i"),F9," ") | Q9: =IF((D9="b"),F9," ") | R9: =IF((D9="o"),F9," ") | S9: =IF((D9="f"),F9," ")
G10: =IF((D10="d"),F10," ") | H10: =IF((D10="h"),F10," ") | I10: =IF((D10="r"),F10," ") | J10: =IF((D10="t"),F10," ") | K10: =IF((D10="e"),F10," ") | L10: =IF((D10="p"),F10," ") | M10: =IF((D10="g"),F10," ") | N10: =IF((D10="a"),F10," ") | O10: =IF((D10="l"),F10," ") | P10: =IF((D10="i"),F10," ") | Q10: =IF((D10="b"),F10," ") | R10: =IF((D10="o"),F10," ") | S10: =IF((D10="f"),F10," ")
G11: =IF((D11="d"),F11," ") | H11: =IF((D11="h"),F11," ") | I11: =IF((D11="r"),F11," ") | J11: =IF((D11="t"),F11," ") | K11: =IF((D11="e"),F11," ") | L11: =IF((D11="p"),F11," ") | M11: =IF((D11="g"),F11," ") | N11: =IF((D11="a"),F11," ") | O11: =IF((D11="l"),F11," ") | P11: =IF((D11="i"),F11," ") | Q11: =IF((D11="b"),F11," ") | R11: =IF((D11="o"),F11," ") | S11: =IF((D11="f"),F11," ")
G12: =IF((D12="d"),F12," ") | H12: =IF((D12="h"),F12," ") | I12: =IF((D12="r"),F12," ") | J12: =IF((D12="t"),F12," ") | K12: =IF((D12="e"),F12," ") | L12: =IF((D12="p"),F12," ") | M12: =IF((D12="g"),F12," ") | N12: =IF((D12="a"),F12," ") | O12: =IF((D12="l"),F12," ") | P12: =IF((D12="i"),F12," ") | Q12: =IF((D12="b"),F12," ") | R12: =IF((D12="o"),F12," ") | S12: =IF((D12="f"),F12," ")
G13: =IF((D13="d"),F13," ") | H13: =IF((D13="h"),F13," ") | I13: =IF((D13="r"),F13," ") | J13: =IF((D13="t"),F13," ") | K13: =IF((D13="e"),F13," ") | L13: =IF((D13="p"),F13," ") | M13: =IF((D13="g"),F13," ") | N13: =IF((D13="a"),F13," ") | O13: =IF((D13="l"),F13," ") | P13: =IF((D13="i"),F13," ") | Q13: =IF((D13="b"),F13," ") | R13: =IF((D13="o"),F13," ") | S13: =IF((D13="f"),F13," ")
G14: =IF((D14="d"),F14," ") | H14: =IF((D14="h"),F14," ") | I14: =IF((D14="r"),F14," ") | J14: =IF((D14="t"),F14," ") | K14: =IF((D14="e"),F14," ") | L14: =IF((D14="p"),F14," ") | M14: =IF((D14="g"),F14," ") | N14: =IF((D14="a"),F14," ") | O14: =IF((D14="l"),F14," ") | P14: =IF((D14="i"),F14," ") | Q14: =IF((D14="b"),F14," ") | R14: =IF((D14="o"),F14," ") | S14: =IF((D14="f"),F14," ")
G15: =IF((D15="d"),F15," ") | H15: =IF((D15="h"),F15," ") | I15: =IF((D15="r"),F15," ") | J15: =IF((D15="t"),F15," ") | K15: =IF((D15="e"),F15," ") | L15: =IF((D15="p"),F15," ") | M15: =IF((D15="g"),F15," ") | N15: =IF((D15="a"),F15," ") | O15: =IF((D15="l"),F15," ") | P15: =IF((D15="i"),F15," ") | Q15: =IF((D15="b"),F15," ") | R15: =IF((D15="o"),F15," ") | S15: =IF((D15="f"),F15," ")
G16: =IF((D16="d"),F16," ") | H16: =IF((D16="h"),F16," ") | I16: =IF((D16="r"),F16," ") | J16: =IF((D16="t"),F16," ") | K16: =IF((D16="e"),F16," ") | L16: =IF((D16="p"),F16," ") | M16: =IF((D16="g"),F16," ") | N16: =IF((D16="a"),F16," ") | O16: =IF((D16="l"),F16," ") | P16: =IF((D16="i"),F16," ") | Q16: =IF((D16="b"),F16," ") | R16: =IF((D16="o"),F16," ") | S16: =IF((D16="f"),F16," ")
G17: =IF((D17="d"),F17," ") | H17: =IF((D17="h"),F17," ") | I17: =IF((D17="r"),F17," ") | J17: =IF((D17="t"),F17," ") | K17: =IF((D17="e"),F17," ") | L17: =IF((D17="p"),F17," ") | M17: =IF((D17="g"),F17," ") | N17: =IF((D17="a"),F17," ") | O17: =IF((D17="l"),F17," ") | P17: =IF((D17="i"),F17," ") | Q17: =IF((D17="b"),F17," ") | R17: =IF((D17="o"),F17," ") | S17: =IF((D17="f"),F17," ")
G18: =IF((D18="d"),F18," ") | H18: =IF((D18="h"),F18," ") | I18: =IF((D18="r"),F18," ") | J18: =IF((D18="t"),F18," ") | K18: =IF((D18="e"),F18," ") | L18: =IF((D18="p"),F18," ") | M18: =IF((D18="g"),F18," ") | N18: =IF((D18="a"),F18," ") | O18: =IF((D18="l"),F18," ") | P18: =IF((D18="i"),F18," ") | Q18: =IF((D18="b"),F18," ") | R18: =IF((D18="o"),F18," ") | S18: =IF((D18="f"),F18," ")
G19: =IF((D19="d"),F19," ") | H19: =IF((D19="h"),F19," ") | I19: =IF((D19="r"),F19," ") | J19: =IF((D19="t"),F19," ") | K19: =IF((D19="e"),F19," ") | L19: =IF((D19="p"),F19," ") | M19: =IF((D19="g"),F19," ") | N19: =IF((D19="a"),F19," ") | O19: =IF((D19="l"),F19," ") | P19: =IF((D19="i"),F19," ") | Q19: =IF((D19="b"),F19," ") | R19: =IF((D19="o"),F19," ") | S19: =IF((D19="f"),F19," ")
G20: =IF((D20="d"),F20," ") | H20: =IF((D20="h"),F20," ") | I20: =IF((D20="r"),F20," ") | J20: =IF((D20="t"),F20," ") | K20: =IF((D20="e"),F20," ") | L20: =IF((D20="p"),F20," ") | M20: =IF((D20="g"),F20," ") | N20: =IF((D20="a"),F20," ") | O20: =IF((D20="l"),F20," ") | P20: =IF((D20="i"),F20," ") | Q20: =IF((D20="b"),F20," ") | R20: =IF((D20="o"),F20," ") | S20: =IF((D20="f"),F20," ")
G21: =IF((D21="d"),F21," ") | H21: =IF((D21="h"),F21," ") | I21: =IF((D21="r"),F21," ") | J21: =IF((D21="t"),F21," ") | K21: =IF((D21="e"),F21," ") | L21: =IF((D21="p"),F21," ") | M21: =IF((D21="g"),F21," ") | N21: =IF((D21="a"),F21," ") | O21: =IF((D21="l"),F21," ") | P21: =IF((D21="i"),F21," ") | Q21: =IF((D21="b"),F21," ") | R21: =IF((D21="o"),F21," ") | S21: =IF((D21="f"),F21," ")
... G36: =IF((D36="d"),F36," ") | H36: =IF((D36="h"),F36," ") | I36: =IF((D36="r"),F36," ") | J36: =IF((D36="t"),F36," ") | K36: =IF((D36="e"),F36," ") | L36: =IF((D36="p"),F36," ") | M36: =IF((D36="g"),F36," ") | N36: =IF((D36="a"),F36," ") | O36: =IF((D36="l"),F36," ") | P36: =IF((D36="i"),F36," ") | Q36: =IF((D36="b"),F36," ") | R36: =IF((D36="o"),F36," ") | S36: =IF((D36="f"),F36," ")
D37: =IF((F37<>0),"Enter Letter"," ") | G37: =IF((D37="d"),F37," ") | H37: =IF((D37="h"),F37," ") | I37: =IF((D37="r"),F37," ") | J37: =IF((D37="t"),F37," ") | K37: =IF((D37="e"),F37," ") | L37: =IF((D37="p"),F37," ") | M37: =IF((D37="g"),F37," ") | N37: =IF((D37="a"),F37," ") | O37: =IF((D37="l"),F37," ") | P37: =IF((D37="i"),F37," ") | Q37: =IF((D37="b"),F37," ") | R37: =IF((D37="o"),F37," ") | S37: =IF((D37="f"),F37," ")
D38: =IF((F38<>0),"Enter Letter"," ") | G38: =IF((D38="d"),F38," ") | H38: =IF((D38="h"),F38," ") | I38: =IF((D38="r"),F38," ") | J38: =IF((D38="t"),F38," ") | K38: =IF((D38="e"),F38," ") | L38: =IF((D38="p"),F38," ") | M38: =IF((D38="g"),F38," ") | N38: =IF((D38="a"),F38," ") | O38: =IF((D38="l"),F38," ") | P38: =IF((D38="i"),F38," ") | Q38: =IF((D38="b"),F38," ") | R38: =IF((D38="o"),F38," ") | S38: =IF((D38="f"),F38," ")
D39: =IF((F39<>0),"Enter Letter"," ") | G39: =IF((D39="d"),F39," ") | H39: =IF((D39="h"),F39," ") | I39: =IF((D39="r"),F39," ") | J39: =IF((D39="t"),F39," ") | K39: =IF((D39="e"),F39," ") | L39: =IF((D39="p"),F39," ") | M39: =IF((D39="g"),F39," ") | N39: =IF((D39="a"),F39," ") | O39: =IF((D39="l"),F39," ") | P39: =IF((D39="i"),F39," ") | Q39: =IF((D39="b"),F39," ") | R39: =IF((D39="o"),F39," ") | S39: =IF((D39="f"),F39," ")
D40: =IF((F40<>0),"Enter Letter"," ") | G40: =IF((D40="d"),F40," ") | H40: =IF((D40="h"),F40," ") | I40: =IF((D40="r"),F40," ") | J40: =IF((D40="t"),F40," ") | K40: =IF((D40="e"),F40," ") | L40: =IF((D40="p"),F40," ") | M40: =IF((D40="g"),F40," ") | N40: =IF((D40="a"),F40," ") | O40: =IF((D40="l"),F40," ") | P40: =IF((D40="i"),F40," ") | Q40: =IF((D40="b"),F40," ") | R40: =IF((D40="o"),F40," ") | S40: =IF((D40="f"),F40," ")
D41: =IF((F41<>0),"Enter Letter"," ") | G41: =IF((D41="d"),F41," ") | H41: =IF((D41="h"),F41," ") | I41: =IF((D41="r"),F41," ") | J41: =IF((D41="t"),F41," ") | K41: =IF((D41="e"),F41," ") | L41: =IF((D41="p"),F41," ") | M41: =IF((D41="g"),F41," ") | N41: =IF((D41="a"),F41," ") | O41: =IF((D41="l"),F41," ") | P41: =IF((D41="i"),F41," ") | Q41: =IF((D41="b"),F41," ") | R41: =IF((D41="o"),F41," ") | S41: =IF((D41="f"),F41," ")
D42: =IF((F42<>0),"Enter Letter"," ") | G42: =IF((D42="d"),F42," ") | H42: =IF((D42="h"),F42," ") | I42: =IF((D42="r"),F42," ") | J42: =IF((D42="t"),F42," ") | K42: =IF((D42="e"),F42," ") | L42: =IF((D42="p"),F42," ") | M42: =IF((D42="g"),F42," ") | N42: =IF((D42="a"),F42," ") | O42: =IF((D42="l"),F42," ") | P42: =IF((D42="i"),F42," ") | Q42: =IF((D42="b"),F42," ") | R42: =IF((D42="o"),F42," ") | S42: =IF((D42="f"),F42," ")
D43: =IF((F43<>0),"Enter Letter"," ") | G43: =IF((D43="d"),F43," ") | H43: =IF((D43="h"),F43," ") | I43: =IF((D43="r"),F43," ") | J43: =IF((D43="t"),F43," ") | K43: =IF((D43="e"),F43," ") | L43: =IF((D43="p"),F43," ") | M43: =IF((D43="g"),F43," ") | N43: =IF((D43="a"),F43," ") | O43: =IF((D43="l"),F43," ") | P43: =IF((D43="i"),F43," ") | Q43: =IF((D43="b"),F43," ") | R43: =IF((D43="o"),F43," ") | S43: =IF((D43="f"),F43," ")
D44: =IF((F44<>0),"Enter Letter"," ") | G44: =IF((D44="d"),F44," ") | H44: =IF((D44="h"),F44," ") | I44: =IF((D44="r"),F44," ") | J44: =IF((D44="t"),F44," ") | K44: =IF((D44="e"),F44," ") | L44: =IF((D44="p"),F44," ") | M44: =IF((D44="g"),F44," ") | N44: =IF((D44="a"),F44," ") | O44: =IF((D44="l"),F44," ") | P44: =IF((D44="i"),F44," ") | Q44: =IF((D44="b"),F44," ") | R44: =IF((D44="o"),F44," ") | S44: =IF((D44="f"),F44," ")
D45: =IF((F45<>0),"Enter Letter"," ") | G45: =IF((D45="d"),F45," ") | H45: =IF((D45="h"),F45," ") | I45: =IF((D45="r"),F45," ") | J45: =IF((D45="t"),F45," ") | K45: =IF((D45="e"),F45," ") | L45: =IF((D45="p"),F45," ") | M45: =IF((D45="g"),F45," ") | N45: =IF((D45="a"),F45," ") | O45: =IF((D45="l"),F45," ") | P45: =IF((D45="i"),F45," ") | Q45: =IF((D45="b"),F45," ") | R45: =IF((D45="o"),F45," ") | S45: =IF((D45="f"),F45," ")
D46: =IF((F46<>0),"Enter Letter"," ") | G46: =IF((D46="d"),F46," ") | H46: =IF((D46="h"),F46," ") | I46: =IF((D46="r"),F46," ") | J46: =IF((D46="t"),F46," ") | K46: =IF((D46="e"),F46," ") | L46: =IF((D46="p"),F46," ") | M46: =IF((D46="g"),F46," ") | N46: =IF((D46="a"),F46," ") | O46: =IF((D46="l"),F46," ") | P46: =IF((D46="i"),F46," ") | Q46: =IF((D46="b"),F46," ") | R46: =IF((D46="o"),F46," ") | S46: =IF((D46="f"),F46," ")
D47: =IF((F47<>0),"Enter Letter"," ") | G47: =IF((D47="d"),F47," ") | H47: =IF((D47="h"),F47," ") | I47: =IF((D47="r"),F47," ") | J47: =IF((D47="t"),F47," ") | K47: =IF((D47="e"),F47," ") | L47: =IF((D47="p"),F47," ") | M47: =IF((D47="g"),F47," ") | N47: =IF((D47="a"),F47," ") | O47: =IF((D47="l"),F47," ") | P47: =IF((D47="i"),F47," ") | Q47: =IF((D47="b"),F47," ") | R47: =IF((D47="o"),F47," ") | S47: =IF((D47="f"),F47," ")
D48: =IF((F48<>0),"Enter Letter"," ") | G48: =IF((D48="d"),F48," ") | H48: =IF((D48="h"),F48," ") | I48: =IF((D48="r"),F48," ") | J48: =IF((D48="t"),F48," ") | K48: =IF((D48="e"),F48," ") | L48: =IF((D48="p"),F48," ") | M48: =IF((D48="g"),F48," ") | N48: =IF((D48="a"),F48," ") | O48: =IF((D48="l"),F48," ") | P48: =IF((D48="i"),F48," ") | Q48: =IF((D48="b"),F48," ") | R48: =IF((D48="o"),F48," ") | S48: =IF((D48="f"),F48," ")
... D204: =IF((F204<>0),"Enter Letter"," ") | G204: =IF((D204="d"),F204," ") | H204: =IF((D204="h"),F204," ") | I204: =IF((D204="r"),F204," ") | J204: =IF((D204="t"),F204," ") | K204: =IF((D204="e"),F204," ") | L204: =IF((D204="p"),F204," ") | M204: =IF((D204="g"),F204," ") | N204: =IF((D204="a"),F204," ") | O204: =IF((D204="l"),F204," ") | P204: =IF((D204="i"),F204," ") | Q204: =IF((D204="b"),F204," ") | R204: =IF((D204="o"),F204," ") | S204: =IF((D204="f"),F204," ")

Sheet SalesMay
A1: Sales Date | B1: Day | C1: Total for Month | D1: =SUM(D4:D58) -> 0 | E1: =SUM(E4:E58)/2 -> 3000 | F1: =SUM(F4:F58)/2 -> 0
C2: Customer Name (rental/other income) | D2: Sales Mileage | E2: Gross takings including tips | F2: Other Income (start up grants)
A5: 43948 | B5: 43948
A6: 43949 | B6: 43949
A7: 43950 | B7: 43950
A8: 43951 | B8: 43951
A9: 43952 | B9: 43952
A10: 43953 | B10: 43953
A11: 43954 | B11: 43954
A12: 43954 | B12: Rental due
A13: 43954 | B13: Any other income
E14: =SUM(E5:E13) -> 0 | F14: =SUM(F5:F13) -> 0
A16: 43955 | B16: 43955
A17: 43956 | B17: 43956 | E17: 200
A18: 43957 | B18: 43957 | E18: 200
A19: 43958 | B19: 43958 | E19: 200
A20: 43959 | B20: 43959 | E20: 200
A21: 43960 | B21: 43960 | E21: 200
A22: 43961 | B22: 43961
A23: 43961 | B23: Rental due
A24: 43961 | B24: Any other income
E25: =SUM(E16:E24) -> 1000 | F25: =SUM(F16:F24) -> 0
A27: 43962 | B27: 43962
A28: 43963 | B28: 43963 | E28: 200
A29: 43964 | B29: 43964 | E29: 200
A30: 43965 | B30: 43965 | E30: 200
A31: 43966 | B31: 43966 | E31: 200
