Workbook

Sheet OpeningCreditors
A1: Purchase Date | B1: Supplier Name | C1: Purchase Invoice Number or Reference | E1: Total for Month | G1: =SUM(G5:G300) -> 0 | H1: =SUM(H5:H300) -> 0 | I1: =SUM(I5:I300) -> 0 | K1: For your information only. Enter How Paid e.g. Cash, Cheque etc., | L1: =SUM(L5:L300) -> 0 | M1: =SUM(M5:M300) -> 0 | N1: =TODAY() -> 46113
E2: Purchase Description | G2: Total Purchase Value incl Vat | H2: =Apr!H2 -> 20 | I2: Purchases Net of Vat | L2: Payments Made to Creditors
H3: Vat Input | L3: Actual Amount Paid | M3: Purchases not yet paid | N3: Purchases Days Outstanding
H5: =IF(G5<>0,G5*H$2/(100+H$2)," ") | I5: =IF((G5<>0),G5-H5," ") | M5: =IF(G5<>0,G5-L5," ") | N5: =IF((G5-L5)<>0,N$1-A5," ")
H6: =IF(G6<>0,G6*H$2/(100+H$2)," ") | I6: =IF((G6<>0),G6-H6," ") | M6: =IF(G6<>0,G6-L6," ") | N6: =IF((G6-L6)<>0,N$1-A6," ")
H7: =IF(G7<>0,G7*H$2/(100+H$2)," ") | I7: =IF((G7<>0),G7-H7," ") | M7: =IF(G7<>0,G7-L7," ") | N7: =IF((G7-L7)<>0,N$1-A7," ")
H8: =IF(G8<>0,G8*H$2/(100+H$2)," ") | I8: =IF((G8<>0),G8-H8," ") | M8: =IF(G8<>0,G8-L8," ") | N8: =IF((G8-L8)<>0,N$1-A8," ")
H9: =IF(G9<>0,G9*H$2/(100+H$2)," ") | I9: =IF((G9<>0),G9-H9," ") | M9: =IF(G9<>0,G9-L9," ") | N9: =IF((G9-L9)<>0,N$1-A9," ")
H10: =IF(G10<>0,G10*H$2/(100+H$2)," ") | I10: =IF((G10<>0),G10-H10," ") | M10: =IF(G10<>0,G10-L10," ") | N10: =IF((G10-L10)<>0,N$1-A10," ")
H11: =IF(G11<>0,G11*H$2/(100+H$2)," ") | I11: =IF((G11<>0),G11-H11," ") | M11: =IF(G11<>0,G11-L11," ") | N11: =IF((G11-L11)<>0,N$1-A11," ")
H12: =IF(G12<>0,G12*H$2/(100+H$2)," ") | I12: =IF((G12<>0),G12-H12," ") | M12: =IF(G12<>0,G12-L12," ") | N12: =IF((G12-L12)<>0,N$1-A12," ")
H13: =IF(G13<>0,G13*H$2/(100+H$2)," ") | I13: =IF((G13<>0),G13-H13," ") | M13: =IF(G13<>0,G13-L13," ") | N13: =IF((G13-L13)<>0,N$1-A13," ")
H14: =IF(G14<>0,G14*H$2/(100+H$2)," ") | I14: =IF((G14<>0),G14-H14," ") | M14: =IF(G14<>0,G14-L14," ") | N14: =IF((G14-L14)<>0,N$1-A14," ")
H15: =IF(G15<>0,G15*H$2/(100+H$2)," ") | I15: =IF((G15<>0),G15-H15," ") | M15: =IF(G15<>0,G15-L15," ") | N15: =IF((G15-L15)<>0,N$1-A15," ")
H16: =IF(G16<>0,G16*H$2/(100+H$2)," ") | I16: =IF((G16<>0),G16-H16," ") | M16: =IF(G16<>0,G16-L16," ") | N16: =IF((G16-L16)<>0,N$1-A16," ")
... H300: =IF(G300<>0,G300*H$2/(100+H$2)," ") | I300: =IF((G300<>0),G300-H300," ") | M300: =IF(G300<>0,G300-L300," ") | N300: =IF((G300-L300)<>0,N$1-A300," ")

Sheet Apr
A1: =G1-H1-SUM(P1:AB1) -> 0 | B1: Check Total | D1: =SUM(D5:D300) -> 0 | E1: Total for Month | G1: =SUM(G2:G300) -> 120 | H1: =SUM(H5:H200) -> 0 | I1: =SUM(I2:I200) -> 120 | K1: For your information only. Enter How Paid e.g. Cash, Cheque etc., | L1: =SUM(L5:L300) -> 0 | M1: =SUM(M5:M200) -> 120 | N1: =TODAY() -> 46113 | P1: =SUM(P5:P300) -> 0 | Q1: =SUM(Q5:Q300) -> 0 | R1: =SUM(R5:R300) -> 0 | S1: =SUM(S5:S300) -> 0 | T1: =SUM(T5:T300) -> 0 | U1: =SUM(U5:U300) -> 0 | V1: =SUM(V5:V300) -> 120 | W1: =SUM(W2:W300) -> 0 | X1: =SUM(X5:X300) -> 0 | Y1: =SUM(Y5:Y300) -> 0 | Z1: =SUM(Z5:Z300) -> 0 | AA1: =SUM(AA5:AA300) -> 0 | AB1: =SUM(AB5:AB300) -> 0 | AD1: =SUM(AD5:AD300) -> 0
A2: =G2 -> 0 | B2: Mileage expenses | C2: =0+D1+[1]Apr!$D$1 -> 0 | D2: Mileage | E2: Purchase Description | F2: v | G2: =IF(C2<[2]Admin!$F$22,(C2-0)*[2]Admin!$G$21,(C2*[2]Admin!$G$21-(C2-[2]Admin!$F$21)*([2]Admin!$G$21-[2]Admin!$G$22)-0)) -> 0 | H2: =IF([1]Apr!$H$4>0,0,[1]Apr!$H$2) -> 20 | I2: =G2 -> 0 | L2: Payments Made to Creditors | P2: Purchases Cost of Sales | S2: Employee Wages excluding Paye | T2: Premises | U2: Repairs & Maintenance | V2: Admistration Telephone Postage & Stationery | W2: =IF((F2="v"),I2," ") -> 0 | X2: Travel Hotel Subsistence Expenses | Y2: Advertising Promotion Entertainment | Z2: Legal & Professional | AA2: Other Expenses | AB2: =AB1 -> 0 | AD2: Contractors
A3: Purchase Date | B3: Supplier Name | C3: Purchase Invoice Number or Reference | F3: Enter Expense Code Letter | G3: Total Purchase Value incl Vat | H3: Vat Input | I3: Purchases Net of Vat | L3: Actual Amount Paid | M3: Purchases not yet paid | N3: Purchases Days Outstanding | P3: Direct Materials | Q3: Sub Contractors | R3: Other Direct Business Costs | T3: Rent & Rates, Light & Heating | W3: Motor Vehicle Expenses | AB3: Fixed Asset Purchases | AD3: CIS Certificates
P4: S | Q4: C | R4: O | S4: W | T4: P | U4: M | V4: G | W4: V | X4: H | Y4: A | Z4: L | AA4: Y | AB4: FA | AD4: Tax Paid | AE4: Certificate No
A5: 45767 | B5: Office Supplies Ltd | F5: g | G5: 120 | I5: =IF((G5<>0),G5-H5," ") -> 120 | M5: =IF(G5<>0,G5-L5," ") -> 120 | N5: =IF((G5-L5)<>0,N$1-A22," ") -> 46113 | P5: =IF((F5="s"),I5," ") | Q5: =IF((F5="c"),I5," ") | R5: =IF((F5="o"),I5," ") | S5: =IF((F5="w"),I5," ") | T5: =IF((F5="p"),I5," ") | U5: =IF((F5="m"),I5," ") | V5: =IF((F5="g"),I5," ") -> 120 | W5: =IF((F5="v"),I5," ") | X5: =IF((F5="h"),I5," ") | Y5: =IF((F5="a"),I5," ") | Z5: =IF((F5="l"),I5," ") | AA5: =IF((F5="y"),I5," ") | AB5: =IF((F5="fa"),I5," ")
H6: =IF(G6<>0,G6*H$2/(100+H$2)," ") | I6: =IF((G6<>0),G6-H6," ") | M6: =IF(G6<>0,G6-L6," ") | N6: =IF((G6-L6)<>0,N$1-A6," ") | P6: =IF((F6="s"),I6," ") | Q6: =IF((F6="c"),I6," ") | R6: =IF((F6="o"),I6," ") | S6: =IF((F6="w"),I6," ") | T6: =IF((F6="p"),I6," ") | U6: =IF((F6="m"),I6," ") | V6: =IF((F6="g"),I6," ") | W6: =IF((F6="v"),I6," ") | X6: =IF((F6="h"),I6," ") | Y6: =IF((F6="a"),I6," ") | Z6: =IF((F6="l"),I6," ") | AA6: =IF((F6="y"),I6," ") | AB6: =IF((F6="fa"),I6," ")
H7: =IF(G7<>0,G7*H$2/(100+H$2)," ") | I7: =IF((G7<>0),G7-H7," ") | M7: =IF(G7<>0,G7-L7," ") | N7: =IF((G7-L7)<>0,N$1-A7," ") | P7: =IF((F7="s"),I7," ") | Q7: =IF((F7="c"),I7," ") | R7: =IF((F7="o"),I7," ") | S7: =IF((F7="w"),I7," ") | T7: =IF((F7="p"),I7," ") | U7: =IF((F7="m"),I7," ") | V7: =IF((F7="g"),I7," ") | W7: =IF((F7="v"),I7," ") | X7: =IF((F7="h"),I7," ") | Y7: =IF((F7="a"),I7," ") | Z7: =IF((F7="l"),I7," ") | AA7: =IF((F7="y"),I7," ") | AB7: =IF((F7="fa"),I7," ")
H8: =IF(G8<>0,G8*H$2/(100+H$2)," ") | I8: =IF((G8<>0),G8-H8," ") | M8: =IF(G8<>0,G8-L8," ") | N8: =IF((G8-L8)<>0,N$1-A8," ") | P8: =IF((F8="s"),I8," ") | Q8: =IF((F8="c"),I8," ") | R8: =IF((F8="o"),I8," ") | S8: =IF((F8="w"),I8," ") | T8: =IF((F8="p"),I8," ") | U8: =IF((F8="m"),I8," ") | V8: =IF((F8="g"),I8," ") | W8: =IF((F8="v"),I8," ") | X8: =IF((F8="h"),I8," ") | Y8: =IF((F8="a"),I8," ") | Z8: =IF((F8="l"),I8," ") | AA8: =IF((F8="y"),I8," ") | AB8: =IF((F8="fa"),I8," ")
H9: =IF(G9<>0,G9*H$2/(100+H$2)," ") | I9: =IF((G9<>0),G9-H9," ") | M9: =IF(G9<>0,G9-L9," ") | N9: =IF((G9-L9)<>0,N$1-A9," ") | P9: =IF((F9="s"),I9," ") | Q9: =IF((F9="c"),I9," ") | R9: =IF((F9="o"),I9," ") | S9: =IF((F9="w"),I9," ") | T9: =IF((F9="p"),I9," ") | U9: =IF((F9="m"),I9," ") | V9: =IF((F9="g"),I9," ") | W9: =IF((F9="v"),I9," ") | X9: =IF((F9="h"),I9," ") | Y9: =IF((F9="a"),I9," ") | Z9: =IF((F9="l"),I9," ") | AA9: =IF((F9="y"),I9," ") | AB9: =IF((F9="fa"),I9," ")
H10: =IF(G10<>0,G10*H$2/(100+H$2)," ") | I10: =IF((G10<>0),G10-H10," ") | M10: =IF(G10<>0,G10-L10," ") | N10: =IF((G10-L10)<>0,N$1-A10," ") | P10: =IF((F10="s"),I10," ") | Q10: =IF((F10="c"),I10," ") | R10: =IF((F10="o"),I10," ") | S10: =IF((F10="w"),I10," ") | T10: =IF((F10="p"),I10," ") | U10: =IF((F10="m"),I10," ") | V10: =IF((F10="g"),I10," ") | W10: =IF((F10="v"),I10," ") | X10: =IF((F10="h"),I10," ") | Y10: =IF((F10="a"),I10," ") | Z10: =IF((F10="l"),I10," ") | AA10: =IF((F10="y"),I10," ") | AB10: =IF((F10="fa"),I10," ")
H11: =IF(G11<>0,G11*H$2/(100+H$2)," ") | I11: =IF((G11<>0),G11-H11," ") | M11: =IF(G11<>0,G11-L11," ") | N11: =IF((G11-L11)<>0,N$1-A11," ") | P11: =IF((F11="s"),I11," ") | Q11: =IF((F11="c"),I11," ") | R11: =IF((F11="o"),I11," ") | S11: =IF((F11="w"),I11," ") | T11: =IF((F11="p"),I11," ") | U11: =IF((F11="m"),I11," ") | V11: =IF((F11="g"),I11," ") | W11: =IF((F11="v"),I11," ") | X11: =IF((F11="h"),I11," ") | Y11: =IF((F11="a"),I11," ") | Z11: =IF((F11="l"),I11," ") | AA11: =IF((F11="y"),I11," ") | AB11: =IF((F11="fa"),I11," ")
H12: =IF(G12<>0,G12*H$2/(100+H$2)," ") | I12: =IF((G12<>0),G12-H12," ") | M12: =IF(G12<>0,G12-L12," ") | N12: =IF((G12-L12)<>0,N$1-A12," ") | P12: =IF((F12="s"),I12," ") | Q12: =IF((F12="c"),I12," ") | R12: =IF((F12="o"),I12," ") | S12: =IF((F12="w"),I12," ") | T12: =IF((F12="p"),I12," ") | U12: =IF((F12="m"),I12," ") | V12: =IF((F12="g"),I12," ") | W12: =IF((F12="v"),I12," ") | X12: =IF((F12="h"),I12," ") | Y12: =IF((F12="a"),I12," ") | Z12: =IF((F12="l"),I12," ") | AA12: =IF((F12="y"),I12," ") | AB12: =IF((F12="fa"),I12," ")
H13: =IF(G13<>0,G13*H$2/(100+H$2)," ") | I13: =IF((G13<>0),G13-H13," ") | M13: =IF(G13<>0,G13-L13," ") | N13: =IF((G13-L13)<>0,N$1-A13," ") | P13: =IF((F13="s"),I13," ") | Q13: =IF((F13="c"),I13," ") | R13: =IF((F13="o"),I13," ") | S13: =IF((F13="w"),I13," ") | T13: =IF((F13="p"),I13," ") | U13: =IF((F13="m"),I13," ") | V13: =IF((F13="g"),I13," ") | W13: =IF((F13="v"),I13," ") | X13: =IF((F13="h"),I13," ") | Y13: =IF((F13="a"),I13," ") | Z13: =IF((F13="l"),I13," ") | AA13: =IF((F13="y"),I13," ") | AB13: =IF((F13="fa"),I13," ")
H14: =IF(G14<>0,G14*H$2/(100+H$2)," ") | I14: =IF((G14<>0),G14-H14," ") | M14: =IF(G14<>0,G14-L14," ") | N14: =IF((G14-L14)<>0,N$1-A14," ") | P14: =IF((F14="s"),I14," ") | Q14: =IF((F14="c"),I14," ") | R14: =IF((F14="o"),I14," ") | S14: =IF((F14="w"),I14," ") | T14: =IF((F14="p"),I14," ") | U14: =IF((F14="m"),I14," ") | V14: =IF((F14="g"),I14," ") | W14: =IF((F14="v"),I14," ") | X14: =IF((F14="h"),I14," ") | Y14: =IF((F14="a"),I14," ") | Z14: =IF((F14="l"),I14," ") | AA14: =IF((F14="y"),I14," ") | AB14: =IF((F14="fa"),I14," ")
H15: =IF(G15<>0,G15*H$2/(100+H$2)," ") | I15: =IF((G15<>0),G15-H15," ") | M15: =IF(G15<>0,G15-L15," ") | N15: =IF((G15-L15)<>0,N$1-A15," ") | P15: =IF((F15="s"),I15," ") | Q15: =IF((F15="c"),I15," ") | R15: =IF((F15="o"),I15," ") | S15: =IF((F15="w"),I15," ") | T15: =IF((F15="p"),I15," ") | U15: =IF((F15="m"),I15," ") | V15: =IF((F15="g"),I15," ") | W15: =IF((F15="v"),I15," ") | X15: =IF((F15="h"),I15," ") | Y15: =IF((F15="a"),I15," ") | Z15: =IF((F15="l"),I15," ") | AA15: =IF((F15="y"),I15," ") | AB15: =IF((F15="fa"),I15," ")
H16: =IF(G16<>0,G16*H$2/(100+H$2)," ") | I16: =IF((G16<>0),G16-H16," ") | M16: =IF(G16<>0,G16-L16," ") | N16: =IF((G16-L16)<>0,N$1-A16," ") | P16: =IF((F16="s"),I16," ") | Q16: =IF((F16="c"),I16," ") | R16: =IF((F16="o"),I16," ") | S16: =IF((F16="w"),I16," ") | T16: =IF((F16="p"),I16," ") | U16: =IF((F16="m"),I16," ") | V16: =IF((F16="g"),I16," ") | W16: =IF((F16="v"),I16," ") | X16: =IF((F16="h"),I16," ") | Y16: =IF((F16="a"),I16," ") | Z16: =IF((F16="l"),I16," ") | AA16: =IF((F16="y"),I16," ") | AB16: =IF((F16="fa"),I16," ")
H17: =IF(G17<>0,G17*H$2/(100+H$2)," ") | I17: =IF((G17<>0),G17-H17," ") | M17: =IF(G17<>0,G17-L17," ") | N17: =IF((G17-L17)<>0,N$1-A17," ") | P17: =IF((F17="s"),I17," ") | Q17: =IF((F17="c"),I17," ") | R17: =IF((F17="o"),I17," ") | S17: =IF((F17="w"),I17," ") | T17: =IF((F17="p"),I17," ") | U17: =IF((F17="m"),I17," ") | V17: =IF((F17="g"),I17," ") | W17: =IF((F17="v"),I17," ") | X17: =IF((F17="h"),I17," ") | Y17: =IF((F17="a"),I17," ") | Z17: =IF((F17="l"),I17," ") | AA17: =IF((F17="y"),I17," ") | AB17: =IF((F17="fa"),I17," ")
... H68: =IF(G68<>0,G68*H$2/(100+H$2)," ") | I68: =IF((G68<>0),G68-H68," ") | M68: =IF(G68<>0,G68-L68," ") | N68: =IF((G68-L68)<>0,N$1-A68," ") | P68: =IF((F68="s"),I68," ") | Q68: =IF((F68="c"),I68," ") | R68: =IF((F68="o"),I68," ") | S68: =IF((F68="w"),I68," ") | T68: =IF((F68="p"),I68," ") | U68: =IF((F68="m"),I68," ") | V68: =IF((F68="g"),I68," ") | W68: =IF((F68="v"),I68," ") | X68: =IF((F68="h"),I68," ") | Y68: =IF((F68="a"),I68," ") | Z68: =IF((F68="l"),I68," ") | AA68: =IF((F68="y"),I68," ") | AB68: =IF((F68="fa"),I68," ")
F69: =IF((G69<>0),"Enter Letter"," ") | H69: =IF(G69<>0,G69*H$2/(100+H$2)," ") | I69: =IF((G69<>0),G69-H69," ") | M69: =IF(G69<>0,G69-L69," ") | N69: =IF((G69-L69)<>0,N$1-A69," ") | P69: =IF((F69="s"),I69," ") | Q69: =IF((F69="c"),I69," ") | R69: =IF((F69="o"),I69," ") | S69: =IF((F69="w"),I69," ") | T69: =IF((F69="p"),I69," ") | U69: =IF((F69="m"),I69," ") | V69: =IF((F69="g"),I69," ") | W69: =IF((F69="v"),I69," ") | X69: =IF((F69="h"),I69," ") | Y69: =IF((F69="a"),I69," ") | Z69: =IF((F69="l"),I69," ") | AA69: =IF((F69="y"),I69," ") | AB69: =IF((F69="fa"),I69," ")
F70: =IF((G70<>0),"Enter Letter"," ") | H70: =IF(G70<>0,G70*H$2/(100+H$2)," ") | I70: =IF((G70<>0),G70-H70," ") | M70: =IF(G70<>0,G70-L70," ") | N70: =IF((G70-L70)<>0,N$1-A70," ") | P70: =IF((F70="s"),I70," ") | Q70: =IF((F70="c"),I70," ") | R70: =IF((F70="o"),I70," ") | S70: =IF((F70="w"),I70," ") | T70: =IF((F70="p"),I70," ") | U70: =IF((F70="m"),I70," ") | V70: =IF((F70="g"),I70," ") | W70: =IF((F70="v"),I70," ") | X70: =IF((F70="h"),I70," ") | Y70: =IF((F70="a"),I70," ") | Z70: =IF((F70="l"),I70," ") | AA70: =IF((F70="y"),I70," ") | AB70: =IF((F70="fa"),I70," ")
F71: =IF((G71<>0),"Enter Letter"," ") | H71: =IF(G71<>0,G71*H$2/(100+H$2)," ") | I71: =IF((G71<>0),G71-H71," ") | M71: =IF(G71<>0,G71-L71," ") | N71: =IF((G71-L71)<>0,N$1-A71," ") | P71: =IF((F71="s"),I71," ") | Q71: =IF((F71="c"),I71," ") | R71: =IF((F71="o"),I71," ") | S71: =IF((F71="w"),I71," ") | T71: =IF((F71="p"),I71," ") | U71: =IF((F71="m"),I71," ") | V71: =IF((F71="g"),I71," ") | W71: =IF((F71="v"),I71," ") | X71: =IF((F71="h"),I71," ") | Y71: =IF((F71="a"),I71," ") | Z71: =IF((F71="l"),I71," ") | AA71: =IF((F71="y"),I71," ") | AB71: =IF((F71="fa"),I71," ")
F72: =IF((G72<>0),"Enter Letter"," ") | H72: =IF(G72<>0,G72*H$2/(100+H$2)," ") | I72: =IF((G72<>0),G72-H72," ") | M72: =IF(G72<>0,G72-L72," ") | N72: =IF((G72-L72)<>0,N$1-A72," ") | P72: =IF((F72="s"),I72," ") | Q72: =IF((F72="c"),I72," ") | R72: =IF((F72="o"),I72," ") | S72: =IF((F72="w"),I72," ") | T72: =IF((F72="p"),I72," ") | U72: =IF((F72="m"),I72," ") | V72: =IF((F72="g"),I72," ") | W72: =IF((F72="v"),I72," ") | X72: =IF((F72="h"),I72," ") | Y72: =IF((F72="a"),I72," ") | Z72: =IF((F72="l"),I72," ") | AA72: =IF((F72="y"),I72," ") | AB72: =IF((F72="fa"),I72," ")
F73: =IF((G73<>0),"Enter Letter"," ") | H73: =IF(G73<>0,G73*H$2/(100+H$2)," ") | I73: =IF((G73<>0),G73-H73," ") | M73: =IF(G73<>0,G73-L73," ") | N73: =IF((G73-L73)<>0,N$1-A73," ") | P73: =IF((F73="s"),I73," ") | Q73: =IF((F73="c"),I73," ") | R73: =IF((F73="o"),I73," ") | S73: =IF((F73="w"),I73," ") | T73: =IF((F73="p"),I73," ") | U73: =IF((F73="m"),I73," ") | V73: =IF((F73="g"),I73," ") | W73: =IF((F73="v"),I73," ") | X73: =IF((F73="h"),I73," ") | Y73: =IF((F73="a"),I73," ") | Z73: =IF((F73="l"),I73," ") | AA73: =IF((F73="y"),I73," ") | AB73: =IF((F73="fa"),I73," ")
F74: =IF((G74<>0),"Enter Letter"," ") | H74: =IF(G74<>0,G74*H$2/(100+H$2)," ") | I74: =IF((G74<>0),G74-H74," ") | M74: =IF(G74<>0,G74-L74," ") | N74: =IF((G74-L74)<>0,N$1-A74," ") | P74: =IF((F74="s"),I74," ") | Q74: =IF((F74="c"),I74," ") | R74: =IF((F74="o"),I74," ") | S74: =IF((F74="w"),I74," ") | T74: =IF((F74="p"),I74," ") | U74: =IF((F74="m"),I74," ") | V74: =IF((F74="g"),I74," ") | W74: =IF((F74="v"),I74," ") | X74: =IF((F74="h"),I74," ") | Y74: =IF((F74="a"),I74," ") | Z74: =IF((F74="l"),I74," ") | AA74: =IF((F74="y"),I74," ") | AB74: =IF((F74="fa"),I74," ")
F75: =IF((G75<>0),"Enter Letter"," ") | H75: =IF(G75<>0,G75*H$2/(100+H$2)," ") | I75: =IF((G75<>0),G75-H75," ") | M75: =IF(G75<>0,G75-L75," ") | N75: =IF((G75-L75)<>0,N$1-A75," ") | P75: =IF((F75="s"),I75," ") | Q75: =IF((F75="c"),I75," ") | R75: =IF((F75="o"),I75," ") | S75: =IF((F75="w"),I75," ") | T75: =IF((F75="p"),I75," ") | U75: =IF((F75="m"),I75," ") | V75: =IF((F75="g"),I75," ") | W75: =IF((F75="v"),I75," ") | X75: =IF((F75="h"),I75," ") | Y75: =IF((F75="a"),I75," ") | Z75: =IF((F75="l"),I75," ") | AA75: =IF((F75="y"),I75," ") | AB75: =IF((F75="fa"),I75," ")
F76: =IF((G76<>0),"Enter Letter"," ") | H76: =IF(G76<>0,G76*H$2/(100+H$2)," ") | I76: =IF((G76<>0),G76-H76," ") | M76: =IF(G76<>0,G76-L76," ") | N76: =IF((G76-L76)<>0,N$1-A76," ") | P76: =IF((F76="s"),I76," ") | Q76: =IF((F76="c"),I76," ") | R76: =IF((F76="o"),I76," ") | S76: =IF((F76="w"),I76," ") | T76: =IF((F76="p"),I76," ") | U76: =IF((F76="m"),I76," ") | V76: =IF((F76="g"),I76," ") | W76: =IF((F76="v"),I76," ") | X76: =IF((F76="h"),I76," ") | Y76: =IF((F76="a"),I76," ") | Z76: =IF((F76="l"),I76," ") | AA76: =IF((F76="y"),I76," ") | AB76: =IF((F76="fa"),I76," ")
F77: =IF((G77<>0),"Enter Letter"," ") | H77: =IF(G77<>0,G77*H$2/(100+H$2)," ") | I77: =IF((G77<>0),G77-H77," ") | M77: =IF(G77<>0,G77-L77," ") | N77: =IF((G77-L77)<>0,N$1-A77," ") | P77: =IF((F77="s"),I77," ") | Q77: =IF((F77="c"),I77," ") | R77: =IF((F77="o"),I77," ") | S77: =IF((F77="w"),I77," ") | T77: =IF((F77="p"),I77," ") | U77: =IF((F77="m"),I77," ") | V77: =IF((F77="g"),I77," ") | W77: =IF((F77="v"),I77," ") | X77: =IF((F77="h"),I77," ") | Y77: =IF((F77="a"),I77," ") | Z77: =IF((F77="l"),I77," ") | AA77: =IF((F77="y"),I77," ") | AB77: =IF((F77="fa"),I77," ")
F78: =IF((G78<>0),"Enter Letter"," ") | H78: =IF(G78<>0,G78*H$2/(100+H$2)," ") | I78: =IF((G78<>0),G78-H78," ") | M78: =IF(G78<>0,G78-L78," ") | N78: =IF((G78-L78)<>0,N$1-A78," ") | P78: =IF((F78="s"),I78," ") | Q78: =IF((F78="c"),I78," ") | R78: =IF((F78="o"),I78," ") | S78: =IF((F78="w"),I78," ") | T78: =IF((F78="p"),I78," ") | U78: =IF((F78="m"),I78," ") | V78: =IF((F78="g"),I78," ") | W78: =IF((F78="v"),I78," ") | X78: =IF((F78="h"),I78," ") | Y78: =IF((F78="a"),I78," ") | Z78: =IF((F78="l"),I78," ") | AA78: =IF((F78="y"),I78," ") | AB78: =IF((F78="fa"),I78," ")
F79: =IF((G79<>0),"Enter Letter"," ") | H79: =IF(G79<>0,G79*H$2/(100+H$2)," ") | I79: =IF((G79<>0),G79-H79," ") | M79: =IF(G79<>0,G79-L79," ") | N79: =IF((G79-L79)<>0,N$1-A79," ") | P79: =IF((F79="s"),I79," ") | Q79: =IF((F79="c"),I79," ") | R79: =IF((F79="o"),I79," ") | S79: =IF((F79="w"),I79," ") | T79: =IF((F79="p"),I79," ") | U79: =IF((F79="m"),I79," ") | V79: =IF((F79="g"),I79," ") | W79: =IF((F79="v"),I79," ") | X79: =IF((F79="h"),I79," ") | Y79: =IF((F79="a"),I79," ") | Z79: =IF((F79="l"),I79," ") | AA79: =IF((F79="y"),I79," ") | AB79: =IF((F79="fa"),I79," ")
F80: =IF((G80<>0),"Enter Letter"," ") | H80: =IF(G80<>0,G80*H$2/(100+H$2)," ") | I80: =IF((G80<>0),G80-H80," ") | M80: =IF(G80<>0,G80-L80," ") | N80: =IF((G80-L80)<>0,N$1-A80," ") | P80: =IF((F80="s"),I80," ") | Q80: =IF((F80="c"),I80," ") | R80: =IF((F80="o"),I80," ") | S80: =IF((F80="w"),I80," ") | T80: =IF((F80="p"),I80," ") | U80: =IF((F80="m"),I80," ") | V80: =IF((F80="g"),I80," ") | W80: =IF((F80="v"),I80," ") | X80: =IF((F80="h"),I80," ") | Y80: =IF((F80="a"),I80," ") | Z80: =IF((F80="l"),I80," ") | AA80: =IF((F80="y"),I80," ") | AB80: =IF((F80="fa"),I80," ")
... F300: =IF((G300<>0),"Enter Letter"," ") | H300: =IF(G300<>0,G300*H$2/(100+H$2)," ") | I300: =IF((G300<>0),G300-H300," ") | M300: =IF(G300<>0,G300-L300," ") | N300: =IF((G300-L300)<>0,N$1-A300," ") | P300: =IF((F300="s"),I300," ") | Q300: =IF((F300="c"),I300," ") | R300: =IF((F300="o"),I300," ") | S300: =IF((F300="w"),I300," ") | T300: =IF((F300="p"),I300," ") | U300: =IF((F300="m"),I300," ") | V300: =IF((F300="g"),I300," ") | W300: =IF((F300="v"),I300," ") | X300: =IF((F300="h"),I300," ") | Y300: =IF((F300="a"),I300," ") | Z300: =IF((F300="l"),I300," ") | AA300: =IF((F300="y"),I300," ") | AB300: =IF((F300="fa"),I300," ")

Sheet May
A1: =G1-H1-SUM(P1:AB1) -> 0 | B1: Check Total | D1: =SUM(D5:D300) -> 0 | E1: Total for Month | G1: =SUM(G2:G300) -> 600 | H1: =SUM(H5:H200) -> 0 | I1: =SUM(I2:I200) -> 600 | K1: For your information only. Enter How Paid e.g. Cash, Cheque etc., | L1: =SUM(L5:L300) -> 0 | M1: =SUM(M5:M200) -> 600 | N1: =TODAY() -> 46113 | P1: =SUM(P5:P300) -> 0 | Q1: =SUM(Q5:Q300) -> 0 | R1: =SUM(R5:R300) -> 0 | S1: =SUM(S5:S300) -> 0 | T1: =SUM(T5:T300) -> 600 | U1: =SUM(U5:U300) -> 0 | V1: =SUM(V5:V300) -> 0 | W1: =SUM(W2:W300) -> 0 | X1: =SUM(X5:X300) -> 0 | Y1: =SUM(Y5:Y300) -> 0 | Z1: =SUM(Z5:Z300) -> 0 | AA1: =SUM(AA5:AA300) -> 0 | AB1: =SUM(AB5:AB300) -> 0 | AD1: =SUM(AD5:AD300) -> 0
A2: =G2+Apr!A2 -> 0 | B2: Mileage expenses | C2: =Apr!C2+D1+[1]May!$D$1 -> 0 | D2: Mileage | E2: Purchase Description | F2: =Apr!F2 -> v | G2: =IF(C2<[2]Admin!$F$22,(C2-Apr!C2)*[2]Admin!$G$21,C2*[2]Admin!$G$21-(C2-[2]Admin!$F$21)*([2]Admin!$G$21-[2]Admin!$G$22)-Apr!G2) -> 0 | H2: =IF([1]May!$H$4>0,0,[1]May!$H$2) -> 20 | I2: =G2 -> 0 | L2: Payments Made to Creditors | P2: Purchases Cost of Sales | S2: Employee Wages excluding Paye | T2: Premises | U2: Repairs & Maintenance | V2: Admistration Telephone Postage & Stationery | W2: =IF((F2="v"),I2," ") -> 0 | X2: Travel Hotel Subsistence Expenses | Y2: Advertising Promotion Entertainment | Z2: Legal & Professional | AA2: Other Expenses | AB2: =AB1+Apr!AB2 -> 0 | AD2: Contractors
A3: Purchase Date | B3: Supplier Name | C3: Purchase Invoice Number or Reference | F3: Enter Expense Code Letter | G3: Total Purchase Value incl Vat | H3: Vat Input | I3: Purchases Net of Vat | L3: Actual Amount Paid | M3: Purchases not yet paid | N3: Purchases Days Outstanding | P3: Direct Materials | Q3: Sub Contractors | R3: Other Direct Business Costs | T3: Rent & Rates, Light & Heating | W3: Motor Vehicle Expenses | AB3: Fixed Asset Purchases | AD3: CIS Certificates
P4: S | Q4: C | R4: O | S4: W | T4: P | U4: M | V4: G | W4: V | X4: H | Y4: A | Z4: L | AA4: Y | AB4: FA | AD4: Tax Paid | AE4: Certificate No
A5: 45787 | B5: Landlord | F5: p | G5: 600 | I5: =IF((G5<>0),G5-H5," ") -> 600 | M5: =IF(G5<>0,G5-L5," ") -> 600 | N5: =IF((G5-L5)<>0,N$1-A5," ") -> 326 | P5: =IF((F5="s"),I5," ") | Q5: =IF((F5="c"),I5," ") | R5: =IF((F5="o"),I5," ") | S5: =IF((F5="w"),I5," ") | T5: =IF((F5="p"),I5," ") -> 600 | U5: =IF((F5="m"),I5," ") | V5: =IF((F5="g"),I5," ") | W5: =IF((F5="v"),I5," ") | X5: =IF((F5="h"),I5," ") | Y5: =IF((F5="a"),I5," ") | Z5: =IF((F5="l"),I5," ") | AA5: =IF((F5="y"),I5," ") | AB5: =IF((F5="fa"),I5," ")
H6: =IF(G6<>0,G6*H$2/(100+H$2)," ") | I6: =IF((G6<>0),G6-H6," ") | M6: =IF(G6<>0,G6-L6," ") | N6: =IF((G6-L6)<>0,N$1-A6," ") | P6: =IF((F6="s"),I6," ") | Q6: =IF((F6="c"),I6," ") | R6: =IF((F6="o"),I6," ") | S6: =IF((F6="w"),I6," ") | T6: =IF((F6="p"),I6," ") | U6: =IF((F6="m"),I6," ") | V6: =IF((F6="g"),I6," ") | W6: =IF((F6="v"),I6," ") | X6: =IF((F6="h"),I6," ") | Y6: =IF((F6="a"),I6," ") | Z6: =IF((F6="l"),I6," ") | AA6: =IF((F6="y"),I6," ") | AB6: =IF((F6="fa"),I6," ")
H7: =IF(G7<>0,G7*H$2/(100+H$2)," ") | I7: =IF((G7<>0),G7-H7," ") | M7: =IF(G7<>0,G7-L7," ") | N7: =IF((G7-L7)<>0,N$1-A7," ") | P7: =IF((F7="s"),I7," ") | Q7: =IF((F7="c"),I7," ") | R7: =IF((F7="o"),I7," ") | S7: =IF((F7="w"),I7," ") | T7: =IF((F7="p"),I7," ") | U7: =IF((F7="m"),I7," ") | V7: =IF((F7="g"),I7," ") | W7: =IF((F7="v"),I7," ") | X7: =IF((F7="h"),I7," ") | Y7: =IF((F7="a"),I7," ") | Z7: =IF((F7="l"),I7," ") | AA7: =IF((F7="y"),I7," ") | AB7: =IF((F7="fa"),I7," ")
H8: =IF(G8<>0,G8*H$2/(100+H$2)," ") | I8: =IF((G8<>0),G8-H8," ") | M8: =IF(G8<>0,G8-L8," ") | N8: =IF((G8-L8)<>0,N$1-A8," ") | P8: =IF((F8="s"),I8," ") | Q8: =IF((F8="c"),I8," ") | R8: =IF((F8="o"),I8," ") | S8: =IF((F8="w"),I8," ") | T8: =IF((F8="p"),I8," ") | U8: =IF((F8="m"),I8," ") | V8: =IF((F8="g"),I8," ") | W8: =IF((F8="v"),I8," ") | X8: =IF((F8="h"),I8," ") | Y8: =IF((F8="a"),I8," ") | Z8: =IF((F8="l"),I8," ") | AA8: =IF((F8="y"),I8," ") | AB8: =IF((F8="fa"),I8," ")
H9: =IF(G9<>0,G9*H$2/(100+H$2)," ") | I9: =IF((G9<>0),G9-H9," ") | M9: =IF(G9<>0,G9-L9," ") | N9: =IF((G9-L9)<>0,N$1-A9," ") | P9: =IF((F9="s"),I9," ") | Q9: =IF((F9="c"),I9," ") | R9: =IF((F9="o"),I9," ") | S9: =IF((F9="w"),I9," ") | T9: =IF((F9="p"),I9," ") | U9: =IF((F9="m"),I9," ") | V9: =IF((F9="g"),I9," ") | W9: =IF((F9="v"),I9," ") | X9: =IF((F9="h"),I9," ") | Y9: =IF((F9="a"),I9," ") | Z9: =IF((F9="l"),I9," ") | AA9: =IF((F9="y"),I9," ") | AB9: =IF((F9="fa"),I9," ")
H10: =IF(G10<>0,G10*H$2/(100+H$2)," ") | I10: =IF((G10<>0),G10-H10," ") | M10: =IF(G10<>0,G10-L10," ") | N10: =IF((G10-L10)<>0,N$1-A10," ") | P10: =IF((F10="s"),I10," ") | Q10: =IF((F10="c"),I10," ") | R10: =IF((F10="o"),I10," ") | S10: =IF((F10="w"),I10," ") | T10: =IF((F10="p"),I10," ") | U10: =IF((F10="m"),I10," ") | V10: =IF((F10="g"),I10," ") | W10: =IF((F10="v"),I10," ") | X10: =IF((F10="h"),I10," ") | Y10: =IF((F10="a"),I10," ") | Z10: =IF((F10="l"),I10," ") | AA10: =IF((F10="y"),I10," ") | AB10: =IF((F10="fa"),I10," ")
H11: =IF(G11<>0,G11*H$2/(100+H$2)," ") | I11: =IF((G11<>0),G11-H11," ") | M11: =IF(G11<>0,G11-L11," ") | N11: =IF((G11-L11)<>0,N$1-A11," ") | P11: =IF((F11="s"),I11," ") | Q11: =IF((F11="c"),I11," ") | R11: =IF((F11="o"),I11," ") | S11: =IF((F11="w"),I11," ") | T11: =IF((F11="p"),I11," ") | U11: =IF((F11="m"),I11," ") | V11: =IF((F11="g"),I11," ") | W11: =IF((F11="v"),I11," ") | X11: =IF((F11="h"),I11," ") | Y11: =IF((F11="a"),I11," ") | Z11: =IF((F11="l"),I11," ") | AA11: =IF((F11="y"),I11," ") | AB11: =IF((F11="fa"),I11," ")
H12: =IF(G12<>0,G12*H$2/(100+H$2)," ") | I12: =IF((G12<>0),G12-H12," ") | M12: =IF(G12<>0,G12-L12," ") | N12: =IF((G12-L12)<>0,N$1-A12," ") | P12: =IF((F12="s"),I12," ") | Q12: =IF((F12="c"),I12," ") | R12: =IF((F12="o"),I12," ") | S12: =IF((F12="w"),I12," ") | T12: =IF((F12="p"),I12," ") | U12: =IF((F12="m"),I12," ") | V12: =IF((F12="g"),I12," ") | W12: =IF((F12="v"),I12," ") | X12: =IF((F12="h"),I12," ") | Y12: =IF((F12="a"),I12," ") | Z12: =IF((F12="l"),I12," ") | AA12: =IF((F12="y"),I12," ") | AB12: =IF((F12="fa"),I12," ")
H13: =IF(G13<>0,G13*H$2/(100+H$2)," ") | I13: =IF((G13<>0),G13-H13," ") | M13: =IF(G13<>0,G13-L13," ") | N13: =IF((G13-L13)<>0,N$1-A13," ") | P13: =IF((F13="s"),I13," ") | Q13: =IF((F13="c"),I13," ") | R13: =IF((F13="o"),I13," ") | S13: =IF((F13="w"),I13," ") | T13: =IF((F13="p"),I13," ") | U13: =IF((F13="m"),I13," ") | V13: =IF((F13="g"),I13," ") | W13: =IF((F13="v"),I13," ") | X13: =IF((F13="h"),I13," ") | Y13: =IF((F13="a"),I13," ") | Z13: =IF((F13="l"),I13," ") | AA13: =IF((F13="y"),I13," ") | AB13: =IF((F13="fa"),I13," ")
H14: =IF(G14<>0,G14*H$2/(100+H$2)," ") | I14: =IF((G14<>0),G14-H14," ") | M14: =IF(G14<>0,G14-L14," ") | N14: =IF((G14-L14)<>0,N$1-A14," ") | P14: =IF((F14="s"),I14," ") | Q14: =IF((F14="c"),I14," ") | R14: =IF((F14="o"),I14," ") | S14: =IF((F14="w"),I14," ") | T14: =IF((F14="p"),I14," ") | U14: =IF((F14="m"),I14," ") | V14: =IF((F14="g"),I14," ") | W14: =IF((F14="v"),I14," ") | X14: =IF((F14="h"),I14," ") | Y14: =IF((F14="a"),I14," ") | Z14: =IF((F14="l"),I14," ") | AA14: =IF((F14="y"),I14," ") | AB14: =IF((F14="fa"),I14," ")
H15: =IF(G15<>0,G15*H$2/(100+H$2)," ") | I15: =IF((G15<>0),G15-H15," ") | M15: =IF(G15<>0,G15-L15," ") | N15: =IF((G15-L15)<>0,N$1-A15," ") | P15: =IF((F15="s"),I15," ") | Q15: =IF((F15="c"),I15," ") | R15: =IF((F15="o"),I15," ") | S15: =IF((F15="w"),I15," ") | T15: =IF((F15="p"),I15," ") | U15: =IF((F15="m"),I15," ") | V15: =IF((F15="g"),I15," ") | W15: =IF((F15="v"),I15," ") | X15: =IF((F15="h"),I15," ") | Y15: =IF((F15="a"),I15," ") | Z15: =IF((F15="l"),I15," ") | AA15: =IF((F15="y"),I15," ") | AB15: =IF((F15="fa"),I15," ")
H16: =IF(G16<>0,G16*H$2/(100+H$2)," ") | I16: =IF((G16<>0),G16-H16," ") | M16: =IF(G16<>0,G16-L16," ") | N16: =IF((G16-L16)<>0,N$1-A16," ") | P16: =IF((F16="s"),I16," ") | Q16: =IF((F16="c"),I16," ") | R16: =IF((F16="o"),I16," ") | S16: =IF((F16="w"),I16," ") | T16: =IF((F16="p"),I16," ") | U16: =IF((F16="m"),I16," ") | V16: =IF((F16="g"),I16," ") | W16: =IF((F16="v"),I16," ") | X16: =IF((F16="h"),I16," ") | Y16: =IF((F16="a"),I16," ") | Z16: =IF((F16="l"),I16," ") | AA16: =IF((F16="y"),I16," ") | AB16: =IF((F16="fa"),I16," ")
H17: =IF(G17<>0,G17*H$2/(100+H$2)," ") | I17: =IF((G17<>0),G17-H17," ") | M17: =IF(G17<>0,G17-L17," ") | N17: =IF((G17-L17)<>0,N$1-A17," ") | P17: =IF((F17="s"),I17," ") | Q17: =IF((F17="c"),I17," ") | R17: =IF((F17="o"),I17," ") | S17: =IF((F17="w"),I17," ") | T17: =IF((F17="p"),I17," ") | U17: =IF((F17="m"),I17," ") | V17: =IF((F17="g"),I17," ") | W17: =IF((F17="v"),I17," ") | X17: =IF((F17="h"),I17," ") | Y17: =IF((F17="a"),I17," ") | Z17: =IF((F17="l"),I17," ") | AA17: =IF((F17="y"),I17," ") | AB17: =IF((F17="fa"),I17," ")
... H68: =IF(G68<>0,G68*H$2/(100+H$2)," ") | I68: =IF((G68<>0),G68-H68," ") | M68: =IF(G68<>0,G68-L68," ") | N68: =IF((G68-L68)<>0,N$1-A68," ") | P68: =IF((F68="s"),I68," ") | Q68: =IF((F68="c"),I68," ") | R68: =IF((F68="o"),I68," ") | S68: =IF((F68="w"),I68," ") | T68: =IF((F68="p"),I68," ") | U68: =IF((F68="m"),I68," ") | V68: =IF((F68="g"),I68," ") | W68: =IF((F68="v"),I68," ") | X68: =IF((F68="h"),I68," ") | Y68: =IF((F68="a"),I68," ") | Z68: =IF((F68="l"),I68," ") | AA68: =IF((F68="y"),I68," ") | AB68: =IF((F68="fa"),I68," ")
F69: =IF((G69<>0),"Enter Letter"," ") | H69: =IF(G69<>0,G69*H$2/(100+H$2)," ") | I69: =IF((G69<>0),G69-H69," ") | M69: =IF(G69<>0,G69-L69," ") | N69: =IF((G69-L69)<>0,N$1-A69," ") | P69: =IF((F69="s"),I69," ") | Q69: =IF((F69="c"),I69," ") | R69: =IF((F69="o"),I69," ") | S69: =IF((F69="w"),I69," ") | T69: =IF((F69="p"),I69," ") | U69: =IF((F69="m"),I69," ") | V69: =IF((F69="g"),I69," ") | W69: =IF((F69="v"),I69," ") | X69: =IF((F69="h"),I69," ") | Y69: =IF((F69="a"),I69," ") | Z69: =IF((F69="l"),I69," ") | AA69: =IF((F69="y"),I69," ") | AB69: =IF((F69="fa"),I69," ")
F70: =IF((G70<>0),"Enter Letter"," ") | H70: =IF(G70<>0,G70*H$2/(100+H$2)," ") | I70: =IF((G70<>0),G70-H70," ") | M70: =IF(G70<>0,G70-L70," ") | N70: =IF((G70-L70)<>0,N$1-A70," ") | P70: =IF((F70="s"),I70," ") | Q70: =IF((F70="c"),I70," ") | R70: =IF((F70="o"),I70," ") | S70: =IF((F70="w"),I70," ") | T70: =IF((F70="p"),I70," ") | U70: =IF((F70="m"),I70," ") | V70: =IF((F70="g"),I70," ") | W70: =IF((F70="v"),I70," ") | X70: =IF((F70="h"),I70," ") | Y70: =IF((F70="a"),I70," ") | Z70: =IF((F70="l"),I70," ") | AA70: =IF((F70="y"),I70," ") | AB70: =IF((F70="fa"),I70," ")
F71: =IF((G71<>0),"Enter Letter"," ") | H71: =IF(G71<>0,G71*H$2/(100+H$2)," ") | I71: =IF((G71<>0),G71-H71," ") | M71: =IF(G71<>0,G71-L71," ") | N71: =IF((G71-L71)<>0,N$1-A71," ") | P71: =IF((F71="s"),I71," ") | Q71: =IF((F71="c"),I71," ") | R71: =IF((F71="o"),I71," ") | S71: =IF((F71="w"),I71," ") | T71: =IF((F71="p"),I71," ") | U71: =IF((F71="m"),I71," ") | V71: =IF((F71="g"),I71," ") | W71: =IF((F71="v"),I71," ") | X71: =IF((F71="h"),I71," ") | Y71: =IF((F71="a"),I71," ") | Z71: =IF((F71="l"),I71," ") | AA71: =IF((F71="y"),I71," ") | AB71: =IF((F71="fa"),I71," ")
F72: =IF((G72<>0),"Enter Letter"," ") | H72: =IF(G72<>0,G72*H$2/(100+H$2)," ") | I72: =IF((G72<>0),G72-H72," ") | M72: =IF(G72<>0,G72-L72," ") | N72: =IF((G72-L72)<>0,N$1-A72," ") | P72: =IF((F72="s"),I72," ") | Q72: =IF((F72="c"),I72," ") | R72: =IF((F72="o"),I72," ") | S72: =IF((F72="w"),I72," ") | T72: =IF((F72="p"),I72," ") | U72: =IF((F72="m"),I72," ") | V72: =IF((F72="g"),I72," ") | W72: =IF((F72="v"),I72," ") | X72: =IF((F72="h"),I72," ") | Y72: =IF((F72="a"),I72," ") | Z72: =IF((F72="l"),I72," ") | AA72: =IF((F72="y"),I72," ") | AB72: =IF((F72="fa"),I72," ")
F73: =IF((G73<>0),"Enter Letter"," ") | H73: =IF(G73<>0,G73*H$2/(100+H$2)," ") | I73: =IF((G73<>0),G73-H73," ") | M73: =IF(G73<>0,G73-L73," ") | N73: =IF((G73-L73)<>0,N$1-A73," ") | P73: =IF((F73="s"),I73," ") | Q73: =IF((F73="c"),I73," ") | R73: =IF((F73="o"),I73," ") | S73: =IF((F73="w"),I73," ") | T73: =IF((F73="p"),I73," ") | U73: =IF((F73="m"),I73," ") | V73: =IF((F73="g"),I73," ") | W73: =IF((F73="v"),I73," ") | X73: =IF((F73="h"),I73," ") | Y73: =IF((F73="a"),I73," ") | Z73: =IF((F73="l"),I73," ") | AA73: =IF((F73="y"),I73," ") | AB73: =IF((F73="fa"),I73," ")
F74: =IF((G74<>0),"Enter Letter"," ") | H74: =IF(G74<>0,G74*H$2/(100+H$2)," ") | I74: =IF((G74<>0),G74-H74," ") | M74: =IF(G74<>0,G74-L74," ") | N74: =IF((G74-L74)<>0,N$1-A74," ") | P74: =IF((F74="s"),I74," ") | Q74: =IF((F74="c"),I74," ") | R74: =IF((F74="o"),I74," ") | S74: =IF((F74="w"),I74," ") | T74: =IF((F74="p"),I74," ") | U74: =IF((F74="m"),I74," ") | V74: =IF((F74="g"),I74," ") | W74: =IF((F74="v"),I74," ") | X74: =IF((F74="h"),I74," ") | Y74: =IF((F74="a"),I74," ") | Z74: =IF((F74="l"),I74," ") | AA74: =IF((F74="y"),I74," ") | AB74: =IF((F74="fa"),I74," ")
F75: =IF((G75<>0),"Enter Letter"," ") | H75: =IF(G75<>0,G75*H$2/(100+H$2)," ") | I75: =IF((G75<>0),G75-H75," ") | M75: =IF(G75<>0,G75-L75," ") | N75: =IF((G75-L75)<>0,N$1-A75," ") | P75: =IF((F75="s"),I75," ") | Q75: =IF((F75="c"),I75," ") | R75: =IF((F75="o"),I75," ") | S75: =IF((F75="w"),I75," ") | T75: =IF((F75="p"),I75," ") | U75: =IF((F75="m"),I75," ") | V75: =IF((F75="g"),I75," ") | W75: =IF((F75="v"),I75," ") | X75: =IF((F75="h"),I75," ") | Y75: =IF((F75="a"),I75," ") | Z75: =IF((F75="l"),I75," ") | AA75: =IF((F75="y"),I75," ") | AB75: =IF((F75="fa"),I75," ")
F76: =IF((G76<>0),"Enter Letter"," ") | H76: =IF(G76<>0,G76*H$2/(100+H$2)," ") | I76: =IF((G76<>0),G76-H76," ") | M76: =IF(G76<>0,G76-L76," ") | N76: =IF((G76-L76)<>0,N$1-A76," ") | P76: =IF((F76="s"),I76," ") | Q76: =IF((F76="c"),I76," ") | R76: =IF((F76="o"),I76," ") | S76: =IF((F76="w"),I76," ") | T76: =IF((F76="p"),I76," ") | U76: =IF((F76="m"),I76," ") | V76: =IF((F76="g"),I76," ") | W76: =IF((F76="v"),I76," ") | X76: =IF((F76="h"),I76," ") | Y76: =IF((F76="a"),I76," ") | Z76: =IF((F76="l"),I76," ") | AA76: =IF((F76="y"),I76," ") | AB76: =IF((F76="fa"),I76," ")
F77: =IF((G77<>0),"Enter Letter"," ") | H77: =IF(G77<>0,G77*H$2/(100+H$2)," ") | I77: =IF((G77<>0),G77-H77," ") | M77: =IF(G77<>0,G77-L77," ") | N77: =IF((G77-L77)<>0,N$1-A77," ") | P77: =IF((F77="s"),I77," ") | Q77: =IF((F77="c"),I77," ") | R77: =IF((F77="o"),I77," ") | S77: =IF((F77="w"),I77," ") | T77: =IF((F77="p"),I77," ") | U77: =IF((F77="m"),I77," ") | V77: =IF((F77="g"),I77," ") | W77: =IF((F77="v"),I77," ") | X77: =IF((F77="h"),I77," ") | Y77: =IF((F77="a"),I77," ") | Z77: =IF((F77="l"),I77," ") | AA77: =IF((F77="y"),I77," ") | AB77: =IF((F77="fa"),I77," ")
F78: =IF((G78<>0),"Enter Letter"," ") | H78: =IF(G78<>0,G78*H$2/(100+H$2)," ") | I78: =IF((G78<>0),G78-H78," ") | M78: =IF(G78<>0,G78-L78," ") | N78: =IF((G78-L78)<>0,N$1-A78," ") | P78: =IF((F78="s"),I78," ") | Q78: =IF((F78="c"),I78," ") | R78: =IF((F78="o"),I78," ") | S78: =IF((F78="w"),I78," ") | T78: =IF((F78="p"),I78," ") | U78: =IF((F78="m"),I78," ") | V78: =IF((F78="g"),I78," ") | W78: =IF((F78="v"),I78," ") | X78: =IF((F78="h"),I78," ") | Y78: =IF((F78="a"),I78," ") | Z78: =IF((F78="l"),I78," ") | AA78: =IF((F78="y"),I78," ") | AB78: =IF((F78="fa"),I78," ")
F79: =IF((G79<>0),"Enter Letter"," ") | H79: =IF(G79<>0,G79*H$2/(100+H$2)," ") | I79: =IF((G79<>0),G79-H79," ") | M79: =IF(G79<>0,G79-L79," ") | N79: =IF((G79-L79)<>0,N$1-A79," ") | P79: =IF((F79="s"),I79," ") | Q79: =IF((F79="c"),I79," ") | R79: =IF((F79="o"),I79," ") | S79: =IF((F79="w"),I79," ") | T79: =IF((F79="p"),I79," ") | U79: =IF((F79="m"),I79," ") | V79: =IF((F79="g"),I79," ") | W79: =IF((F79="v"),I79," ") | X79: =IF((F79="h"),I79," ") | Y79: =IF((F79="a"),I79," ") | Z79: =IF((F79="l"),I79," ") | AA79: =IF((F79="y"),I79," ") | AB79: =IF((F79="fa"),I79," ")
F80: =IF((G80<>0),"Enter Letter"," ") | H80: =IF(G80<>0,G80*H$2/(100+H$2)," ") | I80: =IF((G80<>0),G80-H80," ") | M80: =IF(G80<>0,G80-L80," ") | N80: =IF((G80-L80)<>0,N$1-A80," ") | P80: =IF((F80="s"),I80," ") | Q80: =IF((F80="c"),I80," ") | R80: =IF((F80="o"),I80," ") | S80: =IF((F80="w"),I80," ") | T80: =IF((F80="p"),I80," ") | U80: =IF((F80="m"),I80," ") | V80: =IF((F80="g"),I80," ") | W80: =IF((F80="v"),I80," ") | X80: =IF((F80="h"),I80," ") | Y80: =IF((F80="a"),I80," ") | Z80: =IF((F80="l"),I80," ") | AA80: =IF((F80="y"),I80," ") | AB80: =IF((F80="fa"),I80," ")
... F300: =IF((G300<>0),"Enter Letter"," ") | H300: =IF(G300<>0,G300*H$2/(100+H$2)," ") | I300: =IF((G300<>0),G300-H300," ") | M300: =IF(G300<>0,G300-L300," ") | N300: =IF((G300-L300)<>0,N$1-A300," ") | P300: =IF((F300="s"),I300," ") | Q300: =IF((F300="c"),I300," ") | R300: =IF((F300="o"),I300," ") | S300: =IF((F300="w"),I300," ") | T300: =IF((F300="p"),I300," ") | U300: =IF((F300="m"),I300," ") | V300: =IF((F300="g"),I300," ") | W300: =IF((F300="v"),I300," ") | X300: =IF((F300="h"),I300," ") | Y300: =IF((F300="a"),I300," ") | Z300: =IF((F300="l"),I300," ") | AA300: =IF((F300="y"),I300," ") | AB300: =IF((F300="fa"),I300," ")

Sheet Jun
A1: =G1-H1-SUM(P1:AB1) -> 0 | B1: Check Total | D1: =SUM(D5:D300) -> 0 | E1: Total for Month | G1: =SUM(G2:G300) -> 0 | H1: =SUM(H5:H200) -> 0 | I1: =SUM(I2:I200) -> 0 | K1: For your information only. Enter How Paid e.g. Cash, Cheque etc., | L1: =SUM(L5:L300) -> 0 | M1: =SUM(M5:M200) -> 0 | N1: =TODAY() -> 46113 | P1: =SUM(P5:P300) -> 0 | Q1: =SUM(Q5:Q300) -> 0 | R1: =SUM(R5:R300) -> 0 | S1: =SUM(S5:S300) -> 0 | T1: =SUM(T5:T300) -> 0 | U1: =SUM(U5:U300) -> 0 | V1: =SUM(V5:V300) -> 0 | W1: =SUM(W2:W300) -> 0 | X1: =SUM(X5:X300) -> 0 | Y1: =SUM(Y5:Y300) -> 0 | Z1: =SUM(Z5:Z300) -> 0 | AA1: =SUM(AA5:AA300) -> 0 | AB1: =SUM(AB5:AB300) -> 0 | AD1: =SUM(AD5:AD300) -> 0
A2: =G2+May!A2 -> 0 | B2: Mileage expenses | C2: =May!C2+D1+[1]Jun!$D$1 -> 0 | D2: Mileage | E2: Purchase Description | F2: =May!F2 -> v | G2: =IF(C2<[2]Admin!$F$22,(C2-May!C2)*[2]Admin!$G$21,C2*[2]Admin!$G$21-(C2-[2]Admin!$F$21)*([2]Admin!$G$21-[2]Admin!$G$22)-May!A2) -> 0 | H2: =IF([1]Jun!$H$4>0,0,[1]Jun!$H$2) -> 20 | I2: =G2 -> 0 | L2: Payments Made to Creditors | P2: Purchases Cost of Sales | S2: Employee Wages excluding Paye | T2: Premises | U2: Repairs & Maintenance | V2: Admistration Telephone Postage & Stationery | W2: =IF((F2="v"),I2," ") -> 0 | X2: Travel Hotel Subsistence Expenses | Y2: Advertising Promotion Entertainment | Z2: Legal & Professional | AA2: Other Expenses | AB2: =AB1+May!AB2 -> 0 | AD2: Contractors
A3: Purchase Date | B3: Supplier Name | C3: Purchase Invoice Number or Reference | F3: Enter Expense Code Letter | G3: Total Purchase Value incl Vat | H3: Vat Input | I3: Purchases Net of Vat | L3: Actual Amount Paid | M3: Purchases not yet paid | N3: Purchases Days Outstanding | P3: Direct Materials | Q3: Sub Contractors | R3: Other Direct Business Costs | T3: Rent & Rates, Light & Heating | W3: Motor Vehicle Expenses | AB3: Fixed Asset Purchases | AD3: CIS Certificates
P4: S | Q4: C | R4: O | S4: W | T4: P | U4: M | V4: G | W4: V | X4: H | Y4: A | Z4: L | AA4: Y | AB4: FA | AD4: Tax Paid | AE4: Certificate No
F5: =IF((G5<>0),"Enter Letter"," ") | H5: =IF(G5<>0,G5*H$2/(100+H$2)," ") | I5: =IF((G5<>0),G5-H5," ") | M5: =IF(G5<>0,G5-L5," ") | N5: =IF((G5-L5)<>0,N$1-A5," ") | P5: =IF((F5="s"),I5," ") | Q5: =IF((F5="c"),I5," ") | R5: =IF((F5="o"),I5," ") | S5: =IF((F5="w"),I5," ") | T5: =IF((F5="p"),I5," ") | U5: =IF((F5="m"),I5," ") | V5: =IF((F5="g"),I5," ") | W5: =IF((F5="v"),I5," ") | X5: =IF((F5="h"),I5," ") | Y5: =IF((F5="a"),I5," ") | Z5: =IF((F5="l"),I5," ") | AA5: =IF((F5="y"),I5," ") | AB5: =IF((F5="fa"),I5," ")
F6: =IF((G6<>0),"Enter Letter"," ") | H6: =IF(G6<>0,G6*H$2/(100+H$2)," ") | I6: =IF((G6<>0),G6-H6," ") | M6: =IF(G6<>0,G6-L6," ") | N6: =IF((G6-L6)<>0,N$1-A6," ") | P6: =IF((F6="s"),I6," ") | Q6: =IF((F6="c"),I6," ") | R6: =IF((F6="o"),I6," ") | S6: =IF((F6="w"),I6," ") | T6: =IF((F6="p"),I6," ") | U6: =IF((F6="m"),I6," ") | V6: =IF((F6="g"),I6," ") | W6: =IF((F6="v"),I6," ") | X6: =IF((F6="h"),I6," ") | Y6: =IF((F6="a"),I6," ") | Z6: =IF((F6="l"),I6," ") | AA6: =IF((F6="y"),I6," ") | AB6: =IF((F6="fa"),I6," ")
F7: =IF((G7<>0),"Enter Letter"," ") | H7: =IF(G7<>0,G7*H$2/(100+H$2)," ") | I7: =IF((G7<>0),G7-H7," ") | M7: =IF(G7<>0,G7-L7," ") | N7: =IF((G7-L7)<>0,N$1-A7," ") | P7: =IF((F7="s"),I7," ") | Q7: =IF((F7="c"),I7," ") | R7: =IF((F7="o"),I7," ") | S7: =IF((F7="w"),I7," ") | T7: =IF((F7="p"),I7," ") | U7: =IF((F7="m"),I7," ") | V7: =IF((F7="g"),I7," ") | W7: =IF((F7="v"),I7," ") | X7: =IF((F7="h"),I7," ") | Y7: =IF((F7="a"),I7," ") | Z7: =IF((F7="l"),I7," ") | AA7: =IF((F7="y"),I7," ") | AB7: =IF((F7="fa"),I7," ")
F8: =IF((G8<>0),"Enter Letter"," ") | H8: =IF(G8<>0,G8*H$2/(100+H$2)," ") | I8: =IF((G8<>0),G8-H8," ") | M8: =IF(G8<>0,G8-L8," ") | N8: =IF((G8-L8)<>0,N$1-A8," ") | P8: =IF((F8="s"),I8," ") | Q8: =IF((F8="c"),I8," ") | R8: =IF((F8="o"),I8," ") | S8: =IF((F8="w"),I8," ") | T8: =IF((F8="p"),I8," ") | U8: =IF((F8="m"),I8," ") | V8: =IF((F8="g"),I8," ") | W8: =IF((F8="v"),I8," ") | X8: =IF((F8="h"),I8," ") | Y8: =IF((F8="a"),I8," ") | Z8: =IF((F8="l"),I8," ") | AA8: =IF((F8="y"),I8," ") | AB8: =IF((F8="fa"),I8," ")
F9: =IF((G9<>0),"Enter Letter"," ") | H9: =IF(G9<>0,G9*H$2/(100+H$2)," ") | I9: =IF((G9<>0),G9-H9," ") | M9: =IF(G9<>0,G9-L9," ") | N9: =IF((G9-L9)<>0,N$1-A9," ") | P9: =IF((F9="s"),I9," ") | Q9: =IF((F9="c"),I9," ") | R9: =IF((F9="o"),I9," ") | S9: =IF((F9="w"),I9," ") | T9: =IF((F9="p"),I9," ") | U9: =IF((F9="m"),I9," ") | V9: =IF((F9="g"),I9," ") | W9: =IF((F9="v"),I9," ") | X9: =IF((F9="h"),I9," ") | Y9: =IF((F9="a"),I9," ") | Z9: =IF((F9="l"),I9," ") | AA9: =IF((F9="y"),I9," ") | AB9: =IF((F9="fa"),I9," ")
F10: =IF((G10<>0),"Enter Letter"," ") | H10: =IF(G10<>0,G10*H$2/(100+H$2)," ") | I10: =IF((G10<>0),G10-H10," ") | M10: =IF(G10<>0,G10-L10," ") | N10: =IF((G10-L10)<>0,N$1-A10," ") | P10: =IF((F10="s"),I10," ") | Q10: =IF((F10="c"),I10," ") | R10: =IF((F10="o"),I10," ") | S10: =IF((F10="w"),I10," ") | T10: =IF((F10="p"),I10," ") | U10: =IF((F10="m"),I10," ") | V10: =IF((F10="g"),I10," ") | W10: =IF((F10="v"),I10," ") | X10: =IF((F10="h"),I10," ") | Y10: =IF((F10="a"),I10," ") | Z10: =IF((F10="l"),I10," ") | AA10: =IF((F10="y"),I10," ") | AB10: =IF((F10="fa"),I10," ")
F11: =IF((G11<>0),"Enter Letter"," ") | H11: =IF(G11<>0,G11*H$2/(100+H$2)," ") | I11: =IF((G11<>0),G11-H11," ") | M11: =IF(G11<>0,G11-L11," ") | N11: =IF((G11-L11)<>0,N$1-A11," ") | P11: =IF((F11="s"),I11," ") | Q11: =IF((F11="c"),I11," ") | R11: =IF((F11="o"),I11," ") | S11: =IF((F11="w"),I11," ") | T11: =IF((F11="p"),I11," ") | U11: =IF((F11="m"),I11," ") | V11: =IF((F11="g"),I11," ") | W11: =IF((F11="v"),I11," ") | X11: =IF((F11="h"),I11," ") | Y11: =IF((F11="a"),I11," ") | Z11: =IF((F11="l"),I11," ") | AA11: =IF((F11="y"),I11," ") | AB11: =IF((F11="fa"),I11," ")
F12: =IF((G12<>0),"Enter Letter"," ") | H12: =IF(G12<>0,G12*H$2/(100+H$2)," ") | I12: =IF((G12<>0),G12-H12," ") | M12: =IF(G12<>0,G12-L12," ") | N12: =IF((G12-L12)<>0,N$1-A12," ") | P12: =IF((F12="s"),I12," ") | Q12: =IF((F12="c"),I12," ") | R12: =IF((F12="o"),I12," ") | S12: =IF((F12="w"),I12," ") | T12: =IF((F12="p"),I12," ") | U12: =IF((F12="m"),I12," ") | V12: =IF((F12="g"),I12," ") | W12: =IF((F12="v"),I12," ") | X12: =IF((F12="h"),I12," ") | Y12: =IF((F12="a"),I12," ") | Z12: =IF((F12="l"),I12," ") | AA12: =IF((F12="y"),I12," ") | AB12: =IF((F12="fa"),I12," ")
F13: =IF((G13<>0),"Enter Letter"," ") | H13: =IF(G13<>0,G13*H$2/(100+H$2)," ") | I13: =IF((G13<>0),G13-H13," ") | M13: =IF(G13<>0,G13-L13," ") | N13: =IF((G13-L13)<>0,N$1-A13," ") | P13: =IF((F13="s"),I13," ") | Q13: =IF((F13="c"),I13," ") | R13: =IF((F13="o"),I13," ") | S13: =IF((F13="w"),I13," ") | T13: =IF((F13="p"),I13," ") | U13: =IF((F13="m"),I13," ") | V13: =IF((F13="g"),I13," ") | W13: =IF((F13="v"),I13," ") | X13: =IF((F13="h"),I13," ") | Y13: =IF((F13="a"),I13," ") | Z13: =IF((F13="l"),I13," ") | AA13: =IF((F13="y"),I13," ") | AB13: =IF((F13="fa"),I13," ")
F14: =IF((G14<>0),"Enter Letter"," ") | H14: =IF(G14<>0,G14*H$2/(100+H$2)," ") | I14: =IF((G14<>0),G14-H14," ") | M14: =IF(G14<>0,G14-L14," ") | N14: =IF((G14-L14)<>0,N$1-A14," ") | P14: =IF((F14="s"),I14," ") | Q14: =IF((F14="c"),I14," ") | R14: =IF((F14="o"),I14," ") | S14: =IF((F14="w"),I14," ") | T14: =IF((F14="p"),I14," ") | U14: =IF((F14="m"),I14," ") | V14: =IF((F14="g"),I14," ") | W14: =IF((F14="v"),I14," ") | X14: =IF((F14="h"),I14," ") | Y14: =IF((F14="a"),I14," ") | Z14: =IF((F14="l"),I14," ") | AA14: =IF((F14="y"),I14," ") | AB14: =IF((F14="fa"),I14," ")
F15: =IF((G15<>0),"Enter Letter"," ") | H15: =IF(G15<>0,G15*H$2/(100+H$2)," ") | I15: =IF((G15<>0),G15-H15," ") | M15: =IF(G15<>0,G15-L15," ") | N15: =IF((G15-L15)<>0,N$1-A15," ") | P15: =IF((F15="s"),I15," ") | Q15: =IF((F15="c"),I15," ") | R15: =IF((F15="o"),I15," ") | S15: =IF((F15="w"),I15," ") | T15: =IF((F15="p"),I15," ") | U15: =IF((F15="m"),I15," ") | V15: =IF((F15="g"),I15," ") | W15: =IF((F15="v"),I15," ") | X15: =IF((F15="h"),I15," ") | Y15: =IF((F15="a"),I15," ") | Z15: =IF((F15="l"),I15," ") | AA15: =IF((F15="y"),I15," ") | AB15: =IF((F15="fa"),I15," ")
F16: =IF((G16<>0),"Enter Letter"," ") | H16: =IF(G16<>0,G16*H$2/(100+H$2)," ") | I16: =IF((G16<>0),G16-H16," ") | M16: =IF(G16<>0,G16-L16," ") | N16: =IF((G16-L16)<>0,N$1-A16," ") | P16: =IF((F16="s"),I16," ") | Q16: =IF((F16="c"),I16," ") | R16: =IF((F16="o"),I16," ") | S16: =IF((F16="w"),I16," ") | T16: =IF((F16="p"),I16," ") | U16: =IF((F16="m"),I16," ") | V16: =IF((F16="g"),I16," ") | W16: =IF((F16="v"),I16," ") | X16: =IF((F16="h"),I16," ") | Y16: =IF((F16="a"),I16," ") | Z16: =IF((F16="l"),I16," ") | AA16: =IF((F16="y"),I16," ") | AB16: =IF((F16="fa"),I16," ")
... F300: =IF((G300<>0),"Enter Letter"," ") | H300: =IF(G300<>0,G300*H$2/(100+H$2)," ") | I300: =IF((G300<>0),G300-H300," ") | M300: =IF(G300<>0,G300-L300," ") | N300: =IF((G300-L300)<>0,N$1-A300," ") | P300: =IF((F300="s"),I300," ") | Q300: =IF((F300="c"),I300," ") | R300: =IF((F300="o"),I300," ") | S300: =IF((F300="w"),I300," ") | T300: =IF((F300="p"),I300," ") | U300: =IF((F300="m"),I300," ") | V300: =IF((F300="g"),I300," ") | W300: =IF((F300="v"),I300," ") | X300: =IF((F300="h"),I300," ") | Y300: =IF((F300="a"),I300," ") | Z300: =IF((F300="l"),I300," ") | AA300: =IF((F300="y"),I300," ") | AB300: =IF((F300="fa"),I300," ")

Sheet Jul
A1: =G1-H1-SUM(P1:AB1) -> 0 | B1: Check Total | D1: =SUM(D5:D300) -> 0 | E1: Total for Month | G1: =SUM(G2:G300) -> 480 | H1: =SUM(H5:H200) -> 0 | I1: =SUM(I2:I200) -> 480 | K1: For your information only. Enter How Paid e.g. Cash, Cheque etc., | L1: =SUM(L5:L300) -> 0 | M1: =SUM(M5:M200) -> 480 | N1: =TODAY() -> 46113 | P1: =SUM(P5:P300) -> 0 | Q1: =SUM(Q5:Q300) -> 0 | R1: =SUM(R5:R300) -> 0 | S1: =SUM(S5:S300) -> 0 | T1: =SUM(T5:T300) -> 0 | U1: =SUM(U5:U300) -> 0 | V1: =SUM(V5:V300) -> 0 | W1: =SUM(W2:W300) -> 0 | X1: =SUM(X5:X300) -> 0 | Y1: =SUM(Y5:Y300) -> 0 | Z1: =SUM(Z5:Z300) -> 480 | AA1: =SUM(AA5:AA300) -> 0 | AB1: =SUM(AB5:AB300) -> 0 | AD1: =SUM(AD5:AD300) -> 0
A2: =G2+Jun!A2 -> 0 | B2: Mileage expenses | C2: =Jun!C2+D1+[1]Jul!$D$1 -> 0 | D2: Mileage | E2: Purchase Description | F2: =Jun!F2 -> v | G2: =IF(C2<[2]Admin!$F$22,(C2-Jun!C2)*[2]Admin!$G$21,C2*[2]Admin!$G$21-(C2-[2]Admin!$F$21)*([2]Admin!$G$21-[2]Admin!$G$22)-Jun!A2) -> 0 | H2: =IF([1]Jul!$H$4>0,0,[1]Jul!$H$2) -> 20 | I2: =G2 -> 0 | L2: Payments Made to Creditors | P2: Purchases Cost of Sales | S2: Employee Wages excluding Paye | T2: Premises | U2: Repairs & Maintenance | V2: Admistration Telephone Postage & Stationery | W2: =IF((F2="v"),I2," ") -> 0 | X2: Travel Hotel Subsistence Expenses | Y2: Advertising Promotion Entertainment | Z2: Legal & Professional | AA2: Other Expenses | AB2: =AB1+Jun!AB2 -> 0 | AD2: Contractors
A3: Purchase Date | B3: Supplier Name | C3: Purchase Invoice Number or Reference | F3: Enter Expense Code Letter | G3: Total Purchase Value incl Vat | H3: Vat Input | I3: Purchases Net of Vat | L3: Actual Amount Paid | M3: Purchases not yet paid | N3: Purchases Days Outstanding | P3: Direct Materials | Q3: Sub Contractors | R3: Other Direct Business Costs | T3: Rent & Rates, Light & Heating | W3: Motor Vehicle Expenses | AB3: Fixed Asset Purchases | AD3: CIS Certificates
P4: S | Q4: C | R4: O | S4: W | T4: P | U4: M | V4: G | W4: V | X4: H | Y4: A | Z4: L | AA4: Y | AB4: FA | AD4: Tax Paid | AE4: Certificate No
A5: 45839 | B5: Accountant | F5: l | G5: 480 | I5: =IF((G5<>0),G5-H5," ") -> 480 | M5: =IF(G5<>0,G5-L5," ") -> 480 | N5: =IF((G5-L5)<>0,N$1-A5," ") -> 274 | P5: =IF((F5="s"),I5," ") | Q5: =IF((F5="c"),I5," ") | R5: =IF((F5="o"),I5," ") | S5: =IF((F5="w"),I5," ") | T5: =IF((F5="p"),I5," ") | U5: =IF((F5="m"),I5," ") | V5: =IF((F5="g"),I5," ") | W5: =IF((F5="v"),I5," ") | X5: =IF((F5="h"),I5," ") | Y5: =IF((F5="a"),I5," ") | Z5: =IF((F5="l"),I5," ") -> 480 | AA5: =IF((F5="y"),I5," ") | AB5: =IF((F5="fa"),I5," ")
H6: =IF(G6<>0,G6*H$2/(100+H$2)," ") | I6: =IF((G6<>0),G6-H6," ") | M6: =IF(G6<>0,G6-L6," ") | N6: =IF((G6-L6)<>0,N$1-A6," ") | P6: =IF((F6="s"),I6," ") | Q6: =IF((F6="c"),I6," ") | R6: =IF((F6="o"),I6," ") | S6: =IF((F6="w"),I6," ") | T6: =IF((F6="p"),I6," ") | U6: =IF((F6="m"),I6," ") | V6: =IF((F6="g"),I6," ") | W6: =IF((F6="v"),I6," ") | X6: =IF((F6="h"),I6," ") | Y6: =IF((F6="a"),I6," ") | Z6: =IF((F6="l"),I6," ") | AA6: =IF((F6="y"),I6," ") | AB6: =IF((F6="fa"),I6," ")
H7: =IF(G7<>0,G7*H$2/(100+H$2)," ") | I7: =IF((G7<>0),G7-H7," ") | M7: =IF(G7<>0,G7-L7," ") | N7: =IF((G7-L7)<>0,N$1-A7," ") | P7: =IF((F7="s"),I7," ") | Q7: =IF((F7="c"),I7," ") | R7: =IF((F7="o"),I7," ") | S7: =IF((F7="w"),I7," ") | T7: =IF((F7="p"),I7," ") | U7: =IF((F7="m"),I7," ") | V7: =IF((F7="g"),I7," ") | W7: =IF((F7="v"),I7," ") | X7: =IF((F7="h"),I7," ") | Y7: =IF((F7="a"),I7," ") | Z7: =IF((F7="l"),I7," ") | AA7: =IF((F7="y"),I7," ") | AB7: =IF((F7="fa"),I7," ")
H8: =IF(G8<>0,G8*H$2/(100+H$2)," ") | I8: =IF((G8<>0),G8-H8," ") | M8: =IF(G8<>0,G8-L8," ") | N8: =IF((G8-L8)<>0,N$1-A8," ") | P8: =IF((F8="s"),I8," ") | Q8: =IF((F8="c"),I8," ") | R8: =IF((F8="o"),I8," ") | S8: =IF((F8="w"),I8," ") | T8: =IF((F8="p"),I8," ") | U8: =IF((F8="m"),I8," ") | V8: =IF((F8="g"),I8," ") | W8: =IF((F8="v"),I8," ") | X8: =IF((F8="h"),I8," ") | Y8: =IF((F8="a"),I8," ") | Z8: =IF((F8="l"),I8," ") | AA8: =IF((F8="y"),I8," ") | AB8: =IF((F8="fa"),I8," ")
H9: =IF(G9<>0,G9*H$2/(100+H$2)," ") | I9: =IF((G9<>0),G9-H9," ") | M9: =IF(G9<>0,G9-L9," ") | N9: =IF((G9-L9)<>0,N$1-A9," ") | P9: =IF((F9="s"),I9," ") | Q9: =IF((F9="c"),I9," ") | R9: =IF((F9="o"),I9," ") | S9: =IF((F9="w"),I9," ") | T9: =IF((F9="p"),I9," ") | U9: =IF((F9="m"),I9," ") | V9: =IF((F9="g"),I9," ") | W9: =IF((F9="v"),I9," ") | X9: =IF((F9="h"),I9," ") | Y9: =IF((F9="a"),I9," ") | Z9: =IF((F9="l"),I9," ") | AA9: =IF((F9="y"),I9," ") | AB9: =IF((F9="fa"),I9," ")
H10: =IF(G10<>0,G10*H$2/(100+H$2)," ") | I10: =IF((G10<>0),G10-H10," ") | M10: =IF(G10<>0,G10-L10," ") | N10: =IF((G10-L10)<>0,N$1-A10," ") | P10: =IF((F10="s"),I10," ") | Q10: =IF((F10="c"),I10," ") | R10: =IF((F10="o"),I10," ") | S10: =IF((F10="w"),I10," ") | T10: =IF((F10="p"),I10," ") | U10: =IF((F10="m"),I10," ") | V10: =IF((F10="g"),I10," ") | W10: =IF((F10="v"),I10," ") | X10: =IF((F10="h"),I10," ") | Y10: =IF((F10="a"),I10," ") | Z10: =IF((F10="l"),I10," ") | AA10: =IF((F10="y"),I10," ") | AB10: =IF((F10="fa"),I10," ")
H11: =IF(G11<>0,G11*H$2/(100+H$2)," ") | I11: =IF((G11<>0),G11-H11," ") | M11: =IF(G11<>0,G11-L11," ") | N11: =IF((G11-L11)<>0,N$1-A11," ") | P11: =IF((F11="s"),I11," ") | Q11: =IF((F11="c"),I11," ") | R11: =IF((F11="o"),I11," ") | S11: =IF((F11="w"),I11," ") | T11: =IF((F11="p"),I11," ") | U11: =IF((F11="m"),I11," ") | V11: =IF((F11="g"),I11," ") | W11: =IF((F11="v"),I11," ") | X11: =IF((F11="h"),I11," ") | Y11: =IF((F11="a"),I11," ") | Z11: =IF((F11="l"),I11," ") | AA11: =IF((F11="y"),I11," ") | AB11: =IF((F11="fa"),I11," ")
H12: =IF(G12<>0,G12*H$2/(100+H$2)," ") | I12: =IF((G12<>0),G12-H12," ") | M12: =IF(G12<>0,G12-L12," ") | N12: =IF((G12-L12)<>0,N$1-A12," ") | P12: =IF((F12="s"),I12," ") | Q12: =IF((F12="c"),I12," ") | R12: =IF((F12="o"),I12," ") | S12: =IF((F12="w"),I12," ") | T12: =IF((F12="p"),I12," ") | U12: =IF((F12="m"),I12," ") | V12: =IF((F12="g"),I12," ") | W12: =IF((F12="v"),I12," ") | X12: =IF((F12="h"),I12," ") | Y12: =IF((F12="a"),I12," ") | Z12: =IF((F12="l"),I12," ") | AA12: =IF((F12="y"),I12," ") | AB12: =IF((F12="fa"),I12," ")
H13: =IF(G13<>0,G13*H$2/(100+H$2)," ") | I13: =IF((G13<>0),G13-H13," ") | M13: =IF(G13<>0,G13-L13," ") | N13: =IF((G13-L13)<>0,N$1-A13," ") | P13: =IF((F13="s"),I13," ") | Q13: =IF((F13="c"),I13," ") | R13: =IF((F13="o"),I13," ") | S13: =IF((F13="w"),I13," ") | T13: =IF((F13="p"),I13," ") | U13: =IF((F13="m"),I13," ") | V13: =IF((F13="g"),I13," ") | W13: =IF((F13="v"),I13," ") | X13: =IF((F13="h"),I13," ") | Y13: =IF((F13="a"),I13," ") | Z13: =IF((F13="l"),I13," ") | AA13: =IF((F13="y"),I13," ") | AB13: =IF((F13="fa"),I13," ")
H14: =IF(G14<>0,G14*H$2/(100+H$2)," ") | I14: =IF((G14<>0),G14-H14," ") | M14: =IF(G14<>0,G14-L14," ") | N14: =IF((G14-L14)<>0,N$1-A14," ") | P14: =IF((F14="s"),I14," ") | Q14: =IF((F14="c"),I14," ") | R14: =IF((F14="o"),I14," ") | S14: =IF((F14="w"),I14," ") | T14: =IF((F14="p"),I14," ") | U14: =IF((F14="m"),I14," ") | V14: =IF((F14="g"),I14," ") | W14: =IF((F14="v"),I14," ") | X14: =IF((F14="h"),I14," ") | Y14: =IF((F14="a"),I14," ") | Z14: =IF((F14="l"),I14," ") | AA14: =IF((F14="y"),I14," ") | AB14: =IF((F14="fa"),I14," ")
H15: =IF(G15<>0,G15*H$2/(100+H$2)," ") | I15: =IF((G15<>0),G15-H15," ") | M15: =IF(G15<>0,G15-L15," ") | N15: =IF((G15-L15)<>0,N$1-A15," ") | P15: =IF((F15="s"),I15," ") | Q15: =IF((F15="c"),I15," ") | R15: =IF((F15="o"),I15," ") | S15: =IF((F15="w"),I15," ") | T15: =IF((F15="p"),I15," ") | U15: =IF((F15="m"),I15," ") | V15: =IF((F15="g"),I15," ") | W15: =IF((F15="v"),I15," ") | X15: =IF((F15="h"),I15," ") | Y15: =IF((F15="a"),I15," ") | Z15: =IF((F15="l"),I15," ") | AA15: =IF((F15="y"),I15," ") | AB15: =IF((F15="fa"),I15," ")
H16: =IF(G16<>0,G16*H$2/(100+H$2)," ") | I16: =IF((G16<>0),G16-H16," ") | M16: =IF(G16<>0,G16-L16," ") | N16: =IF((G16-L16)<>0,N$1-A16," ") | P16: =IF((F16="s"),I16," ") | Q16: =IF((F16="c"),I16," ") | R16: =IF((F16="o"),I16," ") | S16: =IF((F16="w"),I16," ") | T16: =IF((F16="p"),I16," ") | U16: =IF((F16="m"),I16," ") | V16: =IF((F16="g"),I16," ") | W16: =IF((F16="v"),I16," ") | X16: =IF((F16="h"),I16," ") | Y16: =IF((F16="a"),I16," ") | Z16: =IF((F16="l"),I16," ") | AA16: =IF((F16="y"),I16," ") | AB16: =IF((F16="fa"),I16," ")
H17: =IF(G17<>0,G17*H$2/(100+H$2)," ") | I17: =IF((G17<>0),G17-H17," ") | M17: =IF(G17<>0,G17-L17," ") | N17: =IF((G17-L17)<>0,N$1-A17," ") | P17: =IF((F17="s"),I17," ") | Q17: =IF((F17="c"),I17," ") | R17: =IF((F17="o"),I17," ") | S17: =IF((F17="w"),I17," ") | T17: =IF((F17="p"),I17," ") | U17: =IF((F17="m"),I17," ") | V17: =IF((F17="g"),I17," ") | W17: =IF((F17="v"),I17," ") | X17: =IF((F17="h"),I17," ") | Y17: =IF((F17="a"),I17," ") | Z17: =IF((F17="l"),I17," ") | AA17: =IF((F17="y"),I17," ") | AB17: =IF((F17="fa"),I17," ")
... H68: =IF(G68<>0,G68*H$2/(100+H$2)," ") | I68: =IF((G68<>0),G68-H68," ") | M68: =IF(G68<>0,G68-L68," ") | N68: =IF((G68-L68)<>0,N$1-A68," ") | P68: =IF((F68="s"),I68," ") | Q68: =IF((F68="c"),I68," ") | R68: =IF((F68="o"),I68," ") | S68: =IF((F68="w"),I68," ") | T68: =IF((F68="p"),I68," ") | U68: =IF((F68="m"),I68," ") | V68: =IF((F68="g"),I68," ") | W68: =IF((F68="v"),I68," ") | X68: =IF((F68="h"),I68," ") | Y68: =IF((F68="a"),I68," ") | Z68: =IF((F68="l"),I68," ") | AA68: =IF((F68="y"),I68," ") | AB68: =IF((F68="fa"),I68," ")
F69: =IF((G69<>0),"Enter Letter"," ") | H69: =IF(G69<>0,G69*H$2/(100+H$2)," ") | I69: =IF((G69<>0),G69-H69," ") | M69: =IF(G69<>0,G69-L69," ") | N69: =IF((G69-L69)<>0,N$1-A69," ") | P69: =IF((F69="s"),I69," ") | Q69: =IF((F69="c"),I69," ") | R69: =IF((F69="o"),I69," ") | S69: =IF((F69="w"),I69," ") | T69: =IF((F69="p"),I69," ") | U69: =IF((F69="m"),I69," ") | V69: =IF((F69="g"),I69," ") | W69: =IF((F69="v"),I69," ") | X69: =IF((F69="h"),I69," ") | Y69: =IF((F69="a"),I69," ") | Z69: =IF((F69="l"),I69," ") | AA69: =IF((F69="y"),I69," ") | AB69: =IF((F69="fa"),I69," ")
F70: =IF((G70<>0),"Enter Letter"," ") | H70: =IF(G70<>0,G70*H$2/(100+H$2)," ") | I70: =IF((G70<>0),G70-H70," ") | M70: =IF(G70<>0,G70-L70," ") | N70: =IF((G70-L70)<>0,N$1-A70," ") | P70: =IF((F70="s"),I70," ") | Q70: =IF((F70="c"),I70," ") | R70: =IF((F70="o"),I70," ") | S70: =IF((F70="w"),I70," ") | T70: =IF((F70="p"),I70," ") | U70: =IF((F70="m"),I70," ") | V70: =IF((F70="g"),I70," ") | W70: =IF((F70="v"),I70," ") | X70: =IF((F70="h"),I70," ") | Y70: =IF((F70="a"),I70," ") | Z70: =IF((F70="l"),I70," ") | AA70: =IF((F70="y"),I70," ") | AB70: =IF((F70="fa"),I70," ")
F71: =IF((G71<>0),"Enter Letter"," ") | H71: =IF(G71<>0,G71*H$2/(100+H$2)," ") | I71: =IF((G71<>0),G71-H71," ") | M71: =IF(G71<>0,G71-L71," ") | N71: =IF((G71-L71)<>0,N$1-A71," ") | P71: =IF((F71="s"),I71," ") | Q71: =IF((F71="c"),I71," ") | R71: =IF((F71="o"),I71," ") | S71: =IF((F71="w"),I71," ") | T71: =IF((F71="p"),I71," ") | U71: =IF((F71="m"),I71," ") | V71: =IF((F71="g"),I71," ") | W71: =IF((F71="v"),I71," ") | X71: =IF((F71="h"),I71," ") | Y71: =IF((F71="a"),I71," ") | Z71: =IF((F71="l"),I71," ") | AA71: =IF((F71="y"),I71," ") | AB71: =IF((F71="fa"),I71," ")
F72: =IF((G72<>0),"Enter Letter"," ") | H72: =IF(G72<>0,G72*H$2/(100+H$2)," ") | I72: =IF((G72<>0),G72-H72," ") | M72: =IF(G72<>0,G72-L72," ") | N72: =IF((G72-L72)<>0,N$1-A72," ") | P72: =IF((F72="s"),I72," ") | Q72: =IF((F72="c"),I72," ") | R72: =IF((F72="o"),I72," ") | S72: =IF((F72="w"),I72," ") | T72: =IF((F72="p"),I72," ") | U72: =IF((F72="m"),I72," ") | V72: =IF((F72="g"),I72," ") | W72: =IF((F72="v"),I72," ") | X72: =IF((F72="h"),I72," ") | Y72: =IF((F72="a"),I72," ") | Z72: =IF((F72="l"),I72," ") | AA72: =IF((F72="y"),I72," ") | AB72: =IF((F72="fa"),I72," ")
F73: =IF((G73<>0),"Enter Letter"," ") | H73: =IF(G73<>0,G73*H$2/(100+H$2)," ") | I73: =IF((G73<>0),G73-H73," ") | M73: =IF(G73<>0,G73-L73," ") | N73: =IF((G73-L73)<>0,N$1-A73," ") | P73: =IF((F73="s"),I73," ") | Q73: =IF((F73="c"),I73," ") | R73: =IF((F73="o"),I73," ") | S73: =IF((F73="w"),I73," ") | T73: =IF((F73="p"),I73," ") | U73: =IF((F73="m"),I73," ") | V73: =IF((F73="g"),I73," ") | W73: =IF((F73="v"),I73," ") | X73: =IF((F73="h"),I73," ") | Y73: =IF((F73="a"),I73," ") | Z73: =IF((F73="l"),I73," ") | AA73: =IF((F73="y"),I73," ") | AB73: =IF((F73="fa"),I73," ")
F74: =IF((G74<>0),"Enter Letter"," ") | H74: =IF(G74<>0,G74*H$2/(100+H$2)," ") | I74: =IF((G74<>0),G74-H74," ") | M74: =IF(G74<>0,G74-L74," ") | N74: =IF((G74-L74)<>0,N$1-A74," ") | P74: =IF((F74="s"),I74," ") | Q74: =IF((F74="c"),I74," ") | R74: =IF((F74="o"),I74," ") | S74: =IF((F74="w"),I74," ") | T74: =IF((F74="p"),I74," ") | U74: =IF((F74="m"),I74," ") | V74: =IF((F74="g"),I74," ") | W74: =IF((F74="v"),I74," ") | X74: =IF((F74="h"),I74," ") | Y74: =IF((F74="a"),I74," ") | Z74: =IF((F74="l"),I74," ") | AA74: =IF((F74="y"),I74," ") | AB74: =IF((F74="fa"),I74," ")
F75: =IF((G75<>0),"Enter Letter"," ") | H75: =IF(G75<>0,G75*H$2/(100+H$2)," ") | I75: =IF((G75<>0),G75-H75," ") | M75: =IF(G75<>0,G75-L75," ") | N75: =IF((G75-L75)<>0,N$1-A75," ") | P75: =IF((F75="s"),I75," ") | Q75: =IF((F75="c"),I75," ") | R75: =IF((F75="o"),I75," ") | S75: =IF((F75="w"),I75," ") | T75: =IF((F75="p"),I75," ") | U75: =IF((F75="m"),I75," ") | V75: =IF((F75="g"),I75," ") | W75: =IF((F75="v"),I75," ") | X75: =IF((F75="h"),I75," ") | Y75: =IF((F75="a"),I75," ") | Z75: =IF((F75="l"),I75," ") | AA75: =IF((F75="y"),I75," ") | AB75: =IF((F75="fa"),I75," ")
F76: =IF((G76<>0),"Enter Letter"," ") | H76: =IF(G76<>0,G76*H$2/(100+H$2)," ") | I76: =IF((G76<>0),G76-H76," ") | M76: =IF(G76<>0,G76-L76," ") | N76: =IF((G76-L76)<>0,N$1-A76," ") | P76: =IF((F76="s"),I76," ") | Q76: =IF((F76="c"),I76," ") | R76: =IF((F76="o"),I76," ") | S76: =IF((F76="w"),I76," ") | T76: =IF((F76="p"),I76," ") | U76: =IF((F76="m"),I76," ") | V76: =IF((F76="g"),I76," ") | W76: =IF((F76="v"),I76," ") | X76: =IF((F76="h"),I76," ") | Y76: =IF((F76="a"),I76," ") | Z76: =IF((F76="l"),I76," ") | AA76: =IF((F76="y"),I76," ") | AB76: =IF((F76="fa"),I76," ")
F77: =IF((G77<>0),"Enter Letter"," ") | H77: =IF(G77<>0,G77*H$2/(100+H$2)," ") | I77: =IF((G77<>0),G77-H77," ") | M77: =IF(G77<>0,G77-L77," ") | N77: =IF((G77-L77)<>0,N$1-A77," ") | P77: =IF((F77="s"),I77," ") | Q77: =IF((F77="c"),I77," ") | R77: =IF((F77="o"),I77," ") | S77: =IF((F77="w"),I77," ") | T77: =IF((F77="p"),I77," ") | U77: =IF((F77="m"),I77," ") | V77: =IF((F77="g"),I77," ") | W77: =IF((F77="v"),I77," ") | X77: =IF((F77="h"),I77," ") | Y77: =IF((F77="a"),I77," ") | Z77: =IF((F77="l"),I77," ") | AA77: =IF((F77="y"),I77," ") | AB77: =IF((F77="fa"),I77," ")
