Workbook

Sheet OpenAccounts
C2: Company Name (including Limited) | J2: Registered Office Address | O2: Tax Reference per CT603 Notice
C3: Company registration number
C4: Telephone number (including STD Code)
C5: First Director's Name | O5: Loss brought forward
C6: Second Director's Name | L6: Postcode | O6: Franked investment income
C8: The principal activity of the company is | K8: If bank interest received Gross e.g. Co-op Enter X
C10: PREVIOUS YEAR BALANCE SHEET | E10: OPENING BALANCE SHEET | G10: Fixed Asset Original Cost | M10: Fixed Asset Accumulated Depreciation
B11: AUDIT CHECK | G11: Land & Buildings | H11: Plant & Machinery | I11: Fixtures & Fittings | J11: Computer Technology | K11: Motor Vehicles | M11: Land & Buildings | N11: Plant & Machinery | O11: Fixtures & Fittings | P11: Computer Technology | Q11: Motor Vehicles
C12: Fixed Assets
B13: =E13-G13-H13-I13-J13-K13+M13+N13+O13+P13+Q13 -> 0 | C13: Tangible assets (note 1)
C14: Current Assets
C15: Stock at cost
C16: Trade Debtors
G17: Current Account | H17: Savings Account | I17: Credit Card Account | J17: Cash Account
B18: =E18-G18-H18-I18-J18 -> 0 | C18: Cash and Bank Balances | K18: Enter all bank balances on this row. Enter accounts overdrawn as negative amounts.
C19: Current Liabilities
C20: Trade Creditors
C21: Net wages due
C22: Wage deductions due
C23: Dividends due
C24: Corporation Tax
G25: HMRC Paye | H25: HMRC Vat | I25: HMRC CIS
B26: =E26-G26-H26-I26 -> 0 | C26: Taxation and Social Security
C28: Long Term Debtors (3-5 years)
C29: Other Creditors
C30: Directors Loan Account
C31: Long Term Creditors (over 1 year)
C32: Capital and Reserves
C33: Called up share capital
C34: Retained Profit and Loss account
C35: Capital Reserves
C37: ACCURACY CHECK | E37: =E13+E15+E16+E18-E20-E21-E22-E23-E24-E26+E28-E30-E31-E33-E34-E35 -> 0
C41: PREVIOUS YEAR PROFIT & LOSS ACCOUNT
C43: Sales Turnover
C44: Investment Grants received
C45: Sales Turnover | G45: =SUM(E43:E44) -> 0
C46: Opening Stock
C47: Purchases
C48: Less Closing Stock | E48: =IF(COUNT(E43:E47,E49:E76,E80:E85)=0,0,E15) -> 0
C49: Sub contractors
...

Sheet TrialBalance
B1: www.diyaccounting.co.uk | C1: Acct Code Letter | D1: =Admin!B9 -> 45748 | F1: =Admin!B10 -> 45777 | O1: =F1 -> 45777 | Q1: =Admin!B12 -> 45808 | Z1: =Q1 -> 45808 | AB1: =Admin!B14 -> 45838 | AK1: =AB1 -> 45838 | AM1: =Admin!B16 -> 45869 | AV1: =AM1 -> 45869 | AX1: =Admin!B18 -> 45900 | BG1: =AX1 -> 45900 | BI1: =Admin!B20 -> 45930 | BR1: =BI1 -> 45930 | BT1: =Admin!B22 -> 45961 | CC1: =BT1 -> 45961 | CE1: =Admin!B24 -> 45991 | CN1: =CE1 -> 45991 | CP1: =Admin!B26 -> 46022 | CY1: =CP1 -> 46022 | DA1: =Admin!B28 -> 46053 | DJ1: =DA1 -> 46053 | DL1: =Admin!B30 -> 46081 | DU1: =DL1 -> 46081 | DW1: =Admin!B32 -> 46112 | EF1: =DW1 -> 46112 | EH1: Year End Accounting | EJ1: =EF1 -> 46112
B2: AUTOMATED TRIAL BALANCE | D2: Opening Balances | F2: Sales | G2: Purchases | H2: Bank Current | I2: Bank Savings | J2: Credit Card | K2: Cash Account | L2: Wages | M2: Monthly Accrual | O2: Closing Balances | Q2: Sales | R2: Purchases | S2: Bank Current | T2: Bank Savings | U2: Credit Card | V2: Cash Account | W2: Wages | X2: Monthly Accrual | Z2: Closing Balances | AB2: Sales | AC2: Purchases | AD2: Bank Current | AE2: Bank Savings | AF2: Credit Card | AG2: Cash Account | AH2: Wages | AI2: Monthly Accrual | AK2: Closing Balances | AM2: Sales | AN2: Purchases | AO2: Bank Current | AP2: Bank Savings | AQ2: Credit Card | AR2: Cash Account | AS2: Wages | AT2: Monthly Accrual | AV2: Closing Balances | AX2: Sales | AY2: Purchases | AZ2: Bank Current | BA2: Bank Savings | BB2: Credit Card | BC2: Cash Account | BD2: Wages | BE2: Monthly Accrual | BG2: Closing Balances | BI2: Sales | BJ2: Purchases | BK2: Bank Current | BL2: Bank Savings | BM2: Credit Card | BN2: Cash Account | BO2: Wages | BP2: Monthly Accrual | BR2: Closing Balances | BT2: Sales | BU2: Purchases | BV2: Bank Current | BW2: Bank Savings | BX2: Credit Card | BY2: Cash Account | BZ2: Wages | CA2: Monthly Accrual | CC2: Closing Balances | CE2: Sales | CF2: Purchases | CG2: Bank Current | CH2: Bank Savings | CI2: Credit Card | CJ2: Cash Account | CK2: Wages | CL2: Monthly Accrual | CN2: Closing Balances | CP2: Sales | CQ2: Purchases | CR2: Bank Current | CS2: Bank Savings | CT2: Credit Card | CU2: Cash Account | CV2: Wages | CW2: Monthly Accrual | CY2: Closing Balances | DA2: Sales | DB2: Purchases | DC2: Bank Current | DD2: Bank Savings | DE2: Credit Card | DF2: Cash Account | DG2: Wages | DH2: Monthly Accrual | DJ2: Closing Balances | DL2: Sales | DM2: Purchases | DN2: Bank Current | DO2: Bank Savings | DP2: Credit Card | DQ2: Cash Account | DR2: Wages | DS2: Monthly Accrual | DU2: Closing Balances | DW2: Sales | DX2: Purchases | DY2: Bank Current | DZ2: Bank Savings | EA2: Credit Card | EB2: Cash Account | EC2: Wages | ED2: Monthly Accrual | EF2: Closing Balances | EJ2: FINAL Balances
B4: BALANCE SHEET ITEMS
B5: FIXED ASSETS
B6: Fixed Asset Land & Property | C6: FL | D6: =OpenAccounts!G13 -> 0 | O6: =SUM(D6:N6) -> 0 | Z6: =SUM(O6:Y6) -> 0 | AK6: =SUM(Z6:AJ6) -> 0 | AV6: =SUM(AK6:AU6) -> 0 | BG6: =SUM(AV6:BF6) -> 0 | BR6: =SUM(BG6:BQ6) -> 0 | CC6: =SUM(BR6:CB6) -> 0 | CN6: =SUM(CC6:CM6) -> 0 | CY6: =SUM(CN6:CX6) -> 0 | DJ6: =SUM(CY6:DI6) -> 0 | DU6: =SUM(DJ6:DT6) -> 0 | EF6: =SUM(DU6:EE6) -> 0 | EH6: =[1]Schedule!$E$64-([1]Schedule!$W$11+[1]Schedule!$W$64) -> 0 | EJ6: =SUM(EF6:EH6) -> 0
B7: Fixed Asset Plant & Machinery | C7: FP | D7: =OpenAccounts!H13 -> 0 | O7: =SUM(D7:N7) -> 0 | Z7: =SUM(O7:Y7) -> 0 | AK7: =SUM(Z7:AJ7) -> 0 | AV7: =SUM(AK7:AU7) -> 0 | BG7: =SUM(AV7:BF7) -> 0 | BR7: =SUM(BG7:BQ7) -> 0 | CC7: =SUM(BR7:CB7) -> 0 | CN7: =SUM(CC7:CM7) -> 0 | CY7: =SUM(CN7:CX7) -> 0 | DJ7: =SUM(CY7:DI7) -> 0 | DU7: =SUM(DJ7:DT7) -> 0 | EF7: =SUM(DU7:EE7) -> 0 | EH7: =[1]Schedule!$E$75-([1]Schedule!$W$22+[1]Schedule!$W$75) -> 0 | EJ7: =SUM(EF7:EH7) -> 0
B8: Fixed Asset Fixtures & Fittings | C8: FF | D8: =OpenAccounts!I13 -> 0 | O8: =SUM(D8:N8) -> 0 | Z8: =SUM(O8:Y8) -> 0 | AK8: =SUM(Z8:AJ8) -> 0 | AV8: =SUM(AK8:AU8) -> 0 | BG8: =SUM(AV8:BF8) -> 0 | BR8: =SUM(BG8:BQ8) -> 0 | CC8: =SUM(BR8:CB8) -> 0 | CN8: =SUM(CC8:CM8) -> 0 | CY8: =SUM(CN8:CX8) -> 0 | DJ8: =SUM(CY8:DI8) -> 0 | DU8: =SUM(DJ8:DT8) -> 0 | EF8: =SUM(DU8:EE8) -> 0 | EH8: =[1]Schedule!$E$83-([1]Schedule!$W$30+[1]Schedule!$W$83) -> 0 | EJ8: =SUM(EF8:EH8) -> 0
B9: Fixed Asset Computers | C9: FC | D9: =OpenAccounts!J13 -> 0 | O9: =SUM(D9:N9) -> 0 | Z9: =SUM(O9:Y9) -> 0 | AK9: =SUM(Z9:AJ9) -> 0 | AV9: =SUM(AK9:AU9) -> 0 | BG9: =SUM(AV9:BF9) -> 0 | BR9: =SUM(BG9:BQ9) -> 0 | CC9: =SUM(BR9:CB9) -> 0 | CN9: =SUM(CC9:CM9) -> 0 | CY9: =SUM(CN9:CX9) -> 0 | DJ9: =SUM(CY9:DI9) -> 0 | DU9: =SUM(DJ9:DT9) -> 0 | EF9: =SUM(DU9:EE9) -> 0 | EH9: =[1]Schedule!$E$94-([1]Schedule!$W$41+[1]Schedule!$W$94) -> 0 | EJ9: =SUM(EF9:EH9) -> 0
B10: Fixed Asset Motor Vehicles | C10: FM | D10: =OpenAccounts!K13 -> 0 | O10: =SUM(D10:N10) -> 0 | Z10: =SUM(O10:Y10) -> 0 | AK10: =SUM(Z10:AJ10) -> 0 | AV10: =SUM(AK10:AU10) -> 0 | BG10: =SUM(AV10:BF10) -> 0 | BR10: =SUM(BG10:BQ10) -> 0 | CC10: =SUM(BR10:CB10) -> 0 | CN10: =SUM(CC10:CM10) -> 0 | CY10: =SUM(CN10:CX10) -> 0 | DJ10: =SUM(CY10:DI10) -> 0 | DU10: =SUM(DJ10:DT10) -> 0 | EF10: =SUM(DU10:EE10) -> 0 | EH10: =[1]Schedule!$E$108-([1]Schedule!$W$55+[1]Schedule!$W$108) -> 0 | EJ10: =SUM(EF10:EH10) -> 0
B11: Accumulated Depreciation Land & Property | D11: =-OpenAccounts!M13 -> 0 | M11: =-([1]Schedule!$I$11+[1]Schedule!$I$64)/12 -> 0 | O11: =SUM(D11:N11) -> 0 | X11: =-([1]Schedule!$I$11+[1]Schedule!$I$64)/12 -> 0 | Z11: =SUM(O11:Y11) -> 0 | AI11: =-([1]Schedule!$I$11+[1]Schedule!$I$64)/12 -> 0 | AK11: =SUM(Z11:AJ11) -> 0 | AT11: =-([1]Schedule!$I$11+[1]Schedule!$I$64)/12 -> 0 | AV11: =SUM(AK11:AU11) -> 0 | BE11: =-([1]Schedule!$I$11+[1]Schedule!$I$64)/12 -> 0 | BG11: =SUM(AV11:BF11) -> 0 | BP11: =-([1]Schedule!$I$11+[1]Schedule!$I$64)/12 -> 0 | BR11: =SUM(BG11:BQ11) -> 0 | CA11: =-([1]Schedule!$I$11+[1]Schedule!$I$64)/12 -> 0 | CC11: =SUM(BR11:CB11) -> 0 | CL11: =-([1]Schedule!$I$11+[1]Schedule!$I$64)/12 -> 0 | CN11: =SUM(CC11:CM11) -> 0 | CW11: =-([1]Schedule!$I$11+[1]Schedule!$I$64)/12 -> 0 | CY11: =SUM(CN11:CX11) -> 0 | DH11: =-([1]Schedule!$I$11+[1]Schedule!$I$64)/12 -> 0 | DJ11: =SUM(CY11:DI11) -> 0 | DS11: =-([1]Schedule!$I$11+[1]Schedule!$I$64)/12 -> 0 | DU11: =SUM(DJ11:DT11) -> 0 | ED11: =-([1]Schedule!$I$11+[1]Schedule!$I$64)/12 -> 0 | EF11: =SUM(DU11:EE11) -> 0 | EH11: =[1]Schedule!$X$11+[1]Schedule!$X$64 -> 0 | EJ11: =SUM(EF11:EH11) -> 0
B12: Accumulated Depreciation Plant & Machinery | D12: =-OpenAccounts!N13 -> 0 | M12: =-([1]Schedule!$I$22+[1]Schedule!$I$75)/12 -> 0 | O12: =SUM(D12:N12) -> 0 | X12: =-([1]Schedule!$I$22+[1]Schedule!$I$75)/12 -> 0 | Z12: =SUM(O12:Y12) -> 0 | AI12: =-([1]Schedule!$I$22+[1]Schedule!$I$75)/12 -> 0 | AK12: =SUM(Z12:AJ12) -> 0 | AT12: =-([1]Schedule!$I$22+[1]Schedule!$I$75)/12 -> 0 | AV12: =SUM(AK12:AU12) -> 0 | BE12: =-([1]Schedule!$I$22+[1]Schedule!$I$75)/12 -> 0 | BG12: =SUM(AV12:BF12) -> 0 | BP12: =-([1]Schedule!$I$22+[1]Schedule!$I$75)/12 -> 0 | BR12: =SUM(BG12:BQ12) -> 0 | CA12: =-([1]Schedule!$I$22+[1]Schedule!$I$75)/12 -> 0 | CC12: =SUM(BR12:CB12) -> 0 | CL12: =-([1]Schedule!$I$22+[1]Schedule!$I$75)/12 -> 0 | CN12: =SUM(CC12:CM12) -> 0 | CW12: =-([1]Schedule!$I$22+[1]Schedule!$I$75)/12 -> 0 | CY12: =SUM(CN12:CX12) -> 0 | DH12: =-([1]Schedule!$I$22+[1]Schedule!$I$75)/12 -> 0 | DJ12: =SUM(CY12:DI12) -> 0 | DS12: =-([1]Schedule!$I$22+[1]Schedule!$I$75)/12 -> 0 | DU12: =SUM(DJ12:DT12) -> 0 | ED12: =-([1]Schedule!$I$22+[1]Schedule!$I$75)/12 -> 0 | EF12: =SUM(DU12:EE12) -> 0 | EH12: =[1]Schedule!$X$22+[1]Schedule!$X$75 -> 0 | EJ12: =SUM(EF12:EH12) -> 0
B13: Accumulated Depreciation Fixtures & Fittings | D13: =-OpenAccounts!O13 -> 0 | M13: =-([1]Schedule!$I$30+[1]Schedule!$I$83)/12 -> 0 | O13: =SUM(D13:N13) -> 0 | X13: =-([1]Schedule!$I$30+[1]Schedule!$I$83)/12 -> 0 | Z13: =SUM(O13:Y13) -> 0 | AI13: =-([1]Schedule!$I$30+[1]Schedule!$I$83)/12 -> 0 | AK13: =SUM(Z13:AJ13) -> 0 | AT13: =-([1]Schedule!$I$30+[1]Schedule!$I$83)/12 -> 0 | AV13: =SUM(AK13:AU13) -> 0 | BE13: =-([1]Schedule!$I$30+[1]Schedule!$I$83)/12 -> 0 | BG13: =SUM(AV13:BF13) -> 0 | BP13: =-([1]Schedule!$I$30+[1]Schedule!$I$83)/12 -> 0 | BR13: =SUM(BG13:BQ13) -> 0 | CA13: =-([1]Schedule!$I$30+[1]Schedule!$I$83)/12 -> 0 | CC13: =SUM(BR13:CB13) -> 0 | CL13: =-([1]Schedule!$I$30+[1]Schedule!$I$83)/12 -> 0 | CN13: =SUM(CC13:CM13) -> 0 | CW13: =-([1]Schedule!$I$30+[1]Schedule!$I$83)/12 -> 0 | CY13: =SUM(CN13:CX13) -> 0 | DH13: =-([1]Schedule!$I$30+[1]Schedule!$I$83)/12 -> 0 | DJ13: =SUM(CY13:DI13) -> 0 | DS13: =-([1]Schedule!$I$30+[1]Schedule!$I$83)/12 -> 0 | DU13: =SUM(DJ13:DT13) -> 0 | ED13: =-([1]Schedule!$I$30+[1]Schedule!$I$83)/12 -> 0 | EF13: =SUM(DU13:EE13) -> 0 | EH13: =[1]Schedule!$X$30+[1]Schedule!$X$83 -> 0 | EJ13: =SUM(EF13:EH13) -> 0
B14: Accumulated Depreciation Computers | D14: =-OpenAccounts!P13 -> 0 | M14: =-([1]Schedule!$I$41+[1]Schedule!$I$94)/12 -> 0 | O14: =SUM(D14:N14) -> 0 | X14: =-([1]Schedule!$I$41+[1]Schedule!$I$94)/12 -> 0 | Z14: =SUM(O14:Y14) -> 0 | AI14: =-([1]Schedule!$I$41+[1]Schedule!$I$94)/12 -> 0 | AK14: =SUM(Z14:AJ14) -> 0 | AT14: =-([1]Schedule!$I$41+[1]Schedule!$I$94)/12 -> 0 | AV14: =SUM(AK14:AU14) -> 0 | BE14: =-([1]Schedule!$I$41+[1]Schedule!$I$94)/12 -> 0 | BG14: =SUM(AV14:BF14) -> 0 | BP14: =-([1]Schedule!$I$41+[1]Schedule!$I$94)/12 -> 0 | BR14: =SUM(BG14:BQ14) -> 0 | CA14: =-([1]Schedule!$I$41+[1]Schedule!$I$94)/12 -> 0 | CC14: =SUM(BR14:CB14) -> 0 | CL14: =-([1]Schedule!$I$41+[1]Schedule!$I$94)/12 -> 0 | CN14: =SUM(CC14:CM14) -> 0 | CW14: =-([1]Schedule!$I$41+[1]Schedule!$I$94)/12 -> 0 | CY14: =SUM(CN14:CX14) -> 0 | DH14: =-([1]Schedule!$I$41+[1]Schedule!$I$94)/12 -> 0 | DJ14: =SUM(CY14:DI14) -> 0 | DS14: =-([1]Schedule!$I$41+[1]Schedule!$I$94)/12 -> 0 | DU14: =SUM(DJ14:DT14) -> 0 | ED14: =-([1]Schedule!$I$41+[1]Schedule!$I$94)/12 -> 0 | EF14: =SUM(DU14:EE14) -> 0 | EH14: =[1]Schedule!$X$41+[1]Schedule!$X$94 -> 0 | EJ14: =SUM(EF14:EH14) -> 0
B15: Accumulated Depreciation Motor Vehicles | D15: =-OpenAccounts!Q13 -> 0 | M15: =-([1]Schedule!$I$55+[1]Schedule!$I$108)/12 -> 0 | O15: =SUM(D15:N15) -> 0 | X15: =-([1]Schedule!$I$55+[1]Schedule!$I$108)/12 -> 0 | Z15: =SUM(O15:Y15) -> 0 | AI15: =-([1]Schedule!$I$55+[1]Schedule!$I$108)/12 -> 0 | AK15: =SUM(Z15:AJ15) -> 0 | AT15: =-([1]Schedule!$I$55+[1]Schedule!$I$108)/12 -> 0 | AV15: =SUM(AK15:AU15) -> 0 | BE15: =-([1]Schedule!$I$55+[1]Schedule!$I$108)/12 -> 0 | BG15: =SUM(AV15:BF15) -> 0 | BP15: =-([1]Schedule!$I$55+[1]Schedule!$I$108)/12 -> 0 | BR15: =SUM(BG15:BQ15) -> 0 | CA15: =-([1]Schedule!$I$55+[1]Schedule!$I$108)/12 -> 0 | CC15: =SUM(BR15:CB15) -> 0 | CL15: =-([1]Schedule!$I$55+[1]Schedule!$I$108)/12 -> 0 | CN15: =SUM(CC15:CM15) -> 0 | CW15: =-([1]Schedule!$I$55+[1]Schedule!$I$108)/12 -> 0 | CY15: =SUM(CN15:CX15) -> 0 | DH15: =-([1]Schedule!$I$55+[1]Schedule!$I$108)/12 -> 0 | DJ15: =SUM(CY15:DI15) -> 0 | DS15: =-([1]Schedule!$I$55+[1]Schedule!$I$108)/12 -> 0 | DU15: =SUM(DJ15:DT15) -> 0 | ED15: =-([1]Schedule!$I$55+[1]Schedule!$I$108)/12 -> 0 | EF15: =SUM(DU15:EE15) -> 0 | EH15: =[1]Schedule!$X$55+[1]Schedule!$X$108 -> 0 | EJ15: =SUM(EF15:EH15) -> 0
B16: Fixed Asset Additions accrued | G16: =[2]Apr!$AI$1 -> 0 | O16: =SUM(D16:N16) -> 0 | R16: =[2]May!$AI$1 -> 0 | Z16: =SUM(O16:Y16) -> 0 | AC16: =[2]Jun!$AI$1 -> 0 | AK16: =SUM(Z16:AJ16) -> 0 | AN16: =[2]Jul!$AI$1 -> 0 | AV16: =SUM(AK16:AU16) -> 0 | AY16: =[2]Aug!$AI$1 -> 0 | BG16: =SUM(AV16:BF16) -> 0 | BJ16: =[2]Sep!$AI$1 -> 0 | BR16: =SUM(BG16:BQ16) -> 0 | BU16: =[2]Oct!$AI$1 -> 0 | CC16: =SUM(BR16:CB16) -> 0 | CF16: =[2]Nov!$AI$1 -> 0 | CN16: =SUM(CC16:CM16) -> 0 | CQ16: =[2]Dec!$AI$1 -> 0 | CY16: =SUM(CN16:CX16) -> 0 | DB16: =[2]Jan!$AI$1 -> 0 | DJ16: =SUM(CY16:DI16) -> 0 | DM16: =[2]Feb!$AI$1 -> 0 | DU16: =SUM(DJ16:DT16) -> 0 | DX16: =[2]Mar!$AI$1 -> 0 | EF16: =SUM(DU16:EE16) -> 0 | EH16: =-[1]Schedule!$E$110 -> 0 | EJ16: =SUM(EF16:EH16) -> 0
B17: Fixed Asset Disposal Value accrued | C17: FS | F17: =-[3]Apr!$U$1 -> 0 | M17: =-(([1]Schedule!$W$1-[1]Schedule!$X$1-[1]Schedule!$V$1)/12) -> 0 | O17: =SUM(D17:N17) -> 0 | Q17: =-[3]May!$U$1 -> 0 | X17: =-(([1]Schedule!$W$1-[1]Schedule!$X$1-[1]Schedule!$V$1)/12) -> 0 | Z17: =SUM(O17:Y17) -> 0 | AB17: =-[3]Jun!$U$1 -> 0 | AI17: =-(([1]Schedule!$W$1-[1]Schedule!$X$1-[1]Schedule!$V$1)/12) -> 0 | AK17: =SUM(Z17:AJ17) -> 0 | AM17: =-[3]Jul!$U$1 -> 0 | AT17: =-(([1]Schedule!$W$1-[1]Schedule!$X$1-[1]Schedule!$V$1)/12) -> 0 | AV17: =SUM(AK17:AU17) -> 0 | AX17: =-[3]Aug!$U$1 -> 0 | BE17: =-(([1]Schedule!$W$1-[1]Schedule!$X$1-[1]Schedule!$V$1)/12) -> 0 | BG17: =SUM(AV17:BF17) -> 0 | BI17: =-[3]Sep!$U$1 -> 0 | BP17: =-(([1]Schedule!$W$1-[1]Schedule!$X$1-[1]Schedule!$V$1)/12) -> 0 | BR17: =SUM(BG17:BQ17) -> 0 | BT17: =-[3]Oct!$U$1 -> 0 | CA17: =-(([1]Schedule!$W$1-[1]Schedule!$X$1-[1]Schedule!$V$1)/12) -> 0 | CC17: =SUM(BR17:CB17) -> 0 | CE17: =-[3]Nov!$U$1 -> 0 | CL17: =-(([1]Schedule!$W$1-[1]Schedule!$X$1-[1]Schedule!$V$1)/12) -> 0 | CN17: =SUM(CC17:CM17) -> 0 | CP17: =-[3]Dec!$U$1 -> 0 | CW17: =-(([1]Schedule!$W$1-[1]Schedule!$X$1-[1]Schedule!$V$1)/12) -> 0 | CY17: =SUM(CN17:CX17) -> 0 | DA17: =-[3]Jan!$U$1 -> 0 | DH17: =-(([1]Schedule!$W$1-[1]Schedule!$X$1-[1]Schedule!$V$1)/12) -> 0 | DJ17: =SUM(CY17:DI17) -> 0 | DL17: =-[3]Feb!$U$1 -> 0 | DS17: =-(([1]Schedule!$W$1-[1]Schedule!$X$1-[1]Schedule!$V$1)/12) -> 0 | DU17: =SUM(DJ17:DT17) -> 0 | DW17: =-[3]Mar!$U$1 -> 0 | ED17: =-(([1]Schedule!$W$1-[1]Schedule!$X$1-[1]Schedule!$V$1)/12) -> 0 | EF17: =SUM(DU17:EE17) -> 0 | EH17: =[1]Schedule!$W$1-[1]Schedule!$X$1 -> 0 | EJ17: =SUM(EF17:EH17) -> 0
B18: CURRENT ASSETS
B19: Stock | D19: =OpenAccounts!E15 -> 0 | M19: =Stock!$F$8-Stock!$L$8-Stock!$R$8-Stock!$X$8+Stock!$Z$8 -> 0 | O19: =SUM(D19:N19) -> 0 | X19: =Stock!$F$10-Stock!$L$10-Stock!$R$10-Stock!$X$10+Stock!$Z$10 -> 0 | Z19: =SUM(O19:Y19) -> 0 | AI19: =Stock!$F$12-Stock!$L$12-Stock!$R$12-Stock!$X$12+Stock!$Z$12 -> 0 | AK19: =SUM(Z19:AJ19) -> 0 | AT19: =Stock!$F$14-Stock!$L$14-Stock!$R$14-Stock!$X$14+Stock!$Z$14 -> 0 | AV19: =SUM(AK19:AU19) -> 0 | BE19: =Stock!$F$16-Stock!$L$16-Stock!$R$16-Stock!$X$16+Stock!$Z$16 -> 0 | BG19: =SUM(AV19:BF19) -> 0 | BP19: =Stock!$F$18-Stock!$L$18-Stock!$R$18-Stock!$X$18+Stock!$Z$18 -> 0 | BR19: =SUM(BG19:BQ19) -> 0 | CA19: =Stock!$F$20-Stock!$L$20-Stock!$R$20-Stock!$X$20+Stock!$Z$20 -> 0 | CC19: =SUM(BR19:CB19) -> 0 | CL19: =Stock!$F$22-Stock!$L$22-Stock!$R$22-Stock!$X$22+Stock!$Z$22 -> 0 | CN19: =SUM(CC19:CM19) -> 0 | CW19: =Stock!$F$24-Stock!$L$24-Stock!$R$24-Stock!$X$24+Stock!$Z$24 -> 0 | CY19: =SUM(CN19:CX19) -> 0 | DH19: =Stock!$F$26-Stock!$L$26-Stock!$R$26-Stock!$X$26+Stock!$Z$26 -> 0 | DJ19: =SUM(CY19:DI19) -> 0 | DS19: =Stock!$F$28-Stock!$L$28-Stock!$R$28-Stock!$X$28+Stock!$Z$28 -> 0 | DU19: =SUM(DJ19:DT19) -> 0 | ED19: =Stock!$F$30-Stock!$L$30-Stock!$R$30-Stock!$X$30+Stock!$Z$30 -> 0 | EF19: =SUM(DU19:EE19) -> 0 | EJ19: =SUM(EF19:EH19) -> 0
B20: Trade Debtors | C20: DR | D20: =OpenAccounts!E16 -> 0 | F20: =[3]Apr!$F$1-[3]Apr!$V$1 -> 0 | H20: =-[4]Apr!$J$1 -> 0 | I20: =-[5]Apr!$J$1 -> 0 | J20: =-[6]Apr!$J$1 -> 0 | K20: =-[7]Apr!$J$1 -> 0 | O20: =SUM(D20:N20) -> 0 | Q20: =[3]May!$F$1-[3]May!$V$1 -> 0 | S20: =-[4]May!$J$1 -> 0 | T20: =-[5]May!$J$1 -> 0 | U20: =-[6]May!$J$1 -> 0 | V20: =-[7]May!$J$1 -> 0 | Z20: =SUM(O20:Y20) -> 0 | AB20: =[3]Jun!$F$1-[3]Jun!$V$1 -> 0 | AD20: =-[4]Jun!$J$1 -> 0 | AE20: =-[5]Jun!$J$1 -> 0 | AF20: =-[6]Jun!$J$1 -> 0 | AG20: =-[7]Jun!$J$1 -> 0 | AK20: =SUM(Z20:AJ20) -> 0 | AM20: =[3]Jul!$F$1-[3]Jul!$V$1 -> 0 | AO20: =-[4]Jul!$J$1 -> 0 | AP20: =-[5]Jul!$J$1 -> 0 | AQ20: =-[6]Jul!$J$1 -> 0 | AR20: =-[7]Jul!$J$1 -> 0 | AV20: =SUM(AK20:AU20) -> 0 | AX20: =[3]Aug!$F$1-[3]Aug!$V$1 -> 0 | AZ20: =-[4]Aug!$J$1 -> 0 | BA20: =-[5]Aug!$J$1 -> 0 | BB20: =-[6]Aug!$J$1 -> 0 | BC20: =-[7]Aug!$J$1 -> 0 | BG20: =SUM(AV20:BF20) -> 0 | BI20: =[3]Sep!$F$1-[3]Sep!$V$1 -> 0 | BK20: =-[4]Sep!$J$1 -> 0 | BL20: =-[5]Sep!$J$1 -> 0 | BM20: =-[6]Sep!$J$1 -> 0 | BN20: =-[7]Sep!$J$1 -> 0 | BR20: =SUM(BG20:BQ20) -> 0 | BT20: =[3]Oct!$F$1-[3]Oct!$V$1 -> 0 | BV20: =-[4]Oct!$J$1 -> 0 | BW20: =-[5]Oct!$J$1 -> 0 | BX20: =-[6]Oct!$J$1 -> 0 | BY20: =-[7]Oct!$J$1 -> 0 | CC20: =SUM(BR20:CB20) -> 0 | CE20: =[3]Nov!$F$1-[3]Nov!$V$1 -> 0 | CG20: =-[4]Nov!$J$1 -> 0 | CH20: =-[5]Nov!$J$1 -> 0 | CI20: =-[6]Nov!$J$1 -> 0 | CJ20: =-[7]Nov!$J$1 -> 0 | CN20: =SUM(CC20:CM20) -> 0 | CP20: =[3]Dec!$F$1-[3]Dec!$V$1 -> 0 | CR20: =-[4]Dec!$J$1 -> 0 | CS20: =-[5]Dec!$J$1 -> 0 | CT20: =-[6]Dec!$J$1 -> 0 | CU20: =-[7]Dec!$J$1 -> 0 | CY20: =SUM(CN20:CX20) -> 0 | DA20: =[3]Jan!$F$1-[3]Jan!$V$1 -> 0 | DC20: =-[4]Jan!$J$1 -> 0 | DD20: =-[5]Jan!$J$1 -> 0 | DE20: =-[6]Jan!$J$1 -> 0 | DF20: =-[7]Jan!$J$1 -> 0 | DJ20: =SUM(CY20:DI20) -> 0 | DL20: =[3]Feb!$F$1-[3]Feb!$V$1 -> 0 | DN20: =-[4]Feb!$J$1 -> 0 | DO20: =-[5]Feb!$J$1 -> 0 | DP20: =-[6]Feb!$J$1 -> 0 | DQ20: =-[7]Feb!$J$1 -> 0 | DU20: =SUM(DJ20:DT20) -> 0 | DW20: =[3]Mar!$F$1-[3]Mar!$V$1 -> 0 | DY20: =-[4]Mar!$J$1 -> 0 | DZ20: =-[5]Mar!$J$1 -> 0 | EA20: =-[6]Mar!$J$1 -> 0 | EB20: =-[7]Mar!$J$1 -> 0 | EF20: =SUM(DU20:EE20) -> 0 | EJ20: =SUM(EF20:EH20) -> 0
B21: Cash & Bank Receipts
B22: Bank Current Account | C22: BB | D22: =OpenAccounts!G18 -> 0 | H22: =[4]Apr!$F$1-[4]Apr!$X$1 -> 0 | O22: =SUM(D22:N22) -> 0 | S22: =[4]May!$F$1-[4]May!$X$1 -> 0 | Z22: =SUM(O22:Y22) -> 0 | AD22: =[4]Jun!$F$1-[4]Jun!$X$1 -> 0 | AK22: =SUM(Z22:AJ22) -> 0 | AO22: =[4]Jul!$F$1-[4]Jul!$X$1 -> 0 | AV22: =SUM(AK22:AU22) -> 0 | AZ22: =[4]Aug!$F$1-[4]Aug!$X$1 -> 0 | BG22: =SUM(AV22:BF22) -> 0 | BK22: =[4]Sep!$F$1-[4]Sep!$X$1 -> 0 | BR22: =SUM(BG22:BQ22) -> 0 | BV22: =[4]Oct!$F$1-[4]Oct!$X$1 -> 0 | CC22: =SUM(BR22:CB22) -> 0 | CG22: =[4]Nov!$F$1-[4]Nov!$X$1 -> 0 | CN22: =SUM(CC22:CM22) -> 0 | CR22: =[4]Dec!$F$1-[4]Dec!$X$1 -> 0 | CY22: =SUM(CN22:CX22) -> 0 | DC22: =[4]Jan!$F$1-[4]Jan!$X$1 -> 0 | DJ22: =SUM(CY22:DI22) -> 0 | DN22: =[4]Feb!$F$1-[4]Feb!$X$1 -> 0 | DU22: =SUM(DJ22:DT22) -> 0 | DY22: =[4]Mar!$F$1-[4]Mar!$X$1 -> 0 | EF22: =SUM(DU22:EE22) -> 0 | EJ22: =SUM(EF22:EH22) -> 0
B23: Bank Savings Account | C23: BS | D23: =OpenAccounts!H18 -> 0 | I23: =[5]Apr!$F$1-[5]Apr!$X$1 -> 0 | O23: =SUM(D23:N23) -> 0 | T23: =[5]May!$F$1-[5]May!$X$1 -> 0 | Z23: =SUM(O23:Y23) -> 0 | AE23: =[5]Jun!$F$1-[5]Jun!$X$1 -> 0 | AK23: =SUM(Z23:AJ23) -> 0 | AP23: =[5]Jul!$F$1-[5]Jul!$X$1 -> 0 | AV23: =SUM(AK23:AU23) -> 0 | BA23: =[5]Aug!$F$1-[5]Aug!$X$1 -> 0 | BG23: =SUM(AV23:BF23) -> 0 | BL23: =[5]Sep!$F$1-[5]Sep!$X$1 -> 0 | BR23: =SUM(BG23:BQ23) -> 0 | BW23: =[5]Oct!$F$1-[5]Oct!$X$1 -> 0 | CC23: =SUM(BR23:CB23) -> 0 | CH23: =[5]Nov!$F$1-[5]Nov!$X$1 -> 0 | CN23: =SUM(CC23:CM23) -> 0 | CS23: =[5]Dec!$F$1-[5]Dec!$X$1 -> 0 | CY23: =SUM(CN23:CX23) -> 0 | DD23: =[5]Jan!$F$1-[5]Jan!$X$1 -> 0 | DJ23: =SUM(CY23:DI23) -> 0 | DO23: =[5]Feb!$F$1-[5]Feb!$X$1 -> 0 | DU23: =SUM(DJ23:DT23) -> 0 | DZ23: =[5]Mar!$F$1-[5]Mar!$X$1 -> 0 | EF23: =SUM(DU23:EE23) -> 0 | EJ23: =SUM(EF23:EH23) -> 0
B24: Credit Card Account | C24: BD | D24: =OpenAccounts!I18 -> 0 | J24: =[6]Apr!$F$1-[6]Apr!$X$1 -> 0 | O24: =SUM(D24:N24) -> 0 | U24: =[6]May!$F$1-[6]May!$X$1 -> 0 | Z24: =SUM(O24:Y24) -> 0 | AF24: =[6]Jun!$F$1-[6]Jun!$X$1 -> 0 | AK24: =SUM(Z24:AJ24) -> 0 | AQ24: =[6]Jul!$F$1-[6]Jul!$X$1 -> 0 | AV24: =SUM(AK24:AU24) -> 0 | BB24: =[6]Aug!$F$1-[6]Aug!$X$1 -> 0 | BG24: =SUM(AV24:BF24) -> 0 | BM24: =[6]Sep!$F$1-[6]Sep!$X$1 -> 0 | BR24: =SUM(BG24:BQ24) -> 0 | BX24: =[6]Oct!$F$1-[6]Oct!$X$1 -> 0 | CC24: =SUM(BR24:CB24) -> 0 | CI24: =[6]Nov!$F$1-[6]Nov!$X$1 -> 0 | CN24: =SUM(CC24:CM24) -> 0 | CT24: =[6]Dec!$F$1-[6]Dec!$X$1 -> 0 | CY24: =SUM(CN24:CX24) -> 0 | DE24: =[6]Jan!$F$1-[6]Jan!$X$1 -> 0 | DJ24: =SUM(CY24:DI24) -> 0 | DP24: =[6]Feb!$F$1-[6]Feb!$X$1 -> 0 | DU24: =SUM(DJ24:DT24) -> 0 | EA24: =[6]Mar!$F$1-[6]Mar!$X$1 -> 0 | EF24: =SUM(DU24:EE24) -> 0 | EJ24: =SUM(EF24:EH24) -> 0
B25: Cash Account | C25: BC | D25: =OpenAccounts!J18 -> 0 | K25: =[7]Apr!$F$1-[7]Apr!$U$1 -> 0 | O25: =SUM(D25:N25) -> 0 | V25: =[7]May!$F$1-[7]May!$U$1 -> 0 | Z25: =SUM(O25:Y25) -> 0 | AG25: =[7]Jun!$F$1-[7]Jun!$U$1 -> 0 | AK25: =SUM(Z25:AJ25) -> 0 | AR25: =[7]Jul!$F$1-[7]Jul!$U$1 -> 0 | AV25: =SUM(AK25:AU25) -> 0 | BC25: =[7]Aug!$F$1-[7]Aug!$U$1 -> 0 | BG25: =SUM(AV25:BF25) -> 0 | BN25: =[7]Sep!$F$1-[7]Sep!$U$1 -> 0 | BR25: =SUM(BG25:BQ25) -> 0 | BY25: =[7]Oct!$F$1-[7]Oct!$U$1 -> 0 | CC25: =SUM(BR25:CB25) -> 0 | CJ25: =[7]Nov!$F$1-[7]Nov!$U$1 -> 0 | CN25: =SUM(CC25:CM25) -> 0 | CU25: =[7]Dec!$F$1-[7]Dec!$U$1 -> 0 | CY25: =SUM(CN25:CX25) -> 0 | DF25: =[7]Jan!$F$1-[7]Jan!$U$1 -> 0 | DJ25: =SUM(CY25:DI25) -> 0 | DQ25: =[7]Feb!$F$1-[7]Feb!$U$1 -> 0 | DU25: =SUM(DJ25:DT25) -> 0 | EB25: =[7]Mar!$F$1-[7]Mar!$U$1 -> 0 | EF25: =SUM(DU25:EE25) -> 0 | EH25: =[8]Boardmeeting!$E$6 -> 0 | EJ25: =SUM(EF25:EH25) -> 0
B26: Intra Cash & Bank Transfers | D26: 0 | H26: =-[4]Apr!$G$1-[4]Apr!$H$1-[4]Apr!$I$1+[4]Apr!$Y$1+[4]Apr!$Z$1+[4]Apr!$AA$1 -> 0 | I26: =-[5]Apr!$G$1-[5]Apr!$H$1-[5]Apr!$I$1+[5]Apr!$Y$1+[5]Apr!$Z$1+[5]Apr!$AA$1 -> 0 | J26: =-[6]Apr!$G$1-[6]Apr!$H$1-[6]Apr!$I$1+[6]Apr!$Y$1+[6]Apr!$Z$1+[6]Apr!$AA$1 -> 0 | K26: =-[7]Apr!$G$1-[7]Apr!$H$1-[7]Apr!$I$1+[7]Apr!$V$1+[7]Apr!$W$1+[7]Apr!$X$1 -> 0 | O26: =SUM(D26:N26) -> 0 | S26: =-[4]May!$G$1-[4]May!$H$1-[4]May!$I$1+[4]May!$Y$1+[4]May!$Z$1+[4]May!$AA$1 -> 0 | T26: =-[5]May!$G$1-[5]May!$H$1-[5]May!$I$1+[5]May!$Y$1+[5]May!$Z$1+[5]May!$AA$1 -> 0 | U26: =-[6]May!$G$1-[6]May!$H$1-[6]May!$I$1+[6]May!$Y$1+[6]May!$Z$1+[6]May!$AA$1 -> 0 | V26: =-[7]May!$G$1-[7]May!$H$1-[7]May!$I$1+[7]May!$V$1+[7]May!$W$1+[7]May!$X$1 -> 0 | Z26: =SUM(O26:Y26) -> 0 | AD26: =-[4]Jun!$G$1-[4]Jun!$H$1-[4]Jun!$I$1+[4]Jun!$Y$1+[4]Jun!$Z$1+[4]Jun!$AA$1 -> 0 | AE26: =-[5]Jun!$G$1-[5]Jun!$H$1-[5]Jun!$I$1+[5]Jun!$Y$1+[5]Jun!$Z$1+[5]Jun!$AA$1 -> 0 | AF26: =-[6]Jun!$G$1-[6]Jun!$H$1-[6]Jun!$I$1+[6]Jun!$Y$1+[6]Jun!$Z$1+[6]Jun!$AA$1 -> 0 | AG26: =-[7]Jun!$G$1-[7]Jun!$H$1-[7]Jun!$I$1+[7]Jun!$V$1+[7]Jun!$W$1+[7]Jun!$X$1 -> 0 | AK26: =SUM(Z26:AJ26) -> 0 | AO26: =-[4]Jul!$G$1-[4]Jul!$H$1-[4]Jul!$I$1+[4]Jul!$Y$1+[4]Jul!$Z$1+[4]Jul!$AA$1 -> 0 | AP26: =-[5]Jul!$G$1-[5]Jul!$H$1-[5]Jul!$I$1+[5]Jul!$Y$1+[5]Jul!$Z$1+[5]Jul!$AA$1 -> 0 | AQ26: =-[6]Jul!$G$1-[6]Jul!$H$1-[6]Jul!$I$1+[6]Jul!$Y$1+[6]Jul!$Z$1+[6]Jul!$AA$1 -> 0 | AR26: =-[7]Jul!$G$1-[7]Jul!$H$1-[7]Jul!$I$1+[7]Jul!$V$1+[7]Jul!$W$1+[7]Jul!$X$1 -> 0 | AV26: =SUM(AK26:AU26) -> 0 | AZ26: =-[4]Aug!$G$1-[4]Aug!$H$1-[4]Aug!$I$1+[4]Aug!$Y$1+[4]Aug!$Z$1+[4]Aug!$AA$1 -> 0 | BA26: =-[5]Aug!$G$1-[5]Aug!$H$1-[5]Aug!$I$1+[5]Aug!$Y$1+[5]Aug!$Z$1+[5]Aug!$AA$1 -> 0 | BB26: =-[6]Aug!$G$1-[6]Aug!$H$1-[6]Aug!$I$1+[6]Aug!$Y$1+[6]Aug!$Z$1+[6]Aug!$AA$1 -> 0 | BC26: =-[7]Aug!$G$1-[7]Aug!$H$1-[7]Aug!$I$1+[7]Aug!$V$1+[7]Aug!$W$1+[7]Aug!$X$1 -> 0 | BG26: =SUM(AV26:BF26) -> 0 | BK26: =-[4]Sep!$G$1-[4]Sep!$H$1-[4]Sep!$I$1+[4]Sep!$Y$1+[4]Sep!$Z$1+[4]Sep!$AA$1 -> 0 | BL26: =-[5]Sep!$G$1-[5]Sep!$H$1-[5]Sep!$I$1+[5]Sep!$Y$1+[5]Sep!$Z$1+[5]Sep!$AA$1 -> 0 | BM26: =-[6]Sep!$G$1-[6]Sep!$H$1-[6]Sep!$I$1+[6]Sep!$Y$1+[6]Sep!$Z$1+[6]Sep!$AA$1 -> 0 | BN26: =-[7]Sep!$G$1-[7]Sep!$H$1-[7]Sep!$I$1+[7]Sep!$V$1+[7]Sep!$W$1+[7]Sep!$X$1 -> 0 | BR26: =SUM(BG26:BQ26) -> 0 | BV26: =-[4]Oct!$G$1-[4]Oct!$H$1-[4]Oct!$I$1+[4]Oct!$Y$1+[4]Oct!$Z$1+[4]Oct!$AA$1 -> 0 | BW26: =-[5]Oct!$G$1-[5]Oct!$H$1-[5]Oct!$I$1+[5]Oct!$Y$1+[5]Oct!$Z$1+[5]Oct!$AA$1 -> 0 | BX26: =-[6]Oct!$G$1-[6]Oct!$H$1-[6]Oct!$I$1+[6]Oct!$Y$1+[6]Oct!$Z$1+[6]Oct!$AA$1 -> 0 | BY26: =-[7]Oct!$G$1-[7]Oct!$H$1-[7]Oct!$I$1+[7]Oct!$V$1+[7]Oct!$W$1+[7]Oct!$X$1 -> 0 | CC26: =SUM(BR26:CB26) -> 0 | CG26: =-[4]Nov!$G$1-[4]Nov!$H$1-[4]Nov!$I$1+[4]Nov!$Y$1+[4]Nov!$Z$1+[4]Nov!$AA$1 -> 0 | CH26: =-[5]Nov!$G$1-[5]Nov!$H$1-[5]Nov!$I$1+[5]Nov!$Y$1+[5]Nov!$Z$1+[5]Nov!$AA$1 -> 0 | CI26: =-[6]Nov!$G$1-[6]Nov!$H$1-[6]Nov!$I$1+[6]Nov!$Y$1+[6]Nov!$Z$1+[6]Nov!$AA$1 -> 0 | CJ26: =-[7]Nov!$G$1-[7]Nov!$H$1-[7]Nov!$I$1+[7]Nov!$V$1+[7]Nov!$W$1+[7]Nov!$X$1 -> 0 | CN26: =SUM(CC26:CM26) -> 0 | CR26: =-[4]Dec!$G$1-[4]Dec!$H$1-[4]Dec!$I$1+[4]Dec!$Y$1+[4]Dec!$Z$1+[4]Dec!$AA$1 -> 0 | CS26: =-[5]Dec!$G$1-[5]Dec!$H$1-[5]Dec!$I$1+[5]Dec!$Y$1+[5]Dec!$Z$1+[5]Dec!$AA$1 -> 0 | CT26: =-[6]Dec!$G$1-[6]Dec!$H$1-[6]Dec!$I$1+[6]Dec!$Y$1+[6]Dec!$Z$1+[6]Dec!$AA$1 -> 0 | CU26: =-[7]Dec!$G$1-[7]Dec!$H$1-[7]Dec!$I$1+[7]Dec!$V$1+[7]Dec!$W$1+[7]Dec!$X$1 -> 0 | CY26: =SUM(CN26:CX26) -> 0 | DC26: =-[4]Jan!$G$1-[4]Jan!$H$1-[4]Jan!$I$1+[4]Jan!$Y$1+[4]Jan!$Z$1+[4]Jan!$AA$1 -> 0 | DD26: =-[5]Jan!$G$1-[5]Jan!$H$1-[5]Jan!$I$1+[5]Jan!$Y$1+[5]Jan!$Z$1+[5]Jan!$AA$1 -> 0 | DE26: =-[6]Jan!$G$1-[6]Jan!$H$1-[6]Jan!$I$1+[6]Jan!$Y$1+[6]Jan!$Z$1+[6]Jan!$AA$1 -> 0 | DF26: =-[7]Jan!$G$1-[7]Jan!$H$1-[7]Jan!$I$1+[7]Jan!$V$1+[7]Jan!$W$1+[7]Jan!$X$1 -> 0 | DJ26: =SUM(CY26:DI26) -> 0 | DN26: =-[4]Feb!$G$1-[4]Feb!$H$1-[4]Feb!$I$1+[4]Feb!$Y$1+[4]Feb!$Z$1+[4]Feb!$AA$1 -> 0 | DO26: =-[5]Feb!$G$1-[5]Feb!$H$1-[5]Feb!$I$1+[5]Feb!$Y$1+[5]Feb!$Z$1+[5]Feb!$AA$1 -> 0 | DP26: =-[6]Feb!$G$1-[6]Feb!$H$1-[6]Feb!$I$1+[6]Feb!$Y$1+[6]Feb!$Z$1+[6]Feb!$AA$1 -> 0 | DQ26: =-[7]Feb!$G$1-[7]Feb!$H$1-[7]Feb!$I$1+[7]Feb!$V$1+[7]Feb!$W$1+[7]Feb!$X$1 -> 0 | DU26: =SUM(DJ26:DT26) -> 0 | DY26: =-[4]Mar!$G$1-[4]Mar!$H$1-[4]Mar!$I$1+[4]Mar!$Y$1+[4]Mar!$Z$1+[4]Mar!$AA$1 -> 0 | DZ26: =-[5]Mar!$G$1-[5]Mar!$H$1-[5]Mar!$I$1+[5]Mar!$Y$1+[5]Mar!$Z$1+[5]Mar!$AA$1 -> 0 | EA26: =-[6]Mar!$G$1-[6]Mar!$H$1-[6]Mar!$I$1+[6]Mar!$Y$1+[6]Mar!$Z$1+[6]Mar!$AA$1 -> 0 | EB26: =-[7]Mar!$G$1-[7]Mar!$H$1-[7]Mar!$I$1+[7]Mar!$V$1+[7]Mar!$W$1+[7]Mar!$X$1 -> 0 | EF26: =SUM(DU26:EE26) -> 0 | EJ26: =SUM(EF26:EH26) -> 0
B27: CURRENT LIABILITIES
B28: Trade Creditors | C28: CR | D28: =-OpenAccounts!E20 -> 0 | G28: =-[2]Apr!$F$1+[2]Apr!$AK$1 -> 0 | H28: =[4]Apr!$AB$1 -> 0 | I28: =[5]Apr!$AB$1 -> 0 | J28: =[6]Apr!$AB$1 -> 0 | K28: =[7]Apr!$Y$1 -> 0 | O28: =SUM(D28:N28) -> 0 | R28: =-[2]May!$F$1+[2]May!$AK$1 -> 0 | S28: =[4]May!$AB$1 -> 0 | T28: =[5]May!$AB$1 -> 0 | U28: =[6]May!$AB$1 -> 0 | V28: =[7]May!$Y$1 -> 0 | Z28: =SUM(O28:Y28) -> 0 | AC28: =-[2]Jun!$F$1+[2]Jun!$AK$1 -> 0 | AD28: =[4]Jun!$AB$1 -> 0 | AE28: =[5]Jun!$AB$1 -> 0 | AF28: =[6]Jun!$AB$1 -> 0 | AG28: =[7]Jun!$Y$1 -> 0 | AK28: =SUM(Z28:AJ28) -> 0 | AN28: =-[2]Jul!$F$1+[2]Jul!$AK$1 -> 0 | AO28: =[4]Jul!$AB$1 -> 0 | AP28: =[5]Jul!$AB$1 -> 0 | AQ28: =[6]Jul!$AB$1 -> 0 | AR28: =[7]Jul!$Y$1 -> 0 | AV28: =SUM(AK28:AU28) -> 0 | AY28: =-[2]Aug!$F$1+[2]Aug!$AK$1 -> 0 | AZ28: =[4]Aug!$AB$1 -> 0 | BA28: =[5]Aug!$AB$1 -> 0 | BB28: =[6]Aug!$AB$1 -> 0 | BC28: =[7]Aug!$Y$1 -> 0 | BG28: =SUM(AV28:BF28) -> 0 | BJ28: =-[2]Sep!$F$1+[2]Sep!$AK$1 -> 0 | BK28: =[4]Sep!$AB$1 -> 0 | BL28: =[5]Sep!$AB$1 -> 0 | BM28: =[6]Sep!$AB$1 -> 0 | BN28: =[7]Sep!$Y$1 -> 0 | BR28: =SUM(BG28:BQ28) -> 0 | BU28: =-[2]Oct!$F$1+[2]Oct!$AK$1 -> 0 | BV28: =[4]Oct!$AB$1 -> 0 | BW28: =[5]Oct!$AB$1 -> 0 | BX28: =[6]Oct!$AB$1 -> 0 | BY28: =[7]Oct!$Y$1 -> 0 | CC28: =SUM(BR28:CB28) -> 0 | CF28: =-[2]Nov!$F$1+[2]Nov!$AK$1 -> 0 | CG28: =[4]Nov!$AB$1 -> 0 | CH28: =[5]Nov!$AB$1 -> 0 | CI28: =[6]Nov!$AB$1 -> 0 | CJ28: =[7]Nov!$Y$1 -> 0 | CN28: =SUM(CC28:CM28) -> 0 | CQ28: =-[2]Dec!$F$1+[2]Dec!$AK$1 -> 0 | CR28: =[4]Dec!$AB$1 -> 0 | CS28: =[5]Dec!$AB$1 -> 0 | CT28: =[6]Dec!$AB$1 -> 0 | CU28: =[7]Dec!$Y$1 -> 0 | CY28: =SUM(CN28:CX28) -> 0 | DB28: =-[2]Jan!$F$1+[2]Jan!$AK$1 -> 0 | DC28: =[4]Jan!$AB$1 -> 0 | DD28: =[5]Jan!$AB$1 -> 0 | DE28: =[6]Jan!$AB$1 -> 0 | DF28: =[7]Jan!$Y$1 -> 0 | DJ28: =SUM(CY28:DI28) -> 0 | DM28: =-[2]Feb!$F$1+[2]Feb!$AK$1 -> 0 | DN28: =[4]Feb!$AB$1 -> 0 | DO28: =[5]Feb!$AB$1 -> 0 | DP28: =[6]Feb!$AB$1 -> 0 | DQ28: =[7]Feb!$Y$1 -> 0 | DU28: =SUM(DJ28:DT28) -> 0 | DX28: =-[2]Mar!$F$1+[2]Mar!$AK$1 -> 0 | DY28: =[4]Mar!$AB$1 -> 0 | DZ28: =[5]Mar!$AB$1 -> 0 | EA28: =[6]Mar!$AB$1 -> 0 | EB28: =[7]Mar!$Y$1 -> 0 | EF28: =SUM(DU28:EE28) -> 0 | EH28: =[1]HPfinance!$E$2 -> 0 | EJ28: =SUM(EF28:EH28) -> 0
B29: Net Wages Creditor | D29: =-OpenAccounts!E21 -> 0 | H29: =[4]Apr!$AC$1 -> 0 | I29: =[5]Apr!$AC$1 -> 0 | J29: =[6]Apr!$AC$1 -> 0 | K29: =[7]Apr!$Z$1 -> 0 | L29: =-WagesInterface!G4-WagesInterface!G17 -> 0 | O29: =SUM(D29:N29) -> 0 | S29: =[4]May!$AC$1 -> 0 | T29: =[5]May!$AC$1 -> 0 | U29: =[6]May!$AC$1 -> 0 | V29: =[7]May!$Z$1 -> 0 | W29: =-WagesInterface!G5-WagesInterface!G18 -> 0 | Z29: =SUM(O29:Y29) -> 0 | AD29: =[4]Jun!$AC$1 -> 0 | AE29: =[5]Jun!$AC$1 -> 0 | AF29: =[6]Jun!$AC$1 -> 0 | AG29: =[7]Jun!$Z$1 -> 0 | AH29: =-WagesInterface!G6-WagesInterface!G19 -> 0 | AK29: =SUM(Z29:AJ29) -> 0 | AO29: =[4]Jul!$AC$1 -> 0 | AP29: =[5]Jul!$AC$1 -> 0 | AQ29: =[6]Jul!$AC$1 -> 0 | AR29: =[7]Jul!$Z$1 -> 0 | AS29: =-WagesInterface!G7-WagesInterface!G20 -> 0 | AV29: =SUM(AK29:AU29) -> 0 | AZ29: =[4]Aug!$AC$1 -> 0 | BA29: =[5]Aug!$AC$1 -> 0 | BB29: =[6]Aug!$AC$1 -> 0 | BC29: =[7]Aug!$Z$1 -> 0 | BD29: =-WagesInterface!G8-WagesInterface!G21 -> 0 | BG29: =SUM(AV29:BF29) -> 0 | BK29: =[4]Sep!$AC$1 -> 0 | BL29: =[5]Sep!$AC$1 -> 0 | BM29: =[6]Sep!$AC$1 -> 0 | BN29: =[7]Sep!$Z$1 -> 0 | BO29: =-WagesInterface!G9-WagesInterface!G22 -> 0 | BR29: =SUM(BG29:BQ29) -> 0 | BV29: =[4]Oct!$AC$1 -> 0 | BW29: =[5]Oct!$AC$1 -> 0 | BX29: =[6]Oct!$AC$1 -> 0 | BY29: =[7]Oct!$Z$1 -> 0 | BZ29: =-WagesInterface!G10-WagesInterface!G23 -> 0 | CC29: =SUM(BR29:CB29) -> 0 | CG29: =[4]Nov!$AC$1 -> 0 | CH29: =[5]Nov!$AC$1 -> 0 | CI29: =[6]Nov!$AC$1 -> 0 | CJ29: =[7]Nov!$Z$1 -> 0 | CK29: =-WagesInterface!G11-WagesInterface!G24 -> 0 | CN29: =SUM(CC29:CM29) -> 0 | CR29: =[4]Dec!$AC$1 -> 0 | CS29: =[5]Dec!$AC$1 -> 0 | CT29: =[6]Dec!$AC$1 -> 0 | CU29: =[7]Dec!$Z$1 -> 0 | CV29: =-WagesInterface!G12-WagesInterface!G25 -> 0 | CY29: =SUM(CN29:CX29) -> 0 | DC29: =[4]Jan!$AC$1 -> 0 | DD29: =[5]Jan!$AC$1 -> 0 | DE29: =[6]Jan!$AC$1 -> 0 | DF29: =[7]Jan!$Z$1 -> 0 | DG29: =-WagesInterface!G13-WagesInterface!G26 -> 0 | DJ29: =SUM(CY29:DI29) -> 0 | DN29: =[4]Feb!$AC$1 -> 0 | DO29: =[5]Feb!$AC$1 -> 0 | DP29: =[6]Feb!$AC$1 -> 0 | DQ29: =[7]Feb!$Z$1 -> 0 | DR29: =-WagesInterface!G14-WagesInterface!G27 -> 0 | DU29: =SUM(DJ29:DT29) -> 0 | DY29: =[4]Mar!$AC$1 -> 0 | DZ29: =[5]Mar!$AC$1 -> 0 | EA29: =[6]Mar!$AC$1 -> 0 | EB29: =[7]Mar!$Z$1 -> 0 | EC29: =-WagesInterface!G15-WagesInterface!G28 -> 0 | EF29: =SUM(DU29:EE29) -> 0 | EJ29: =SUM(EF29:EH29) -> 0
B30: Other Deductions from wages | D30: =-OpenAccounts!E22 -> 0 | L30: =-WagesInterface!F4-WagesInterface!F17 -> 0 | O30: =SUM(D30:N30) -> 0 | W30: =-WagesInterface!F5-WagesInterface!F18 -> 0 | Z30: =SUM(O30:Y30) -> 0 | AH30: =-WagesInterface!F6-WagesInterface!F19 -> 0 | AK30: =SUM(Z30:AJ30) -> 0 | AS30: =-WagesInterface!F7-WagesInterface!F20 -> 0 | AV30: =SUM(AK30:AU30) -> 0 | BD30: =-WagesInterface!F8-WagesInterface!F21 -> 0 | BG30: =SUM(AV30:BF30) -> 0 | BO30: =-WagesInterface!F9-WagesInterface!F22 -> 0 | BR30: =SUM(BG30:BQ30) -> 0 | BZ30: =-WagesInterface!F10-WagesInterface!F23 -> 0 | CC30: =SUM(BR30:CB30) -> 0 | CK30: =-WagesInterface!F11-WagesInterface!F24 -> 0 | CN30: =SUM(CC30:CM30) -> 0 | CV30: =-WagesInterface!F12-WagesInterface!F25 -> 0 | CY30: =SUM(CN30:CX30) -> 0 | DG30: =-WagesInterface!F13-WagesInterface!F26 -> 0 | DJ30: =SUM(CY30:DI30) -> 0 | DR30: =-WagesInterface!F14-WagesInterface!F27 -> 0 | DU30: =SUM(DJ30:DT30) -> 0 | EC30: =-WagesInterface!F15-WagesInterface!F28 -> 0 | EF30: =SUM(DU30:EE30) -> 0 | EJ30: =SUM(EF30:EH30) -> 0
B31: Dividends Creditor | C31: DV | D31: =-OpenAccounts!E23 -> 0 | H31: =[4]Apr!$AL$1 -> 0 | I31: =[5]Apr!$AL$1 -> 0 | J31: =[6]Apr!$AL$1 -> 0 | K31: =[7]Apr!$AI$1 -> 0 | O31: =SUM(D31:N31) -> 0 | S31: =[4]May!$AL$1 -> 0 | T31: =[5]May!$AL$1 -> 0 | U31: =[6]May!$AL$1 -> 0 | V31: =[7]May!$AI$1 -> 0 | Z31: =SUM(O31:Y31) -> 0 | AD31: =[4]Jun!$AL$1 -> 0 | AE31: =[5]Jun!$AL$1 -> 0 | AF31: =[6]Jun!$AL$1 -> 0 | AG31: =[7]Jun!$AI$1 -> 0 | AK31: =SUM(Z31:AJ31) -> 0 | AO31: =[4]Jul!$AL$1 -> 0 | AP31: =[5]Jul!$AL$1 -> 0 | AQ31: =[6]Jul!$AL$1 -> 0 | AR31: =[7]Jul!$AI$1 -> 0 | AV31: =SUM(AK31:AU31) -> 0 | AZ31: =[4]Aug!$AL$1 -> 0 | BA31: =[5]Aug!$AL$1 -> 0 | BB31: =[6]Aug!$AL$1 -> 0 | BC31: =[7]Aug!$AI$1 -> 0 | BG31: =SUM(AV31:BF31) -> 0 | BK31: =[4]Sep!$AL$1 -> 0 | BL31: =[5]Sep!$AL$1 -> 0 | BM31: =[6]Sep!$AL$1 -> 0 | BN31: =[7]Sep!$AI$1 -> 0 | BR31: =SUM(BG31:BQ31) -> 0 | BV31: =[4]Oct!$AL$1 -> 0 | BW31: =[5]Oct!$AL$1 -> 0 | BX31: =[6]Oct!$AL$1 -> 0 | BY31: =[7]Oct!$AI$1 -> 0 | CC31: =SUM(BR31:CB31) -> 0 | CG31: =[4]Nov!$AL$1 -> 0 | CH31: =[5]Nov!$AL$1 -> 0 | CI31: =[6]Nov!$AL$1 -> 0 | CJ31: =[7]Nov!$AI$1 -> 0 | CN31: =SUM(CC31:CM31) -> 0 | CR31: =[4]Dec!$AL$1 -> 0 | CS31: =[5]Dec!$AL$1 -> 0 | CT31: =[6]Dec!$AL$1 -> 0 | CU31: =[7]Dec!$AI$1 -> 0 | CY31: =SUM(CN31:CX31) -> 0 | DC31: =[4]Jan!$AL$1 -> 0 | DD31: =[5]Jan!$AL$1 -> 0 | DE31: =[6]Jan!$AL$1 -> 0 | DF31: =[7]Jan!$AI$1 -> 0 | DJ31: =SUM(CY31:DI31) -> 0 | DN31: =[4]Feb!$AL$1 -> 0 | DO31: =[5]Feb!$AL$1 -> 0 | DP31: =[6]Feb!$AL$1 -> 0 | DQ31: =[7]Feb!$AI$1 -> 0 | DU31: =SUM(DJ31:DT31) -> 0 | DY31: =[4]Mar!$AL$1 -> 0 | DZ31: =[5]Mar!$AL$1 -> 0 | EA31: =[6]Mar!$AL$1 -> 0 | EB31: =[7]Mar!$AI$1 -> 0 | EF31: =SUM(DU31:EE31) -> 0 | EH31: =-[8]Boardmeeting!$E$4 -> 0 | EJ31: =SUM(EF31:EH31) -> 0
B32: Creditor HMRC CIS | C32: RC | D32: =-OpenAccounts!I26 -> 0 | F32: =[3]Apr!$V$1 -> 0 | G32: =-[2]Apr!$AK$1 -> 0 | H32: =-[4]Apr!$O$1+[4]Apr!$AJ$1 -> 0 | I32: =-[5]Apr!$O$1+[5]Apr!$AJ$1 -> 0 | J32: =-[6]Apr!$O$1+[6]Apr!$AJ$1 -> 0 | K32: =[7]Apr!$AG$1 -> 0 | O32: =SUM(D32:N32) -> 0 | Q32: =[3]May!$V$1 -> 0 | R32: =-[2]May!$AK$1 -> 0 | S32: =-[4]May!$O$1+[4]May!$AJ$1 -> 0 | T32: =-[5]May!$O$1+[5]May!$AJ$1 -> 0 | U32: =-[6]May!$O$1+[6]May!$AJ$1 -> 0 | V32: =[7]May!$AG$1 -> 0 | Z32: =SUM(O32:Y32) -> 0 | AB32: =[3]Jun!$V$1 -> 0 | AC32: =-[2]Jun!$AK$1 -> 0 | AD32: =-[4]Jun!$O$1+[4]Jun!$AJ$1 -> 0 | AE32: =-[5]Jun!$O$1+[5]Jun!$AJ$1 -> 0 | AF32: =-[6]Jun!$O$1+[6]Jun!$AJ$1 -> 0 | AG32: =[7]Jun!$AG$1 -> 0 | AK32: =SUM(Z32:AJ32) -> 0 | AM32: =[3]Jul!$V$1 -> 0 | AN32: =-[2]Jul!$AK$1 -> 0 | AO32: =-[4]Jul!$O$1+[4]Jul!$AJ$1 -> 0 | AP32: =-[5]Jul!$O$1+[5]Jul!$AJ$1 -> 0 | AQ32: =-[6]Jul!$O$1+[6]Jul!$AJ$1 -> 0 | AR32: =[7]Jul!$AG$1 -> 0 | AV32: =SUM(AK32:AU32) -> 0 | AX32: =[3]Aug!$V$1 -> 0 | AY32: =-[2]Aug!$AK$1 -> 0 | AZ32: =-[4]Aug!$O$1+[4]Aug!$AJ$1 -> 0 | BA32: =-[5]Aug!$O$1+[5]Aug!$AJ$1 -> 0 | BB32: =-[6]Aug!$O$1+[6]Aug!$AJ$1 -> 0 | BC32: =[7]Aug!$AG$1 -> 0 | BG32: =SUM(AV32:BF32) -> 0 | BI32: =[3]Sep!$V$1 -> 0 | BJ32: =-[2]Sep!$AK$1 -> 0 | BK32: =-[4]Sep!$O$1+[4]Sep!$AJ$1 -> 0 | BL32: =-[5]Sep!$O$1+[5]Sep!$AJ$1 -> 0 | BM32: =-[6]Sep!$O$1+[6]Sep!$AJ$1 -> 0 | BN32: =[7]Sep!$AG$1 -> 0 | BR32: =SUM(BG32:BQ32) -> 0 | BT32: =[3]Oct!$V$1 -> 0 | BU32: =-[2]Oct!$AK$1 -> 0 | BV32: =-[4]Oct!$O$1+[4]Oct!$AJ$1 -> 0 | BW32: =-[5]Oct!$O$1+[5]Oct!$AJ$1 -> 0 | BX32: =-[6]Oct!$O$1+[6]Oct!$AJ$1 -> 0 | BY32: =[7]Oct!$AG$1 -> 0 | CC32: =SUM(BR32:CB32) -> 0 | CE32: =[3]Nov!$V$1 -> 0 | CF32: =-[2]Nov!$AK$1 -> 0 | CG32: =-[4]Nov!$O$1+[4]Nov!$AJ$1 -> 0 | CH32: =-[5]Nov!$O$1+[5]Nov!$AJ$1 -> 0 | CI32: =-[6]Nov!$O$1+[6]Nov!$AJ$1 -> 0 | CJ32: =[7]Nov!$AG$1 -> 0 | CN32: =SUM(CC32:CM32) -> 0 | CP32: =[3]Dec!$V$1 -> 0 | CQ32: =-[2]Dec!$AK$1 -> 0 | CR32: =-[4]Dec!$O$1+[4]Dec!$AJ$1 -> 0 | CS32: =-[5]Dec!$O$1+[5]Dec!$AJ$1 -> 0 | CT32: =-[6]Dec!$O$1+[6]Dec!$AJ$1 -> 0 | CU32: =[7]Dec!$AG$1 -> 0 | CY32: =SUM(CN32:CX32) -> 0 | DA32: =[3]Jan!$V$1 -> 0 | DB32: =-[2]Jan!$AK$1 -> 0 | DC32: =-[4]Jan!$O$1+[4]Jan!$AJ$1 -> 0 | DD32: =-[5]Jan!$O$1+[5]Jan!$AJ$1 -> 0 | DE32: =-[6]Jan!$O$1+[6]Jan!$AJ$1 -> 0 | DF32: =[7]Jan!$AG$1 -> 0 | DJ32: =SUM(CY32:DI32) -> 0 | DL32: =[3]Feb!$V$1 -> 0 | DM32: =-[2]Feb!$AK$1 -> 0 | DN32: =-[4]Feb!$O$1+[4]Feb!$AJ$1 -> 0 | DO32: =-[5]Feb!$O$1+[5]Feb!$AJ$1 -> 0 | DP32: =-[6]Feb!$O$1+[6]Feb!$AJ$1 -> 0 | DQ32: =[7]Feb!$AG$1 -> 0 | DU32: =SUM(DJ32:DT32) -> 0 | DW32: =[3]Mar!$V$1 -> 0 | DX32: =-[2]Mar!$AK$1 -> 0 | DY32: =-[4]Mar!$O$1+[4]Mar!$AJ$1 -> 0 | DZ32: =-[5]Mar!$O$1+[5]Mar!$AJ$1 -> 0 | EA32: =-[6]Mar!$O$1+[6]Mar!$AJ$1 -> 0 | EB32: =[7]Mar!$AG$1 -> 0 | EF32: =SUM(DU32:EE32) -> 0 | EJ32: =SUM(EF32:EH32) -> 0
B33: Creditor HMRC Vat | C33: RV | D33: =-OpenAccounts!H26 -> 0 | F33: =-[3]Apr!$G$1 -> 0 | G33: =[2]Apr!$G$1 -> 0 | H33: =-[4]Apr!$N$1+[4]Apr!$AI$1 -> 0 | I33: =-[5]Apr!$N$1+[5]Apr!$AI$1 -> 0 | J33: =-[6]Apr!$N$1+[6]Apr!$AI$1 -> 0 | K33: =[7]Apr!$AF$1 -> 0 | O33: =SUM(D33:N33) -> 0 | Q33: =-[3]May!$G$1 -> 0 | R33: =[2]May!$G$1 -> 0 | S33: =-[4]May!$N$1+[4]May!$AI$1 -> 0 | T33: =-[5]May!$N$1+[5]May!$AI$1 -> 0 | U33: =-[6]May!$N$1+[6]May!$AI$1 -> 0 | V33: =[7]May!$AF$1 -> 0 | Z33: =SUM(O33:Y33) -> 0 | AB33: =-[3]Jun!$G$1 -> 0 | AC33: =[2]Jun!$G$1 -> 0 | AD33: =-[4]Jun!$N$1+[4]Jun!$AI$1 -> 0 | AE33: =-[5]Jun!$N$1+[5]Jun!$AI$1 -> 0 | AF33: =-[6]Jun!$N$1+[6]Jun!$AI$1 -> 0 | AG33: =[7]Jun!$AF$1 -> 0 | AK33: =SUM(Z33:AJ33) -> 0 | AM33: =-[3]Jul!$G$1 -> 0 | AN33: =[2]Jul!$G$1 -> 0 | AO33: =-[4]Jul!$N$1+[4]Jul!$AI$1 -> 0 | AP33: =-[5]Jul!$N$1+[5]Jul!$AI$1 -> 0 | AQ33: =-[6]Jul!$N$1+[6]Jul!$AI$1 -> 0 | AR33: =[7]Jul!$AF$1 -> 0 | AV33: =SUM(AK33:AU33) -> 0 | AX33: =-[3]Aug!$G$1 -> 0 | AY33: =[2]Aug!$G$1 -> 0 | AZ33: =-[4]Aug!$N$1+[4]Aug!$AI$1 -> 0 | BA33: =-[5]Aug!$N$1+[5]Aug!$AI$1 -> 0 | BB33: =-[6]Aug!$N$1+[6]Aug!$AI$1 -> 0 | BC33: =[7]Aug!$AF$1 -> 0 | BG33: =SUM(AV33:BF33) -> 0 | BI33: =-[3]Sep!$G$1 -> 0 | BJ33: =[2]Sep!$G$1 -> 0 | BK33: =-[4]Sep!$N$1+[4]Sep!$AI$1 -> 0 | BL33: =-[5]Sep!$N$1+[5]Sep!$AI$1 -> 0 | BM33: =-[6]Sep!$N$1+[6]Sep!$AI$1 -> 0 | BN33: =[7]Sep!$AF$1 -> 0 | BR33: =SUM(BG33:BQ33) -> 0 | BT33: =-[3]Oct!$G$1 -> 0 | BU33: =[2]Oct!$G$1 -> 0 | BV33: =-[4]Oct!$N$1+[4]Oct!$AI$1 -> 0 | BW33: =-[5]Oct!$N$1+[5]Oct!$AI$1 -> 0 | BX33: =-[6]Oct!$N$1+[6]Oct!$AI$1 -> 0 | BY33: =[7]Oct!$AF$1 -> 0 | CC33: =SUM(BR33:CB33) -> 0 | CE33: =-[3]Nov!$G$1 -> 0 | CF33: =[2]Nov!$G$1 -> 0 | CG33: =-[4]Nov!$N$1+[4]Nov!$AI$1 -> 0 | CH33: =-[5]Nov!$N$1+[5]Nov!$AI$1 -> 0 | CI33: =-[6]Nov!$N$1+[6]Nov!$AI$1 -> 0 | CJ33: =[7]Nov!$AF$1 -> 0 | CN33: =SUM(CC33:CM33) -> 0 | CP33: =-[3]Dec!$G$1 -> 0 | CQ33: =[2]Dec!$G$1 -> 0 | CR33: =-[4]Dec!$N$1+[4]Dec!$AI$1 -> 0 | CS33: =-[5]Dec!$N$1+[5]Dec!$AI$1 -> 0 | CT33: =-[6]Dec!$N$1+[6]Dec!$AI$1 -> 0 | CU33: =[7]Dec!$AF$1 -> 0 | CY33: =SUM(CN33:CX33) -> 0 | DA33: =-[3]Jan!$G$1 -> 0 | DB33: =[2]Jan!$G$1 -> 0 | DC33: =-[4]Jan!$N$1+[4]Jan!$AI$1 -> 0 | DD33: =-[5]Jan!$N$1+[5]Jan!$AI$1 -> 0 | DE33: =-[6]Jan!$N$1+[6]Jan!$AI$1 -> 0 | DF33: =[7]Jan!$AF$1 -> 0 | DJ33: =SUM(CY33:DI33) -> 0 | DL33: =-[3]Feb!$G$1 -> 0 | DM33: =[2]Feb!$G$1 -> 0 | DN33: =-[4]Feb!$N$1+[4]Feb!$AI$1 -> 0 | DO33: =-[5]Feb!$N$1+[5]Feb!$AI$1 -> 0 | DP33: =-[6]Feb!$N$1+[6]Feb!$AI$1 -> 0 | DQ33: =[7]Feb!$AF$1 -> 0 | DU33: =SUM(DJ33:DT33) -> 0 | DW33: =-[3]Mar!$G$1 -> 0 | DX33: =[2]Mar!$G$1 -> 0 | DY33: =-[4]Mar!$N$1+[4]Mar!$AI$1 -> 0 | DZ33: =-[5]Mar!$N$1+[5]Mar!$AI$1 -> 0 | EA33: =-[6]Mar!$N$1+[6]Mar!$AI$1 -> 0 | EB33: =[7]Mar!$AF$1 -> 0 | EF33: =SUM(DU33:EE33) -> 0 | EJ33: =SUM(EF33:EH33) -> 0
B34: Creditor HMRC Paye | C34: RP | D34: =-OpenAccounts!G26 -> 0 | H34: =[4]Apr!$AH$1 -> 0 | I34: =[5]Apr!$AH$1 -> 0 | J34: =[6]Apr!$AH$1 -> 0 | K34: =[7]Apr!$AE$1 -> 0 | L34: =-(WagesInterface!D4+WagesInterface!E4+WagesInterface!H4)-(WagesInterface!D17+WagesInterface!E17+WagesInterface!H17)+(WagesInterface!I4+WagesInterface!I17) -> 0 | O34: =SUM(D34:N34) -> 0 | S34: =[4]May!$AH$1 -> 0 | T34: =[5]May!$AH$1 -> 0 | U34: =[6]May!$AH$1 -> 0 | V34: =[7]May!$AE$1 -> 0 | W34: =-(WagesInterface!D5+WagesInterface!E5+WagesInterface!H5)-(WagesInterface!D18+WagesInterface!E18+WagesInterface!H18)+(WagesInterface!I5+WagesInterface!I18) -> 0 | Z34: =SUM(O34:Y34) -> 0 | AD34: =[4]Jun!$AH$1 -> 0 | AE34: =[5]Jun!$AH$1 -> 0 | AF34: =[6]Jun!$AH$1 -> 0 | AG34: =[7]Jun!$AE$1 -> 0 | AH34: =-(WagesInterface!D6+WagesInterface!E6+WagesInterface!H6)-(WagesInterface!D19+WagesInterface!E19+WagesInterface!H19)+(WagesInterface!I6+WagesInterface!I19) -> 0 | AK34: =SUM(Z34:AJ34) -> 0 | AO34: =[4]Jul!$AH$1 -> 0 | AP34: =[5]Jul!$AH$1 -> 0 | AQ34: =[6]Jul!$AH$1 -> 0 | AR34: =[7]Jul!$AE$1 -> 0 | AS34: =-(WagesInterface!D7+WagesInterface!E7+WagesInterface!H7)-(WagesInterface!D20+WagesInterface!E20+WagesInterface!H20)+(WagesInterface!I7+WagesInterface!I20) -> 0 | AV34: =SUM(AK34:AU34) -> 0 | AZ34: =[4]Aug!$AH$1 -> 0 | BA34: =[5]Aug!$AH$1 -> 0 | BB34: =[6]Aug!$AH$1 -> 0 | BC34: =[7]Aug!$AE$1 -> 0 | BD34: =-(WagesInterface!D8+WagesInterface!E8+WagesInterface!H8)-(WagesInterface!D21+WagesInterface!E21+WagesInterface!H21)+(WagesInterface!I8+WagesInterface!I21) -> 0 | BG34: =SUM(AV34:BF34) -> 0 | BK34: =[4]Sep!$AH$1 -> 0 | BL34: =[5]Sep!$AH$1 -> 0 | BM34: =[6]Sep!$AH$1 -> 0 | BN34: =[7]Sep!$AE$1 -> 0 | BO34: =-(WagesInterface!D9+WagesInterface!E9+WagesInterface!H9)-(WagesInterface!D22+WagesInterface!E22+WagesInterface!H22)+(WagesInterface!I9+WagesInterface!I22) -> 0 | BR34: =SUM(BG34:BQ34) -> 0 | BV34: =[4]Oct!$AH$1 -> 0 | BW34: =[5]Oct!$AH$1 -> 0 | BX34: =[6]Oct!$AH$1 -> 0 | BY34: =[7]Oct!$AE$1 -> 0 | BZ34: =-(WagesInterface!D10+WagesInterface!E10+WagesInterface!H10)-(WagesInterface!D23+WagesInterface!E23+WagesInterface!H23)+(WagesInterface!I10+WagesInterface!I23) -> 0 | CC34: =SUM(BR34:CB34) -> 0 | CG34: =[4]Nov!$AH$1 -> 0 | CH34: =[5]Nov!$AH$1 -> 0 | CI34: =[6]Nov!$AH$1 -> 0 | CJ34: =[7]Nov!$AE$1 -> 0 | CK34: =-(WagesInterface!D11+WagesInterface!E11+WagesInterface!H11)-(WagesInterface!D24+WagesInterface!E24+WagesInterface!H24)+(WagesInterface!I11+WagesInterface!I24) -> 0 | CN34: =SUM(CC34:CM34) -> 0 | CR34: =[4]Dec!$AH$1 -> 0 | CS34: =[5]Dec!$AH$1 -> 0 | CT34: =[6]Dec!$AH$1 -> 0 | CU34: =[7]Dec!$AE$1 -> 0 | CV34: =-(WagesInterface!D12+WagesInterface!E12+WagesInterface!H12)-(WagesInterface!D25+WagesInterface!E25+WagesInterface!H25)+(WagesInterface!I12+WagesInterface!I25) -> 0 | CY34: =SUM(CN34:CX34) -> 0 | DC34: =[4]Jan!$AH$1 -> 0 | DD34: =[5]Jan!$AH$1 -> 0 | DE34: =[6]Jan!$AH$1 -> 0 | DF34: =[7]Jan!$AE$1 -> 0 | DG34: =-(WagesInterface!D13+WagesInterface!E13+WagesInterface!H13)-(WagesInterface!D26+WagesInterface!E26+WagesInterface!H26)+(WagesInterface!I13+WagesInterface!I26) -> 0 | DJ34: =SUM(CY34:DI34) -> 0 | DN34: =[4]Feb!$AH$1 -> 0 | DO34: =[5]Feb!$AH$1 -> 0 | DP34: =[6]Feb!$AH$1 -> 0 | DQ34: =[7]Feb!$AE$1 -> 0 | DR34: =-(WagesInterface!D14+WagesInterface!E14+WagesInterface!H14)-(WagesInterface!D27+WagesInterface!E27+WagesInterface!H27)+(WagesInterface!I14+WagesInterface!I27) -> 0 | DU34: =SUM(DJ34:DT34) -> 0 | DY34: =[4]Mar!$AH$1 -> 0 | DZ34: =[5]Mar!$AH$1 -> 0 | EA34: =[6]Mar!$AH$1 -> 0 | EB34: =[7]Mar!$AE$1 -> 0 | EC34: =-(WagesInterface!D15+WagesInterface!E15+WagesInterface!H15)-(WagesInterface!D28+WagesInterface!E28+WagesInterface!H28)+(WagesInterface!I15+WagesInterface!I28) -> 0 | EF34: =SUM(DU34:EE34) -> 0 | EJ34: =SUM(EF34:EH34) -> 0
B35: Creditor HMRC Corporation Tax | C35: RT | D35: =-OpenAccounts!E24 -> 0 | H35: =[4]Apr!$AK$1 -> 0 | I35: =[5]Apr!$AK$1 -> 0 | J35: =[6]Apr!$AK$1 -> 0 | K35: =[7]Apr!$AH$1 -> 0 | O35: =SUM(D35:N35) -> 0 | S35: =[4]May!$AK$1 -> 0 | T35: =[5]May!$AK$1 -> 0 | U35: =[6]May!$AK$1 -> 0 | V35: =[7]May!$AH$1 -> 0 | Z35: =SUM(O35:Y35) -> 0 | AD35: =[4]Jun!$AK$1 -> 0 | AE35: =[5]Jun!$AK$1 -> 0 | AF35: =[6]Jun!$AK$1 -> 0 | AG35: =[7]Jun!$AH$1 -> 0 | AK35: =SUM(Z35:AJ35) -> 0 | AO35: =[4]Jul!$AK$1 -> 0 | AP35: =[5]Jul!$AK$1 -> 0 | AQ35: =[6]Jul!$AK$1 -> 0 | AR35: =[7]Jul!$AH$1 -> 0 | AV35: =SUM(AK35:AU35) -> 0 | AZ35: =[4]Aug!$AK$1 -> 0 | BA35: =[5]Aug!$AK$1 -> 0 | BB35: =[6]Aug!$AK$1 -> 0 | BC35: =[7]Aug!$AH$1 -> 0 | BG35: =SUM(AV35:BF35) -> 0 | BK35: =[4]Sep!$AK$1 -> 0 | BL35: =[5]Sep!$AK$1 -> 0 | BM35: =[6]Sep!$AK$1 -> 0 | BN35: =[7]Sep!$AH$1 -> 0 | BR35: =SUM(BG35:BQ35) -> 0 | BV35: =[4]Oct!$AK$1 -> 0 | BW35: =[5]Oct!$AK$1 -> 0 | BX35: =[6]Oct!$AK$1 -> 0 | BY35: =[7]Oct!$AH$1 -> 0 | CC35: =SUM(BR35:CB35) -> 0 | CG35: =[4]Nov!$AK$1 -> 0 | CH35: =[5]Nov!$AK$1 -> 0 | CI35: =[6]Nov!$AK$1 -> 0 | CJ35: =[7]Nov!$AH$1 -> 0 | CN35: =SUM(CC35:CM35) -> 0 | CR35: =[4]Dec!$AK$1 -> 0 | CS35: =[5]Dec!$AK$1 -> 0 | CT35: =[6]Dec!$AK$1 -> 0 | CU35: =[7]Dec!$AH$1 -> 0 | CY35: =SUM(CN35:CX35) -> 0 | DC35: =[4]Jan!$AK$1 -> 0 | DD35: =[5]Jan!$AK$1 -> 0 | DE35: =[6]Jan!$AK$1 -> 0 | DF35: =[7]Jan!$AH$1 -> 0 | DJ35: =SUM(CY35:DI35) -> 0 | DN35: =[4]Feb!$AK$1 -> 0 | DO35: =[5]Feb!$AK$1 -> 0 | DP35: =[6]Feb!$AK$1 -> 0 | DQ35: =[7]Feb!$AH$1 -> 0 | DU35: =SUM(DJ35:DT35) -> 0 | DY35: =[4]Mar!$AK$1 -> 0 | DZ35: =[5]Mar!$AK$1 -> 0 | EA35: =[6]Mar!$AK$1 -> 0 | EB35: =[7]Mar!$AH$1 -> 0 | ED35: =-CorporationTax!K35 -> 0 | EF35: =SUM(DU35:EE35) -> 0 | EH35: =-EH58 -> 0 | EJ35: =SUM(EF35:EH35) -> 0
B36: OTHER ASSETS
B37: Debtor Long Term (repayable 3 - 5 years) | C37: LDR | D37: =OpenAccounts!E28 -> 0 | H37: =-[4]Apr!$L$1+[4]Apr!$AF$1 -> 0 | I37: =-[5]Apr!$L$1+[5]Apr!$AF$1 -> 0 | J37: =-[6]Apr!$L$1+[6]Apr!$AF$1 -> 0 | K37: =-[7]Apr!$L$1+[7]Apr!$AC$1 -> 0 | O37: =SUM(D37:N37) -> 0 | S37: =-[4]May!$L$1+[4]May!$AF$1 -> 0 | T37: =-[5]May!$L$1+[5]May!$AF$1 -> 0 | U37: =-[6]May!$L$1+[6]May!$AF$1 -> 0 | V37: =-[7]May!$L$1+[7]May!$AC$1 -> 0 | Z37: =SUM(O37:Y37) -> 0 | AD37: =-[4]Jun!$L$1+[4]Jun!$AF$1 -> 0 | AE37: =-[5]Jun!$L$1+[5]Jun!$AF$1 -> 0 | AF37: =-[6]Jun!$L$1+[6]Jun!$AF$1 -> 0 | AG37: =-[7]Jun!$L$1+[7]Jun!$AC$1 -> 0 | AK37: =SUM(Z37:AJ37) -> 0 | AO37: =-[4]Jul!$L$1+[4]Jul!$AF$1 -> 0 | AP37: =-[5]Jul!$L$1+[5]Jul!$AF$1 -> 0 | AQ37: =-[6]Jul!$L$1+[6]Jul!$AF$1 -> 0 | AR37: =-[7]Jul!$L$1+[7]Jul!$AC$1 -> 0 | AV37: =SUM(AK37:AU37) -> 0 | AZ37: =-[4]Aug!$L$1+[4]Aug!$AF$1 -> 0 | BA37: =-[5]Aug!$L$1+[5]Aug!$AF$1 -> 0 | BB37: =-[6]Aug!$L$1+[6]Aug!$AF$1 -> 0 | BC37: =-[7]Aug!$L$1+[7]Aug!$AC$1 -> 0 | BG37: =SUM(AV37:BF37) -> 0 | BK37: =-[4]Sep!$L$1+[4]Sep!$AF$1 -> 0 | BL37: =-[5]Sep!$L$1+[5]Sep!$AF$1 -> 0 | BM37: =-[6]Sep!$L$1+[6]Sep!$AF$1 -> 0 | BN37: =-[7]Sep!$L$1+[7]Sep!$AC$1 -> 0 | BR37: =SUM(BG37:BQ37) -> 0 | BV37: =-[4]Oct!$L$1+[4]Oct!$AF$1 -> 0 | BW37: =-[5]Oct!$L$1+[5]Oct!$AF$1 -> 0 | BX37: =-[6]Oct!$L$1+[6]Oct!$AF$1 -> 0 | BY37: =-[7]Oct!$L$1+[7]Oct!$AC$1 -> 0 | CC37: =SUM(BR37:CB37) -> 0 | CG37: =-[4]Nov!$L$1+[4]Nov!$AF$1 -> 0 | CH37: =-[5]Nov!$L$1+[5]Nov!$AF$1 -> 0 | CI37: =-[6]Nov!$L$1+[6]Nov!$AF$1 -> 0 | CJ37: =-[7]Nov!$L$1+[7]Nov!$AC$1 -> 0 | CN37: =SUM(CC37:CM37) -> 0 | CR37: =-[4]Dec!$L$1+[4]Dec!$AF$1 -> 0 | CS37: =-[5]Dec!$L$1+[5]Dec!$AF$1 -> 0 | CT37: =-[6]Dec!$L$1+[6]Dec!$AF$1 -> 0 | CU37: =-[7]Dec!$L$1+[7]Dec!$AC$1 -> 0 | CY37: =SUM(CN37:CX37) -> 0 | DC37: =-[4]Jan!$L$1+[4]Jan!$AF$1 -> 0 | DD37: =-[5]Jan!$L$1+[5]Jan!$AF$1 -> 0 | DE37: =-[6]Jan!$L$1+[6]Jan!$AF$1 -> 0 | DF37: =-[7]Jan!$L$1+[7]Jan!$AC$1 -> 0 | DJ37: =SUM(CY37:DI37) -> 0 | DN37: =-[4]Feb!$L$1+[4]Feb!$AF$1 -> 0 | DO37: =-[5]Feb!$L$1+[5]Feb!$AF$1 -> 0 | DP37: =-[6]Feb!$L$1+[6]Feb!$AF$1 -> 0 | DQ37: =-[7]Feb!$L$1+[7]Feb!$AC$1 -> 0 | DU37: =SUM(DJ37:DT37) -> 0 | DY37: =-[4]Mar!$L$1+[4]Mar!$AF$1 -> 0 | DZ37: =-[5]Mar!$L$1+[5]Mar!$AF$1 -> 0 | EA37: =-[6]Mar!$L$1+[6]Mar!$AF$1 -> 0 | EB37: =-[7]Mar!$L$1+[7]Mar!$AC$1 -> 0 | EF37: =SUM(DU37:EE37) -> 0 | EJ37: =SUM(EF37:EH37) -> 0
B38: OTHER CREDITORS
B39: Directors Loan Account | C39: DL | D39: =-OpenAccounts!E30 -> 0 | H39: =-[4]Apr!$P$1+[4]Apr!$AM$1 -> 0 | I39: =-[5]Apr!$P$1+[5]Apr!$AM$1 -> 0 | J39: =-[6]Apr!$P$1+[6]Apr!$AM$1 -> 0 | K39: =-[7]Apr!$N$1+[7]Apr!$AJ$1 -> 0 | O39: =SUM(D39:N39) -> 0 | S39: =-[4]May!$P$1+[4]May!$AM$1 -> 0 | T39: =-[5]May!$P$1+[5]May!$AM$1 -> 0 | U39: =-[6]May!$P$1+[6]May!$AM$1 -> 0 | V39: =-[7]May!$N$1+[7]May!$AJ$1 -> 0 | Z39: =SUM(O39:Y39) -> 0 | AD39: =-[4]Jun!$P$1+[4]Jun!$AM$1 -> 0 | AE39: =-[5]Jun!$P$1+[5]Jun!$AM$1 -> 0 | AF39: =-[6]Jun!$P$1+[6]Jun!$AM$1 -> 0 | AG39: =-[7]Jun!$N$1+[7]Jun!$AJ$1 -> 0 | AK39: =SUM(Z39:AJ39) -> 0 | AO39: =-[4]Jul!$P$1+[4]Jul!$AM$1 -> 0 | AP39: =-[5]Jul!$P$1+[5]Jul!$AM$1 -> 0 | AQ39: =-[6]Jul!$P$1+[6]Jul!$AM$1 -> 0 | AR39: =-[7]Jul!$N$1+[7]Jul!$AJ$1 -> 0 | AV39: =SUM(AK39:AU39) -> 0 | AZ39: =-[4]Aug!$P$1+[4]Aug!$AM$1 -> 0 | BA39: =-[5]Aug!$P$1+[5]Aug!$AM$1 -> 0 | BB39: =-[6]Aug!$P$1+[6]Aug!$AM$1 -> 0 | BC39: =-[7]Aug!$N$1+[7]Aug!$AJ$1 -> 0 | BG39: =SUM(AV39:BF39) -> 0 | BK39: =-[4]Sep!$P$1+[4]Sep!$AM$1 -> 0 | BL39: =-[5]Sep!$P$1+[5]Sep!$AM$1 -> 0 | BM39: =-[6]Sep!$P$1+[6]Sep!$AM$1 -> 0 | BN39: =-[7]Sep!$N$1+[7]Sep!$AJ$1 -> 0 | BR39: =SUM(BG39:BQ39) -> 0 | BV39: =-[4]Oct!$P$1+[4]Oct!$AM$1 -> 0 | BW39: =-[5]Oct!$P$1+[5]Oct!$AM$1 -> 0 | BX39: =-[6]Oct!$P$1+[6]Oct!$AM$1 -> 0 | BY39: =-[7]Oct!$N$1+[7]Oct!$AJ$1 -> 0 | CC39: =SUM(BR39:CB39) -> 0 | CG39: =-[4]Nov!$P$1+[4]Nov!$AM$1 -> 0 | CH39: =-[5]Nov!$P$1+[5]Nov!$AM$1 -> 0 | CI39: =-[6]Nov!$P$1+[6]Nov!$AM$1 -> 0 | CJ39: =-[7]Nov!$N$1+[7]Nov!$AJ$1 -> 0 | CN39: =SUM(CC39:CM39) -> 0 | CR39: =-[4]Dec!$P$1+[4]Dec!$AM$1 -> 0 | CS39: =-[5]Dec!$P$1+[5]Dec!$AM$1 -> 0 | CT39: =-[6]Dec!$P$1+[6]Dec!$AM$1 -> 0 | CU39: =-[7]Dec!$N$1+[7]Dec!$AJ$1 -> 0 | CY39: =SUM(CN39:CX39) -> 0 | DC39: =-[4]Jan!$P$1+[4]Jan!$AM$1 -> 0 | DD39: =-[5]Jan!$P$1+[5]Jan!$AM$1 -> 0 | DE39: =-[6]Jan!$P$1+[6]Jan!$AM$1 -> 0 | DF39: =-[7]Jan!$N$1+[7]Jan!$AJ$1 -> 0 | DJ39: =SUM(CY39:DI39) -> 0 | DN39: =-[4]Feb!$P$1+[4]Feb!$AM$1 -> 0 | DO39: =-[5]Feb!$P$1+[5]Feb!$AM$1 -> 0 | DP39: =-[6]Feb!$P$1+[6]Feb!$AM$1 -> 0 | DQ39: =-[7]Feb!$N$1+[7]Feb!$AJ$1 -> 0 | DU39: =SUM(DJ39:DT39) -> 0 | DY39: =-[4]Mar!$P$1+[4]Mar!$AM$1 -> 0 | DZ39: =-[5]Mar!$P$1+[5]Mar!$AM$1 -> 0 | EA39: =-[6]Mar!$P$1+[6]Mar!$AM$1 -> 0 | EB39: =-[7]Mar!$N$1+[7]Mar!$AJ$1 -> 0 | EF39: =SUM(DU39:EE39) -> 0 | EJ39: =SUM(EF39:EH39) -> 0
B40: Creditor Long Term (falling due after 1 year) | C40: LCR | D40: =-OpenAccounts!E31 -> 0 | H40: =-[4]Apr!$M$1+[4]Apr!$AG$1 -> 0 | I40: =-[5]Apr!$M$1+[5]Apr!$AG$1 -> 0 | J40: =-[6]Apr!$M$1+[6]Apr!$AG$1 -> 0 | K40: =-[7]Apr!$M$1+[7]Apr!$AD$1 -> 0 | O40: =SUM(D40:N40) -> 0 | S40: =-[4]May!$M$1+[4]May!$AG$1 -> 0 | T40: =-[5]May!$M$1+[5]May!$AG$1 -> 0 | U40: =-[6]May!$M$1+[6]May!$AG$1 -> 0 | V40: =-[7]May!$M$1+[7]May!$AD$1 -> 0 | Z40: =SUM(O40:Y40) -> 0 | AD40: =-[4]Jun!$M$1+[4]Jun!$AG$1 -> 0 | AE40: =-[5]Jun!$M$1+[5]Jun!$AG$1 -> 0 | AF40: =-[6]Jun!$M$1+[6]Jun!$AG$1 -> 0 | AG40: =-[7]Jun!$M$1+[7]Jun!$AD$1 -> 0 | AK40: =SUM(Z40:AJ40) -> 0 | AO40: =-[4]Jul!$M$1+[4]Jul!$AG$1 -> 0 | AP40: =-[5]Jul!$M$1+[5]Jul!$AG$1 -> 0 | AQ40: =-[6]Jul!$M$1+[6]Jul!$AG$1 -> 0 | AR40: =-[7]Jul!$M$1+[7]Jul!$AD$1 -> 0 | AV40: =SUM(AK40:AU40) -> 0 | AZ40: =-[4]Aug!$M$1+[4]Aug!$AG$1 -> 0 | BA40: =-[5]Aug!$M$1+[5]Aug!$AG$1 -> 0 | BB40: =-[6]Aug!$M$1+[6]Aug!$AG$1 -> 0 | BC40: =-[7]Aug!$M$1+[7]Aug!$AD$1 -> 0 | BG40: =SUM(AV40:BF40) -> 0 | BK40: =-[4]Sep!$M$1+[4]Sep!$AG$1 -> 0 | BL40: =-[5]Sep!$M$1+[5]Sep!$AG$1 -> 0 | BM40: =-[6]Sep!$M$1+[6]Sep!$AG$1 -> 0 | BN40: =-[7]Sep!$M$1+[7]Sep!$AD$1 -> 0 | BR40: =SUM(BG40:BQ40) -> 0 | BV40: =-[4]Oct!$M$1+[4]Oct!$AG$1 -> 0 | BW40: =-[5]Oct!$M$1+[5]Oct!$AG$1 -> 0 | BX40: =-[6]Oct!$M$1+[6]Oct!$AG$1 -> 0 | BY40: =-[7]Oct!$M$1+[7]Oct!$AD$1 -> 0 | CC40: =SUM(BR40:CB40) -> 0 | CG40: =-[4]Nov!$M$1+[4]Nov!$AG$1 -> 0 | CH40: =-[5]Nov!$M$1+[5]Nov!$AG$1 -> 0 | CI40: =-[6]Nov!$M$1+[6]Nov!$AG$1 -> 0 | CJ40: =-[7]Nov!$M$1+[7]Nov!$AD$1 -> 0 | CN40: =SUM(CC40:CM40) -> 0 | CR40: =-[4]Dec!$M$1+[4]Dec!$AG$1 -> 0 | CS40: =-[5]Dec!$M$1+[5]Dec!$AG$1 -> 0 | CT40: =-[6]Dec!$M$1+[6]Dec!$AG$1 -> 0 | CU40: =-[7]Dec!$M$1+[7]Dec!$AD$1 -> 0 | CY40: =SUM(CN40:CX40) -> 0 | DC40: =-[4]Jan!$M$1+[4]Jan!$AG$1 -> 0 | DD40: =-[5]Jan!$M$1+[5]Jan!$AG$1 -> 0 | DE40: =-[6]Jan!$M$1+[6]Jan!$AG$1 -> 0 | DF40: =-[7]Jan!$M$1+[7]Jan!$AD$1 -> 0 | DJ40: =SUM(CY40:DI40) -> 0 | DN40: =-[4]Feb!$M$1+[4]Feb!$AG$1 -> 0 | DO40: =-[5]Feb!$M$1+[5]Feb!$AG$1 -> 0 | DP40: =-[6]Feb!$M$1+[6]Feb!$AG$1 -> 0 | DQ40: =-[7]Feb!$M$1+[7]Feb!$AD$1 -> 0 | DU40: =SUM(DJ40:DT40) -> 0 | DY40: =-[4]Mar!$M$1+[4]Mar!$AG$1 -> 0 | DZ40: =-[5]Mar!$M$1+[5]Mar!$AG$1 -> 0 | EA40: =-[6]Mar!$M$1+[6]Mar!$AG$1 -> 0 | EB40: =-[7]Mar!$M$1+[7]Mar!$AD$1 -> 0 | EF40: =SUM(DU40:EE40) -> 0 | EH40: =-[1]HPfinance!$E$2 -> 0 | EJ40: =SUM(EF40:EH40) -> 0
B41: CAPITAL & RESERVES
...

Sheet MnthP&L
A1: Monthly Management Accounts Profit and Loss Account | B1: Total Year to | C1: =Admin!B10 -> 45777 | D1: =Admin!B12 -> 45808 | E1: =Admin!B14 -> 45838 | F1: =Admin!B16 -> 45869 | G1: =Admin!B18 -> 45900 | H1: =Admin!B20 -> 45930 | I1: =Admin!B22 -> 45961 | J1: =Admin!B24 -> 45991 | K1: =Admin!B26 -> 46022 | L1: =Admin!B28 -> 46053 | M1: =Admin!B30 -> 46081 | N1: =Admin!B32 -> 46112
B2: =Admin!B32 -> 46112
B3: £ | C3: £ | D3: £ | E3: £ | F3: £ | G3: £ | H3: £ | I3: £ | J3: £ | K3: £ | L3: £ | M3: £ | N3: £
A4: Sales Product A | B4: =SUM(C4:N4) -> 0 | C4: =-TrialBalance!O53-0 -> 0 | D4: =-TrialBalance!Z53-C4 -> 0 | E4: =-TrialBalance!AK53-SUM(C4:D4) -> 0 | F4: =-TrialBalance!AV53-SUM(C4:E4) -> 0 | G4: =-TrialBalance!BG53-SUM(C4:F4) -> 0 | H4: =-TrialBalance!BR53-SUM(C4:G4) -> 0 | I4: =-TrialBalance!CC53-SUM(C4:H4) -> 0 | J4: =-TrialBalance!CN53-SUM(C4:I4) -> 0 | K4: =-TrialBalance!CY53-SUM(C4:J4) -> 0 | L4: =-TrialBalance!DJ53-SUM(C4:K4) -> 0 | M4: =-TrialBalance!DU53-SUM(C4:L4) -> 0 | N4: =-TrialBalance!EF53-SUM(C4:M4) -> 0
A5: Sales Product B | B5: =SUM(C5:N5) -> 0 | C5: =-TrialBalance!O54-0 -> 0 | D5: =-TrialBalance!Z54-C5 -> 0 | E5: =-TrialBalance!AK54-SUM(C5:D5) -> 0 | F5: =-TrialBalance!AV54-SUM(C5:E5) -> 0 | G5: =-TrialBalance!BG54-SUM(C5:F5) -> 0 | H5: =-TrialBalance!BR54-SUM(C5:G5) -> 0 | I5: =-TrialBalance!CC54-SUM(C5:H5) -> 0 | J5: =-TrialBalance!CN54-SUM(C5:I5) -> 0 | K5: =-TrialBalance!CY54-SUM(C5:J5) -> 0 | L5: =-TrialBalance!DJ54-SUM(C5:K5) -> 0 | M5: =-TrialBalance!DU54-SUM(C5:L5) -> 0 | N5: =-TrialBalance!EF54-SUM(C5:M5) -> 0
A6: Sales Product C | B6: =SUM(C6:N6) -> 0 | C6: =-TrialBalance!O55-0 -> 0 | D6: =-TrialBalance!Z55-C6 -> 0 | E6: =-TrialBalance!AK55-SUM(C6:D6) -> 0 | F6: =-TrialBalance!AV55-SUM(C6:E6) -> 0 | G6: =-TrialBalance!BG55-SUM(C6:F6) -> 0 | H6: =-TrialBalance!BR55-SUM(C6:G6) -> 0 | I6: =-TrialBalance!CC55-SUM(C6:H6) -> 0 | J6: =-TrialBalance!CN55-SUM(C6:I6) -> 0 | K6: =-TrialBalance!CY55-SUM(C6:J6) -> 0 | L6: =-TrialBalance!DJ55-SUM(C6:K6) -> 0 | M6: =-TrialBalance!DU55-SUM(C6:L6) -> 0 | N6: =-TrialBalance!EF55-SUM(C6:M6) -> 0
A7: Other Income | B7: =SUM(C7:N7) -> 0 | C7: =-TrialBalance!O56 -> 0 | D7: =-TrialBalance!Z56-C7 -> 0 | E7: =-TrialBalance!AK56-SUM(C7:D7) -> 0 | F7: =-TrialBalance!AV56-SUM(C7:E7) -> 0 | G7: =-TrialBalance!BG56-SUM(C7:F7) -> 0 | H7: =-TrialBalance!BR56-SUM(C7:G7) -> 0 | I7: =-TrialBalance!CC56-SUM(C7:H7) -> 0 | J7: =-TrialBalance!CN56-SUM(C7:I7) -> 0 | K7: =-TrialBalance!CY56-SUM(C7:J7) -> 0 | L7: =-TrialBalance!DJ56-SUM(C7:K7) -> 0 | M7: =-TrialBalance!DU56-SUM(C7:L7) -> 0 | N7: =-TrialBalance!EF56-SUM(C7:M7) -> 0
A8: Investment Grants received | B8: =SUM(C8:N8) -> 0 | C8: =-TrialBalance!O57 -> 0 | D8: =-TrialBalance!Z57-C8 -> 0 | E8: =-TrialBalance!AK57-SUM(C8:D8) -> 0 | F8: =-TrialBalance!AV57-SUM(C8:E8) -> 0 | G8: =-TrialBalance!BG57-SUM(C8:F8) -> 0 | H8: =-TrialBalance!BR57-SUM(C8:G8) -> 0 | I8: =-TrialBalance!CC57-SUM(C8:H8) -> 0 | J8: =-TrialBalance!CN57-SUM(C8:I8) -> 0 | K8: =-TrialBalance!CY57-SUM(C8:J8) -> 0 | L8: =-TrialBalance!DJ57-SUM(C8:K8) -> 0 | M8: =-TrialBalance!DU57-SUM(C8:L8) -> 0 | N8: =-TrialBalance!EF57-SUM(C8:M8) -> 0
A9: Sales Turnover | B9: =SUM(B4:B8) -> 0 | C9: =SUM(C4:C8) -> 0 | D9: =SUM(D4:D8) -> 0 | E9: =SUM(E4:E8) -> 0 | F9: =SUM(F4:F8) -> 0 | G9: =SUM(G4:G8) -> 0 | H9: =SUM(H4:H8) -> 0 | I9: =SUM(I4:I8) -> 0 | ... N9: =SUM(N4:N8) -> 0
A10: Cost of Sales
A11: Purchases | B11: =SUM(C11:N11) -> 0 | C11: =TrialBalance!O60-0 -> 0 | D11: =TrialBalance!Z60-C11 -> 0 | E11: =TrialBalance!AK60-SUM(C11:D11) -> 0 | F11: =TrialBalance!AV60-SUM(C11:E11) -> 0 | G11: =TrialBalance!BG60-SUM(C11:F11) -> 0 | H11: =TrialBalance!BR60-SUM(C11:G11) -> 0 | I11: =TrialBalance!CC60-SUM(C11:H11) -> 0 | J11: =TrialBalance!CN60-SUM(C11:I11) -> 0 | K11: =TrialBalance!CY60-SUM(C11:J11) -> 0 | L11: =TrialBalance!DJ60-SUM(C11:K11) -> 0 | M11: =TrialBalance!DU60-SUM(C11:L11) -> 0 | N11: =TrialBalance!EF60-SUM(C11:M11) -> 0
A12: Sub contractors | B12: =SUM(C12:N12) -> 0 | C12: =TrialBalance!O61-0 -> 0 | D12: =TrialBalance!Z61-C12 -> 0 | E12: =TrialBalance!AK61-SUM(C12:D12) -> 0 | F12: =TrialBalance!AV61-SUM(C12:E12) -> 0 | G12: =TrialBalance!BG61-SUM(C12:F12) -> 0 | H12: =TrialBalance!BR61-SUM(C12:G12) -> 0 | I12: =TrialBalance!CC61-SUM(C12:H12) -> 0 | J12: =TrialBalance!CN61-SUM(C12:I12) -> 0 | K12: =TrialBalance!CY61-SUM(C12:J12) -> 0 | L12: =TrialBalance!DJ61-SUM(C12:K12) -> 0 | M12: =TrialBalance!DU61-SUM(C12:L12) -> 0 | N12: =TrialBalance!EF61-SUM(C12:M12) -> 0
A13: Other Direct Cost of Sales | B13: =SUM(C13:N13) -> 0 | C13: =TrialBalance!O62-0 -> 0 | D13: =TrialBalance!Z62-C13 -> 0 | E13: =TrialBalance!AK62-SUM(C13:D13) -> 0 | F13: =TrialBalance!AV62-SUM(C13:E13) -> 0 | G13: =TrialBalance!BG62-SUM(C13:F13) -> 0 | H13: =TrialBalance!BR62-SUM(C13:G13) -> 0 | I13: =TrialBalance!CC62-SUM(C13:H13) -> 0 | J13: =TrialBalance!CN62-SUM(C13:I13) -> 0 | K13: =TrialBalance!CY62-SUM(C13:J13) -> 0 | L13: =TrialBalance!DJ62-SUM(C13:K13) -> 0 | M13: =TrialBalance!DU62-SUM(C13:L13) -> 0 | N13: =TrialBalance!EF62-SUM(C13:M13) -> 0
A14: Cost of Sales | B14: =SUM(B11:B13) -> 0 | C14: =SUM(C11:C13) -> 0 | D14: =SUM(D11:D13) -> 0 | E14: =SUM(E11:E13) -> 0 | F14: =SUM(F11:F13) -> 0 | G14: =SUM(G11:G13) -> 0 | H14: =SUM(H11:H13) -> 0 | I14: =SUM(I11:I13) -> 0 | ... N14: =SUM(N11:N13) -> 0
A16: Gross Profit | B16: =B9-B14 -> 0 | C16: =C9-C14 -> 0 | D16: =D9-D14 -> 0 | E16: =E9-E14 -> 0 | F16: =F9-F14 -> 0 | G16: =G9-G14 -> 0 | H16: =H9-H14 -> 0 | I16: =I9-I14 -> 0 | ... N16: =N9-N14 -> 0
A17: Administrative Expenses
A18: Wages and Salaries | B18: =SUM(C18:N18) -> 0 | C18: =TrialBalance!O64+TrialBalance!O65-0 -> 0 | D18: =TrialBalance!Z64+TrialBalance!Z65-C18 -> 0 | E18: =TrialBalance!AK64+TrialBalance!AK65-SUM(C18:D18) -> 0 | F18: =TrialBalance!AV64+TrialBalance!AV65-SUM(C18:E18) -> 0 | G18: =TrialBalance!BG64+TrialBalance!BG65-SUM(C18:F18) -> 0 | H18: =TrialBalance!BR64+TrialBalance!BR65-SUM(C18:G18) -> 0 | I18: =TrialBalance!CC64+TrialBalance!CC65-SUM(C18:H18) -> 0 | J18: =TrialBalance!CN64+TrialBalance!CN65-SUM(C18:I18) -> 0 | K18: =TrialBalance!CY64+TrialBalance!CY65-SUM(C18:J18) -> 0 | L18: =TrialBalance!DJ64+TrialBalance!DJ65-SUM(C18:K18) -> 0 | M18: =TrialBalance!DU64+TrialBalance!DU65-SUM(C18:L18) -> 0 | N18: =TrialBalance!EF64+TrialBalance!EF65-SUM(C18:M18) -> 0
